Workbook

Sheet 요약
A1: CENTRAL MARITIME vs 네오맥스 견적 비교
A2: 노란 칸(환율·할인율)만 바꾸면 모든 시트가 자동 재계산됩니다. CENTRAL 출처: 견적서 JU26092325-A~F (2026-09-29) / 네오맥스 출처: SSL INTERNATIONAL → NEO-MAX 인보이스 5건
A4: 적용 환율 (KRW/USD) | C4: 1350 | D4: ← 사용자 지정 환율
A5: CENTRAL 할인율 (D/C) | C5: 0.1 | D5: ← CENTRAL 견적서 5건 모두 10% 할인 적용
A7: ① 직접 비교 가능한 건: 프린터 카트리지 & 용지 (NORTH VALLEY) — 동일 요청서
A8: 구분 | C8: CENTRAL (원화, 할인후) | D8: 네오맥스 (원화) | E8: 차액 (네오 − CENTRAL) | F8: 차이율 | G8: 더 저렴한 곳
A9: 공통 품목 37개 (같은 품목끼리) | C9: =프린터_상세비교!I55 -> 4051910 | D9: =프린터_상세비교!K55 -> 4918490 | E9: =D9-C9 -> 866580 | F9: =IF(C9=0,"",D9/C9-1) -> 0.21386951 | G9: =IF(E9>0,"CENTRAL",IF(E9<0,"네오맥스","동일")) -> CENTRAL
A10: 공통 품목 — 네오맥스 TEPRA 오기 정정 시 | C10: =프린터_상세비교!I56 -> 4051910 | D10: =프린터_상세비교!K56 -> 4549440 | E10: =D10-C10 -> 497530 | F10: =IF(C10=0,"",D10/C10-1) -> 0.12278901 | G10: =IF(E10>0,"CENTRAL",IF(E10<0,"네오맥스","동일")) -> CENTRAL
A11: 각 업체 견적 전체 (한쪽만 있는 품목·배송비 포함) | C11: =프린터_상세비교!I58 -> 4406592 | D11: =프린터_상세비교!K58 -> 6052610 | E11: =D11-C11 -> 1646018 | F11: =IF(C11=0,"",D11/C11-1) -> 0.37353538 | G11: =IF(E11>0,"CENTRAL",IF(E11<0,"네오맥스","동일")) -> CENTRAL
A12: ="공통 품목 중 CENTRAL이 저렴한 품목 "&프린터_상세비교!I60&"개 / 네오맥스가 저렴한 품목 "&프린터_상세비교!K60&"개" -> 공통 품목 중 CENTRAL이 저렴한 품목 36개 / 네오맥스가 저렴한 품목 1개
A13: ※ 단가 구조 참고: 대부분 품목에서 네오맥스 단가 = CENTRAL USD 정가 × 약 1,368원입니다(예: TONER 88 B 77.85 USD ↔ 106,480원). 결국 차이는 CENTRAL의 10% 할인과 적용 환율 차이에서 나옵니다.
A15: ② 요청서별 견적 현황 — 나머지 건은 한 업체만 견적 (같은 요청서 아님)
A16: 요청서 | B16: 대상 선박 | C16: CENTRAL Ref | D16: CENTRAL 정가 (USD) | E16: CENTRAL 할인후 (USD) | F16: CENTRAL 할인후 (원화) | G16: 네오맥스 Ref | H16: 네오맥스 (원화) | I16: 비교 가능 여부
A17: PRINTER CARTRIDGES & PAPER ROLLS | B17: NORTH VALLEY | C17: JU26092325-F | D17: 3626.82 | E17: =ROUND(D17*(1-요약!$C$5),2) -> 3264.14 | F17: =ROUND(E17*요약!$C$4,0) -> 4406589 | G17: SSL-26092215 | H17: 6052610 | I17: ✔ 동일 요청서 → [프린터_상세비교]
A18: ER ELECTRICAL | B18: LNG 운반선 4척 | C18: JU26092325-A | D18: 13972.82 | E18: =ROUND(D18*(1-요약!$C$5),2) -> 12575.54 | F18: =ROUND(E18*요약!$C$4,0) -> 16976979 | G18: — | I18: ✖ CENTRAL만 견적
A19: ER STORES | B19: LNG 운반선 4척 | C19: JU26092325-C | D19: 4425.72 | E19: =ROUND(D19*(1-요약!$C$5),2) -> 3983.15 | F19: =ROUND(E19*요약!$C$4,0) -> 5377253 | G19: — | I19: ✖ CENTRAL만 (유사품목 단가 참고 → [유사품목_단가참고])
A20: GALLEY APPLIANCES | B20: NORTH VALLEY | C20: JU26092325-D | D20: 3524.31 | E20: =ROUND(D20*(1-요약!$C$5),2) -> 3171.88 | F20: =ROUND(E20*요약!$C$4,0) -> 4282038 | G20: — | I20: ✖ CENTRAL만 견적
A21: GALLEY CONSUMABLES | B21: NORTH VALLEY | C21: JU26092325-E | D21: 12854.27 | E21: =ROUND(D21*(1-요약!$C$5),2) -> 11568.84 | F21: =ROUND(E21*요약!$C$4,0) -> 15617934 | G21: — | I21: ✖ CENTRAL만 견적
A22: PAINT (ORANGE RAL2004) | B22: NORTH VALLEY | C22: — | G22: SSL-26092825 | H22: 885500 | I22: ✖ 네오맥스만 견적
A23: ENGINE CONSUMABLES | B23: NORTH VALLEY | C23: — | G23: SSL-26092824 | H23: 12514360 | I23: ✖ 네오맥스만 견적
A24: TOOLS, FITTINGS & MAINTENANCE | B24: NORTH VALLEY | C24: — | G24: SSL-26092823 | H24: 7903740 | I24: ✖ 네오맥스만 견적
A25: STATIONERY | B25: NORTH VALLEY | C25: — | G25: SSL-26092822 | H25: 3112780 | I25: ✖ 네오맥스만 견적
A26: 합계 (참고용 — 품목 구성이 달라 업체 간 직접 비교 불가) | D26: =SUM(D17:D25) -> 38403.94 | E26: =SUM(E17:E25) -> 34563.55 | F26: =SUM(F17:F25) -> 46660793 | H26: =SUM(H17:H25) -> 30468990
A27: ※ 파란 글씨 = 견적서/인보이스 원본 금액(하드코딩). CENTRAL 할인후 금액 = 정가 × (1 − 할인율), 원화 = 할인후 USD × 환율. 네오맥스 금액은 인보이스 TOTAL 그대로(배송비 포함).
A29: ③ 확인 필요 사항
A30: 1. 네오맥스 파일은 견적서가 아니라 SSL INTERNATIONAL → NEO-MAX 앞 인보이스(청구서)입니다. 프린터 건은 PO No. 260922-1540이 이미 기재되어 있습니다(발주 완료 건일 수 있음).
A31: 2. 프린터 건 외 4개 요청서는 CENTRAL 견적에 없는 품목입니다. 반대로 CENTRAL의 ER ELECTRICAL / ER STORES / GALLEY 2건은 네오맥스 견적이 없습니다 → 공정 비교를 위해 서로 빠진 요청서 견적을 추가로 받아야 합니다.
A32: 3. [네오맥스 단가 오기] 프린터 #42 TEPRA 9MM RED 단가 82,280원 — 같은 규격 다른 색상은 8,470원. 0이 하나 더 붙은 것으로 보이며 5개 기준 369,050원 과다 청구.
A33: 4. [네오맥스 산식 오류] ENGINE CONSUMABLES #6·#7·#29, STATIONERY #13·#14·#17 은 수량×단가 ≠ 금액. STATIONERY TOTAL은 수량×단가 기준으로 맞고 행 금액만 틀림, ENGINE CONSUMABLES TOTAL은 행 합계와 40원 차이 → [네오맥스_단독견적] 시트 빨간 행 참고.
A34: 5. [CENTRAL 미견적] 프린터 #18·#19 SMART TONER B/Y — 모델 정보 요청하며 단가 공란. 네오맥스도 해당 품목 없음.
A35: 6. [품목 상이] LEXMARK: CENTRAL은 78C0Z50(이미징 키트) 2개, 네오맥스는 78C20 토너 4색 각 1개 — 요청서 원본과 대조 필요.
A36: 7. 네오맥스 인보이스에 배송비 200,000원 별도 포함. CENTRAL 견적은 배송비 언급 없음 → 납품 조건 확인 필요.

Sheet 프린터_상세비교
A1: 프린터 카트리지 & 용지 — 품목별 단가 비교 (NORTH VALLEY)
A2: CENTRAL JU26092325-F vs 네오맥스(SSL) SSL-26092215 | CENTRAL 원화단가 = USD 단가 × 환율 × (1 − 할인율) | 초록 = 더 저렴한 쪽
A4: 구분 | B4: 요청서 No. (네오 기준) | C4: CENTRAL No. | D4: 품목 | E4: 수량 | F4: 단위 | G4: CENTRAL 단가 (USD) | H4: CENTRAL 단가 (원, 할인후) | I4: CENTRAL 금액 (원) | J4: 네오맥스 단가 (원) | K4: 네오맥스 금액 (원) | L4: 차액 (네오 − CENTRAL) | M4: 차이율 | N4: 저렴한 곳 | O4: 비고
A5: 공통 | B5: 1 | C5: 1 | D5: TONER 88 B | E5: 1 | F5: PCS | G5: 77.85 | H5: =ROUND(G5*요약!$C$4*(1-요약!$C$5),0) -> 94588 | I5: =E5*H5 -> 94588 | J5: 106480 | K5: =E5*J5 -> 106480 | L5: =K5-I5 -> 11892 | M5: =IF(I5=0,"",K5/I5-1) -> 0.12572419 | N5: =IF(L5>0,"CENTRAL",IF(L5<0,"네오맥스","동일")) -> CENTRAL
A6: 공통 | B6: 2 | C6: 2 | D6: TONER 88 Y | E6: 1 | F6: PCS | G6: 129.15 | H6: =ROUND(G6*요약!$C$4*(1-요약!$C$5),0) -> 156917 | I6: =E6*H6 -> 156917 | J6: 176660 | K6: =E6*J6 -> 176660 | L6: =K6-I6 -> 19743 | M6: =IF(I6=0,"",K6/I6-1) -> 0.12581811 | N6: =IF(L6>0,"CENTRAL",IF(L6<0,"네오맥스","동일")) -> CENTRAL
A7: 공통 | B7: 3 | C7: 3 | D7: TONER 88 M | E7: 1 | F7: PCS | G7: 129.15 | H7: =ROUND(G7*요약!$C$4*(1-요약!$C$5),0) -> 156917 | I7: =E7*H7 -> 156917 | J7: 176660 | K7: =E7*J7 -> 176660 | L7: =K7-I7 -> 19743 | M7: =IF(I7=0,"",K7/I7-1) -> 0.12581811 | N7: =IF(L7>0,"CENTRAL",IF(L7<0,"네오맥스","동일")) -> CENTRAL
A8: 공통 | B8: 4 | C8: 4 | D8: TONER 88 C | E8: 1 | F8: PCS | G8: 129.15 | H8: =ROUND(G8*요약!$C$4*(1-요약!$C$5),0) -> 156917 | I8: =E8*H8 -> 156917 | J8: 176660 | K8: =E8*J8 -> 176660 | L8: =K8-I8 -> 19743 | M8: =IF(I8=0,"",K8/I8-1) -> 0.12581811 | N8: =IF(L8>0,"CENTRAL",IF(L8<0,"네오맥스","동일")) -> CENTRAL
A9: 공통 | B9: 5 | C9: 5 | D9: LIQUID EPSON 008 B | E9: 5 | F9: PCS | G9: 21.23 | H9: =ROUND(G9*요약!$C$4*(1-요약!$C$5),0) -> 25794 | I9: =E9*H9 -> 128970 | J9: 29040 | K9: =E9*J9 -> 145200 | L9: =K9-I9 -> 16230 | M9: =IF(I9=0,"",K9/I9-1) -> 0.12584322 | N9: =IF(L9>0,"CENTRAL",IF(L9<0,"네오맥스","동일")) -> CENTRAL
A10: 공통 | B10: 6 | C10: 6 | D10: LIQUID EPSON 008 C | E10: 3 | F10: PCS | G10: 12.38 | H10: =ROUND(G10*요약!$C$4*(1-요약!$C$5),0) -> 15042 | I10: =E10*H10 -> 45126 | J10: 16940 | K10: =E10*J10 -> 50820 | L10: =K10-I10 -> 5694 | M10: =IF(I10=0,"",K10/I10-1) -> 0.12618003 | N10: =IF(L10>0,"CENTRAL",IF(L10<0,"네오맥스","동일")) -> CENTRAL
A11: 공통 | B11: 7 | C11: 7 | D11: LIQUID EPSON 008 Y | E11: 4 | F11: PCS | G11: 12.38 | H11: =ROUND(G11*요약!$C$4*(1-요약!$C$5),0) -> 15042 | I11: =E11*H11 -> 60168 | J11: 16940 | K11: =E11*J11 -> 67760 | L11: =K11-I11 -> 7592 | M11: =IF(I11=0,"",K11/I11-1) -> 0.12618003 | N11: =IF(L11>0,"CENTRAL",IF(L11<0,"네오맥스","동일")) -> CENTRAL
A12: 공통 | B12: 8 | C12: 8 | D12: LIQUID EPSON 008 M | E12: 3 | F12: PCS | G12: 12.38 | H12: =ROUND(G12*요약!$C$4*(1-요약!$C$5),0) -> 15042 | I12: =E12*H12 -> 45126 | J12: 16940 | K12: =E12*J12 -> 50820 | L12: =K12-I12 -> 5694 | M12: =IF(I12=0,"",K12/I12-1) -> 0.12618003 | N12: =IF(L12>0,"CENTRAL",IF(L12<0,"네오맥스","동일")) -> CENTRAL
A13: 공통 | B13: 9 | C13: 9 | D13: LCL MAINTENANCE BOX | E13: 2 | F13: PCS | G13: 15.92 | H13: =ROUND(G13*요약!$C$4*(1-요약!$C$5),0) -> 19343 | I13: =E13*H13 -> 38686 | J13: 21780 | K13: =E13*J13 -> 43560 | L13: =K13-I13 -> 4874 | M13: =IF(I13=0,"",K13/I13-1) -> 0.12598873 | N13: =IF(L13>0,"CENTRAL",IF(L13<0,"네오맥스","동일")) -> CENTRAL
A14: 공통 | B14: 10 | C14: 10 | D14: HP 215 A M | E14: 3 | F14: PCS | G14: 78.73 | H14: =ROUND(G14*요약!$C$4*(1-요약!$C$5),0) -> 95657 | I14: =E14*H14 -> 286971 | J14: 100430 | K14: =E14*J14 -> 301290 | L14: =K14-I14 -> 14319 | M14: =IF(I14=0,"",K14/I14-1) -> 0.049897028 | N14: =IF(L14>0,"CENTRAL",IF(L14<0,"네오맥스","동일")) -> CENTRAL | O14: HP 215A: 네오맥스는 M만 저가, CENTRAL은 B만 저가
A15: 공통 | B15: 11 | C15: 11 | D15: HP 215 A Y | E15: 2 | F15: PCS | G15: 78.73 | H15: =ROUND(G15*요약!$C$4*(1-요약!$C$5),0) -> 95657 | I15: =E15*H15 -> 191314 | J15: 107690 | K15: =E15*J15 -> 215380 | L15: =K15-I15 -> 24066 | M15: =IF(I15=0,"",K15/I15-1) -> 0.1257932 | N15: =IF(L15>0,"CENTRAL",IF(L15<0,"네오맥스","동일")) -> CENTRAL
A16: 공통 | B16: 12 | C16: 12 | D16: HP 215 A C | E16: 5 | F16: PCS | G16: 78.73 | H16: =ROUND(G16*요약!$C$4*(1-요약!$C$5),0) -> 95657 | I16: =E16*H16 -> 478285 | J16: 107690 | K16: =E16*J16 -> 538450 | L16: =K16-I16 -> 60165 | M16: =IF(I16=0,"",K16/I16-1) -> 0.1257932 | N16: =IF(L16>0,"CENTRAL",IF(L16<0,"네오맥스","동일")) -> CENTRAL
A17: 공통 | B17: 13 | C17: 13 | D17: HP 215 A B | E17: 6 | F17: PCS | G17: 73.42 | H17: =ROUND(G17*요약!$C$4*(1-요약!$C$5),0) -> 89205 | I17: =E17*H17 -> 535230 | J17: 107690 | K17: =E17*J17 -> 646140 | L17: =K17-I17 -> 110910 | M17: =IF(I17=0,"",K17/I17-1) -> 0.20721933 | N17: =IF(L17>0,"CENTRAL",IF(L17<0,"네오맥스","동일")) -> CENTRAL
A18: 공통 | B18: 14 | C18: 14 | D18: INK JET CARTRIDGE HP954XL B | E18: 2 | F18: PCS | G18: 30.96 | H18: =ROUND(G18*요약!$C$4*(1-요약!$C$5),0) -> 37616 | I18: =E18*H18 -> 75232 | J18: 42350 | K18: =E18*J18 -> 84700 | L18: =K18-I18 -> 9468 | M18: =IF(I18=0,"",K18/I18-1) -> 0.1258507 | N18: =IF(L18>0,"CENTRAL",IF(L18<0,"네오맥스","동일")) -> CENTRAL
A19: 공통 | B19: 15 | C19: 15 | D19: INK JET CARTRIDGE HP954XL C | E19: 2 | F19: PCS | G19: 33.62 | H19: =ROUND(G19*요약!$C$4*(1-요약!$C$5),0) -> 40848 | I19: =E19*H19 -> 81696 | J19: 45980 | K19: =E19*J19 -> 91960 | L19: =K19-I19 -> 10264 | M19: =IF(I19=0,"",K19/I19-1) -> 0.12563651 | N19: =IF(L19>0,"CENTRAL",IF(L19<0,"네오맥스","동일")) -> CENTRAL
A20: 공통 | B20: 16 | C20: 16 | D20: INK JET CARTRIDGE HP954XL Y | E20: 2 | F20: PCS | G20: 33.62 | H20: =ROUND(G20*요약!$C$4*(1-요약!$C$5),0) -> 40848 | I20: =E20*H20 -> 81696 | J20: 45980 | K20: =E20*J20 -> 91960 | L20: =K20-I20 -> 10264 | M20: =IF(I20=0,"",K20/I20-1) -> 0.12563651 | N20: =IF(L20>0,"CENTRAL",IF(L20<0,"네오맥스","동일")) -> CENTRAL
A21: 공통 | B21: 17 | C21: 17 | D21: INK JET CARTRIDGE HP954XL M | E21: 2 | F21: PCS | G21: 33.62 | H21: =ROUND(G21*요약!$C$4*(1-요약!$C$5),0) -> 40848 | I21: =E21*H21 -> 81696 | J21: 45980 | K21: =E21*J21 -> 91960 | L21: =K21-I21 -> 10264 | M21: =IF(I21=0,"",K21/I21-1) -> 0.12563651 | N21: =IF(L21>0,"CENTRAL",IF(L21<0,"네오맥스","동일")) -> CENTRAL
A22: 공통 | B22: 22 | C22: 20 | D22: EPSON 9MM X 9M SC9R-PX BLACK ON RED | E22: 2 | F22: PCS | G22: 6.19 | H22: =ROUND(G22*요약!$C$4*(1-요약!$C$5),0) -> 7521 | I22: =E22*H22 -> 15042 | J22: 8470 | K22: =E22*J22 -> 16940 | L22: =K22-I22 -> 1898 | M22: =IF(I22=0,"",K22/I22-1) -> 0.12618003 | N22: =IF(L22>0,"CENTRAL",IF(L22<0,"네오맥스","동일")) -> CENTRAL
A23: 공통 | B23: 23 | C23: 21 | D23: EPSON 24MM X 9M SC24Y BLACK ON YELLOW | E23: 2 | F23: PCS | G23: 7.96 | H23: =ROUND(G23*요약!$C$4*(1-요약!$C$5),0) -> 9671 | I23: =E23*H23 -> 19342 | J23: 10890 | K23: =E23*J23 -> 21780 | L23: =K23-I23 -> 2438 | M23: =IF(I23=0,"",K23/I23-1) -> 0.12604694 | N23: =IF(L23>0,"CENTRAL",IF(L23<0,"네오맥스","동일")) -> CENTRAL
A24: 공통 | B24: 25 | C24: 22 | D24: EPSON 24MM X 9M SC24G-PX BLACK ON GREEN | E24: 1 | F24: PCS | G24: 7.96 | H24: =ROUND(G24*요약!$C$4*(1-요약!$C$5),0) -> 9671 | I24: =E24*H24 -> 9671 | J24: 10890 | K24: =E24*J24 -> 10890 | L24: =K24-I24 -> 1219 | M24: =IF(I24=0,"",K24/I24-1) -> 0.12604694 | N24: =IF(L24>0,"CENTRAL",IF(L24<0,"네오맥스","동일")) -> CENTRAL
A25: 공통 | B25: 26 | C25: 23 | D25: EPSON 9MM X 9M SC9G-PX BLACK ON GREEN | E25: 2 | F25: PCS | G25: 6.19 | H25: =ROUND(G25*요약!$C$4*(1-요약!$C$5),0) -> 7521 | I25: =E25*H25 -> 15042 | J25: 8470 | K25: =E25*J25 -> 16940 | L25: =K25-I25 -> 1898 | M25: =IF(I25=0,"",K25/I25-1) -> 0.12618003 | N25: =IF(L25>0,"CENTRAL",IF(L25<0,"네오맥스","동일")) -> CENTRAL
A26: 공통 | B26: 27 | C26: 24 | D26: EPSON 12MM X 9M SC12B-PX BLACK ON BLUE | E26: 2 | F26: PCS | G26: 6.19 | H26: =ROUND(G26*요약!$C$4*(1-요약!$C$5),0) -> 7521 | I26: =E26*H26 -> 15042 | J26: 8470 | K26: =E26*J26 -> 16940 | L26: =K26-I26 -> 1898 | M26: =IF(I26=0,"",K26/I26-1) -> 0.12618003 | N26: =IF(L26>0,"CENTRAL",IF(L26<0,"네오맥스","동일")) -> CENTRAL
... A32: 공통 | B32: 40 | C32: 31 | D32: RIBBON CARTRIDGE HANAROTEC JP3800 JP 3750 DL3800 JP 4850 M 3388 | E32: 4 | F32: PCS | G32: 10.62 | H32: =ROUND(G32*요약!$C$4*(1-요약!$C$5),0) -> 12903 | I32: =E32*H32 -> 51612 | J32: 6050 | K32: =E32*J32 -> 24200 | L32: =K32-I32 -> -27412 | M32: =IF(I32=0,"",K32/I32-1) -> -0.53111679 | N32: =IF(L32>0,"CENTRAL",IF(L32<0,"네오맥스","동일")) -> 네오맥스
A33: 공통 | B33: 42 | C33: 32 | D33: TAPE CARTRIDGE FOR"TEPRA" TAPE, WRITER 9MM RED W/BLACK LTR | E33: 5 | F33: PCS | G33: 6.19 | H33: =ROUND(G33*요약!$C$4*(1-요약!$C$5),0) -> 7521 | I33: =E33*H33 -> 37605 | J33: 82280 | K33: =E33*J33 -> 411400 | L33: =K33-I33 -> 373795 | M33: =IF(I33=0,"",K33/I33-1) -> 9.9400346 | N33: =IF(L33>0,"CENTRAL",IF(L33<0,"네오맥스","동일")) -> CENTRAL | O33: ⚠ 단가 오기 의심: 동일 규격 타 색상 8,470원 (0 하나 더 붙음)
A34: 공통 | B34: 43 | C34: 33 | D34: TAPE CARTRIDGE FOR"TEPRA" TAPE, WRITER 9MM YELLOW W/BLACK LTR | E34: 5 | F34: PCS | G34: 6.19 | H34: =ROUND(G34*요약!$C$4*(1-요약!$C$5),0) -> 7521 | I34: =E34*H34 -> 37605 | J34: 8470 | K34: =E34*J34 -> 42350 | L34: =K34-I34 -> 4745 | M34: =IF(I34=0,"",K34/I34-1) -> 0.12618003 | N34: =IF(L34>0,"CENTRAL",IF(L34<0,"네오맥스","동일")) -> CENTRAL
A35: 공통 | B35: 44 | C35: 34 | D35: TAPE FOR TEPRA-PRO TAPE WRITER, W:9MM WHITE WITH BLACK LETTER | E35: 5 | F35: PCS | G35: 6.19 | H35: =ROUND(G35*요약!$C$4*(1-요약!$C$5),0) -> 7521 | I35: =E35*H35 -> 37605 | J35: 8470 | K35: =E35*J35 -> 42350 | L35: =K35-I35 -> 4745 | M35: =IF(I35=0,"",K35/I35-1) -> 0.12618003 | N35: =IF(L35>0,"CENTRAL",IF(L35<0,"네오맥스","동일")) -> CENTRAL
A36: 공통 | B36: 45 | C36: 35 | D36: TAPE CARTRIDGE FOR"TEPRA" TAPE, WRITER 12MM RED W/BLACK LTR | E36: 5 | F36: PCS | G36: 6.19 | H36: =ROUND(G36*요약!$C$4*(1-요약!$C$5),0) -> 7521 | I36: =E36*H36 -> 37605 | J36: 8470 | K36: =E36*J36 -> 42350 | L36: =K36-I36 -> 4745 | M36: =IF(I36=0,"",K36/I36-1) -> 0.12618003 | N36: =IF(L36>0,"CENTRAL",IF(L36<0,"네오맥스","동일")) -> CENTRAL
A37: 공통 | B37: 46 | C37: 36 | D37: TAPE CARTRIDGE FOR"TEPRA" TAPE, WRITER 12MM YELLOW W/BLACK LTR | E37: 5 | F37: PCS | G37: 6.19 | H37: =ROUND(G37*요약!$C$4*(1-요약!$C$5),0) -> 7521 | I37: =E37*H37 -> 37605 | J37: 8470 | K37: =E37*J37 -> 42350 | L37: =K37-I37 -> 4745 | M37: =IF(I37=0,"",K37/I37-1) -> 0.12618003 | N37: =IF(L37>0,"CENTRAL",IF(L37<0,"네오맥스","동일")) -> CENTRAL
A38: 공통 | B38: 47 | C38: 37 | D38: TAPE FOR TEPRA-PRO TAPE WRITER, W:12MM WHITE WITH BLACK LETTER | E38: 5 | F38: PCS | G38: 6.19 | H38: =ROUND(G38*요약!$C$4*(1-요약!$C$5),0) -> 7521 | I38: =E38*H38 -> 37605 | J38: 8470 | K38: =E38*J38 -> 42350 | L38: =K38-I38 -> 4745 | M38: =IF(I38=0,"",K38/I38-1) -> 0.12618003 | N38: =IF(L38>0,"CENTRAL",IF(L38<0,"네오맥스","동일")) -> CENTRAL
A39: 공통 | B39: 48 | C39: 38 | D39: INMARSAT-C & NBDP PRINTER PAPER ROLL (FURUNO PP-520) | E39: 10 | F39: PCS | G39: 4.07 | H39: =ROUND(G39*요약!$C$4*(1-요약!$C$5),0) -> 4945 | I39: =E39*H39 -> 49450 | J39: 5560 | K39: =E39*J39 -> 55600 | L39: =K39-I39 -> 6150 | M39: =IF(I39=0,"",K39/I39-1) -> 0.12436805 | N39: =IF(L39>0,"CENTRAL",IF(L39<0,"네오맥스","동일")) -> CENTRAL
A40: 공통 | B40: 49 | C40: 39 | D40: GPS PRINTER (FURUNO PP-505) | E40: 5 | F40: PCS | G40: 1.24 | H40: =ROUND(G40*요약!$C$4*(1-요약!$C$5),0) -> 1507 | I40: =E40*H40 -> 7535 | J40: 1690 | K40: =E40*J40 -> 8450 | L40: =K40-I40 -> 915 | M40: =IF(I40=0,"",K40/I40-1) -> 0.12143331 | N40: =IF(L40>0,"CENTRAL",IF(L40<0,"네오맥스","동일")) -> CENTRAL
A41: 공통 | B41: 50 | C41: 40 | D41: NAVTEX (FURUNO NX-700) & ECHO SOUNDER PRINTER (FURUNO FE-800) | E41: 10 | F41: PCS | G41: 0.71 | H41: =ROUND(G41*요약!$C$4*(1-요약!$C$5),0) -> 863 | I41: =E41*H41 -> 8630 | J41: 960 | K41: =E41*J41 -> 9600 | L41: =K41-I41 -> 970 | M41: =IF(I41=0,"",K41/I41-1) -> 0.11239861 | N41: =IF(L41>0,"CENTRAL",IF(L41<0,"네오맥스","동일")) -> CENTRAL
A42: CENTRAL만 | C42: 18 | D42: SMART TONER FOR LASER PRINT B | E42: 2 | F42: PCS | O42: CENTRAL 단가 공란 — 모델 정보 요청
A43: CENTRAL만 | C43: 19 | D43: SMART TONER FOR LASER PRINT Y | E43: 2 | F43: PCS | O43: CENTRAL 단가 공란 — 모델 정보 요청
A44: CENTRAL만 | C44: 25 | D44: CARTRIDGE 78C0Z50 LEXMARK MC2425 MC2535 MC2640 | E44: 2 | F44: PCS | G44: 145.96 | H44: =ROUND(G44*요약!$C$4*(1-요약!$C$5),0) -> 177341 | I44: =E44*H44 -> 354682 | O44: LEXMARK 이미징 키트. 네오맥스는 78C20 토너 4색으로 견적 → 요청서 확인
A45: 네오맥스만 | B45: 21 | D45: EPSON 24MM X 9M SC24R-PX BLACK ON RED | E45: 1 | F45: PCS | J45: 10890 | K45: =E45*J45 -> 10890
A46: 네오맥스만 | B46: 24 | D46: EPSON 18MM X 9M SC18G-PX BLACK ON GREEN | E46: 1 | F46: PCS | J46: 10890 | K46: =E46*J46 -> 10890
...

Sheet 유사품목_단가참고
A1: 유사품목 단가 참고 — CENTRAL ER STORES vs 네오맥스 ENGINE CONSUMABLES
A2: ⚠ 서로 다른 요청서·선박(LNG 4척 vs NORTH VALLEY)이고 규격·브랜드가 다를 수 있음. 단가 수준만 가늠하는 참고용입니다.
A4: # | B4: CENTRAL 품목 / 규격 | C4: CENTRAL No. | D4: CENTRAL 단가 (USD) | E4: CENTRAL 단가 (원, 할인후) | F4: 네오맥스 품목 / 규격 | G4: 네오맥스 No. | H4: 네오맥스 단가 (원) | I4: 비교 기준 | J4: CENTRAL 환산계수 | K4: 네오맥스 환산계수 | L4: CENTRAL 비교단가 | M4: 네오맥스 비교단가 | N4: 차이율 (네오/CENT −1) | O4: 저렴한 곳 | P4: 비고
A5: 1 | B5: WASTE COTTON STERILIZED WHITE | C5: 1 | D5: 1.15 | E5: =ROUND(D5*요약!$C$4*(1-요약!$C$5),0) -> 1397 | F5: RAGS, WHITE 100% COTTON, STERILIZED (LOCAL BRAND, 100% COTTON, WHITE, PER KG PRICE) | G5: 18 | H5: 1380 | I5: 1 KG | J5: 1 | K5: 1 | L5: =E5*J5 -> 1397 | M5: =H5*K5 -> 1380 | N5: =IF(L5=0,"",M5/L5-1) -> -0.012168933 | O5: =IF(M5>L5,"CENTRAL",IF(M5<L5,"네오맥스","동일")) -> 네오맥스
A6: 2 | B6: LUBRICANT SPRAY WD-40 MULTIUSE, 350ML | C6: 2 | D6: 4.42 | E6: =ROUND(D6*요약!$C$4*(1-요약!$C$5),0) -> 5370 | F6: WD 40 , 360 ML, SPRAY (BEX) | G6: 22 | H6: 6320 | I6: 1 캔 (350 vs 360ML) | J6: 1 | K6: 1 | L6: =E6*J6 -> 5370 | M6: =H6*K6 -> 6320 | N6: =IF(L6=0,"",M6/L6-1) -> 0.17690875 | O6: =IF(M6>L6,"CENTRAL",IF(M6<L6,"네오맥스","동일")) -> CENTRAL | P6: 네오맥스 비고 "BEX" — 정품 WD-40인지 확인
A7: 3 | B7: SILICONE GREASE, NORMAL TEMPERATURE 100GRM | C7: 5 | D7: 7.08 | E7: =ROUND(D7*요약!$C$4*(1-요약!$C$5),0) -> 8602 | F7: SILICONE GREASE (LOCAL BRAND, 200G) | G7: 23 | H7: 17710 | I7: 100 G | J7: 1 | K7: 0.5 | L7: =E7*J7 -> 8602 | M7: =H7*K7 -> 8855 | N7: =IF(L7=0,"",M7/L7-1) -> 0.029411765 | O7: =IF(M7>L7,"CENTRAL",IF(M7<L7,"네오맥스","동일")) -> CENTRAL | P7: 네오맥스 200G → 100G 환산
A8: 4 | B8: TAPE OIL GAUGE STAINLESS STEEL, METRIC 30MTR | C8: 40 | D8: 90.23 | E8: =ROUND(D8*요약!$C$4*(1-요약!$C$5),0) -> 109629 | F8: OIL GAUGING TAPE 30M | G8: 47 | H8: 35420 | I8: 1 EA (30M) | J8: 1 | K8: 1 | L8: =E8*J8 -> 109629 | M8: =H8*K8 -> 35420 | N8: =IF(L8=0,"",M8/L8-1) -> -0.67691031 | O8: =IF(M8>L8,"CENTRAL",IF(M8<L8,"네오맥스","동일")) -> 네오맥스 | P8: CENTRAL은 스테인리스 명시, 네오맥스 재질 미표기
A9: 5 | B9: WATER FINDING PASTE 75GRM, YELLOW TO RED | C9: 41 | D9: 3.54 | E9: =ROUND(D9*요약!$C$4*(1-요약!$C$5),0) -> 4301 | F9: WATER FINDING PASTE (SM, 75G) | G9: 48 | H9: 4420 | I9: 1 EA (75G) | J9: 1 | K9: 1 | L9: =E9*J9 -> 4301 | M9: =H9*K9 -> 4420 | N9: =IF(L9=0,"",M9/L9-1) -> 0.027667984 | O9: =IF(M9>L9,"CENTRAL",IF(M9<L9,"네오맥스","동일")) -> CENTRAL
A10: 6 | B10: GASOLINE AND OIL FINDING PASTE, 75GRM BLUE TO RED | C10: 42 | D10: 3.98 | E10: =ROUND(D10*요약!$C$4*(1-요약!$C$5),0) -> 4836 | F10: OIL FINDING PASTE (SM, 75G) | G10: 49 | H10: 5060 | I10: 1 EA (75G) | J10: 1 | K10: 1 | L10: =E10*J10 -> 4836 | M10: =H10*K10 -> 5060 | N10: =IF(L10=0,"",M10/L10-1) -> 0.046319272 | O10: =IF(M10>L10,"CENTRAL",IF(M10<L10,"네오맥스","동일")) -> CENTRAL
A11: 7 | B11: COPPER RING KIT 30SIZES/568PCS, IN ACRYL CASE | C11: 45 | D11: 35.38 | E11: =ROUND(D11*요약!$C$4*(1-요약!$C$5),0) -> 42987 | F11: COPPER RING KIT | G11: 66 | H11: 50600 | I11: 1 KIT | J11: 1 | K11: 1 | L11: =E11*J11 -> 42987 | M11: =H11*K11 -> 50600 | N11: =IF(L11=0,"",M11/L11-1) -> 0.17710005 | O11: =IF(M11>L11,"CENTRAL",IF(M11<L11,"네오맥스","동일")) -> CENTRAL | P11: CENTRAL 30사이즈/568pcs, 네오맥스 규격 미표기
A12: 8 | B12: YATCH MOPS COMPLETE | C12: 54 | D12: 1.51 | E12: =ROUND(D12*요약!$C$4*(1-요약!$C$5),0) -> 1835 | F12: YAUTT MOPS | G12: 8 | H12: 2530 | I12: 1 EA (완제품) | J12: 1 | K12: 1 | L12: =E12*J12 -> 1835 | M12: =H12*K12 -> 2530 | N12: =IF(L12=0,"",M12/L12-1) -> 0.37874659 | O12: =IF(M12>L12,"CENTRAL",IF(M12<L12,"네오맥스","동일")) -> CENTRAL | P12: 네오 IMPA 174271
A13: 9 | B13: REPLACABLE HEAD FOR YACHT MOP | C13: 55 | D13: 0.88 | E13: =ROUND(D13*요약!$C$4*(1-요약!$C$5),0) -> 1069 | F13: YAUTT MOPS | G13: 9 | H13: 1510 | I13: 1 EA (교체용 헤드) | J13: 1 | K13: 1 | L13: =E13*J13 -> 1069 | M13: =H13*K13 -> 1510 | N13: =IF(L13=0,"",M13/L13-1) -> 0.41253508 | O13: =IF(M13>L13,"CENTRAL",IF(M13<L13,"네오맥스","동일")) -> CENTRAL | P13: 네오 IMPA 174272
A14: 10 | B14: PLASTIC BAG FOR GARBAGE DISPOSAL (OFFER: 800X900, 50'S/PACK) | C14: 52 | D14: 7.52 | E14: =ROUND(D14*요약!$C$4*(1-요약!$C$5),0) -> 9137 | F14: PLASTIC BAGS FOR GARBAGE | G14: 6 | H14: 115 | I14: 1 매 | J14: 0.02 | K14: 1 | L14: =E14*J14 -> 182.74 | M14: =H14*K14 -> 115 | N14: =IF(L14=0,"",M14/L14-1) -> -0.3706906 | O14: =IF(M14>L14,"CENTRAL",IF(M14<L14,"네오맥스","동일")) -> 네오맥스 | P14: CENTRAL 800X900 50매/팩 → 1매 환산
A15: 11 | B15: ANTI-SEIZE COMPOUND 500GRM | C15: 3 | D15: 4.42 | E15: =ROUND(D15*요약!$C$4*(1-요약!$C$5),0) -> 5370 | F15: ANTI-SEIZE COPPER PASTE WEICON, KP 500P BRUSH TOP CAN 500GRM (PERMATEX, USA) | G15: TOOLS #9 | H15: 50600 | I15: 1 EA (500G) | J15: 1 | K15: 1 | L15: =E15*J15 -> 5370 | M15: =H15*K15 -> 50600 | N15: =IF(L15=0,"",M15/L15-1) -> 8.4227188 | O15: =IF(M15>L15,"CENTRAL",IF(M15<L15,"네오맥스","동일")) -> CENTRAL | P15: 네오맥스 TOOLS 건 #9 PERMATEX 구리 페이스트 — 브랜드 상이
A17: ※ 환산계수: 포장 단위가 다를 때 같은 기준으로 맞추는 배수 (예: 200G 제품 단가 × 0.5 = 100G 단가). 수정 가능.

Sheet 네오맥스_단독견적
A1: 네오맥스(SSL) 견적 — CENTRAL에 없는 요청서 4건
A2: 빨간 행 = 인보이스상 수량 × 단가 ≠ 금액 (산식 오류). 계산금액 열은 수량 × 단가로 다시 계산한 값.
A4: 요청서 | B4: No. | C4: IMPA | D4: 품목 | E4: 수량 | F4: 단위 | G4: 단가 (원) | H4: 인보이스 금액 (원) | I4: 계산금액 (수량×단가) | J4: 차이 | K4: 비고
A5: PAINT (SSL-26092825)
A6: PAINT | B6: 1 | D6: PAINT (ORANGE (RAL2004)) - 15L | E6: 2 | F6: CAN | G6: 442750 | H6: 885500 | I6: =E6*G6 -> 885500 | J6: =H6-I6 -> 0 | K6: LEAD TIME : 3 DAYS
A7: 소계 (행 합계) | H7: =SUM(H6:H6) -> 885500 | I7: =SUM(I6:I6) -> 885500 | J7: =H7-I7 -> 0
A8: 인보이스 TOTAL (원본) | H8: 885500 | J8: =H8-H7 -> 0 | K8: =IF(J8=0,"행 합계와 일치","⚠ 행 합계와 "&TEXT(J8,"#,##0")&"원 차이") -> 행 합계와 일치
A10: ENGINE CONSUMABLES (SSL-26092824)
A11: ENGINE CONSUMABLES | B11: 1 | D11: C TO C MULTI USB 3.0 PD90W | E11: 10 | F11: EA | G11: 37690 | H11: 376900 | I11: =E11*G11 -> 376900 | J11: =H11-I11 -> 0
A12: ENGINE CONSUMABLES | B12: 2 | D12: EPSON LABEL MAKER LW-K200BL | E12: 2 | F12: EA | G12: 78430 | H12: 156860 | I12: =E12*G12 -> 156860 | J12: =H12-I12 -> 0
A13: ENGINE CONSUMABLES | B13: 3 | D13: HP 27 INCHIES MONITOR | E13: 6 | F13: PCS | G13: 251730 | H13: 1510380 | I13: =E13*G13 -> 1510380 | J13: =H13-I13 -> 0
A14: ENGINE CONSUMABLES | B14: 4 | C14: 174122 | D14: BUCKETS | E14: 10 | F14: PCS | G14: 4040 | H14: 40400 | I14: =E14*G14 -> 40400 | J14: =H14-I14 -> 0
A15: ENGINE CONSUMABLES | B15: 5 | C15: 174141 | D15: DUST PANS | E15: 5 | F15: PCS | G15: 880 | H15: 4400 | I15: =E15*G15 -> 4400 | J15: =H15-I15 -> 0
A16: ENGINE CONSUMABLES | B16: 6 | C16: 174176 | D16: PLASTIC BAGS FOR GARBAGE | E16: 200 | F16: PCS | G16: 115 | H16: 24000 | I16: =E16*G16 -> 23000 | J16: =H16-I16 -> 1000
A17: ENGINE CONSUMABLES | B17: 7 | C17: 174232 | D17: ROLL TYPE PAPER TOWEL | E17: 10 | F17: PCS | G17: 863 | H17: 9400 | I17: =E17*G17 -> 8630 | J17: =H17-I17 -> 770
A18: ENGINE CONSUMABLES | B18: 8 | C18: 174271 | D18: YAUTT MOPS | E18: 10 | F18: PCS | G18: 2530 | H18: 25300 | I18: =E18*G18 -> 25300 | J18: =H18-I18 -> 0
A19: ENGINE CONSUMABLES | B19: 9 | C19: 174272 | D19: YAUTT MOPS | E19: 30 | F19: PCS | G19: 1510 | H19: 45300 | I19: =E19*G19 -> 45300 | J19: =H19-I19 -> 0
A20: ENGINE CONSUMABLES | B20: 10 | C20: 174291 | D20: RUBBER SQUEEGEES | E20: 10 | F20: PCS | G20: 2530 | H20: 25300 | I20: =E20*G20 -> 25300 | J20: =H20-I20 -> 0
A21: ENGINE CONSUMABLES | B21: 11 | C21: 174292 | D21: RUBBER SQUEEGEES | E21: 10 | F21: PCS | G21: 2530 | H21: 25300 | I21: =E21*G21 -> 25300 | J21: =H21-I21 -> 0
A22: ENGINE CONSUMABLES | B22: 12 | C22: 190109 | D22: LEATHER PALM WORKING GLOVES | E22: 100 | F22: PCS | G22: 1640 | H22: 164000 | I22: =E22*G22 -> 164000 | J22: =H22-I22 -> 0 | K22: LOCAL
A23: ENGINE CONSUMABLES | B23: 13 | C23: 232603 | D23: OIL FUNNELS | E23: 5 | F23: PCS | G23: 11380 | H23: 56900 | I23: =E23*G23 -> 56900 | J23: =H23-I23 -> 0 | K23: 100MM
A24: ENGINE CONSUMABLES | B24: 14 | C24: 232604 | D24: OIL FUNNELS | E24: 5 | F24: PCS | G24: 15180 | H24: 75900 | I24: =E24*G24 -> 75900 | J24: =H24-I24 -> 0 | K24: 150MM
A25: ENGINE CONSUMABLES | B25: 15 | C25: 232606 | D25: OIL FUNNELS | E25: 5 | F25: PCS | G25: 18970 | H25: 94850 | I25: =E25*G25 -> 94850 | J25: =H25-I25 -> 0 | K25: 200MM
A26: ENGINE CONSUMABLES | B26: 16 | C26: 232607 | D26: OIL FUNNELS | E26: 4 | F26: PCE | G26: 25300 | H26: 101200 | I26: =E26*G26 -> 101200 | J26: =H26-I26 -> 0 | K26: 250MM
A27: ENGINE CONSUMABLES | B27: 17 | C27: 232608 | D27: OIL FUNNELS | E27: 5 | F27: PCS | G27: 31620 | H27: 158100 | I27: =E27*G27 -> 158100 | J27: =H27-I27 -> 0 | K27: 350MM N/A, 300MM QUOTED INSTEAD
A28: ENGINE CONSUMABLES | B28: 18 | C28: 232907 | D28: RAGS, WHITE 100% COTTON, STERILIZED | E28: 300 | F28: KG | G28: 1380 | H28: 414000 | I28: =E28*G28 -> 414000 | J28: =H28-I28 -> 0 | K28: LOCAL BRAND, 100% COTTON, WHITE, PER KG PRICE
A29: ENGINE CONSUMABLES | B29: 19 | C29: 331156 | D29: EAR PLUGS | E29: 2 | F29: BOX | G29: 50600 | H29: 101200 | I29: =E29*G29 -> 101200 | J29: =H29-I29 -> 0 | K29: 100'S/BOX, PER BOX PRICE
A30: ENGINE CONSUMABLES | B30: 20 | C30: 450566 | D30: COPASLIP HIGH PERFORMANCE COMPOUND (500 GRM) | E30: 5 | F30: PCE | G30: 6320 | H30: 31600 | I30: =E30*G30 -> 31600 | J30: =H30-I30 -> 0 | K30: SM
A31: ENGINE CONSUMABLES | B31: 21 | C31: 450594 | D31: MOLYSLIP AS 40 | E31: 5 | F31: PCE | G31: 151800 | H31: 759000 | I31: =E31*G31 -> 759000 | J31: =H31-I31 -> 0 | K31: MOLYSLIP, 500G
A32: ENGINE CONSUMABLES | B32: 22 | C32: 450702 | D32: WD 40 , 360 ML, SPRAY | E32: 24 | F32: CAN | G32: 6320 | H32: 151680 | I32: =E32*G32 -> 151680 | J32: =H32-I32 -> 0 | K32: BEX
A33: ENGINE CONSUMABLES | B33: 23 | C33: 450757 | D33: SILICONE GREASE | E33: 5 | F33: PCE | G33: 17710 | H33: 88550 | I33: =E33*G33 -> 88550 | J33: =H33-I33 -> 0 | K33: LOCAL BRAND, 200G
... A35: ENGINE CONSUMABLES | B35: 25 | C35: 510364 | D35: PAINT ROLLERS | E35: 50 | F35: PCS | G35: 3410 | H35: 170500 | I35: =E35*G35 -> 170500 | J35: =H35-I35 -> 0 | K35: WOOL 100%
A36: ENGINE CONSUMABLES | B36: 26 | C36: 510646 | D36: COUNTER BRUSHES | E36: 5 | F36: PCS | G36: 1510 | H36: 7550 | I36: =E36*G36 -> 7550 | J36: =H36-I36 -> 0
A37: ENGINE CONSUMABLES | B37: 27 | C37: 510888 | D37: VIRAN BRUSHERS | E37: 10 | F37: PCS | G37: 2530 | H37: 25300 | I37: =E37*G37 -> 25300 | J37: =H37-I37 -> 0 | K37: SUBSTITUTE
A38: ENGINE CONSUMABLES | B38: 28 | C38: 590722 | D38: PNEUMATIC VACUUM CLEANERS | E38: 5 | F38: PCS | G38: 120170 | H38: 600850 | I38: =E38*G38 -> 600850 | J38: =H38-I38 -> 0 | K38: MBK 20LTR
A39: ENGINE CONSUMABLES | B39: 29 | C39: 610418 | D39: NUT SPINNER HANDLES | E39: 3 | F39: PCE | G39: 15180 | H39: 45500 | I39: =E39*G39 -> 45540 | J39: =H39-I39 -> -40
A40: ENGINE CONSUMABLES | B40: 30 | C40: 610473 | D40: SOCKET ADAPTER | E40: 3 | F40: PCE | G40: 2270 | H40: 6810 | I40: =E40*G40 -> 6810 | J40: =H40-I40 -> 0
A41: ENGINE CONSUMABLES | B41: 31 | C41: 610474 | D41: SOCKET ADAPTER | E41: 3 | F41: PCE | G41: 3030 | H41: 9090 | I41: =E41*G41 -> 9090 | J41: =H41-I41 -> 0
A42: ENGINE CONSUMABLES | B42: 32 | C42: 610475 | D42: SOCKET ADAPTER | E42: 3 | F42: PCE | G42: 6950 | H42: 20850 | I42: =E42*G42 -> 20850 | J42: =H42-I42 -> 0
A43: ENGINE CONSUMABLES | B43: 33 | C43: 611421 | D43: TORQUE WRENCH 20-200NM | E43: 2 | F43: PCE | G43: 284620 | H43: 569240 | I43: =E43*G43 -> 569240 | J43: =H43-I43 -> 0
...

Sheet CENTRAL_단독견적
A1: CENTRAL MARITIME 견적 — 네오맥스에 없는 요청서 4건 (원화 환산)
A2: 원화 금액 = USD 금액 × (1 − 할인율) × 환율. OFFER = CENTRAL이 다른 규격·용량으로 대체 제안한 내용 (주황 행).
A4: 요청서 | B4: No. | C4: 품목 | D4: 수량 | E4: 단위 | F4: 단가 (USD) | G4: 금액 (USD) | H4: 할인후 금액 (원) | I4: CENTRAL 대체 제안 (OFFER)
A5: ER ELECTRICAL (JU26092325-A / LNG 운반선 4척)
A6: ER ELECTRICAL | B6: 1 | C6: LED DRIVER FOR FLOOD LIGHT (PF GOL) DAEYANG DLD-45060-STN => 153X58X37 | D6: 20 | E6: PCS | F6: 57.5 | G6: =D6*F6 -> 1150 | H6: =ROUND(G6*(1-요약!$C$5)*요약!$C$4,0) -> 1397250
A7: ER ELECTRICAL | B7: 2 | C7: EXPLOSION PROOF LED FLOOD LIGHT FOR MARINE USE DAEYANG AC 220V 50/60 HZ 125 W X 2 DROWING NO. LR6530160 WEIGHT 27 KG | D7: 10 | E7: PCS | F7: 884.62 | G7: =D7*F7 -> 8846.2 | H7: =ROUND(G7*(1-요약!$C$5)*요약!$C$4,0) -> 10748133
A8: ER ELECTRICAL | B8: 3 | C8: BATTERY DRILL MASHINE MAKITA DHP 485 18 V X 2 BATTERY | D8: 2 | E8: PCS | F8: 398.08 | G8: =D8*F8 -> 796.16 | H8: =ROUND(G8*(1-요약!$C$5)*요약!$C$4,0) -> 967334 | I8: DDF489Z
A9: ER ELECTRICAL | B9: 4 | C9: BATTERY TYPE AA | D9: 50 | E9: PCS | F9: 0.45 | G9: =D9*F9 -> 22.5 | H9: =ROUND(G9*(1-요약!$C$5)*요약!$C$4,0) -> 27338
A10: ER ELECTRICAL | B10: 5 | C10: BATTERY TYPE AAA | D10: 50 | E10: PCS | F10: 0.45 | G10: =D10*F10 -> 22.5 | H10: =ROUND(G10*(1-요약!$C$5)*요약!$C$4,0) -> 27338
A11: ER ELECTRICAL | B11: 6 | C11: BATTERY TYPE C | D11: 20 | E11: PCS | F11: 2.57 | G11: =D11*F11 -> 51.4 | H11: =ROUND(G11*(1-요약!$C$5)*요약!$C$4,0) -> 62451
A12: ER ELECTRICAL | B12: 7 | C12: BATTERY TYPE D | D12: 20 | E12: PCS | F12: 2.57 | G12: =D12*F12 -> 51.4 | H12: =ROUND(G12*(1-요약!$C$5)*요약!$C$4,0) -> 62451
A13: ER ELECTRICAL | B13: 8 | C13: ELECTRIC SCREWDRIVER WITH FRONT -MOUNTED LED RECHERGEBALE DRILL BIT SET, ERGONOMIC SPEED-ADJUSTABLE DESING,WITH MULTIPLE BITS, SUITABLE FOR EQUIPMENT MAINTENANCE AND PROJECTS. | D13: 2 | E13: PCS | F13: 54.67 | G13: =D13*F13 -> 109.34 | H13: =ROUND(G13*(1-요약!$C$5)*요약!$C$4,0) -> 132848
A14: ER ELECTRICAL | B14: 9 | C14: SILICONE BATTERY GUN 20 V BATTERY X 2 WITH LED LIGHT CAULING GUN TOOL | D14: 2 | E14: PCS | F14: 226.46 | G14: =D14*F14 -> 452.92 | H14: =ROUND(G14*(1-요약!$C$5)*요약!$C$4,0) -> 550298
A15: ER ELECTRICAL | B15: 10 | C15: 11-IN 1 USB-C EXPANSION DOCK WITH 4K ULTRA HD, FAST PD, GIGABIT ETHERNET, MICROPHONE AUDIO,SD/TF CARD READER-HIGHT-SPEED MULTE PORT ADAPTER FOR USB DEVICES SUCH AS MACBOOKS, WINDOWS AND MORE | D15: 6 | E15: PCS | F15: 43.35 | G15: =D15*F15 -> 260.1 | H15: =ROUND(G15*(1-요약!$C$5)*요약!$C$4,0) -> 316022
A16: ER ELECTRICAL | B16: 11 | C16: AX 1800 WIFI 6 USB 3.0 WIRELES NETWORK CARD, 2.4 & 5G DUAL BAND WIFI RECEIVER,LOW LATENCY GAMING ADAPTER,PLUG AND PLAY DRIVER FREE COMPATIBLE WITH WINDOWS 10/11 FOR DESKTOP LAPTOP | D16: 1 | E16: PCS | F16: 130.92 | G16: =D16*F16 -> 130.92 | H16: =ROUND(G16*(1-요약!$C$5)*요약!$C$4,0) -> 159068
A17: ER ELECTRICAL | B17: 12 | C17: USB TO USB-C ADAPTER | D17: 10 | E17: PCS | F17: 5.75 | G17: =D17*F17 -> 57.5 | H17: =ROUND(G17*(1-요약!$C$5)*요약!$C$4,0) -> 69863
A18: ER ELECTRICAL | B18: 13 | C18: USB-C TO USB SDAPTER | D18: 10 | E18: PCS | F18: 5.75 | G18: =D18*F18 -> 57.5 | H18: =ROUND(G18*(1-요약!$C$5)*요약!$C$4,0) -> 69863
A19: ER ELECTRICAL | B19: 14 | C19: TOECH LIGHT PELICAN 3315 | D19: 10 | E19: PCS | F19: 59.45 | G19: =D19*F19 -> 594.5 | H19: =ROUND(G19*(1-요약!$C$5)*요약!$C$4,0) -> 722318
A20: ER ELECTRICAL | B20: 15 | C20: SMART TV PANASONIK 55" W85C 4K 3840X2160 60HZ QD MIND LED GOOGLE TV (2026) BUNDLE | D20: 1 | E20: PCS | F20: 313.64 | G20: =D20*F20 -> 313.64 | H20: =ROUND(G20*(1-요약!$C$5)*요약!$C$4,0) -> 381073
A21: ER ELECTRICAL | B21: 16 | C21: MAKITA REPLACMENT BATTERY COMPATIBLE BL1860 LITHIUM-ION CODLES TOOL | D21: 2 | E21: PCS | F21: 528.12 | G21: =D21*F21 -> 1056.24 | H21: =ROUND(G21*(1-요약!$C$5)*요약!$C$4,0) -> 1283332
A22: 소계 | G22: =SUM(G6:G21) -> 13972.82 | H22: =SUM(H6:H21) -> 16976980
A24: ER STORES (JU26092325-C / LNG 운반선 4척)
A25: ER STORES | B25: 1 | C25: WASTE COTTON STERILIZED WHITE | D25: 200 | E25: KG | F25: 1.15 | G25: =D25*F25 -> 230 | H25: =ROUND(G25*(1-요약!$C$5)*요약!$C$4,0) -> 279450
A26: ER STORES | B26: 2 | C26: LUBRICANT SPRAY WD-40 MULTIUSE, 350ML | D26: 30 | E26: PCS | F26: 4.42 | G26: =D26*F26 -> 132.6 | H26: =ROUND(G26*(1-요약!$C$5)*요약!$C$4,0) -> 161109
A27: ER STORES | B27: 3 | C27: ANTI-SEIZE COMPOUND 500GRM | D27: 6 | E27: PCS | F27: 4.42 | G27: =D27*F27 -> 26.52 | H27: =ROUND(G27*(1-요약!$C$5)*요약!$C$4,0) -> 32222
A28: ER STORES | B28: 4 | C28: LEAK DETECTION SPRAY WEICON, 400ML | D28: 10 | E28: PCS | F28: 4.42 | G28: =D28*F28 -> 44.2 | H28: =ROUND(G28*(1-요약!$C$5)*요약!$C$4,0) -> 53703 | I28: 220ML
A29: ER STORES | B29: 5 | C29: SILICONE GREASE, NORMAL TEMPERATURE 100GRM | D29: 10 | E29: PCS | F29: 7.08 | G29: =D29*F29 -> 70.8 | H29: =ROUND(G29*(1-요약!$C$5)*요약!$C$4,0) -> 86022
A30: ER STORES | B30: 6 | C30: WRENCH ADJUSTABLE HEAVY-DUTY, 150MM | D30: 5 | E30: PCS | F30: 4.42 | G30: =D30*F30 -> 22.1 | H30: =ROUND(G30*(1-요약!$C$5)*요약!$C$4,0) -> 26852
A31: ER STORES | B31: 7 | C31: WRENCH ADJUSTABLE HEAVY-DUTY, 250MM | D31: 5 | E31: PCS | F31: 7.08 | G31: =D31*F31 -> 35.4 | H31: =ROUND(G31*(1-요약!$C$5)*요약!$C$4,0) -> 43011
A32: ER STORES | B32: 8 | C32: WRENCH ADJUSTABLE HEAVY-DUTY, 300MM | D32: 5 | E32: PCS | F32: 8.85 | G32: =D32*F32 -> 44.25 | H32: =ROUND(G32*(1-요약!$C$5)*요약!$C$4,0) -> 53764
A33: ER STORES | B33: 9 | C33: PLIER VISE-GRIP COMBINATION, 175MM | D33: 2 | E33: PCS | F33: 6.28 | G33: =D33*F33 -> 12.56 | H33: =ROUND(G33*(1-요약!$C$5)*요약!$C$4,0) -> 15260
A34: ER STORES | B34: 10 | C34: PLIER VISE-GRIP COMBINATION, 200MM | D34: 2 | E34: PCS | F34: 7.7 | G34: =D34*F34 -> 15.4 | H34: =ROUND(G34*(1-요약!$C$5)*요약!$C$4,0) -> 18711
A35: ER STORES | B35: 11 | C35: CUTTER TUBE COPPER & BRASS, FOR 3 - 30MM | D35: 2 | E35: PCS | F35: 4.42 | G35: =D35*F35 -> 8.84 | H35: =ROUND(G35*(1-요약!$C$5)*요약!$C$4,0) -> 10741
A36: ER STORES | B36: 12 | C36: CUTTER TUBE COPPER & BRASS, FOR 6 - 60MM | D36: 2 | E36: PCS | F36: 15.92 | G36: =D36*F36 -> 31.84 | H36: =ROUND(G36*(1-요약!$C$5)*요약!$C$4,0) -> 38686
A37: ER STORES | B37: 13 | C37: HAMMER BLACKSMITH DOUBLE FACE, WITH HANDLE NO.8 (3.6KGS) | D37: 3 | E37: PCS | F37: 12.74 | G37: =D37*F37 -> 38.22 | H37: =ROUND(G37*(1-요약!$C$5)*요약!$C$4,0) -> 46437
A38: ER STORES | B38: 14 | C38: HAMMER BLACKSMITH DOUBLE FACE, WITH HANDLE NO.12 (5.4KGS) | D38: 3 | E38: PCS | F38: 16.63 | G38: =D38*F38 -> 49.89 | H38: =ROUND(G38*(1-요약!$C$5)*요약!$C$4,0) -> 60616
A39: ER STORES | B39: 15 | C39: HAMMER BLACKSMITH DOUBLE FACE, WITH HANDLE NO.18 (8.1KGS) | D39: 3 | E39: PCS | F39: 29.72 | G39: =D39*F39 -> 89.16 | H39: =ROUND(G39*(1-요약!$C$5)*요약!$C$4,0) -> 108329
A40: ER STORES | B40: 16 | C40: SCREWDRIVER INSULATED HANDLE, HEAVY-DUTY SLOTTED 4.5X50MM | D40: 5 | E40: PCS | F40: 0.98 | G40: =D40*F40 -> 4.9 | H40: =ROUND(G40*(1-요약!$C$5)*요약!$C$4,0) -> 5954
... A72: ER STORES | B72: 48 | C72: WERA 9-PIECE TORX KEY SET, 139 X 72 X 25 MM SIZE, L SHAPE, LONG ARM | D72: 5 | E72: PCS | F72: 11.5 | G72: =D72*F72 -> 57.5 | H72: =ROUND(G72*(1-요약!$C$5)*요약!$C$4,0) -> 69863
A73: ER STORES | B73: 49 | C73: PARALLEL BENCH VISE | D73: 1 | E73: PCS | F73: 778.46 | G73: =D73*F73 -> 778.46 | H73: =ROUND(G73*(1-요약!$C$5)*요약!$C$4,0) -> 945829 | I73: 255 X 300 X 140
...
