Workbook

Sheet 요약
A1: 선박별 견적 현황
A2: ="기준일 "&TEXT(TODAY(),"yyyy-mm-dd")&" · 선박 시트·스케줄 시트에서 자동 집계 (입력 불필요)"
A3: ="⏰ 알림: 4일 이내 "&COUNTIFS(스케줄!$I$5:$I$14,">=0",스케줄!$I$5:$I$14,"<=4")&"척 · 1주 이내 "&COUNTIFS(스케줄!$I$5:$I$14,">4",스케줄!$I$5:$I$14,"<=7")&"척 · 일정 미정 "&COUNTIFS(스케줄!$A$5:$A$14,"<>",스케줄!$C$5:$C$14,"")&"척"
A4: 선박 | B4: 우선순위 | C4: 다음 일정 | D4: 예정일 | E4: D-day | F4: 알림 | G4: 품목 | H4: 견적접수 | I4: 확인필요 | J4: 공급불가 | K4: 미접수 | L4: 견적금액 (KRW) | M4: 일정 초과 품목 | N4: 만료 임박/지남 | O4: 발주완료
A5: AEOLUS | B5: Routine | C5: =IFERROR(IF(INDEX(스케줄!$B$5:$B$14,MATCH($A5,스케줄!$A$5:$A$14,0))="","-",INDEX(스케줄!$B$5:$B$14,MATCH($A5,스케줄!$A$5:$A$14,0))),"-") | D5: =IFERROR(IF(N(INDEX(스케줄!$C$5:$C$14,MATCH($A5,스케줄!$A$5:$A$14,0)))=0,"",INDEX(스케줄!$C$5:$C$14,MATCH($A5,스케줄!$A$5:$A$14,0))),"") | E5: =IFERROR(INDEX(스케줄!$I$5:$I$14,MATCH($A5,스케줄!$A$5:$A$14,0)),"") | F5: =IFERROR(INDEX(스케줄!$J$5:$J$14,MATCH($A5,스케줄!$A$5:$A$14,0)),"") | G5: =COUNTA('AEOLUS'!$E$6:$E$205) | H5: =COUNTIF('AEOLUS'!$M$6:$M$205,"견적접수") | I5: =COUNTIF('AEOLUS'!$M$6:$M$205,"확인필요") | J5: =COUNTIF('AEOLUS'!$M$6:$M$205,"공급불가") | K5: =COUNTIF('AEOLUS'!$M$6:$M$205,"미접수") | L5: =SUM('AEOLUS'!$O$6:$O$205) | M5: =COUNTIF('AEOLUS'!$R$6:$R$205,"초과*") | N5: =COUNTIFS('AEOLUS'!$W$6:$W$205,"<="&(TODAY()+5)) | O5: =COUNTIF('AEOLUS'!$Y$6:$Y$205,"발주완료")
A6: MELICERTES | B6: URGENT | C6: =IFERROR(IF(INDEX(스케줄!$B$5:$B$14,MATCH($A6,스케줄!$A$5:$A$14,0))="","-",INDEX(스케줄!$B$5:$B$14,MATCH($A6,스케줄!$A$5:$A$14,0))),"-") | D6: =IFERROR(IF(N(INDEX(스케줄!$C$5:$C$14,MATCH($A6,스케줄!$A$5:$A$14,0)))=0,"",INDEX(스케줄!$C$5:$C$14,MATCH($A6,스케줄!$A$5:$A$14,0))),"") | E6: =IFERROR(INDEX(스케줄!$I$5:$I$14,MATCH($A6,스케줄!$A$5:$A$14,0)),"") | F6: =IFERROR(INDEX(스케줄!$J$5:$J$14,MATCH($A6,스케줄!$A$5:$A$14,0)),"") | G6: =COUNTA('MELICERTES'!$E$6:$E$205) | H6: =COUNTIF('MELICERTES'!$M$6:$M$205,"견적접수") | I6: =COUNTIF('MELICERTES'!$M$6:$M$205,"확인필요") | J6: =COUNTIF('MELICERTES'!$M$6:$M$205,"공급불가") | K6: =COUNTIF('MELICERTES'!$M$6:$M$205,"미접수") | L6: =SUM('MELICERTES'!$O$6:$O$205) | M6: =COUNTIF('MELICERTES'!$R$6:$R$205,"초과*") | N6: =COUNTIFS('MELICERTES'!$W$6:$W$205,"<="&(TODAY()+5)) | O6: =COUNTIF('MELICERTES'!$Y$6:$Y$205,"발주완료")
A7: NELEUS | B7: Routine | C7: =IFERROR(IF(INDEX(스케줄!$B$5:$B$14,MATCH($A7,스케줄!$A$5:$A$14,0))="","-",INDEX(스케줄!$B$5:$B$14,MATCH($A7,스케줄!$A$5:$A$14,0))),"-") | D7: =IFERROR(IF(N(INDEX(스케줄!$C$5:$C$14,MATCH($A7,스케줄!$A$5:$A$14,0)))=0,"",INDEX(스케줄!$C$5:$C$14,MATCH($A7,스케줄!$A$5:$A$14,0))),"") | E7: =IFERROR(INDEX(스케줄!$I$5:$I$14,MATCH($A7,스케줄!$A$5:$A$14,0)),"") | F7: =IFERROR(INDEX(스케줄!$J$5:$J$14,MATCH($A7,스케줄!$A$5:$A$14,0)),"") | G7: =COUNTA('NELEUS'!$E$6:$E$205) | H7: =COUNTIF('NELEUS'!$M$6:$M$205,"견적접수") | I7: =COUNTIF('NELEUS'!$M$6:$M$205,"확인필요") | J7: =COUNTIF('NELEUS'!$M$6:$M$205,"공급불가") | K7: =COUNTIF('NELEUS'!$M$6:$M$205,"미접수") | L7: =SUM('NELEUS'!$O$6:$O$205) | M7: =COUNTIF('NELEUS'!$R$6:$R$205,"초과*") | N7: =COUNTIFS('NELEUS'!$W$6:$W$205,"<="&(TODAY()+5)) | O7: =COUNTIF('NELEUS'!$Y$6:$Y$205,"발주완료")
A8: ONEIROI | B8: URGENT | C8: =IFERROR(IF(INDEX(스케줄!$B$5:$B$14,MATCH($A8,스케줄!$A$5:$A$14,0))="","-",INDEX(스케줄!$B$5:$B$14,MATCH($A8,스케줄!$A$5:$A$14,0))),"-") | D8: =IFERROR(IF(N(INDEX(스케줄!$C$5:$C$14,MATCH($A8,스케줄!$A$5:$A$14,0)))=0,"",INDEX(스케줄!$C$5:$C$14,MATCH($A8,스케줄!$A$5:$A$14,0))),"") | E8: =IFERROR(INDEX(스케줄!$I$5:$I$14,MATCH($A8,스케줄!$A$5:$A$14,0)),"") | F8: =IFERROR(INDEX(스케줄!$J$5:$J$14,MATCH($A8,스케줄!$A$5:$A$14,0)),"") | G8: =COUNTA('ONEIROI'!$E$6:$E$205) | H8: =COUNTIF('ONEIROI'!$M$6:$M$205,"견적접수") | I8: =COUNTIF('ONEIROI'!$M$6:$M$205,"확인필요") | J8: =COUNTIF('ONEIROI'!$M$6:$M$205,"공급불가") | K8: =COUNTIF('ONEIROI'!$M$6:$M$205,"미접수") | L8: =SUM('ONEIROI'!$O$6:$O$205) | M8: =COUNTIF('ONEIROI'!$R$6:$R$205,"초과*") | N8: =COUNTIFS('ONEIROI'!$W$6:$W$205,"<="&(TODAY()+5)) | O8: =COUNTIF('ONEIROI'!$Y$6:$Y$205,"발주완료")
A9: 합계 | G9: =SUM(G5:G8) | H9: =SUM(H5:H8) | I9: =SUM(I5:I8) | J9: =SUM(J5:J8) | K9: =SUM(K5:K8) | L9: =SUM(L5:L8) | M9: =SUM(M5:M8) | N9: =SUM(N5:N8) | O9: =SUM(O5:O8)
A11: 선박명을 누르면 해당 시트로 이동합니다. 일정 수정은 '스케줄' 시트. 통화: KRW (RFQ 기준).

Sheet 스케줄
A1: 선박 스케줄 · 알림
A2: 노란 칸(일정·예정일·종료일·운송소요일)만 수정하면 D-day와 알림이 자동으로 바뀝니다 · 1주 전 = 주황, 4일 전 = 빨강 · 파일을 열 때마다 오늘 날짜 기준으로 다시 계산
A4: 선박 | B4: 일정 | C4: 예정일 (시작) | D4: 종료일 | E4: 운송 소요(일) | F4: 부산 출고 마감 | G4: 1주 전 (D-7) | H4: 4일 전 (D-4) | I4: 남은 일수 | J4: 알림 | K4: 비고
A5: AEOLUS | B5: 한국 통과 | C5: 46336 | F5: =IF(C5="","",C5-N(E5)) | G5: =IF(C5="","",C5-7) | H5: =IF(C5="","",C5-4) | I5: =IF(C5="","",C5-TODAY()) | J5: =IF(A5="","",IF(C5="","일정 미정 – 입력 필요",IF(I5<0,IF(AND(D5<>"",D5>=TODAY()),"진행중 (종료일까지)","지남 – 다음 일정 입력"),IF(I5=0,"오늘 도착",IF(I5<=4,"4일 전 – 최종 확인",IF(I5<=7,"1주 전 – 준비 시작","대기"))))))
A6: MELICERTES | F6: =IF(C6="","",C6-N(E6)) | G6: =IF(C6="","",C6-7) | H6: =IF(C6="","",C6-4) | I6: =IF(C6="","",C6-TODAY()) | J6: =IF(A6="","",IF(C6="","일정 미정 – 입력 필요",IF(I6<0,IF(AND(D6<>"",D6>=TODAY()),"진행중 (종료일까지)","지남 – 다음 일정 입력"),IF(I6=0,"오늘 도착",IF(I6<=4,"4일 전 – 최종 확인",IF(I6<=7,"1주 전 – 준비 시작","대기")))))) | K6: 일정 확인 필요 (RFQ상 Sabetta ETA 19-Oct 지남)
A7: NELEUS | F7: =IF(C7="","",C7-N(E7)) | G7: =IF(C7="","",C7-7) | H7: =IF(C7="","",C7-4) | I7: =IF(C7="","",C7-TODAY()) | J7: =IF(A7="","",IF(C7="","일정 미정 – 입력 필요",IF(I7<0,IF(AND(D7<>"",D7>=TODAY()),"진행중 (종료일까지)","지남 – 다음 일정 입력"),IF(I7=0,"오늘 도착",IF(I7<=4,"4일 전 – 최종 확인",IF(I7<=7,"1주 전 – 준비 시작","대기")))))) | K7: 일정 확인 필요
A8: ONEIROI | B8: 네덜란드 보급 | C8: 46338 | D8: 46339 | F8: =IF(C8="","",C8-N(E8)) | G8: =IF(C8="","",C8-7) | H8: =IF(C8="","",C8-4) | I8: =IF(C8="","",C8-TODAY()) | J8: =IF(A8="","",IF(C8="","일정 미정 – 입력 필요",IF(I8<0,IF(AND(D8<>"",D8>=TODAY()),"진행중 (종료일까지)","지남 – 다음 일정 입력"),IF(I8=0,"오늘 도착",IF(I8<=4,"4일 전 – 최종 확인",IF(I8<=7,"1주 전 – 준비 시작","대기")))))) | K8: EXW 부산 → 네덜란드 포워딩 기간 별도
F9: =IF(C9="","",C9-N(E9)) | G9: =IF(C9="","",C9-7) | H9: =IF(C9="","",C9-4) | I9: =IF(C9="","",C9-TODAY()) | J9: =IF(A9="","",IF(C9="","일정 미정 – 입력 필요",IF(I9<0,IF(AND(D9<>"",D9>=TODAY()),"진행중 (종료일까지)","지남 – 다음 일정 입력"),IF(I9=0,"오늘 도착",IF(I9<=4,"4일 전 – 최종 확인",IF(I9<=7,"1주 전 – 준비 시작","대기"))))))
F10: =IF(C10="","",C10-N(E10)) | G10: =IF(C10="","",C10-7) | H10: =IF(C10="","",C10-4) | I10: =IF(C10="","",C10-TODAY()) | J10: =IF(A10="","",IF(C10="","일정 미정 – 입력 필요",IF(I10<0,IF(AND(D10<>"",D10>=TODAY()),"진행중 (종료일까지)","지남 – 다음 일정 입력"),IF(I10=0,"오늘 도착",IF(I10<=4,"4일 전 – 최종 확인",IF(I10<=7,"1주 전 – 준비 시작","대기"))))))
F11: =IF(C11="","",C11-N(E11)) | G11: =IF(C11="","",C11-7) | H11: =IF(C11="","",C11-4) | I11: =IF(C11="","",C11-TODAY()) | J11: =IF(A11="","",IF(C11="","일정 미정 – 입력 필요",IF(I11<0,IF(AND(D11<>"",D11>=TODAY()),"진행중 (종료일까지)","지남 – 다음 일정 입력"),IF(I11=0,"오늘 도착",IF(I11<=4,"4일 전 – 최종 확인",IF(I11<=7,"1주 전 – 준비 시작","대기"))))))
F12: =IF(C12="","",C12-N(E12)) | G12: =IF(C12="","",C12-7) | H12: =IF(C12="","",C12-4) | I12: =IF(C12="","",C12-TODAY()) | J12: =IF(A12="","",IF(C12="","일정 미정 – 입력 필요",IF(I12<0,IF(AND(D12<>"",D12>=TODAY()),"진행중 (종료일까지)","지남 – 다음 일정 입력"),IF(I12=0,"오늘 도착",IF(I12<=4,"4일 전 – 최종 확인",IF(I12<=7,"1주 전 – 준비 시작","대기"))))))
F13: =IF(C13="","",C13-N(E13)) | G13: =IF(C13="","",C13-7) | H13: =IF(C13="","",C13-4) | I13: =IF(C13="","",C13-TODAY()) | J13: =IF(A13="","",IF(C13="","일정 미정 – 입력 필요",IF(I13<0,IF(AND(D13<>"",D13>=TODAY()),"진행중 (종료일까지)","지남 – 다음 일정 입력"),IF(I13=0,"오늘 도착",IF(I13<=4,"4일 전 – 최종 확인",IF(I13<=7,"1주 전 – 준비 시작","대기"))))))
F14: =IF(C14="","",C14-N(E14)) | G14: =IF(C14="","",C14-7) | H14: =IF(C14="","",C14-4) | I14: =IF(C14="","",C14-TODAY()) | J14: =IF(A14="","",IF(C14="","일정 미정 – 입력 필요",IF(I14<0,IF(AND(D14<>"",D14>=TODAY()),"진행중 (종료일까지)","지남 – 다음 일정 입력"),IF(I14=0,"오늘 도착",IF(I14<=4,"4일 전 – 최종 확인",IF(I14<=7,"1주 전 – 준비 시작","대기"))))))
A16: 선박 1척 = 1줄 (다음 일정만). 일정이 끝나면 같은 줄의 일정·날짜를 다음 일정으로 바꿔 쓰세요.

Sheet AEOLUS
A1: AEOLUS | D1: IMO 9958298 · Routine · 납품항/ETA: TBA
A2: =IFERROR(IF(N(INDEX(스케줄!$C$5:$C$14,MATCH("AEOLUS",스케줄!$A$5:$A$14,0)))=0,"다음 일정: 미정 (스케줄 시트에 입력)","다음 일정: "&INDEX(스케줄!$B$5:$B$14,MATCH("AEOLUS",스케줄!$A$5:$A$14,0))&" "&TEXT(INDEX(스케줄!$C$5:$C$14,MATCH("AEOLUS",스케줄!$A$5:$A$14,0)),"mm/dd")&IF(N(INDEX(스케줄!$D$5:$D$14,MATCH("AEOLUS",스케줄!$A$5:$A$14,0)))=0,"","~"&TEXT(INDEX(스케줄!$D$5:$D$14,MATCH("AEOLUS",스케줄!$A$5:$A$14,0)),"mm/dd"))),"") | F2: =IFERROR(INDEX(스케줄!$I$5:$I$14,MATCH("AEOLUS",스케줄!$A$5:$A$14,0)),"") | G2: =IFERROR(INDEX(스케줄!$J$5:$J$14,MATCH("AEOLUS",스케줄!$A$5:$A$14,0)),"") | I2: 부산 출고 마감 | J2: =IFERROR(INDEX(스케줄!$F$5:$F$14,MATCH("AEOLUS",스케줄!$A$5:$A$14,0)),"")
A3: 품목 | B3: =COUNTA($E$6:$E$205) | C3: 견적접수 | D3: =COUNTIF($M$6:$M$205,"견적접수") | E3: 확인필요 | F3: =COUNTIF($M$6:$M$205,"확인필요") | G3: 공급불가 | H3: =COUNTIF($M$6:$M$205,"공급불가") | I3: 미접수 | J3: =COUNTIF($M$6:$M$205,"미접수") | K3: 견적금액 합계 (KRW) | M3: =SUM($O$6:$O$205)
A4: 노란 칸 = 입력 / 회색 칸 = 자동 계산 · 새 품목·다른 업체 견적은 아래 빈 줄에 추가 · ▼ 필터로 상태별 보기 · 일정은 '스케줄' 시트에서 수정
A5: No | B5: RFQ No. | C5: 파일 | D5: Maker | E5: 품목 (Item) | F5: Model | G5: Part No. / Drawing | H5: Equipment / System | I5: Spec / 비고 | J5: 수량 | K5: 단위 | L5: 견적업체 | M5: 견적상태 | N5: 단가 (KRW) | O5: 금액 (KRW) | P5: 납기 (일) | Q5: 준비 예상일 | R5: 일정 대비 | S5: 정품/ OEM | T5: 인도조건 | U5: 유효 (일) | V5: 접수일 | W5: 만료일 | X5: 업체 회신 원문 | Y5: 진행상태 | Z5: 다음 조치
A6: =IF(E6="","",ROW()-5) | B6: KQU-000116304 | C6: 01 | D6: NORGREN | E6: Air filter | F6: Hanwha - MAN B&W 5G70ME-C10.5-GA | G6: Plate/Drawing no. 5672-0260-0001 Part no. 57 | H6: Emission Control System | I6: Filter Maker: Norgren, Type: F05G-2AN-AM3 | J6: 8 | K6: set | L6: RMS | M6: 견적접수 | N6: 621000 | O6: =IF(OR(N6="",J6=""),"",N6*J6) | P6: 5 | Q6: =IF(OR(P6="",Y6="발주완료",Y6="취소"),"",TODAY()+P6) | R6: =IF(OR(Q6="",NOT(ISNUMBER($J$2))),"",IF(Q6<=$J$2,"가능","초과 "&(Q6-$J$2)&"일")) | S6: OEM | T6: EX WORK BUSAN | U6: 20 | W6: =IF(OR(V6="",U6=""),"",V6+U6) | X6: D/T: 5 DAYS, OEM, EX WORK BUSAN [VALI: 20 DAYS] | Y6: 검토중
A7: =IF(E7="","",ROW()-5) | B7: KQU-000116304 | C7: 01 | D7: NORGREN | E7: Air filter element | F7: Hanwha - MAN B&W 5G70ME-C10.5-GA | G7: Plate/Drawing no. 5672-0260-0001 | H7: Emission Control System | I7: Service Kit- F05G 40 MIC / Maker part No.: 3653-28 | J7: 100 | K7: pcs | L7: RMS | M7: 견적접수 | N7: 99500 | O7: =IF(OR(N7="",J7=""),"",N7*J7) | P7: 90 | Q7: =IF(OR(P7="",Y7="발주완료",Y7="취소"),"",TODAY()+P7) | R7: =IF(OR(Q7="",NOT(ISNUMBER($J$2))),"",IF(Q7<=$J$2,"가능","초과 "&(Q7-$J$2)&"일")) | S7: OEM | T7: EX WORK BUSAN | U7: 20 | W7: =IF(OR(V7="",U7=""),"",V7+U7) | X7: D/T: 90 DAYS, OEM, EX WORK BUSAN [VALI: 20 DAYS] | Y7: 검토중
A8: =IF(E8="","",ROW()-5) | B8: KQU-000116306 | C8: 04 | D8: WAGO | E8: WAGO module for EGR system | F8: WAGO / 750-8216/040-00 | G8: As attached | H8: EGR System | J8: 1 | K8: set | L8: RMS | M8: 견적접수 | N8: 2300000 | O8: =IF(OR(N8="",J8=""),"",N8*J8) | P8: 60 | Q8: =IF(OR(P8="",Y8="발주완료",Y8="취소"),"",TODAY()+P8) | R8: =IF(OR(Q8="",NOT(ISNUMBER($J$2))),"",IF(Q8<=$J$2,"가능","초과 "&(Q8-$J$2)&"일")) | S8: OEM | T8: EX WORK BUSAN | U8: 20 | W8: =IF(OR(V8="",U8=""),"",V8+U8) | X8: D/T: 60 DAYS, OEM, EX WORK BUSAN [VALI: 20 DAYS] | Y8: 검토중
A9: =IF(E9="","",ROW()-5) | O9: =IF(OR(N9="",J9=""),"",N9*J9) | Q9: =IF(OR(P9="",Y9="발주완료",Y9="취소"),"",TODAY()+P9) | R9: =IF(OR(Q9="",NOT(ISNUMBER($J$2))),"",IF(Q9<=$J$2,"가능","초과 "&(Q9-$J$2)&"일")) | W9: =IF(OR(V9="",U9=""),"",V9+U9)
A10: =IF(E10="","",ROW()-5) | O10: =IF(OR(N10="",J10=""),"",N10*J10) | Q10: =IF(OR(P10="",Y10="발주완료",Y10="취소"),"",TODAY()+P10) | R10: =IF(OR(Q10="",NOT(ISNUMBER($J$2))),"",IF(Q10<=$J$2,"가능","초과 "&(Q10-$J$2)&"일")) | W10: =IF(OR(V10="",U10=""),"",V10+U10)
A11: =IF(E11="","",ROW()-5) | O11: =IF(OR(N11="",J11=""),"",N11*J11) | Q11: =IF(OR(P11="",Y11="발주완료",Y11="취소"),"",TODAY()+P11) | R11: =IF(OR(Q11="",NOT(ISNUMBER($J$2))),"",IF(Q11<=$J$2,"가능","초과 "&(Q11-$J$2)&"일")) | W11: =IF(OR(V11="",U11=""),"",V11+U11)
A12: =IF(E12="","",ROW()-5) | O12: =IF(OR(N12="",J12=""),"",N12*J12) | Q12: =IF(OR(P12="",Y12="발주완료",Y12="취소"),"",TODAY()+P12) | R12: =IF(OR(Q12="",NOT(ISNUMBER($J$2))),"",IF(Q12<=$J$2,"가능","초과 "&(Q12-$J$2)&"일")) | W12: =IF(OR(V12="",U12=""),"",V12+U12)
A13: =IF(E13="","",ROW()-5) | O13: =IF(OR(N13="",J13=""),"",N13*J13) | Q13: =IF(OR(P13="",Y13="발주완료",Y13="취소"),"",TODAY()+P13) | R13: =IF(OR(Q13="",NOT(ISNUMBER($J$2))),"",IF(Q13<=$J$2,"가능","초과 "&(Q13-$J$2)&"일")) | W13: =IF(OR(V13="",U13=""),"",V13+U13)
A14: =IF(E14="","",ROW()-5) | O14: =IF(OR(N14="",J14=""),"",N14*J14) | Q14: =IF(OR(P14="",Y14="발주완료",Y14="취소"),"",TODAY()+P14) | R14: =IF(OR(Q14="",NOT(ISNUMBER($J$2))),"",IF(Q14<=$J$2,"가능","초과 "&(Q14-$J$2)&"일")) | W14: =IF(OR(V14="",U14=""),"",V14+U14)
A15: =IF(E15="","",ROW()-5) | O15: =IF(OR(N15="",J15=""),"",N15*J15) | Q15: =IF(OR(P15="",Y15="발주완료",Y15="취소"),"",TODAY()+P15) | R15: =IF(OR(Q15="",NOT(ISNUMBER($J$2))),"",IF(Q15<=$J$2,"가능","초과 "&(Q15-$J$2)&"일")) | W15: =IF(OR(V15="",U15=""),"",V15+U15)
A16: =IF(E16="","",ROW()-5) | O16: =IF(OR(N16="",J16=""),"",N16*J16) | Q16: =IF(OR(P16="",Y16="발주완료",Y16="취소"),"",TODAY()+P16) | R16: =IF(OR(Q16="",NOT(ISNUMBER($J$2))),"",IF(Q16<=$J$2,"가능","초과 "&(Q16-$J$2)&"일")) | W16: =IF(OR(V16="",U16=""),"",V16+U16)
A17: =IF(E17="","",ROW()-5) | O17: =IF(OR(N17="",J17=""),"",N17*J17) | Q17: =IF(OR(P17="",Y17="발주완료",Y17="취소"),"",TODAY()+P17) | R17: =IF(OR(Q17="",NOT(ISNUMBER($J$2))),"",IF(Q17<=$J$2,"가능","초과 "&(Q17-$J$2)&"일")) | W17: =IF(OR(V17="",U17=""),"",V17+U17)
A18: =IF(E18="","",ROW()-5) | O18: =IF(OR(N18="",J18=""),"",N18*J18) | Q18: =IF(OR(P18="",Y18="발주완료",Y18="취소"),"",TODAY()+P18) | R18: =IF(OR(Q18="",NOT(ISNUMBER($J$2))),"",IF(Q18<=$J$2,"가능","초과 "&(Q18-$J$2)&"일")) | W18: =IF(OR(V18="",U18=""),"",V18+U18)
A19: =IF(E19="","",ROW()-5) | O19: =IF(OR(N19="",J19=""),"",N19*J19) | Q19: =IF(OR(P19="",Y19="발주완료",Y19="취소"),"",TODAY()+P19) | R19: =IF(OR(Q19="",NOT(ISNUMBER($J$2))),"",IF(Q19<=$J$2,"가능","초과 "&(Q19-$J$2)&"일")) | W19: =IF(OR(V19="",U19=""),"",V19+U19)
A20: =IF(E20="","",ROW()-5) | O20: =IF(OR(N20="",J20=""),"",N20*J20) | Q20: =IF(OR(P20="",Y20="발주완료",Y20="취소"),"",TODAY()+P20) | R20: =IF(OR(Q20="",NOT(ISNUMBER($J$2))),"",IF(Q20<=$J$2,"가능","초과 "&(Q20-$J$2)&"일")) | W20: =IF(OR(V20="",U20=""),"",V20+U20)
... A205: =IF(E205="","",ROW()-5) | O205: =IF(OR(N205="",J205=""),"",N205*J205) | Q205: =IF(OR(P205="",Y205="발주완료",Y205="취소"),"",TODAY()+P205) | R205: =IF(OR(Q205="",NOT(ISNUMBER($J$2))),"",IF(Q205<=$J$2,"가능","초과 "&(Q205-$J$2)&"일")) | W205: =IF(OR(V205="",U205=""),"",V205+U205)

Sheet MELICERTES
A1: MELICERTES | D1: IMO 9958303 · URGENT · 납품항/ETA: Sabetta, ETA 19-Oct-2026
A2: =IFERROR(IF(N(INDEX(스케줄!$C$5:$C$14,MATCH("MELICERTES",스케줄!$A$5:$A$14,0)))=0,"다음 일정: 미정 (스케줄 시트에 입력)","다음 일정: "&INDEX(스케줄!$B$5:$B$14,MATCH("MELICERTES",스케줄!$A$5:$A$14,0))&" "&TEXT(INDEX(스케줄!$C$5:$C$14,MATCH("MELICERTES",스케줄!$A$5:$A$14,0)),"mm/dd")&IF(N(INDEX(스케줄!$D$5:$D$14,MATCH("MELICERTES",스케줄!$A$5:$A$14,0)))=0,"","~"&TEXT(INDEX(스케줄!$D$5:$D$14,MATCH("MELICERTES",스케줄!$A$5:$A$14,0)),"mm/dd"))),"") | F2: =IFERROR(INDEX(스케줄!$I$5:$I$14,MATCH("MELICERTES",스케줄!$A$5:$A$14,0)),"") | G2: =IFERROR(INDEX(스케줄!$J$5:$J$14,MATCH("MELICERTES",스케줄!$A$5:$A$14,0)),"") | I2: 부산 출고 마감 | J2: =IFERROR(INDEX(스케줄!$F$5:$F$14,MATCH("MELICERTES",스케줄!$A$5:$A$14,0)),"")
A3: 품목 | B3: =COUNTA($E$6:$E$205) | C3: 견적접수 | D3: =COUNTIF($M$6:$M$205,"견적접수") | E3: 확인필요 | F3: =COUNTIF($M$6:$M$205,"확인필요") | G3: 공급불가 | H3: =COUNTIF($M$6:$M$205,"공급불가") | I3: 미접수 | J3: =COUNTIF($M$6:$M$205,"미접수") | K3: 견적금액 합계 (KRW) | M3: =SUM($O$6:$O$205)
A4: 노란 칸 = 입력 / 회색 칸 = 자동 계산 · 새 품목·다른 업체 견적은 아래 빈 줄에 추가 · ▼ 필터로 상태별 보기 · 일정은 '스케줄' 시트에서 수정
A5: No | B5: RFQ No. | C5: 파일 | D5: Maker | E5: 품목 (Item) | F5: Model | G5: Part No. / Drawing | H5: Equipment / System | I5: Spec / 비고 | J5: 수량 | K5: 단위 | L5: 견적업체 | M5: 견적상태 | N5: 단가 (KRW) | O5: 금액 (KRW) | P5: 납기 (일) | Q5: 준비 예상일 | R5: 일정 대비 | S5: 정품/ OEM | T5: 인도조건 | U5: 유효 (일) | V5: 접수일 | W5: 만료일 | X5: 업체 회신 원문 | Y5: 진행상태 | Z5: 다음 조치
A6: =IF(E6="","",ROW()-5) | B6: KQU-000116304 | C6: 01 | D6: NORGREN | E6: Air Filter Element | F6: Hanwha-Man B&W 5G70ME-C10.5-GA | H6: Emission Control System 5672-0260-00001 | I6: Service Kit F05G 40 MIC/ MAKER: NORGREN | J6: 100 | K6: pcs | L6: RMS | M6: 견적접수 | N6: 99500 | O6: =IF(OR(N6="",J6=""),"",N6*J6) | P6: 90 | Q6: =IF(OR(P6="",Y6="발주완료",Y6="취소"),"",TODAY()+P6) | R6: =IF(OR(Q6="",NOT(ISNUMBER($J$2))),"",IF(Q6<=$J$2,"가능","초과 "&(Q6-$J$2)&"일")) | S6: OEM | T6: EX WORK BUSAN | U6: 20 | W6: =IF(OR(V6="",U6=""),"",V6+U6) | X6: D/T: 90 DAYS, OEM, EX WORK BUSAN [VALI: 20 DAYS] | Y6: 검토중 | Z6: 긴급 – 납기 90일, 단축 가능 여부 확인
A7: =IF(E7="","",ROW()-5) | B7: KQU-000116305 | C7: 03 | D7: DANFOSS | E7: Pressure transmitter DANFOSS | F7: DANFOSS | G7: MBS3350 / 0...6 BAR (060G6727) | H7: Main Engine | J7: 1 | K7: PCE | L7: RMS | M7: 견적접수 | N7: 261500 | O7: =IF(OR(N7="",J7=""),"",N7*J7) | P7: 90 | Q7: =IF(OR(P7="",Y7="발주완료",Y7="취소"),"",TODAY()+P7) | R7: =IF(OR(Q7="",NOT(ISNUMBER($J$2))),"",IF(Q7<=$J$2,"가능","초과 "&(Q7-$J$2)&"일")) | S7: GENUINE | T7: EX WORK BUSAN | U7: 20 | W7: =IF(OR(V7="",U7=""),"",V7+U7) | X7: ALL; D/T: 90 DAYS, GENUINE, EX WORK BUSAN [VALI: 20 DAYS] | Y7: 검토중 | Z7: 긴급 – 납기 90일, 단축 가능 여부 확인
A8: =IF(E8="","",ROW()-5) | B8: KQU-000116305 | C8: 03 | D8: DANFOSS | E8: Pressure transmitter DANFOSS | F8: DANFOSS | G8: MBS3300 / -1…15 BAR (060G6736) | H8: Main Engine | J8: 1 | K8: PCE | L8: RMS | M8: 견적접수 | N8: 250000 | O8: =IF(OR(N8="",J8=""),"",N8*J8) | P8: 90 | Q8: =IF(OR(P8="",Y8="발주완료",Y8="취소"),"",TODAY()+P8) | R8: =IF(OR(Q8="",NOT(ISNUMBER($J$2))),"",IF(Q8<=$J$2,"가능","초과 "&(Q8-$J$2)&"일")) | S8: GENUINE | T8: EX WORK BUSAN | U8: 20 | W8: =IF(OR(V8="",U8=""),"",V8+U8) | X8: ALL; D/T: 90 DAYS, GENUINE, EX WORK BUSAN [VALI: 20 DAYS] | Y8: 검토중 | Z8: 긴급 – 납기 90일, 단축 가능 여부 확인
A9: =IF(E9="","",ROW()-5) | B9: KQU-000116305 | C9: 03 | D9: DANFOSS | E9: Pressure transmitter DANFOSS | F9: DANFOSS | G9: MBS9300 / -0.1 ... 0.2 BAR (064G5260) | H9: Main Engine | J9: 1 | K9: PCE | L9: RMS | M9: 견적접수 | N9: 337000 | O9: =IF(OR(N9="",J9=""),"",N9*J9) | P9: 90 | Q9: =IF(OR(P9="",Y9="발주완료",Y9="취소"),"",TODAY()+P9) | R9: =IF(OR(Q9="",NOT(ISNUMBER($J$2))),"",IF(Q9<=$J$2,"가능","초과 "&(Q9-$J$2)&"일")) | S9: GENUINE | T9: EX WORK BUSAN | U9: 20 | W9: =IF(OR(V9="",U9=""),"",V9+U9) | X9: ALL; D/T: 90 DAYS, GENUINE, EX WORK BUSAN [VALI: 20 DAYS] | Y9: 검토중 | Z9: 긴급 – 납기 90일, 단축 가능 여부 확인
A10: =IF(E10="","",ROW()-5) | B10: KQU-000116306 | C10: 04 | D10: WAGO | E10: SD Card for EGR O2 sensors | F10: WAGO / 758-879/000-001 | H10: ME EGR O2 Sensor | J10: 3 | K10: pcs | L10: RMS | M10: 공급불가 | O10: =IF(OR(N10="",J10=""),"",N10*J10) | Q10: =IF(OR(P10="",Y10="발주완료",Y10="취소"),"",TODAY()+P10) | R10: =IF(OR(Q10="",NOT(ISNUMBER($J$2))),"",IF(Q10<=$J$2,"가능","초과 "&(Q10-$J$2)&"일")) | W10: =IF(OR(V10="",U10=""),"",V10+U10) | X10: NOT AVAILABLE | Y10: 타업체 문의 | Z10: 타 업체 견적 요청
A11: =IF(E11="","",ROW()-5) | B11: KQU-000116308 | C11: 07 | D11: VEGA | E11: DIFF. PRESS TRANSMITTER MASTER | F11: VEGABAR 83 | G11: S/N:6290676 Order NO.:3026652/1 2022 | H11: Main Engine EGR Water (1701) | J11: 1 | K11: pce | L11: RMS | M11: 공급불가 | O11: =IF(OR(N11="",J11=""),"",N11*J11) | Q11: =IF(OR(P11="",Y11="발주완료",Y11="취소"),"",TODAY()+P11) | R11: =IF(OR(Q11="",NOT(ISNUMBER($J$2))),"",IF(Q11<=$J$2,"가능","초과 "&(Q11-$J$2)&"일")) | W11: =IF(OR(V11="",U11=""),"",V11+U11) | X11: NOT AVAILABLE | Y11: 타업체 문의 | Z11: 타 업체 견적 요청
A12: =IF(E12="","",ROW()-5) | B12: KQU-000116308 | C12: 07 | D12: VEGA | E12: DIFF. PRESS TRANSMITTER SLAVE | F12: VEGABAR 83 | G12: S/N: 60392712 Order NO.:3029976/2 2022 | H12: Main Engine EGR Water (1701) | J12: 1 | K12: pce | L12: RMS | M12: 공급불가 | O12: =IF(OR(N12="",J12=""),"",N12*J12) | Q12: =IF(OR(P12="",Y12="발주완료",Y12="취소"),"",TODAY()+P12) | R12: =IF(OR(Q12="",NOT(ISNUMBER($J$2))),"",IF(Q12<=$J$2,"가능","초과 "&(Q12-$J$2)&"일")) | W12: =IF(OR(V12="",U12=""),"",V12+U12) | X12: NOT AVAILABLE | Y12: 타업체 문의 | Z12: 타 업체 견적 요청
A13: =IF(E13="","",ROW()-5) | B13: KQU-000116309 | C13: 08 | D13: SIEMENS | E13: Ip Converter Siemens Sipart sp2 | F13: Siemens | G13: C73451-A430-D80 | H13: Main engine | J13: 2 | K13: pcs | L13: RMS | M13: 견적접수 | N13: 870000 | O13: =IF(OR(N13="",J13=""),"",N13*J13) | P13: 60 | Q13: =IF(OR(P13="",Y13="발주완료",Y13="취소"),"",TODAY()+P13) | R13: =IF(OR(Q13="",NOT(ISNUMBER($J$2))),"",IF(Q13<=$J$2,"가능","초과 "&(Q13-$J$2)&"일")) | S13: OEM | T13: EX WORK BUSAN | U13: 20 | W13: =IF(OR(V13="",U13=""),"",V13+U13) | X13: D/T: 60 DAYS, OEM, EX WORK BUSAN [VALI: 20 DAYS] | Y13: 검토중 | Z13: 긴급 – 납기 60일, 단축 가능 여부 확인
A14: =IF(E14="","",ROW()-5) | B14: KQU-000116313 | C14: 15 | D14: AQUAFILTER | E14: AIPRO-20M-QM | F14: TYPE: AQUAFILTER EXCITO-5-B | H14: COMPONENT FOR WATER FOUNTAIN FILTERS | J14: 6 | K14: PCS | L14: RMS | M14: 확인필요 | O14: =IF(OR(N14="",J14=""),"",N14*J14) | Q14: =IF(OR(P14="",Y14="발주완료",Y14="취소"),"",TODAY()+P14) | R14: =IF(OR(Q14="",NOT(ISNUMBER($J$2))),"",IF(Q14<=$J$2,"가능","초과 "&(Q14-$J$2)&"일")) | W14: =IF(OR(V14="",U14=""),"",V14+U14) | X14: NEED TO CHECK ACTUAL PICTURES | Y14: 정보 송부필요 | Z14: 실물 사진 RMS에 송부
A15: =IF(E15="","",ROW()-5) | B15: KQU-000116313 | C15: 15 | D15: AQUAFILTER | E15: AISTRO-2-QM | F15: TYPE: AQUAFILTER EXCITO-5-B | H15: COMPONENT FOR WATER FOUNTAIN FILTERS | J15: 6 | K15: PCS | L15: RMS | M15: 확인필요 | O15: =IF(OR(N15="",J15=""),"",N15*J15) | Q15: =IF(OR(P15="",Y15="발주완료",Y15="취소"),"",TODAY()+P15) | R15: =IF(OR(Q15="",NOT(ISNUMBER($J$2))),"",IF(Q15<=$J$2,"가능","초과 "&(Q15-$J$2)&"일")) | W15: =IF(OR(V15="",U15=""),"",V15+U15) | X15: NEED TO CHECK ACTUAL PICTURES | Y15: 정보 송부필요 | Z15: 실물 사진 RMS에 송부
A16: =IF(E16="","",ROW()-5) | B16: KQU-000116313 | C16: 15 | D16: AQUAFILTER | E16: AICRO-3-QM | F16: TYPE: AQUAFILTER EXCITO-5-B | H16: COMPONENT FOR WATER FOUNTAIN FILTERS | J16: 6 | K16: PCS | L16: RMS | M16: 확인필요 | O16: =IF(OR(N16="",J16=""),"",N16*J16) | Q16: =IF(OR(P16="",Y16="발주완료",Y16="취소"),"",TODAY()+P16) | R16: =IF(OR(Q16="",NOT(ISNUMBER($J$2))),"",IF(Q16<=$J$2,"가능","초과 "&(Q16-$J$2)&"일")) | W16: =IF(OR(V16="",U16=""),"",V16+U16) | X16: NEED TO CHECK ACTUAL PICTURES | Y16: 정보 송부필요 | Z16: 실물 사진 RMS에 송부
A17: =IF(E17="","",ROW()-5) | B17: KQU-000116313 | C17: 15 | D17: AQUAFILTER | E17: AICRO-4-QM | F17: TYPE: AQUAFILTER EXCITO-5-B | H17: COMPONENT FOR WATER FOUNTAIN FILTERS | J17: 6 | K17: PCS | L17: RMS | M17: 확인필요 | O17: =IF(OR(N17="",J17=""),"",N17*J17) | Q17: =IF(OR(P17="",Y17="발주완료",Y17="취소"),"",TODAY()+P17) | R17: =IF(OR(Q17="",NOT(ISNUMBER($J$2))),"",IF(Q17<=$J$2,"가능","초과 "&(Q17-$J$2)&"일")) | W17: =IF(OR(V17="",U17=""),"",V17+U17) | X17: NEED TO CHECK ACTUAL PICTURES | Y17: 정보 송부필요 | Z17: 실물 사진 RMS에 송부
A18: =IF(E18="","",ROW()-5) | B18: KQU-000116313 | C18: 15 | D18: AQUAFILTER | E18: UF MEMBRANE | F18: TYPE: AQUAFILTER EXCITO-5-B | H18: COMPONENT FOR WATER FOUNTAIN FILTERS | J18: 6 | K18: PCS | L18: RMS | M18: 확인필요 | O18: =IF(OR(N18="",J18=""),"",N18*J18) | Q18: =IF(OR(P18="",Y18="발주완료",Y18="취소"),"",TODAY()+P18) | R18: =IF(OR(Q18="",NOT(ISNUMBER($J$2))),"",IF(Q18<=$J$2,"가능","초과 "&(Q18-$J$2)&"일")) | W18: =IF(OR(V18="",U18=""),"",V18+U18) | X18: NEED TO CHECK ACTUAL PICTURES | Y18: 정보 송부필요 | Z18: 실물 사진 RMS에 송부
A19: =IF(E19="","",ROW()-5) | B19: KQU-000116301 | C19: 27 | D19: MRC | E19: Handset with cord | F19: MRC / LVD -115D | H19: Telephone system | I19: RMS: 전화기 ASSY로 견적 | J19: 2 | K19: pcs | L19: RMS | M19: 견적접수 | N19: 390000 | O19: =IF(OR(N19="",J19=""),"",N19*J19) | P19: 14 | Q19: =IF(OR(P19="",Y19="발주완료",Y19="취소"),"",TODAY()+P19) | R19: =IF(OR(Q19="",NOT(ISNUMBER($J$2))),"",IF(Q19<=$J$2,"가능","초과 "&(Q19-$J$2)&"일")) | S19: COMPATIBLE | T19: EX WORK BUSAN | W19: =IF(OR(V19="",U19=""),"",V19+U19) | X19: QUOTE AS TELEPHONE ASSY & NEED TO CHECK IP ADDRESS, ID & PASSWORD // D/T: 10 WORKING DAYS, COMPATIBLE, EX WORK BUSAN | Y19: 정보 송부필요 | Z19: IP 주소·ID·비밀번호 확인해 RMS 회신 / 호환품(COMPATIBLE) 승인 여부 / 유효기간 미기재
A20: =IF(E20="","",ROW()-5) | O20: =IF(OR(N20="",J20=""),"",N20*J20) | Q20: =IF(OR(P20="",Y20="발주완료",Y20="취소"),"",TODAY()+P20) | R20: =IF(OR(Q20="",NOT(ISNUMBER($J$2))),"",IF(Q20<=$J$2,"가능","초과 "&(Q20-$J$2)&"일")) | W20: =IF(OR(V20="",U20=""),"",V20+U20)
A21: =IF(E21="","",ROW()-5) | O21: =IF(OR(N21="",J21=""),"",N21*J21) | Q21: =IF(OR(P21="",Y21="발주완료",Y21="취소"),"",TODAY()+P21) | R21: =IF(OR(Q21="",NOT(ISNUMBER($J$2))),"",IF(Q21<=$J$2,"가능","초과 "&(Q21-$J$2)&"일")) | W21: =IF(OR(V21="",U21=""),"",V21+U21)
A22: =IF(E22="","",ROW()-5) | O22: =IF(OR(N22="",J22=""),"",N22*J22) | Q22: =IF(OR(P22="",Y22="발주완료",Y22="취소"),"",TODAY()+P22) | R22: =IF(OR(Q22="",NOT(ISNUMBER($J$2))),"",IF(Q22<=$J$2,"가능","초과 "&(Q22-$J$2)&"일")) | W22: =IF(OR(V22="",U22=""),"",V22+U22)
A23: =IF(E23="","",ROW()-5) | O23: =IF(OR(N23="",J23=""),"",N23*J23) | Q23: =IF(OR(P23="",Y23="발주완료",Y23="취소"),"",TODAY()+P23) | R23: =IF(OR(Q23="",NOT(ISNUMBER($J$2))),"",IF(Q23<=$J$2,"가능","초과 "&(Q23-$J$2)&"일")) | W23: =IF(OR(V23="",U23=""),"",V23+U23)
A24: =IF(E24="","",ROW()-5) | O24: =IF(OR(N24="",J24=""),"",N24*J24) | Q24: =IF(OR(P24="",Y24="발주완료",Y24="취소"),"",TODAY()+P24) | R24: =IF(OR(Q24="",NOT(ISNUMBER($J$2))),"",IF(Q24<=$J$2,"가능","초과 "&(Q24-$J$2)&"일")) | W24: =IF(OR(V24="",U24=""),"",V24+U24)
A25: =IF(E25="","",ROW()-5) | O25: =IF(OR(N25="",J25=""),"",N25*J25) | Q25: =IF(OR(P25="",Y25="발주완료",Y25="취소"),"",TODAY()+P25) | R25: =IF(OR(Q25="",NOT(ISNUMBER($J$2))),"",IF(Q25<=$J$2,"가능","초과 "&(Q25-$J$2)&"일")) | W25: =IF(OR(V25="",U25=""),"",V25+U25)
A26: =IF(E26="","",ROW()-5) | O26: =IF(OR(N26="",J26=""),"",N26*J26) | Q26: =IF(OR(P26="",Y26="발주완료",Y26="취소"),"",TODAY()+P26) | R26: =IF(OR(Q26="",NOT(ISNUMBER($J$2))),"",IF(Q26<=$J$2,"가능","초과 "&(Q26-$J$2)&"일")) | W26: =IF(OR(V26="",U26=""),"",V26+U26)
A27: =IF(E27="","",ROW()-5) | O27: =IF(OR(N27="",J27=""),"",N27*J27) | Q27: =IF(OR(P27="",Y27="발주완료",Y27="취소"),"",TODAY()+P27) | R27: =IF(OR(Q27="",NOT(ISNUMBER($J$2))),"",IF(Q27<=$J$2,"가능","초과 "&(Q27-$J$2)&"일")) | W27: =IF(OR(V27="",U27=""),"",V27+U27)
A28: =IF(E28="","",ROW()-5) | O28: =IF(OR(N28="",J28=""),"",N28*J28) | Q28: =IF(OR(P28="",Y28="발주완료",Y28="취소"),"",TODAY()+P28) | R28: =IF(OR(Q28="",NOT(ISNUMBER($J$2))),"",IF(Q28<=$J$2,"가능","초과 "&(Q28-$J$2)&"일")) | W28: =IF(OR(V28="",U28=""),"",V28+U28)
A29: =IF(E29="","",ROW()-5) | O29: =IF(OR(N29="",J29=""),"",N29*J29) | Q29: =IF(OR(P29="",Y29="발주완료",Y29="취소"),"",TODAY()+P29) | R29: =IF(OR(Q29="",NOT(ISNUMBER($J$2))),"",IF(Q29<=$J$2,"가능","초과 "&(Q29-$J$2)&"일")) | W29: =IF(OR(V29="",U29=""),"",V29+U29)
A30: =IF(E30="","",ROW()-5) | O30: =IF(OR(N30="",J30=""),"",N30*J30) | Q30: =IF(OR(P30="",Y30="발주완료",Y30="취소"),"",TODAY()+P30) | R30: =IF(OR(Q30="",NOT(ISNUMBER($J$2))),"",IF(Q30<=$J$2,"가능","초과 "&(Q30-$J$2)&"일")) | W30: =IF(OR(V30="",U30=""),"",V30+U30)
A31: =IF(E31="","",ROW()-5) | O31: =IF(OR(N31="",J31=""),"",N31*J31) | Q31: =IF(OR(P31="",Y31="발주완료",Y31="취소"),"",TODAY()+P31) | R31: =IF(OR(Q31="",NOT(ISNUMBER($J$2))),"",IF(Q31<=$J$2,"가능","초과 "&(Q31-$J$2)&"일")) | W31: =IF(OR(V31="",U31=""),"",V31+U31)
... A205: =IF(E205="","",ROW()-5) | O205: =IF(OR(N205="",J205=""),"",N205*J205) | Q205: =IF(OR(P205="",Y205="발주완료",Y205="취소"),"",TODAY()+P205) | R205: =IF(OR(Q205="",NOT(ISNUMBER($J$2))),"",IF(Q205<=$J$2,"가능","초과 "&(Q205-$J$2)&"일")) | W205: =IF(OR(V205="",U205=""),"",V205+U205)

Sheet NELEUS
A1: NELEUS | D1: IMO 9958315 · Routine · 납품항/ETA: TBA
A2: =IFERROR(IF(N(INDEX(스케줄!$C$5:$C$14,MATCH("NELEUS",스케줄!$A$5:$A$14,0)))=0,"다음 일정: 미정 (스케줄 시트에 입력)","다음 일정: "&INDEX(스케줄!$B$5:$B$14,MATCH("NELEUS",스케줄!$A$5:$A$14,0))&" "&TEXT(INDEX(스케줄!$C$5:$C$14,MATCH("NELEUS",스케줄!$A$5:$A$14,0)),"mm/dd")&IF(N(INDEX(스케줄!$D$5:$D$14,MATCH("NELEUS",스케줄!$A$5:$A$14,0)))=0,"","~"&TEXT(INDEX(스케줄!$D$5:$D$14,MATCH("NELEUS",스케줄!$A$5:$A$14,0)),"mm/dd"))),"") | F2: =IFERROR(INDEX(스케줄!$I$5:$I$14,MATCH("NELEUS",스케줄!$A$5:$A$14,0)),"") | G2: =IFERROR(INDEX(스케줄!$J$5:$J$14,MATCH("NELEUS",스케줄!$A$5:$A$14,0)),"") | I2: 부산 출고 마감 | J2: =IFERROR(INDEX(스케줄!$F$5:$F$14,MATCH("NELEUS",스케줄!$A$5:$A$14,0)),"")
A3: 품목 | B3: =COUNTA($E$6:$E$205) | C3: 견적접수 | D3: =COUNTIF($M$6:$M$205,"견적접수") | E3: 확인필요 | F3: =COUNTIF($M$6:$M$205,"확인필요") | G3: 공급불가 | H3: =COUNTIF($M$6:$M$205,"공급불가") | I3: 미접수 | J3: =COUNTIF($M$6:$M$205,"미접수") | K3: 견적금액 합계 (KRW) | M3: =SUM($O$6:$O$205)
A4: 노란 칸 = 입력 / 회색 칸 = 자동 계산 · 새 품목·다른 업체 견적은 아래 빈 줄에 추가 · ▼ 필터로 상태별 보기 · 일정은 '스케줄' 시트에서 수정
A5: No | B5: RFQ No. | C5: 파일 | D5: Maker | E5: 품목 (Item) | F5: Model | G5: Part No. / Drawing | H5: Equipment / System | I5: Spec / 비고 | J5: 수량 | K5: 단위 | L5: 견적업체 | M5: 견적상태 | N5: 단가 (KRW) | O5: 금액 (KRW) | P5: 납기 (일) | Q5: 준비 예상일 | R5: 일정 대비 | S5: 정품/ OEM | T5: 인도조건 | U5: 유효 (일) | V5: 접수일 | W5: 만료일 | X5: 업체 회신 원문 | Y5: 진행상태 | Z5: 다음 조치
A6: =IF(E6="","",ROW()-5) | B6: KQU-000116304 | C6: 01 | D6: NORGREN | E6: Air Filter | F6: Hanwha - MAN B&W 5G70ME-C10.5-GA | G6: Plate/Drawing no. 5672-0260-0001 Part no. 57 | H6: Emission Control System | J6: 6 | K6: set | L6: RMS | M6: 확인필요 | O6: =IF(OR(N6="",J6=""),"",N6*J6) | Q6: =IF(OR(P6="",Y6="발주완료",Y6="취소"),"",TODAY()+P6) | R6: =IF(OR(Q6="",NOT(ISNUMBER($J$2))),"",IF(Q6<=$J$2,"가능","초과 "&(Q6-$J$2)&"일")) | W6: =IF(OR(V6="",U6=""),"",V6+U6) | X6: NEED TO CHECK NAMEPLATE OR DETAILS | Y6: 정보 송부필요 | Z6: 명판 사진/상세정보 RMS에 송부
A7: =IF(E7="","",ROW()-5) | B7: KQU-000116304 | C7: 01 | D7: NORGREN | E7: Service Kit for Air Filter | F7: Norgren / Kit F05G 40 mic | G7: Part no. 3653-28 | H7: Emission Control System | J7: 40 | K7: pcs | L7: RMS | M7: 확인필요 | O7: =IF(OR(N7="",J7=""),"",N7*J7) | Q7: =IF(OR(P7="",Y7="발주완료",Y7="취소"),"",TODAY()+P7) | R7: =IF(OR(Q7="",NOT(ISNUMBER($J$2))),"",IF(Q7<=$J$2,"가능","초과 "&(Q7-$J$2)&"일")) | W7: =IF(OR(V7="",U7=""),"",V7+U7) | X7: NEED TO CHECK NAMEPLATE OR DETAILS | Y7: 정보 송부필요 | Z7: 명판 사진/상세정보 RMS에 송부
A8: =IF(E8="","",ROW()-5) | B8: KQU-000116305 | C8: 03 | D8: DANFOSS | E8: Pressure Transmitter | F8: Danfoss | G8: Type: MBS 3350 Code No.: 060G6529 | H8: Emission Control System | I8: 0...10 bar / 4...20 mA / 10-32 VDC | J8: 2 | K8: pcs | L8: RMS | M8: 견적접수 | N8: 249000 | O8: =IF(OR(N8="",J8=""),"",N8*J8) | P8: 90 | Q8: =IF(OR(P8="",Y8="발주완료",Y8="취소"),"",TODAY()+P8) | R8: =IF(OR(Q8="",NOT(ISNUMBER($J$2))),"",IF(Q8<=$J$2,"가능","초과 "&(Q8-$J$2)&"일")) | S8: GENUINE | T8: EX WORK BUSAN | U8: 20 | W8: =IF(OR(V8="",U8=""),"",V8+U8) | X8: ALL; D/T: 90 DAYS, GENUINE, EX WORK BUSAN [VALI: 20 DAYS] | Y8: 검토중
A9: =IF(E9="","",ROW()-5) | B9: KQU-000116305 | C9: 03 | D9: DANFOSS | E9: Pressure Transmitter | F9: Danfoss | G9: Type: MBS 3300 Code No.: 060G6395 | H9: Emission Control System | I9: 0...10 bar / 4...20 mA / 10-32 VDC | J9: 2 | K9: pcs | L9: RMS | M9: 견적접수 | N9: 180000 | O9: =IF(OR(N9="",J9=""),"",N9*J9) | P9: 90 | Q9: =IF(OR(P9="",Y9="발주완료",Y9="취소"),"",TODAY()+P9) | R9: =IF(OR(Q9="",NOT(ISNUMBER($J$2))),"",IF(Q9<=$J$2,"가능","초과 "&(Q9-$J$2)&"일")) | S9: GENUINE | T9: EX WORK BUSAN | U9: 20 | W9: =IF(OR(V9="",U9=""),"",V9+U9) | X9: ALL; D/T: 90 DAYS, GENUINE, EX WORK BUSAN [VALI: 20 DAYS] | Y9: 검토중
A10: =IF(E10="","",ROW()-5) | O10: =IF(OR(N10="",J10=""),"",N10*J10) | Q10: =IF(OR(P10="",Y10="발주완료",Y10="취소"),"",TODAY()+P10) | R10: =IF(OR(Q10="",NOT(ISNUMBER($J$2))),"",IF(Q10<=$J$2,"가능","초과 "&(Q10-$J$2)&"일")) | W10: =IF(OR(V10="",U10=""),"",V10+U10)
A11: =IF(E11="","",ROW()-5) | O11: =IF(OR(N11="",J11=""),"",N11*J11) | Q11: =IF(OR(P11="",Y11="발주완료",Y11="취소"),"",TODAY()+P11) | R11: =IF(OR(Q11="",NOT(ISNUMBER($J$2))),"",IF(Q11<=$J$2,"가능","초과 "&(Q11-$J$2)&"일")) | W11: =IF(OR(V11="",U11=""),"",V11+U11)
A12: =IF(E12="","",ROW()-5) | O12: =IF(OR(N12="",J12=""),"",N12*J12) | Q12: =IF(OR(P12="",Y12="발주완료",Y12="취소"),"",TODAY()+P12) | R12: =IF(OR(Q12="",NOT(ISNUMBER($J$2))),"",IF(Q12<=$J$2,"가능","초과 "&(Q12-$J$2)&"일")) | W12: =IF(OR(V12="",U12=""),"",V12+U12)
A13: =IF(E13="","",ROW()-5) | O13: =IF(OR(N13="",J13=""),"",N13*J13) | Q13: =IF(OR(P13="",Y13="발주완료",Y13="취소"),"",TODAY()+P13) | R13: =IF(OR(Q13="",NOT(ISNUMBER($J$2))),"",IF(Q13<=$J$2,"가능","초과 "&(Q13-$J$2)&"일")) | W13: =IF(OR(V13="",U13=""),"",V13+U13)
A14: =IF(E14="","",ROW()-5) | O14: =IF(OR(N14="",J14=""),"",N14*J14) | Q14: =IF(OR(P14="",Y14="발주완료",Y14="취소"),"",TODAY()+P14) | R14: =IF(OR(Q14="",NOT(ISNUMBER($J$2))),"",IF(Q14<=$J$2,"가능","초과 "&(Q14-$J$2)&"일")) | W14: =IF(OR(V14="",U14=""),"",V14+U14)
A15: =IF(E15="","",ROW()-5) | O15: =IF(OR(N15="",J15=""),"",N15*J15) | Q15: =IF(OR(P15="",Y15="발주완료",Y15="취소"),"",TODAY()+P15) | R15: =IF(OR(Q15="",NOT(ISNUMBER($J$2))),"",IF(Q15<=$J$2,"가능","초과 "&(Q15-$J$2)&"일")) | W15: =IF(OR(V15="",U15=""),"",V15+U15)
A16: =IF(E16="","",ROW()-5) | O16: =IF(OR(N16="",J16=""),"",N16*J16) | Q16: =IF(OR(P16="",Y16="발주완료",Y16="취소"),"",TODAY()+P16) | R16: =IF(OR(Q16="",NOT(ISNUMBER($J$2))),"",IF(Q16<=$J$2,"가능","초과 "&(Q16-$J$2)&"일")) | W16: =IF(OR(V16="",U16=""),"",V16+U16)
A17: =IF(E17="","",ROW()-5) | O17: =IF(OR(N17="",J17=""),"",N17*J17) | Q17: =IF(OR(P17="",Y17="발주완료",Y17="취소"),"",TODAY()+P17) | R17: =IF(OR(Q17="",NOT(ISNUMBER($J$2))),"",IF(Q17<=$J$2,"가능","초과 "&(Q17-$J$2)&"일")) | W17: =IF(OR(V17="",U17=""),"",V17+U17)
A18: =IF(E18="","",ROW()-5) | O18: =IF(OR(N18="",J18=""),"",N18*J18) | Q18: =IF(OR(P18="",Y18="발주완료",Y18="취소"),"",TODAY()+P18) | R18: =IF(OR(Q18="",NOT(ISNUMBER($J$2))),"",IF(Q18<=$J$2,"가능","초과 "&(Q18-$J$2)&"일")) | W18: =IF(OR(V18="",U18=""),"",V18+U18)
A19: =IF(E19="","",ROW()-5) | O19: =IF(OR(N19="",J19=""),"",N19*J19) | Q19: =IF(OR(P19="",Y19="발주완료",Y19="취소"),"",TODAY()+P19) | R19: =IF(OR(Q19="",NOT(ISNUMBER($J$2))),"",IF(Q19<=$J$2,"가능","초과 "&(Q19-$J$2)&"일")) | W19: =IF(OR(V19="",U19=""),"",V19+U19)
A20: =IF(E20="","",ROW()-5) | O20: =IF(OR(N20="",J20=""),"",N20*J20) | Q20: =IF(OR(P20="",Y20="발주완료",Y20="취소"),"",TODAY()+P20) | R20: =IF(OR(Q20="",NOT(ISNUMBER($J$2))),"",IF(Q20<=$J$2,"가능","초과 "&(Q20-$J$2)&"일")) | W20: =IF(OR(V20="",U20=""),"",V20+U20)
A21: =IF(E21="","",ROW()-5) | O21: =IF(OR(N21="",J21=""),"",N21*J21) | Q21: =IF(OR(P21="",Y21="발주완료",Y21="취소"),"",TODAY()+P21) | R21: =IF(OR(Q21="",NOT(ISNUMBER($J$2))),"",IF(Q21<=$J$2,"가능","초과 "&(Q21-$J$2)&"일")) | W21: =IF(OR(V21="",U21=""),"",V21+U21)
... A205: =IF(E205="","",ROW()-5) | O205: =IF(OR(N205="",J205=""),"",N205*J205) | Q205: =IF(OR(P205="",Y205="발주완료",Y205="취소"),"",TODAY()+P205) | R205: =IF(OR(Q205="",NOT(ISNUMBER($J$2))),"",IF(Q205<=$J$2,"가능","초과 "&(Q205-$J$2)&"일")) | W205: =IF(OR(V205="",U205=""),"",V205+U205)

Sheet ONEIROI
A1: ONEIROI | D1: IMO 9958327 · URGENT · 납품항/ETA: Europe - port TBA
A2: =IFERROR(IF(N(INDEX(스케줄!$C$5:$C$14,MATCH("ONEIROI",스케줄!$A$5:$A$14,0)))=0,"다음 일정: 미정 (스케줄 시트에 입력)","다음 일정: "&INDEX(스케줄!$B$5:$B$14,MATCH("ONEIROI",스케줄!$A$5:$A$14,0))&" "&TEXT(INDEX(스케줄!$C$5:$C$14,MATCH("ONEIROI",스케줄!$A$5:$A$14,0)),"mm/dd")&IF(N(INDEX(스케줄!$D$5:$D$14,MATCH("ONEIROI",스케줄!$A$5:$A$14,0)))=0,"","~"&TEXT(INDEX(스케줄!$D$5:$D$14,MATCH("ONEIROI",스케줄!$A$5:$A$14,0)),"mm/dd"))),"") | F2: =IFERROR(INDEX(스케줄!$I$5:$I$14,MATCH("ONEIROI",스케줄!$A$5:$A$14,0)),"") | G2: =IFERROR(INDEX(스케줄!$J$5:$J$14,MATCH("ONEIROI",스케줄!$A$5:$A$14,0)),"") | I2: 부산 출고 마감 | J2: =IFERROR(INDEX(스케줄!$F$5:$F$14,MATCH("ONEIROI",스케줄!$A$5:$A$14,0)),"")
A3: 품목 | B3: =COUNTA($E$6:$E$205) | C3: 견적접수 | D3: =COUNTIF($M$6:$M$205,"견적접수") | E3: 확인필요 | F3: =COUNTIF($M$6:$M$205,"확인필요") | G3: 공급불가 | H3: =COUNTIF($M$6:$M$205,"공급불가") | I3: 미접수 | J3: =COUNTIF($M$6:$M$205,"미접수") | K3: 견적금액 합계 (KRW) | M3: =SUM($O$6:$O$205)
A4: 노란 칸 = 입력 / 회색 칸 = 자동 계산 · 새 품목·다른 업체 견적은 아래 빈 줄에 추가 · ▼ 필터로 상태별 보기 · 일정은 '스케줄' 시트에서 수정
A5: No | B5: RFQ No. | C5: 파일 | D5: Maker | E5: 품목 (Item) | F5: Model | G5: Part No. / Drawing | H5: Equipment / System | I5: Spec / 비고 | J5: 수량 | K5: 단위 | L5: 견적업체 | M5: 견적상태 | N5: 단가 (KRW) | O5: 금액 (KRW) | P5: 납기 (일) | Q5: 준비 예상일 | R5: 일정 대비 | S5: 정품/ OEM | T5: 인도조건 | U5: 유효 (일) | V5: 접수일 | W5: 만료일 | X5: 업체 회신 원문 | Y5: 진행상태 | Z5: 다음 조치
A6: =IF(E6="","",ROW()-5) | B6: KQU-000116304 | C6: 01 | D6: NORGREN | E6: AIR FILTER ELEMENT | F6: NORGREN F05G-2AN-AM3 | G6: 3653-28 | H6: MAIN ENGINE/ EGR | I6: SERVICE KIT-F05G 40 MIC | J6: 100 | K6: EA | L6: RMS | M6: 확인필요 | O6: =IF(OR(N6="",J6=""),"",N6*J6) | Q6: =IF(OR(P6="",Y6="발주완료",Y6="취소"),"",TODAY()+P6) | R6: =IF(OR(Q6="",NOT(ISNUMBER($J$2))),"",IF(Q6<=$J$2,"가능","초과 "&(Q6-$J$2)&"일")) | W6: =IF(OR(V6="",U6=""),"",V6+U6) | X6: NEED TO CHECK NAMEPLATE OR DETAILS | Y6: 정보 송부필요 | Z6: 명판 사진/상세정보 RMS에 송부
A7: =IF(E7="","",ROW()-5) | B7: KQU-000116300 | C7: 10 | D7: HSME | E7: PMI SENSOR | F7: HSME CORPORATION/ VIHBW-M20-W27-S4 | G7: VIHBW-M20-W27-S4 | H7: MAIN ENGINE/ CYLINDER UNIT | J7: 1 | K7: EA | L7: RMS | M7: 확인필요 | O7: =IF(OR(N7="",J7=""),"",N7*J7) | Q7: =IF(OR(P7="",Y7="발주완료",Y7="취소"),"",TODAY()+P7) | R7: =IF(OR(Q7="",NOT(ISNUMBER($J$2))),"",IF(Q7<=$J$2,"가능","초과 "&(Q7-$J$2)&"일")) | W7: =IF(OR(V7="",U7=""),"",V7+U7) | X7: NEED TO CHECK DETAILED PICTURES. | Y7: 정보 송부필요 | Z7: 상세 사진 RMS에 송부
A8: =IF(E8="","",ROW()-5) | B8: KQU-000116307 | C8: 11 | D8: GRUNDFOS | E8: IMPELLER | F8: GRUNDFOS/PN-SN A-99574543 | G8: Drawings not available | H8: M/E EGR WTS. WATER SUPPLY PUMP | J8: 1 | K8: pcs | L8: RMS | M8: 견적접수 | N8: 34000 | O8: =IF(OR(N8="",J8=""),"",N8*J8) | P8: 9 | Q8: =IF(OR(P8="",Y8="발주완료",Y8="취소"),"",TODAY()+P8) | R8: =IF(OR(Q8="",NOT(ISNUMBER($J$2))),"",IF(Q8<=$J$2,"가능","초과 "&(Q8-$J$2)&"일")) | S8: GENUINE | T8: EX WORK BUSAN | U8: 20 | W8: =IF(OR(V8="",U8=""),"",V8+U8) | X8: D/T: 7 WORKING DAYS, GENUINE, EX WORK BUSAN [VALI: 20 DAYS] | Y8: 검토중 | Z8: 네덜란드 보급 맞춰 포워딩 확인
A9: =IF(E9="","",ROW()-5) | B9: KQU-000116307 | C9: 11 | D9: GRUNDFOS | E9: M/SEAL | F9: GRUNDFOS/PN-SN A-99574543 | G9: Drawings not available | H9: M/E EGR WTS. WATER SUPPLY PUMP | J9: 1 | K9: pcs | L9: RMS | M9: 견적접수 | N9: 290000 | O9: =IF(OR(N9="",J9=""),"",N9*J9) | P9: 9 | Q9: =IF(OR(P9="",Y9="발주완료",Y9="취소"),"",TODAY()+P9) | R9: =IF(OR(Q9="",NOT(ISNUMBER($J$2))),"",IF(Q9<=$J$2,"가능","초과 "&(Q9-$J$2)&"일")) | S9: GENUINE | T9: EX WORK BUSAN | U9: 20 | W9: =IF(OR(V9="",U9=""),"",V9+U9) | X9: D/T: 7 WORKING DAYS, GENUINE, EX WORK BUSAN [VALI: 20 DAYS] | Y9: 검토중 | Z9: 네덜란드 보급 맞춰 포워딩 확인
A10: =IF(E10="","",ROW()-5) | B10: KQU-000116314 | C10: 25 | D10: HACCP MASTER | E10: Cooking Range Hot Plate | F10: HACCP MASTER / ER641 | G10: A4-210x297 - 5 | H10: Galley & Laundry equipment. Electric Cooking Range | I10: Low insulation, Details on drawing | J10: 4 | K10: pcs | L10: RMS | M10: 견적접수 | N10: 320000 | O10: =IF(OR(N10="",J10=""),"",N10*J10) | P10: 3 | Q10: =IF(OR(P10="",Y10="발주완료",Y10="취소"),"",TODAY()+P10) | R10: =IF(OR(Q10="",NOT(ISNUMBER($J$2))),"",IF(Q10<=$J$2,"가능","초과 "&(Q10-$J$2)&"일")) | S10: GENUINE | T10: EX WORK BUSAN | W10: =IF(OR(V10="",U10=""),"",V10+U10) | X10: D/T: 3 DAYS, GENUINE, EX WORK BUSAN | Y10: 검토중 | Z10: 유효기간 미기재 – RMS 확인
A11: =IF(E11="","",ROW()-5) | B11: 선박요청서-30 | C11: 30 | D11: Parker | E11: Solenoid Valve for Ballast Hyd. System D1VW4CNJWF (THR TYPE) | F11: Parker | G11: VPKVVDV4301 | H11: Hyd.VRC | I11: DWG:VO61-W2008-9 / RMS: 신형 D1VW004CNJW로 견적 | J11: 3 | K11: pcs | L11: RMS | M11: 견적접수 | N11: 500000 | O11: =IF(OR(N11="",J11=""),"",N11*J11) | P11: 90 | Q11: =IF(OR(P11="",Y11="발주완료",Y11="취소"),"",TODAY()+P11) | R11: =IF(OR(Q11="",NOT(ISNUMBER($J$2))),"",IF(Q11<=$J$2,"가능","초과 "&(Q11-$J$2)&"일")) | S11: GENUINE | T11: EX WORK BUSAN | U11: 20 | W11: =IF(OR(V11="",U11=""),"",V11+U11) | X11: #1 = QUOTE AS NEW TYPE: D1VW004CNJW (OBSOLETE D1VW4CNJWF) / D/T: 90 DAYS, GENUINE, EX WORK BUSAN [VALI: 20 DAYS] | Y11: 검토중 | Z11: 신형 대체품 호환 확인
A12: =IF(E12="","",ROW()-5) | B12: 선박요청서-30 | C12: 30 | D12: Parker | E12: Solenoid Valve for Ballast Hyd. System D1VW20DNJWF (O/S TYPE) | F12: Parker | G12: VPKVVDV4201 | H12: Hyd.VRC | I12: DWG:VO61-W2008-10 / RMS: 신형 D1VW020DNJW로 견적 | J12: 3 | K12: pcs | L12: RMS | M12: 견적접수 | N12: 649000 | O12: =IF(OR(N12="",J12=""),"",N12*J12) | P12: 90 | Q12: =IF(OR(P12="",Y12="발주완료",Y12="취소"),"",TODAY()+P12) | R12: =IF(OR(Q12="",NOT(ISNUMBER($J$2))),"",IF(Q12<=$J$2,"가능","초과 "&(Q12-$J$2)&"일")) | S12: GENUINE | T12: EX WORK BUSAN | U12: 20 | W12: =IF(OR(V12="",U12=""),"",V12+U12) | X12: #2 = QUOTE AS NEW TYPE: D1VW020DNJW (OBSOLETE D1VW020DNJW) / D/T: 90 DAYS, GENUINE, EX WORK BUSAN [VALI: 20 DAYS] | Y12: 검토중 | Z12: 신형 대체품 호환 확인 (RMS 비고의 OBSOLETE 형번 오기 확인)
A13: =IF(E13="","",ROW()-5) | B13: 선박요청서-30 | C13: 30 | E13: Solenoid Valve for Ballast Hyd. System DHW-0713P | G13: VATVDV43001 | H13: Hyd.VRC | I13: DWG:VO61-W2008-6 | J13: 3 | K13: pcs | L13: RMS | M13: 공급불가 | O13: =IF(OR(N13="",J13=""),"",N13*J13) | Q13: =IF(OR(P13="",Y13="발주완료",Y13="취소"),"",TODAY()+P13) | R13: =IF(OR(Q13="",NOT(ISNUMBER($J$2))),"",IF(Q13<=$J$2,"가능","초과 "&(Q13-$J$2)&"일")) | W13: =IF(OR(V13="",U13=""),"",V13+U13) | X13: NOT AVAILABLE | Y13: 타업체 문의 | Z13: 타 업체 견적 요청
A14: =IF(E14="","",ROW()-5) | B14: 선박요청서-30 | C14: 30 | E14: Solenoid Valve for Ballast Hyd. System DHW-0751/2 | G14: VATVDV42005 | H14: Hyd.VRC | I14: DWG:VO61-W2008-7 | J14: 3 | K14: pcs | L14: RMS | M14: 공급불가 | O14: =IF(OR(N14="",J14=""),"",N14*J14) | Q14: =IF(OR(P14="",Y14="발주완료",Y14="취소"),"",TODAY()+P14) | R14: =IF(OR(Q14="",NOT(ISNUMBER($J$2))),"",IF(Q14<=$J$2,"가능","초과 "&(Q14-$J$2)&"일")) | W14: =IF(OR(V14="",U14=""),"",V14+U14) | X14: NOT AVAILABLE | Y14: 타업체 문의 | Z14: 타 업체 견적 요청
A15: =IF(E15="","",ROW()-5) | B15: 선박요청서-31 | C15: 31 | D15: GRUNDFOS | E15: PUMP COMPLETE | F15: GRUNDFOS/CRN3-7 | H15: ME EGR WTS PUMP | I15: RMS: 모터 포함 펌프 완품으로 견적 | J15: 1 | K15: SET | L15: RMS | M15: 견적접수 | N15: 1996560 | O15: =IF(OR(N15="",J15=""),"",N15*J15) | P15: 10 | Q15: =IF(OR(P15="",Y15="발주완료",Y15="취소"),"",TODAY()+P15) | R15: =IF(OR(Q15="",NOT(ISNUMBER($J$2))),"",IF(Q15<=$J$2,"가능","초과 "&(Q15-$J$2)&"일")) | S15: GENUINE | T15: EX WORK BUSAN | U15: 20 | W15: =IF(OR(V15="",U15=""),"",V15+U15) | X15: #1 = QUOTE AS PUMP WITH MOTOR COMPLETE (→ Motor Rated voltage : 3 x 220-255D / 380-440Y V, 60HZ에 사용 됩니다. / ALL: D/T: 10 DAYS, GENUINE, EX WORK BUSAN [VALI: 20 DAYS] | Y15: 검토중 | Z15: 모터 전압/60Hz 선내 사양 일치 확인
A16: =IF(E16="","",ROW()-5) | B16: 선박요청서-31 | C16: 31 | D16: GRUNDFOS | E16: O-RING | F16: GRUNDFOS/CRN3-7 | G16: CRN3-7-37 | H16: ME EGR WTS PUMP | J16: 4 | K16: EA | L16: RMS | M16: 견적접수 | N16: 16638 | O16: =IF(OR(N16="",J16=""),"",N16*J16) | P16: 10 | Q16: =IF(OR(P16="",Y16="발주완료",Y16="취소"),"",TODAY()+P16) | R16: =IF(OR(Q16="",NOT(ISNUMBER($J$2))),"",IF(Q16<=$J$2,"가능","초과 "&(Q16-$J$2)&"일")) | S16: GENUINE | T16: EX WORK BUSAN | U16: 20 | W16: =IF(OR(V16="",U16=""),"",V16+U16) | X16: ALL: D/T: 10 DAYS, GENUINE, EX WORK BUSAN [VALI: 20 DAYS] | Y16: 검토중
A17: =IF(E17="","",ROW()-5) | B17: 선박요청서-31 | C17: 31 | D17: GRUNDFOS | E17: CHAMBER | F17: GRUNDFOS/CRN3-7 | G17: CRN3-7-4 | H17: ME EGR WTS PUMP | J17: 8 | K17: EA | L17: RMS | M17: 견적접수 | N17: 44368 | O17: =IF(OR(N17="",J17=""),"",N17*J17) | P17: 10 | Q17: =IF(OR(P17="",Y17="발주완료",Y17="취소"),"",TODAY()+P17) | R17: =IF(OR(Q17="",NOT(ISNUMBER($J$2))),"",IF(Q17<=$J$2,"가능","초과 "&(Q17-$J$2)&"일")) | S17: GENUINE | T17: EX WORK BUSAN | U17: 20 | W17: =IF(OR(V17="",U17=""),"",V17+U17) | X17: ALL: D/T: 10 DAYS, GENUINE, EX WORK BUSAN [VALI: 20 DAYS] | Y17: 검토중
A18: =IF(E18="","",ROW()-5) | B18: 선박요청서-31 | C18: 31 | D18: GRUNDFOS | E18: CHAMBER WITH BEARING | F18: GRUNDFOS/CRN3-7 | G18: CRN3-7-4A | H18: ME EGR WTS PUMP | J18: 2 | K18: EA | L18: RMS | M18: 견적접수 | N18: 49914 | O18: =IF(OR(N18="",J18=""),"",N18*J18) | P18: 10 | Q18: =IF(OR(P18="",Y18="발주완료",Y18="취소"),"",TODAY()+P18) | R18: =IF(OR(Q18="",NOT(ISNUMBER($J$2))),"",IF(Q18<=$J$2,"가능","초과 "&(Q18-$J$2)&"일")) | S18: GENUINE | T18: EX WORK BUSAN | U18: 20 | W18: =IF(OR(V18="",U18=""),"",V18+U18) | X18: ALL: D/T: 10 DAYS, GENUINE, EX WORK BUSAN [VALI: 20 DAYS] | Y18: 검토중
A19: =IF(E19="","",ROW()-5) | B19: 선박요청서-31 | C19: 31 | D19: GRUNDFOS | E19: SPACING PIPE | F19: GRUNDFOS/CRN3-7 | G19: CRN3-7-64 | H19: ME EGR WTS PUMP | J19: 7 | K19: EA | L19: RMS | M19: 견적접수 | N19: 9982.8 | O19: =IF(OR(N19="",J19=""),"",N19*J19) | P19: 10 | Q19: =IF(OR(P19="",Y19="발주완료",Y19="취소"),"",TODAY()+P19) | R19: =IF(OR(Q19="",NOT(ISNUMBER($J$2))),"",IF(Q19<=$J$2,"가능","초과 "&(Q19-$J$2)&"일")) | S19: GENUINE | T19: EX WORK BUSAN | U19: 20 | W19: =IF(OR(V19="",U19=""),"",V19+U19) | X19: ALL: D/T: 10 DAYS, GENUINE, EX WORK BUSAN [VALI: 20 DAYS] | Y19: 검토중
A20: =IF(E20="","",ROW()-5) | B20: 선박요청서-31 | C20: 31 | D20: GRUNDFOS | E20: SPACING PIPE | F20: GRUNDFOS/CRN3-7 | G20: CRN3-7-64A | H20: ME EGR WTS PUMP | J20: 2 | K20: EA | L20: RMS | M20: 견적접수 | N20: 6655.2 | O20: =IF(OR(N20="",J20=""),"",N20*J20) | P20: 10 | Q20: =IF(OR(P20="",Y20="발주완료",Y20="취소"),"",TODAY()+P20) | R20: =IF(OR(Q20="",NOT(ISNUMBER($J$2))),"",IF(Q20<=$J$2,"가능","초과 "&(Q20-$J$2)&"일")) | S20: GENUINE | T20: EX WORK BUSAN | U20: 20 | W20: =IF(OR(V20="",U20=""),"",V20+U20) | X20: ALL: D/T: 10 DAYS, GENUINE, EX WORK BUSAN [VALI: 20 DAYS] | Y20: 검토중
A21: =IF(E21="","",ROW()-5) | B21: 선박요청서-31 | C21: 31 | D21: GRUNDFOS | E21: SPACING PIPE | F21: GRUNDFOS/CRN3-7 | G21: CRN3-7-64C | H21: ME EGR WTS PUMP | J21: 2 | K21: EA | L21: RMS | M21: 견적접수 | N21: 27730 | O21: =IF(OR(N21="",J21=""),"",N21*J21) | P21: 10 | Q21: =IF(OR(P21="",Y21="발주완료",Y21="취소"),"",TODAY()+P21) | R21: =IF(OR(Q21="",NOT(ISNUMBER($J$2))),"",IF(Q21<=$J$2,"가능","초과 "&(Q21-$J$2)&"일")) | S21: GENUINE | T21: EX WORK BUSAN | U21: 20 | W21: =IF(OR(V21="",U21=""),"",V21+U21) | X21: ALL: D/T: 10 DAYS, GENUINE, EX WORK BUSAN [VALI: 20 DAYS] | Y21: 검토중
A22: =IF(E22="","",ROW()-5) | B22: 선박요청서-31 | C22: 31 | D22: GRUNDFOS | E22: PACKING FOR IMPELLER | F22: GRUNDFOS/CRN3-8 | H22: ME EGR WTS PUMP | J22: 14 | K22: EA | L22: RMS | M22: 공급불가 | O22: =IF(OR(N22="",J22=""),"",N22*J22) | Q22: =IF(OR(P22="",Y22="발주완료",Y22="취소"),"",TODAY()+P22) | R22: =IF(OR(Q22="",NOT(ISNUMBER($J$2))),"",IF(Q22<=$J$2,"가능","초과 "&(Q22-$J$2)&"일")) | W22: =IF(OR(V22="",U22=""),"",V22+U22) | X22: NOT AVAILABLE | Y22: 타업체 문의 | Z22: 타 업체 견적 요청
A23: =IF(E23="","",ROW()-5) | B23: 선박요청서-31 | C23: 31 | D23: GRUNDFOS | E23: IMPELLER | F23: GRUNDFOS/CRN3-7 | G23: CRN3-7-49 | H23: ME EGR WTS PUMP | J23: 8 | K23: EA | L23: RMS | M23: 견적접수 | N23: 33276 | O23: =IF(OR(N23="",J23=""),"",N23*J23) | P23: 10 | Q23: =IF(OR(P23="",Y23="발주완료",Y23="취소"),"",TODAY()+P23) | R23: =IF(OR(Q23="",NOT(ISNUMBER($J$2))),"",IF(Q23<=$J$2,"가능","초과 "&(Q23-$J$2)&"일")) | S23: GENUINE | T23: EX WORK BUSAN | U23: 20 | W23: =IF(OR(V23="",U23=""),"",V23+U23) | X23: ALL: D/T: 10 DAYS, GENUINE, EX WORK BUSAN [VALI: 20 DAYS] | Y23: 검토중
A24: =IF(E24="","",ROW()-5) | B24: 선박요청서-31 | C24: 31 | D24: GRUNDFOS | E24: IMPELLER, SPECIAL | F24: GRUNDFOS/CRN3-7 | G24: CRN3-7-49G | H24: ME EGR WTS PUMP | J24: 2 | K24: EA | L24: RMS | M24: 공급불가 | O24: =IF(OR(N24="",J24=""),"",N24*J24) | Q24: =IF(OR(P24="",Y24="발주완료",Y24="취소"),"",TODAY()+P24) | R24: =IF(OR(Q24="",NOT(ISNUMBER($J$2))),"",IF(Q24<=$J$2,"가능","초과 "&(Q24-$J$2)&"일")) | W24: =IF(OR(V24="",U24=""),"",V24+U24) | X24: NOT AVAILABLE | Y24: 타업체 문의 | Z24: 타 업체 견적 요청
A25: =IF(E25="","",ROW()-5) | B25: 선박요청서-31 | C25: 31 | D25: GRUNDFOS | E25: WASHER | F25: GRUNDFOS/CRN3-7 | G25: CRN3-7-66 | H25: ME EGR WTS PUMP | J25: 4 | K25: EA | L25: RMS | M25: 견적접수 | N25: 14419.6 | O25: =IF(OR(N25="",J25=""),"",N25*J25) | P25: 10 | Q25: =IF(OR(P25="",Y25="발주완료",Y25="취소"),"",TODAY()+P25) | R25: =IF(OR(Q25="",NOT(ISNUMBER($J$2))),"",IF(Q25<=$J$2,"가능","초과 "&(Q25-$J$2)&"일")) | S25: GENUINE | T25: EX WORK BUSAN | U25: 20 | W25: =IF(OR(V25="",U25=""),"",V25+U25) | X25: ALL: D/T: 10 DAYS, GENUINE, EX WORK BUSAN [VALI: 20 DAYS] | Y25: 검토중
A26: =IF(E26="","",ROW()-5) | B26: 선박요청서-31 | C26: 31 | D26: GRUNDFOS | E26: NUT | F26: GRUNDFOS/CRN3-7 | G26: CRN3-7-67 | H26: ME EGR WTS PUMP | J26: 2 | K26: EA | L26: RMS | M26: 견적접수 | N26: 8873.6 | O26: =IF(OR(N26="",J26=""),"",N26*J26) | P26: 10 | Q26: =IF(OR(P26="",Y26="발주완료",Y26="취소"),"",TODAY()+P26) | R26: =IF(OR(Q26="",NOT(ISNUMBER($J$2))),"",IF(Q26<=$J$2,"가능","초과 "&(Q26-$J$2)&"일")) | S26: GENUINE | T26: EX WORK BUSAN | U26: 20 | W26: =IF(OR(V26="",U26=""),"",V26+U26) | X26: ALL: D/T: 10 DAYS, GENUINE, EX WORK BUSAN [VALI: 20 DAYS] | Y26: 검토중
A27: =IF(E27="","",ROW()-5) | B27: 선박요청서-31 | C27: 31 | D27: GRUNDFOS | E27: M/SEAL | F27: GRUNDFOS/CRN3-7 | H27: ME EGR WTS PUMP | J27: 2 | K27: SET | L27: RMS | M27: 견적접수 | N27: 288392 | O27: =IF(OR(N27="",J27=""),"",N27*J27) | P27: 10 | Q27: =IF(OR(P27="",Y27="발주완료",Y27="취소"),"",TODAY()+P27) | R27: =IF(OR(Q27="",NOT(ISNUMBER($J$2))),"",IF(Q27<=$J$2,"가능","초과 "&(Q27-$J$2)&"일")) | S27: GENUINE | T27: EX WORK BUSAN | U27: 20 | W27: =IF(OR(V27="",U27=""),"",V27+U27) | X27: ALL: D/T: 10 DAYS, GENUINE, EX WORK BUSAN [VALI: 20 DAYS] | Y27: 검토중
A28: =IF(E28="","",ROW()-5) | B28: 선박요청서-31 | C28: 31 | D28: GRUNDFOS | E28: BEARING RING | F28: GRUNDFOS/CRN3-7 | G28: CRN3-7-47A | H28: ME EGR WTS PUMP | J28: 2 | K28: EA | L28: RMS | M28: 견적접수 | N28: 33276 | O28: =IF(OR(N28="",J28=""),"",N28*J28) | P28: 10 | Q28: =IF(OR(P28="",Y28="발주완료",Y28="취소"),"",TODAY()+P28) | R28: =IF(OR(Q28="",NOT(ISNUMBER($J$2))),"",IF(Q28<=$J$2,"가능","초과 "&(Q28-$J$2)&"일")) | S28: GENUINE | T28: EX WORK BUSAN | U28: 20 | W28: =IF(OR(V28="",U28=""),"",V28+U28) | X28: ALL: D/T: 10 DAYS, GENUINE, EX WORK BUSAN [VALI: 20 DAYS] | Y28: 검토중
A29: =IF(E29="","",ROW()-5) | O29: =IF(OR(N29="",J29=""),"",N29*J29) | Q29: =IF(OR(P29="",Y29="발주완료",Y29="취소"),"",TODAY()+P29) | R29: =IF(OR(Q29="",NOT(ISNUMBER($J$2))),"",IF(Q29<=$J$2,"가능","초과 "&(Q29-$J$2)&"일")) | W29: =IF(OR(V29="",U29=""),"",V29+U29)
A30: =IF(E30="","",ROW()-5) | O30: =IF(OR(N30="",J30=""),"",N30*J30) | Q30: =IF(OR(P30="",Y30="발주완료",Y30="취소"),"",TODAY()+P30) | R30: =IF(OR(Q30="",NOT(ISNUMBER($J$2))),"",IF(Q30<=$J$2,"가능","초과 "&(Q30-$J$2)&"일")) | W30: =IF(OR(V30="",U30=""),"",V30+U30)
A31: =IF(E31="","",ROW()-5) | O31: =IF(OR(N31="",J31=""),"",N31*J31) | Q31: =IF(OR(P31="",Y31="발주완료",Y31="취소"),"",TODAY()+P31) | R31: =IF(OR(Q31="",NOT(ISNUMBER($J$2))),"",IF(Q31<=$J$2,"가능","초과 "&(Q31-$J$2)&"일")) | W31: =IF(OR(V31="",U31=""),"",V31+U31)
A32: =IF(E32="","",ROW()-5) | O32: =IF(OR(N32="",J32=""),"",N32*J32) | Q32: =IF(OR(P32="",Y32="발주완료",Y32="취소"),"",TODAY()+P32) | R32: =IF(OR(Q32="",NOT(ISNUMBER($J$2))),"",IF(Q32<=$J$2,"가능","초과 "&(Q32-$J$2)&"일")) | W32: =IF(OR(V32="",U32=""),"",V32+U32)
A33: =IF(E33="","",ROW()-5) | O33: =IF(OR(N33="",J33=""),"",N33*J33) | Q33: =IF(OR(P33="",Y33="발주완료",Y33="취소"),"",TODAY()+P33) | R33: =IF(OR(Q33="",NOT(ISNUMBER($J$2))),"",IF(Q33<=$J$2,"가능","초과 "&(Q33-$J$2)&"일")) | W33: =IF(OR(V33="",U33=""),"",V33+U33)
A34: =IF(E34="","",ROW()-5) | O34: =IF(OR(N34="",J34=""),"",N34*J34) | Q34: =IF(OR(P34="",Y34="발주완료",Y34="취소"),"",TODAY()+P34) | R34: =IF(OR(Q34="",NOT(ISNUMBER($J$2))),"",IF(Q34<=$J$2,"가능","초과 "&(Q34-$J$2)&"일")) | W34: =IF(OR(V34="",U34=""),"",V34+U34)
A35: =IF(E35="","",ROW()-5) | O35: =IF(OR(N35="",J35=""),"",N35*J35) | Q35: =IF(OR(P35="",Y35="발주완료",Y35="취소"),"",TODAY()+P35) | R35: =IF(OR(Q35="",NOT(ISNUMBER($J$2))),"",IF(Q35<=$J$2,"가능","초과 "&(Q35-$J$2)&"일")) | W35: =IF(OR(V35="",U35=""),"",V35+U35)
A36: =IF(E36="","",ROW()-5) | O36: =IF(OR(N36="",J36=""),"",N36*J36) | Q36: =IF(OR(P36="",Y36="발주완료",Y36="취소"),"",TODAY()+P36) | R36: =IF(OR(Q36="",NOT(ISNUMBER($J$2))),"",IF(Q36<=$J$2,"가능","초과 "&(Q36-$J$2)&"일")) | W36: =IF(OR(V36="",U36=""),"",V36+U36)
A37: =IF(E37="","",ROW()-5) | O37: =IF(OR(N37="",J37=""),"",N37*J37) | Q37: =IF(OR(P37="",Y37="발주완료",Y37="취소"),"",TODAY()+P37) | R37: =IF(OR(Q37="",NOT(ISNUMBER($J$2))),"",IF(Q37<=$J$2,"가능","초과 "&(Q37-$J$2)&"일")) | W37: =IF(OR(V37="",U37=""),"",V37+U37)
A38: =IF(E38="","",ROW()-5) | O38: =IF(OR(N38="",J38=""),"",N38*J38) | Q38: =IF(OR(P38="",Y38="발주완료",Y38="취소"),"",TODAY()+P38) | R38: =IF(OR(Q38="",NOT(ISNUMBER($J$2))),"",IF(Q38<=$J$2,"가능","초과 "&(Q38-$J$2)&"일")) | W38: =IF(OR(V38="",U38=""),"",V38+U38)
A39: =IF(E39="","",ROW()-5) | O39: =IF(OR(N39="",J39=""),"",N39*J39) | Q39: =IF(OR(P39="",Y39="발주완료",Y39="취소"),"",TODAY()+P39) | R39: =IF(OR(Q39="",NOT(ISNUMBER($J$2))),"",IF(Q39<=$J$2,"가능","초과 "&(Q39-$J$2)&"일")) | W39: =IF(OR(V39="",U39=""),"",V39+U39)
A40: =IF(E40="","",ROW()-5) | O40: =IF(OR(N40="",J40=""),"",N40*J40) | Q40: =IF(OR(P40="",Y40="발주완료",Y40="취소"),"",TODAY()+P40) | R40: =IF(OR(Q40="",NOT(ISNUMBER($J$2))),"",IF(Q40<=$J$2,"가능","초과 "&(Q40-$J$2)&"일")) | W40: =IF(OR(V40="",U40=""),"",V40+U40)
...

Sheet RFQ목록
A1: RFQ 목록 (발송한 견적요청서)
A2: RFQ별로 몇 품목이 견적 들어왔는지 선박 시트에서 자동 집계 · 새 RFQ는 빈 줄에 추가
A4: 파일 | B4: RFQ No. | C4: Maker | D4: Category | E4: RFQ일 | F4: 대상 선박 | G4: 품목수 | H4: 견적접수 | I4: 확인필요 | J4: 공급불가 | K4: 미접수/ 미입력 | L4: 견적금액 (KRW) | M4: 비고
A5: 01 | B5: KQU-000116304 | C5: NORGREN (EGR air filters & service kits) | D5: Main Engine | E5: 46314 | F5: AEOLUS / MELICERTES / NELEUS / ONEIROI | G5: 6 | H5: =IF($B5="","",COUNTIFS('AEOLUS'!$B$6:$B$205,$B5,'AEOLUS'!$M$6:$M$205,"견적접수")+COUNTIFS('MELICERTES'!$B$6:$B$205,$B5,'MELICERTES'!$M$6:$M$205,"견적접수")+COUNTIFS('NELEUS'!$B$6:$B$205,$B5,'NELEUS'!$M$6:$M$205,"견적접수")+COUNTIFS('ONEIROI'!$B$6:$B$205,$B5,'ONEIROI'!$M$6:$M$205,"견적접수")) | I5: =IF($B5="","",COUNTIFS('AEOLUS'!$B$6:$B$205,$B5,'AEOLUS'!$M$6:$M$205,"확인필요")+COUNTIFS('MELICERTES'!$B$6:$B$205,$B5,'MELICERTES'!$M$6:$M$205,"확인필요")+COUNTIFS('NELEUS'!$B$6:$B$205,$B5,'NELEUS'!$M$6:$M$205,"확인필요")+COUNTIFS('ONEIROI'!$B$6:$B$205,$B5,'ONEIROI'!$M$6:$M$205,"확인필요")) | J5: =IF($B5="","",COUNTIFS('AEOLUS'!$B$6:$B$205,$B5,'AEOLUS'!$M$6:$M$205,"공급불가")+COUNTIFS('MELICERTES'!$B$6:$B$205,$B5,'MELICERTES'!$M$6:$M$205,"공급불가")+COUNTIFS('NELEUS'!$B$6:$B$205,$B5,'NELEUS'!$M$6:$M$205,"공급불가")+COUNTIFS('ONEIROI'!$B$6:$B$205,$B5,'ONEIROI'!$M$6:$M$205,"공급불가")) | K5: =IF(OR($B5="",G5=""),"",G5-H5-I5-J5) | L5: =IF($B5="","",SUMIFS('AEOLUS'!$O$6:$O$205,'AEOLUS'!$B$6:$B$205,$B5)+SUMIFS('MELICERTES'!$O$6:$O$205,'MELICERTES'!$B$6:$B$205,$B5)+SUMIFS('NELEUS'!$O$6:$O$205,'NELEUS'!$B$6:$B$205,$B5)+SUMIFS('ONEIROI'!$O$6:$O$205,'ONEIROI'!$B$6:$B$205,$B5)) | M5: RMS 회신
A6: 03 | B6: KQU-000116305 | C6: DANFOSS (pressure transmitters) | D6: Main Engine | E6: 46314 | F6: MELICERTES / NELEUS | G6: 5 | H6: =IF($B6="","",COUNTIFS('AEOLUS'!$B$6:$B$205,$B6,'AEOLUS'!$M$6:$M$205,"견적접수")+COUNTIFS('MELICERTES'!$B$6:$B$205,$B6,'MELICERTES'!$M$6:$M$205,"견적접수")+COUNTIFS('NELEUS'!$B$6:$B$205,$B6,'NELEUS'!$M$6:$M$205,"견적접수")+COUNTIFS('ONEIROI'!$B$6:$B$205,$B6,'ONEIROI'!$M$6:$M$205,"견적접수")) | I6: =IF($B6="","",COUNTIFS('AEOLUS'!$B$6:$B$205,$B6,'AEOLUS'!$M$6:$M$205,"확인필요")+COUNTIFS('MELICERTES'!$B$6:$B$205,$B6,'MELICERTES'!$M$6:$M$205,"확인필요")+COUNTIFS('NELEUS'!$B$6:$B$205,$B6,'NELEUS'!$M$6:$M$205,"확인필요")+COUNTIFS('ONEIROI'!$B$6:$B$205,$B6,'ONEIROI'!$M$6:$M$205,"확인필요")) | J6: =IF($B6="","",COUNTIFS('AEOLUS'!$B$6:$B$205,$B6,'AEOLUS'!$M$6:$M$205,"공급불가")+COUNTIFS('MELICERTES'!$B$6:$B$205,$B6,'MELICERTES'!$M$6:$M$205,"공급불가")+COUNTIFS('NELEUS'!$B$6:$B$205,$B6,'NELEUS'!$M$6:$M$205,"공급불가")+COUNTIFS('ONEIROI'!$B$6:$B$205,$B6,'ONEIROI'!$M$6:$M$205,"공급불가")) | K6: =IF(OR($B6="",G6=""),"",G6-H6-I6-J6) | L6: =IF($B6="","",SUMIFS('AEOLUS'!$O$6:$O$205,'AEOLUS'!$B$6:$B$205,$B6)+SUMIFS('MELICERTES'!$O$6:$O$205,'MELICERTES'!$B$6:$B$205,$B6)+SUMIFS('NELEUS'!$O$6:$O$205,'NELEUS'!$B$6:$B$205,$B6)+SUMIFS('ONEIROI'!$O$6:$O$205,'ONEIROI'!$B$6:$B$205,$B6)) | M6: RMS 회신
A7: 04 | B7: KQU-000116306 | C7: WAGO | D7: Main Engine | E7: 46314 | F7: AEOLUS / MELICERTES | G7: 2 | H7: =IF($B7="","",COUNTIFS('AEOLUS'!$B$6:$B$205,$B7,'AEOLUS'!$M$6:$M$205,"견적접수")+COUNTIFS('MELICERTES'!$B$6:$B$205,$B7,'MELICERTES'!$M$6:$M$205,"견적접수")+COUNTIFS('NELEUS'!$B$6:$B$205,$B7,'NELEUS'!$M$6:$M$205,"견적접수")+COUNTIFS('ONEIROI'!$B$6:$B$205,$B7,'ONEIROI'!$M$6:$M$205,"견적접수")) | I7: =IF($B7="","",COUNTIFS('AEOLUS'!$B$6:$B$205,$B7,'AEOLUS'!$M$6:$M$205,"확인필요")+COUNTIFS('MELICERTES'!$B$6:$B$205,$B7,'MELICERTES'!$M$6:$M$205,"확인필요")+COUNTIFS('NELEUS'!$B$6:$B$205,$B7,'NELEUS'!$M$6:$M$205,"확인필요")+COUNTIFS('ONEIROI'!$B$6:$B$205,$B7,'ONEIROI'!$M$6:$M$205,"확인필요")) | J7: =IF($B7="","",COUNTIFS('AEOLUS'!$B$6:$B$205,$B7,'AEOLUS'!$M$6:$M$205,"공급불가")+COUNTIFS('MELICERTES'!$B$6:$B$205,$B7,'MELICERTES'!$M$6:$M$205,"공급불가")+COUNTIFS('NELEUS'!$B$6:$B$205,$B7,'NELEUS'!$M$6:$M$205,"공급불가")+COUNTIFS('ONEIROI'!$B$6:$B$205,$B7,'ONEIROI'!$M$6:$M$205,"공급불가")) | K7: =IF(OR($B7="",G7=""),"",G7-H7-I7-J7) | L7: =IF($B7="","",SUMIFS('AEOLUS'!$O$6:$O$205,'AEOLUS'!$B$6:$B$205,$B7)+SUMIFS('MELICERTES'!$O$6:$O$205,'MELICERTES'!$B$6:$B$205,$B7)+SUMIFS('NELEUS'!$O$6:$O$205,'NELEUS'!$B$6:$B$205,$B7)+SUMIFS('ONEIROI'!$O$6:$O$205,'ONEIROI'!$B$6:$B$205,$B7)) | M7: RMS 회신
A8: 07 | B8: KQU-000116308 | C8: VEGA (VEGABAR 83) | D8: Main Engine | E8: 46314 | F8: MELICERTES | G8: 2 | H8: =IF($B8="","",COUNTIFS('AEOLUS'!$B$6:$B$205,$B8,'AEOLUS'!$M$6:$M$205,"견적접수")+COUNTIFS('MELICERTES'!$B$6:$B$205,$B8,'MELICERTES'!$M$6:$M$205,"견적접수")+COUNTIFS('NELEUS'!$B$6:$B$205,$B8,'NELEUS'!$M$6:$M$205,"견적접수")+COUNTIFS('ONEIROI'!$B$6:$B$205,$B8,'ONEIROI'!$M$6:$M$205,"견적접수")) | I8: =IF($B8="","",COUNTIFS('AEOLUS'!$B$6:$B$205,$B8,'AEOLUS'!$M$6:$M$205,"확인필요")+COUNTIFS('MELICERTES'!$B$6:$B$205,$B8,'MELICERTES'!$M$6:$M$205,"확인필요")+COUNTIFS('NELEUS'!$B$6:$B$205,$B8,'NELEUS'!$M$6:$M$205,"확인필요")+COUNTIFS('ONEIROI'!$B$6:$B$205,$B8,'ONEIROI'!$M$6:$M$205,"확인필요")) | J8: =IF($B8="","",COUNTIFS('AEOLUS'!$B$6:$B$205,$B8,'AEOLUS'!$M$6:$M$205,"공급불가")+COUNTIFS('MELICERTES'!$B$6:$B$205,$B8,'MELICERTES'!$M$6:$M$205,"공급불가")+COUNTIFS('NELEUS'!$B$6:$B$205,$B8,'NELEUS'!$M$6:$M$205,"공급불가")+COUNTIFS('ONEIROI'!$B$6:$B$205,$B8,'ONEIROI'!$M$6:$M$205,"공급불가")) | K8: =IF(OR($B8="",G8=""),"",G8-H8-I8-J8) | L8: =IF($B8="","",SUMIFS('AEOLUS'!$O$6:$O$205,'AEOLUS'!$B$6:$B$205,$B8)+SUMIFS('MELICERTES'!$O$6:$O$205,'MELICERTES'!$B$6:$B$205,$B8)+SUMIFS('NELEUS'!$O$6:$O$205,'NELEUS'!$B$6:$B$205,$B8)+SUMIFS('ONEIROI'!$O$6:$O$205,'ONEIROI'!$B$6:$B$205,$B8)) | M8: RMS 회신
A9: 08 | B9: KQU-000116309 | C9: SIEMENS (SIPART PS2 I/P converter) | D9: Main Engine | E9: 46314 | F9: MELICERTES | G9: 1 | H9: =IF($B9="","",COUNTIFS('AEOLUS'!$B$6:$B$205,$B9,'AEOLUS'!$M$6:$M$205,"견적접수")+COUNTIFS('MELICERTES'!$B$6:$B$205,$B9,'MELICERTES'!$M$6:$M$205,"견적접수")+COUNTIFS('NELEUS'!$B$6:$B$205,$B9,'NELEUS'!$M$6:$M$205,"견적접수")+COUNTIFS('ONEIROI'!$B$6:$B$205,$B9,'ONEIROI'!$M$6:$M$205,"견적접수")) | I9: =IF($B9="","",COUNTIFS('AEOLUS'!$B$6:$B$205,$B9,'AEOLUS'!$M$6:$M$205,"확인필요")+COUNTIFS('MELICERTES'!$B$6:$B$205,$B9,'MELICERTES'!$M$6:$M$205,"확인필요")+COUNTIFS('NELEUS'!$B$6:$B$205,$B9,'NELEUS'!$M$6:$M$205,"확인필요")+COUNTIFS('ONEIROI'!$B$6:$B$205,$B9,'ONEIROI'!$M$6:$M$205,"확인필요")) | J9: =IF($B9="","",COUNTIFS('AEOLUS'!$B$6:$B$205,$B9,'AEOLUS'!$M$6:$M$205,"공급불가")+COUNTIFS('MELICERTES'!$B$6:$B$205,$B9,'MELICERTES'!$M$6:$M$205,"공급불가")+COUNTIFS('NELEUS'!$B$6:$B$205,$B9,'NELEUS'!$M$6:$M$205,"공급불가")+COUNTIFS('ONEIROI'!$B$6:$B$205,$B9,'ONEIROI'!$M$6:$M$205,"공급불가")) | K9: =IF(OR($B9="",G9=""),"",G9-H9-I9-J9) | L9: =IF($B9="","",SUMIFS('AEOLUS'!$O$6:$O$205,'AEOLUS'!$B$6:$B$205,$B9)+SUMIFS('MELICERTES'!$O$6:$O$205,'MELICERTES'!$B$6:$B$205,$B9)+SUMIFS('NELEUS'!$O$6:$O$205,'NELEUS'!$B$6:$B$205,$B9)+SUMIFS('ONEIROI'!$O$6:$O$205,'ONEIROI'!$B$6:$B$205,$B9)) | M9: RMS 회신
A10: 10 | B10: KQU-000116300 | C10: HSME (PMI sensor) | D10: Main Engine | E10: 46314 | F10: ONEIROI | G10: 1 | H10: =IF($B10="","",COUNTIFS('AEOLUS'!$B$6:$B$205,$B10,'AEOLUS'!$M$6:$M$205,"견적접수")+COUNTIFS('MELICERTES'!$B$6:$B$205,$B10,'MELICERTES'!$M$6:$M$205,"견적접수")+COUNTIFS('NELEUS'!$B$6:$B$205,$B10,'NELEUS'!$M$6:$M$205,"견적접수")+COUNTIFS('ONEIROI'!$B$6:$B$205,$B10,'ONEIROI'!$M$6:$M$205,"견적접수")) | I10: =IF($B10="","",COUNTIFS('AEOLUS'!$B$6:$B$205,$B10,'AEOLUS'!$M$6:$M$205,"확인필요")+COUNTIFS('MELICERTES'!$B$6:$B$205,$B10,'MELICERTES'!$M$6:$M$205,"확인필요")+COUNTIFS('NELEUS'!$B$6:$B$205,$B10,'NELEUS'!$M$6:$M$205,"확인필요")+COUNTIFS('ONEIROI'!$B$6:$B$205,$B10,'ONEIROI'!$M$6:$M$205,"확인필요")) | J10: =IF($B10="","",COUNTIFS('AEOLUS'!$B$6:$B$205,$B10,'AEOLUS'!$M$6:$M$205,"공급불가")+COUNTIFS('MELICERTES'!$B$6:$B$205,$B10,'MELICERTES'!$M$6:$M$205,"공급불가")+COUNTIFS('NELEUS'!$B$6:$B$205,$B10,'NELEUS'!$M$6:$M$205,"공급불가")+COUNTIFS('ONEIROI'!$B$6:$B$205,$B10,'ONEIROI'!$M$6:$M$205,"공급불가")) | K10: =IF(OR($B10="",G10=""),"",G10-H10-I10-J10) | L10: =IF($B10="","",SUMIFS('AEOLUS'!$O$6:$O$205,'AEOLUS'!$B$6:$B$205,$B10)+SUMIFS('MELICERTES'!$O$6:$O$205,'MELICERTES'!$B$6:$B$205,$B10)+SUMIFS('NELEUS'!$O$6:$O$205,'NELEUS'!$B$6:$B$205,$B10)+SUMIFS('ONEIROI'!$O$6:$O$205,'ONEIROI'!$B$6:$B$205,$B10)) | M10: RMS 회신
