Workbook

Sheet 요약
B2: OPEX 요약 - 업체별 / 선박별
B3: 단위: KRW (부가세 포함 합계 기준). 'OPEX 상세' 시트에서 자동 집계. USD 적용환율: | I3: =설정!$C$4 -> 1350
A5: No | B5: 업체명 | C5: NORTH LIGHT | D5: NORTH MOON | E5: NORTH OCEAN | F5: NORTH VALLEY | G5: OFFICE | H5: 공통(미배분) | I5: 업체 총합계 | K5: 공급가액 | L5: 부가세 | M5: 추가가능 부가세 | N5: VAT추가 시 예상 총액 | O5: 상태
A6: 1 | B6: 고려문화사 | C6: =SUMIFS('OPEX 상세'!$Q$5:$Q$280,'OPEX 상세'!$C$5:$C$280,$B6,'OPEX 상세'!$D$5:$D$280,C$5) -> 0 | D6: =SUMIFS('OPEX 상세'!$Q$5:$Q$280,'OPEX 상세'!$C$5:$C$280,$B6,'OPEX 상세'!$D$5:$D$280,D$5) -> 0 | E6: =SUMIFS('OPEX 상세'!$Q$5:$Q$280,'OPEX 상세'!$C$5:$C$280,$B6,'OPEX 상세'!$D$5:$D$280,E$5) -> 0 | F6: =SUMIFS('OPEX 상세'!$Q$5:$Q$280,'OPEX 상세'!$C$5:$C$280,$B6,'OPEX 상세'!$D$5:$D$280,F$5) -> 0 | G6: =SUMIFS('OPEX 상세'!$Q$5:$Q$280,'OPEX 상세'!$C$5:$C$280,$B6,'OPEX 상세'!$D$5:$D$280,G$5) -> 0 | H6: =SUMIFS('OPEX 상세'!$Q$5:$Q$280,'OPEX 상세'!$C$5:$C$280,$B6,'OPEX 상세'!$D$5:$D$280,H$5) -> 1302400 | I6: =SUM(C6:H6) -> 1302400 | K6: =SUMIFS('OPEX 상세'!$O$5:$O$280,'OPEX 상세'!$C$5:$C$280,$B6) -> 1184000 | L6: =SUMIFS('OPEX 상세'!$P$5:$P$280,'OPEX 상세'!$C$5:$C$280,$B6) -> 118400 | M6: =SUMIFS('OPEX 상세'!$S$5:$S$280,'OPEX 상세'!$C$5:$C$280,$B6) -> 0 | N6: =I6+M6 -> 1302400 | O6: =IF(COUNTIF('OPEX 상세'!$C$5:$C$280,$B6)=0,"입력대기",IF(M6>0,"VAT 추가 가능",""))
A7: 2 | B7: 네오맥스 | C7: =SUMIFS('OPEX 상세'!$Q$5:$Q$280,'OPEX 상세'!$C$5:$C$280,$B7,'OPEX 상세'!$D$5:$D$280,C$5) -> 0 | D7: =SUMIFS('OPEX 상세'!$Q$5:$Q$280,'OPEX 상세'!$C$5:$C$280,$B7,'OPEX 상세'!$D$5:$D$280,D$5) -> 0 | E7: =SUMIFS('OPEX 상세'!$Q$5:$Q$280,'OPEX 상세'!$C$5:$C$280,$B7,'OPEX 상세'!$D$5:$D$280,E$5) -> 0 | F7: =SUMIFS('OPEX 상세'!$Q$5:$Q$280,'OPEX 상세'!$C$5:$C$280,$B7,'OPEX 상세'!$D$5:$D$280,F$5) -> 0 | G7: =SUMIFS('OPEX 상세'!$Q$5:$Q$280,'OPEX 상세'!$C$5:$C$280,$B7,'OPEX 상세'!$D$5:$D$280,G$5) -> 0 | H7: =SUMIFS('OPEX 상세'!$Q$5:$Q$280,'OPEX 상세'!$C$5:$C$280,$B7,'OPEX 상세'!$D$5:$D$280,H$5) -> 0 | I7: =SUM(C7:H7) -> 0 | K7: =SUMIFS('OPEX 상세'!$O$5:$O$280,'OPEX 상세'!$C$5:$C$280,$B7) -> 0 | L7: =SUMIFS('OPEX 상세'!$P$5:$P$280,'OPEX 상세'!$C$5:$C$280,$B7) -> 0 | M7: =SUMIFS('OPEX 상세'!$S$5:$S$280,'OPEX 상세'!$C$5:$C$280,$B7) -> 0 | N7: =I7+M7 -> 0 | O7: =IF(COUNTIF('OPEX 상세'!$C$5:$C$280,$B7)=0,"입력대기",IF(M7>0,"VAT 추가 가능","")) -> 입력대기
A8: 3 | B8: 디앤오 | C8: =SUMIFS('OPEX 상세'!$Q$5:$Q$280,'OPEX 상세'!$C$5:$C$280,$B8,'OPEX 상세'!$D$5:$D$280,C$5) -> 7620000 | D8: =SUMIFS('OPEX 상세'!$Q$5:$Q$280,'OPEX 상세'!$C$5:$C$280,$B8,'OPEX 상세'!$D$5:$D$280,D$5) -> 7620000 | E8: =SUMIFS('OPEX 상세'!$Q$5:$Q$280,'OPEX 상세'!$C$5:$C$280,$B8,'OPEX 상세'!$D$5:$D$280,E$5) -> 38880000 | F8: =SUMIFS('OPEX 상세'!$Q$5:$Q$280,'OPEX 상세'!$C$5:$C$280,$B8,'OPEX 상세'!$D$5:$D$280,F$5) -> 38880000 | G8: =SUMIFS('OPEX 상세'!$Q$5:$Q$280,'OPEX 상세'!$C$5:$C$280,$B8,'OPEX 상세'!$D$5:$D$280,G$5) -> 0 | H8: =SUMIFS('OPEX 상세'!$Q$5:$Q$280,'OPEX 상세'!$C$5:$C$280,$B8,'OPEX 상세'!$D$5:$D$280,H$5) -> 0 | I8: =SUM(C8:H8) -> 93000000 | K8: =SUMIFS('OPEX 상세'!$O$5:$O$280,'OPEX 상세'!$C$5:$C$280,$B8) -> 93000000 | L8: =SUMIFS('OPEX 상세'!$P$5:$P$280,'OPEX 상세'!$C$5:$C$280,$B8) -> 0 | M8: =SUMIFS('OPEX 상세'!$S$5:$S$280,'OPEX 상세'!$C$5:$C$280,$B8) -> 0 | N8: =I8+M8 -> 93000000 | O8: =IF(COUNTIF('OPEX 상세'!$C$5:$C$280,$B8)=0,"입력대기",IF(M8>0,"VAT 추가 가능",""))
A9: 4 | B9: 비아이자이로 | C9: =SUMIFS('OPEX 상세'!$Q$5:$Q$280,'OPEX 상세'!$C$5:$C$280,$B9,'OPEX 상세'!$D$5:$D$280,C$5) -> 41790000 | D9: =SUMIFS('OPEX 상세'!$Q$5:$Q$280,'OPEX 상세'!$C$5:$C$280,$B9,'OPEX 상세'!$D$5:$D$280,D$5) -> 41090000 | E9: =SUMIFS('OPEX 상세'!$Q$5:$Q$280,'OPEX 상세'!$C$5:$C$280,$B9,'OPEX 상세'!$D$5:$D$280,E$5) -> 40840000 | F9: =SUMIFS('OPEX 상세'!$Q$5:$Q$280,'OPEX 상세'!$C$5:$C$280,$B9,'OPEX 상세'!$D$5:$D$280,F$5) -> 42500000 | G9: =SUMIFS('OPEX 상세'!$Q$5:$Q$280,'OPEX 상세'!$C$5:$C$280,$B9,'OPEX 상세'!$D$5:$D$280,G$5) -> 0 | H9: =SUMIFS('OPEX 상세'!$Q$5:$Q$280,'OPEX 상세'!$C$5:$C$280,$B9,'OPEX 상세'!$D$5:$D$280,H$5) -> 0 | I9: =SUM(C9:H9) -> 166220000 | K9: =SUMIFS('OPEX 상세'!$O$5:$O$280,'OPEX 상세'!$C$5:$C$280,$B9) -> 166220000 | L9: =SUMIFS('OPEX 상세'!$P$5:$P$280,'OPEX 상세'!$C$5:$C$280,$B9) -> 0 | M9: =SUMIFS('OPEX 상세'!$S$5:$S$280,'OPEX 상세'!$C$5:$C$280,$B9) -> 0 | N9: =I9+M9 -> 166220000 | O9: =IF(COUNTIF('OPEX 상세'!$C$5:$C$280,$B9)=0,"입력대기",IF(M9>0,"VAT 추가 가능",""))
A10: 5 | B10: 시웨이글로벌 | C10: =SUMIFS('OPEX 상세'!$Q$5:$Q$280,'OPEX 상세'!$C$5:$C$280,$B10,'OPEX 상세'!$D$5:$D$280,C$5) -> 0 | D10: =SUMIFS('OPEX 상세'!$Q$5:$Q$280,'OPEX 상세'!$C$5:$C$280,$B10,'OPEX 상세'!$D$5:$D$280,D$5) -> 0 | E10: =SUMIFS('OPEX 상세'!$Q$5:$Q$280,'OPEX 상세'!$C$5:$C$280,$B10,'OPEX 상세'!$D$5:$D$280,E$5) -> 0 | F10: =SUMIFS('OPEX 상세'!$Q$5:$Q$280,'OPEX 상세'!$C$5:$C$280,$B10,'OPEX 상세'!$D$5:$D$280,F$5) -> 0 | G10: =SUMIFS('OPEX 상세'!$Q$5:$Q$280,'OPEX 상세'!$C$5:$C$280,$B10,'OPEX 상세'!$D$5:$D$280,G$5) -> 0 | H10: =SUMIFS('OPEX 상세'!$Q$5:$Q$280,'OPEX 상세'!$C$5:$C$280,$B10,'OPEX 상세'!$D$5:$D$280,H$5) -> 27300000 | I10: =SUM(C10:H10) -> 27300000 | K10: =SUMIFS('OPEX 상세'!$O$5:$O$280,'OPEX 상세'!$C$5:$C$280,$B10) -> 27300000 | L10: =SUMIFS('OPEX 상세'!$P$5:$P$280,'OPEX 상세'!$C$5:$C$280,$B10) -> 0 | M10: =SUMIFS('OPEX 상세'!$S$5:$S$280,'OPEX 상세'!$C$5:$C$280,$B10) -> 2730000 | N10: =I10+M10 -> 30030000 | O10: =IF(COUNTIF('OPEX 상세'!$C$5:$C$280,$B10)=0,"입력대기",IF(M10>0,"VAT 추가 가능","")) -> VAT 추가 가능
A11: 6 | B11: 옥슨앤파트너스 | C11: =SUMIFS('OPEX 상세'!$Q$5:$Q$280,'OPEX 상세'!$C$5:$C$280,$B11,'OPEX 상세'!$D$5:$D$280,C$5) -> 55145066 | D11: =SUMIFS('OPEX 상세'!$Q$5:$Q$280,'OPEX 상세'!$C$5:$C$280,$B11,'OPEX 상세'!$D$5:$D$280,D$5) -> 92090802 | E11: =SUMIFS('OPEX 상세'!$Q$5:$Q$280,'OPEX 상세'!$C$5:$C$280,$B11,'OPEX 상세'!$D$5:$D$280,E$5) -> 81692477 | F11: =SUMIFS('OPEX 상세'!$Q$5:$Q$280,'OPEX 상세'!$C$5:$C$280,$B11,'OPEX 상세'!$D$5:$D$280,F$5) -> 49108352 | G11: =SUMIFS('OPEX 상세'!$Q$5:$Q$280,'OPEX 상세'!$C$5:$C$280,$B11,'OPEX 상세'!$D$5:$D$280,G$5) -> 241500 | H11: =SUMIFS('OPEX 상세'!$Q$5:$Q$280,'OPEX 상세'!$C$5:$C$280,$B11,'OPEX 상세'!$D$5:$D$280,H$5) -> 0 | I11: =SUM(C11:H11) -> 278278197 | K11: =SUMIFS('OPEX 상세'!$O$5:$O$280,'OPEX 상세'!$C$5:$C$280,$B11) -> 278278197 | L11: =SUMIFS('OPEX 상세'!$P$5:$P$280,'OPEX 상세'!$C$5:$C$280,$B11) -> 0 | M11: =SUMIFS('OPEX 상세'!$S$5:$S$280,'OPEX 상세'!$C$5:$C$280,$B11) -> 0 | N11: =I11+M11 -> 278278197 | O11: =IF(COUNTIF('OPEX 상세'!$C$5:$C$280,$B11)=0,"입력대기",IF(M11>0,"VAT 추가 가능",""))
A12: 7 | B12: 제이앤캐이 | C12: =SUMIFS('OPEX 상세'!$Q$5:$Q$280,'OPEX 상세'!$C$5:$C$280,$B12,'OPEX 상세'!$D$5:$D$280,C$5) -> 36551070 | D12: =SUMIFS('OPEX 상세'!$Q$5:$Q$280,'OPEX 상세'!$C$5:$C$280,$B12,'OPEX 상세'!$D$5:$D$280,D$5) -> 45255564 | E12: =SUMIFS('OPEX 상세'!$Q$5:$Q$280,'OPEX 상세'!$C$5:$C$280,$B12,'OPEX 상세'!$D$5:$D$280,E$5) -> 59556592 | F12: =SUMIFS('OPEX 상세'!$Q$5:$Q$280,'OPEX 상세'!$C$5:$C$280,$B12,'OPEX 상세'!$D$5:$D$280,F$5) -> 53916216 | G12: =SUMIFS('OPEX 상세'!$Q$5:$Q$280,'OPEX 상세'!$C$5:$C$280,$B12,'OPEX 상세'!$D$5:$D$280,G$5) -> 0 | H12: =SUMIFS('OPEX 상세'!$Q$5:$Q$280,'OPEX 상세'!$C$5:$C$280,$B12,'OPEX 상세'!$D$5:$D$280,H$5) -> 0 | I12: =SUM(C12:H12) -> 195279442 | K12: =SUMIFS('OPEX 상세'!$O$5:$O$280,'OPEX 상세'!$C$5:$C$280,$B12) -> 195279442 | L12: =SUMIFS('OPEX 상세'!$P$5:$P$280,'OPEX 상세'!$C$5:$C$280,$B12) -> 0 | M12: =SUMIFS('OPEX 상세'!$S$5:$S$280,'OPEX 상세'!$C$5:$C$280,$B12) -> 0 | N12: =I12+M12 -> 195279442 | O12: =IF(COUNTIF('OPEX 상세'!$C$5:$C$280,$B12)=0,"입력대기",IF(M12>0,"VAT 추가 가능",""))
A13: 8 | B13: 한국해양개발 | C13: =SUMIFS('OPEX 상세'!$Q$5:$Q$280,'OPEX 상세'!$C$5:$C$280,$B13,'OPEX 상세'!$D$5:$D$280,C$5) -> 1030200 | D13: =SUMIFS('OPEX 상세'!$Q$5:$Q$280,'OPEX 상세'!$C$5:$C$280,$B13,'OPEX 상세'!$D$5:$D$280,D$5) -> 1809200 | E13: =SUMIFS('OPEX 상세'!$Q$5:$Q$280,'OPEX 상세'!$C$5:$C$280,$B13,'OPEX 상세'!$D$5:$D$280,E$5) -> 1809200 | F13: =SUMIFS('OPEX 상세'!$Q$5:$Q$280,'OPEX 상세'!$C$5:$C$280,$B13,'OPEX 상세'!$D$5:$D$280,F$5) -> 1809200 | G13: =SUMIFS('OPEX 상세'!$Q$5:$Q$280,'OPEX 상세'!$C$5:$C$280,$B13,'OPEX 상세'!$D$5:$D$280,G$5) -> 0 | H13: =SUMIFS('OPEX 상세'!$Q$5:$Q$280,'OPEX 상세'!$C$5:$C$280,$B13,'OPEX 상세'!$D$5:$D$280,H$5) -> 0 | I13: =SUM(C13:H13) -> 6457800 | K13: =SUMIFS('OPEX 상세'!$O$5:$O$280,'OPEX 상세'!$C$5:$C$280,$B13) -> 6421000 | L13: =SUMIFS('OPEX 상세'!$P$5:$P$280,'OPEX 상세'!$C$5:$C$280,$B13) -> 36800 | M13: =SUMIFS('OPEX 상세'!$S$5:$S$280,'OPEX 상세'!$C$5:$C$280,$B13) -> 0 | N13: =I13+M13 -> 6457800 | O13: =IF(COUNTIF('OPEX 상세'!$C$5:$C$280,$B13)=0,"입력대기",IF(M13>0,"VAT 추가 가능",""))
A14: 9 | B14: 한일후지코리아 | C14: =SUMIFS('OPEX 상세'!$Q$5:$Q$280,'OPEX 상세'!$C$5:$C$280,$B14,'OPEX 상세'!$D$5:$D$280,C$5) -> 0 | D14: =SUMIFS('OPEX 상세'!$Q$5:$Q$280,'OPEX 상세'!$C$5:$C$280,$B14,'OPEX 상세'!$D$5:$D$280,D$5) -> 0 | E14: =SUMIFS('OPEX 상세'!$Q$5:$Q$280,'OPEX 상세'!$C$5:$C$280,$B14,'OPEX 상세'!$D$5:$D$280,E$5) -> 0 | F14: =SUMIFS('OPEX 상세'!$Q$5:$Q$280,'OPEX 상세'!$C$5:$C$280,$B14,'OPEX 상세'!$D$5:$D$280,F$5) -> 0 | G14: =SUMIFS('OPEX 상세'!$Q$5:$Q$280,'OPEX 상세'!$C$5:$C$280,$B14,'OPEX 상세'!$D$5:$D$280,G$5) -> 0 | H14: =SUMIFS('OPEX 상세'!$Q$5:$Q$280,'OPEX 상세'!$C$5:$C$280,$B14,'OPEX 상세'!$D$5:$D$280,H$5) -> 0 | I14: =SUM(C14:H14) -> 0 | K14: =SUMIFS('OPEX 상세'!$O$5:$O$280,'OPEX 상세'!$C$5:$C$280,$B14) -> 0 | L14: =SUMIFS('OPEX 상세'!$P$5:$P$280,'OPEX 상세'!$C$5:$C$280,$B14) -> 0 | M14: =SUMIFS('OPEX 상세'!$S$5:$S$280,'OPEX 상세'!$C$5:$C$280,$B14) -> 0 | N14: =I14+M14 -> 0 | O14: =IF(COUNTIF('OPEX 상세'!$C$5:$C$280,$B14)=0,"입력대기",IF(M14>0,"VAT 추가 가능","")) -> 입력대기
A15: 10 | B15: 해인쉽스서비스 | C15: =SUMIFS('OPEX 상세'!$Q$5:$Q$280,'OPEX 상세'!$C$5:$C$280,$B15,'OPEX 상세'!$D$5:$D$280,C$5) -> 10206800 | D15: =SUMIFS('OPEX 상세'!$Q$5:$Q$280,'OPEX 상세'!$C$5:$C$280,$B15,'OPEX 상세'!$D$5:$D$280,D$5) -> 3120000 | E15: =SUMIFS('OPEX 상세'!$Q$5:$Q$280,'OPEX 상세'!$C$5:$C$280,$B15,'OPEX 상세'!$D$5:$D$280,E$5) -> 18017500 | F15: =SUMIFS('OPEX 상세'!$Q$5:$Q$280,'OPEX 상세'!$C$5:$C$280,$B15,'OPEX 상세'!$D$5:$D$280,F$5) -> 9932500 | G15: =SUMIFS('OPEX 상세'!$Q$5:$Q$280,'OPEX 상세'!$C$5:$C$280,$B15,'OPEX 상세'!$D$5:$D$280,G$5) -> 0 | H15: =SUMIFS('OPEX 상세'!$Q$5:$Q$280,'OPEX 상세'!$C$5:$C$280,$B15,'OPEX 상세'!$D$5:$D$280,H$5) -> 0 | I15: =SUM(C15:H15) -> 41276800 | K15: =SUMIFS('OPEX 상세'!$O$5:$O$280,'OPEX 상세'!$C$5:$C$280,$B15) -> 41276800 | L15: =SUMIFS('OPEX 상세'!$P$5:$P$280,'OPEX 상세'!$C$5:$C$280,$B15) -> 0 | M15: =SUMIFS('OPEX 상세'!$S$5:$S$280,'OPEX 상세'!$C$5:$C$280,$B15) -> 0 | N15: =I15+M15 -> 41276800 | O15: =IF(COUNTIF('OPEX 상세'!$C$5:$C$280,$B15)=0,"입력대기",IF(M15>0,"VAT 추가 가능",""))
A16: 11 | B16: 화인컴에스이 | C16: =SUMIFS('OPEX 상세'!$Q$5:$Q$280,'OPEX 상세'!$C$5:$C$280,$B16,'OPEX 상세'!$D$5:$D$280,C$5) -> 0 | D16: =SUMIFS('OPEX 상세'!$Q$5:$Q$280,'OPEX 상세'!$C$5:$C$280,$B16,'OPEX 상세'!$D$5:$D$280,D$5) -> 0 | E16: =SUMIFS('OPEX 상세'!$Q$5:$Q$280,'OPEX 상세'!$C$5:$C$280,$B16,'OPEX 상세'!$D$5:$D$280,E$5) -> 0 | F16: =SUMIFS('OPEX 상세'!$Q$5:$Q$280,'OPEX 상세'!$C$5:$C$280,$B16,'OPEX 상세'!$D$5:$D$280,F$5) -> 0 | G16: =SUMIFS('OPEX 상세'!$Q$5:$Q$280,'OPEX 상세'!$C$5:$C$280,$B16,'OPEX 상세'!$D$5:$D$280,G$5) -> 0 | H16: =SUMIFS('OPEX 상세'!$Q$5:$Q$280,'OPEX 상세'!$C$5:$C$280,$B16,'OPEX 상세'!$D$5:$D$280,H$5) -> 12600000 | I16: =SUM(C16:H16) -> 12600000 | K16: =SUMIFS('OPEX 상세'!$O$5:$O$280,'OPEX 상세'!$C$5:$C$280,$B16) -> 12600000 | L16: =SUMIFS('OPEX 상세'!$P$5:$P$280,'OPEX 상세'!$C$5:$C$280,$B16) -> 0 | M16: =SUMIFS('OPEX 상세'!$S$5:$S$280,'OPEX 상세'!$C$5:$C$280,$B16) -> 1260000 | N16: =I16+M16 -> 13860000 | O16: =IF(COUNTIF('OPEX 상세'!$C$5:$C$280,$B16)=0,"입력대기",IF(M16>0,"VAT 추가 가능","")) -> VAT 추가 가능
B17: 합계 | C17: =SUM(C6:C16) -> 152343136 | D17: =SUM(D6:D16) -> 190985566 | E17: =SUM(E6:E16) -> 240795769 | F17: =SUM(F6:F16) -> 196146268 | G17: =SUM(G6:G16) -> 241500 | H17: =SUM(H6:H16) -> 41202400 | I17: =SUM(I6:I16) -> 821714639 | K17: =SUM(K6:K16) -> 821559439 | L17: =SUM(L6:L16) -> 155200 | M17: =SUM(M6:M16) -> 3990000 | N17: =SUM(N6:N16) -> 825704639
B18: 검증 (상세 합계와 차이) | I18: =I17-'OPEX 상세'!Q281 -> 0
B20: 선박별 공급가액 / 부가세
B21: 선박 | C21: 공급가액 | D21: 부가세 | E21: 합계 | F21: 추가가능 부가세 | G21: 비중
B22: NORTH LIGHT | C22: =SUMIFS('OPEX 상세'!$O$5:$O$280,'OPEX 상세'!$D$5:$D$280,$B22) -> 152333936 | D22: =SUMIFS('OPEX 상세'!$P$5:$P$280,'OPEX 상세'!$D$5:$D$280,$B22) -> 9200 | E22: =C22+D22 -> 152343136 | F22: =SUMIFS('OPEX 상세'!$S$5:$S$280,'OPEX 상세'!$D$5:$D$280,$B22) -> 0 | G22: =IF($E$28=0,0,E22/$E$28) -> 0.18539664
B23: NORTH MOON | C23: =SUMIFS('OPEX 상세'!$O$5:$O$280,'OPEX 상세'!$D$5:$D$280,$B23) -> 190976366 | D23: =SUMIFS('OPEX 상세'!$P$5:$P$280,'OPEX 상세'!$D$5:$D$280,$B23) -> 9200 | E23: =C23+D23 -> 190985566 | F23: =SUMIFS('OPEX 상세'!$S$5:$S$280,'OPEX 상세'!$D$5:$D$280,$B23) -> 0 | G23: =IF($E$28=0,0,E23/$E$28) -> 0.23242322
B24: NORTH OCEAN | C24: =SUMIFS('OPEX 상세'!$O$5:$O$280,'OPEX 상세'!$D$5:$D$280,$B24) -> 240786569 | D24: =SUMIFS('OPEX 상세'!$P$5:$P$280,'OPEX 상세'!$D$5:$D$280,$B24) -> 9200 | E24: =C24+D24 -> 240795769 | F24: =SUMIFS('OPEX 상세'!$S$5:$S$280,'OPEX 상세'!$D$5:$D$280,$B24) -> 0 | G24: =IF($E$28=0,0,E24/$E$28) -> 0.29304062
B25: NORTH VALLEY | C25: =SUMIFS('OPEX 상세'!$O$5:$O$280,'OPEX 상세'!$D$5:$D$280,$B25) -> 196137068 | D25: =SUMIFS('OPEX 상세'!$P$5:$P$280,'OPEX 상세'!$D$5:$D$280,$B25) -> 9200 | E25: =C25+D25 -> 196146268 | F25: =SUMIFS('OPEX 상세'!$S$5:$S$280,'OPEX 상세'!$D$5:$D$280,$B25) -> 0 | G25: =IF($E$28=0,0,E25/$E$28) -> 0.23870363
B26: OFFICE | C26: =SUMIFS('OPEX 상세'!$O$5:$O$280,'OPEX 상세'!$D$5:$D$280,$B26) -> 241500 | D26: =SUMIFS('OPEX 상세'!$P$5:$P$280,'OPEX 상세'!$D$5:$D$280,$B26) -> 0 | E26: =C26+D26 -> 241500 | F26: =SUMIFS('OPEX 상세'!$S$5:$S$280,'OPEX 상세'!$D$5:$D$280,$B26) -> 0 | G26: =IF($E$28=0,0,E26/$E$28) -> 0.00029389765
B27: 공통(미배분) | C27: =SUMIFS('OPEX 상세'!$O$5:$O$280,'OPEX 상세'!$D$5:$D$280,$B27) -> 41084000 | D27: =SUMIFS('OPEX 상세'!$P$5:$P$280,'OPEX 상세'!$D$5:$D$280,$B27) -> 118400 | E27: =C27+D27 -> 41202400 | F27: =SUMIFS('OPEX 상세'!$S$5:$S$280,'OPEX 상세'!$D$5:$D$280,$B27) -> 3990000 | G27: =IF($E$28=0,0,E27/$E$28) -> 0.050141981
B28: 합계 | C28: =SUM(C22:C27) -> 821559439 | D28: =SUM(D22:D27) -> 155200 | E28: =SUM(E22:E27) -> 821714639 | F28: =SUM(F22:F27) -> 3990000 | G28: =SUM(G22:G27) -> 1
B30: 참고
B31: · OFFICE: 선박이 아닌 사무실 물품 (옥슨앤파트너스 감독님 작업복/헬멧 등).
B32: · 옥슨앤파트너스: 2026-10-02 선박별 인보이스 기준 PO 단위 입력 (일자 = 납품일). 인보이스에 없는 건은 비고에 '※ 10/2 인보이스 미포함' 표시.
B33: · 공통(미배분): 금액이 작거나 선박별로 쪼개기 애매한 건 (고려문화사 로그북, 시웨이글로벌, 화인컴에스이).
B34: · 시웨이글로벌 / 화인컴에스이: 적재허가서 문제로 현재 부가세별도. 부가세 10% 추가 시 '추가가능 부가세' 만큼 증가.
B35: · 네오맥스 / 한일후지코리아: 데이터 입력 대기. 'OPEX 상세' 시트 빈 행에 입력하면 자동 반영.
B36: · USD 항목(디앤오 Server, NAS)은 '설정' 시트 환율로 원화 환산. 환율 확정 시 설정 시트 노란 칸만 수정.

Sheet OPEX 상세
A1: OPEX 상세 내역
A2: 입력: 파란 글씨 칸만 입력 / 검정 글씨는 자동계산. 비과세 = 부가세 없음(부가세별도). 과세 + 'VAT포함' = 입력금액에 부가세 포함, 과세 + 'VAT별도' = 입력금액에 10% 가산. USD는 설정 시트 환율로 환산. VAT추가가능 'Y' = 현재 미포함이나 추가될 수 있는 부가세 별도 집계. 일자는 2026-09-30 형식으로 입력 (옥슨은 납품일).
A4: No | B4: 일자 | C4: 업체명 | D4: 선박 | E4: OPEX 코드 | F4: OPEX 계정명 (자동) | G4: 업체 구매코드 | H4: PO / 인보이스 No. | I4: 품목 / 내역 | J4: 과세구분 | K4: 통화 | L4: 입력금액 (통화기준) | M4: 금액기준 (과세시) | N4: 원화금액 (KRW) | O4: 공급가액 (KRW) | P4: 부가세 (KRW) | Q4: 합계 (KRW) | R4: VAT 추가가능 | S4: 추가가능 부가세 | T4: 비고 (REMARK)
A5: =IF(C5="","",COUNTA($C$5:C5)) -> 1 | C5: 고려문화사 | D5: 공통(미배분) | F5: =IF(E5="","",IFERROR(INDEX(코드관리!$C$7:$C$66,MATCH(E5,코드관리!$B$7:$B$66,0)),"미등록 코드")) | I5: 로그북 제작 | J5: 과세 | K5: KRW | L5: 1302400 | M5: VAT포함 | N5: =IF(L5="","",IF(K5="USD",ROUND(L5*설정!$C$4,0),L5)) -> 1302400 | O5: =IF(N5="","",IF(AND(J5="과세",M5="VAT포함"),ROUND(N5/(1+설정!$C$5),0),N5)) -> 1184000 | P5: =IF(N5="","",IF(J5="과세",IF(M5="VAT포함",N5-O5,ROUND(O5*설정!$C$5,0)),0)) -> 118400 | Q5: =IF(N5="","",O5+P5) -> 1302400 | S5: =IF(OR(N5="",R5<>"Y"),"",ROUND(O5*설정!$C$5,0)) | T5: 과세. 1,302,400원 = 부가세 포함으로 가정(공급가 1,184,000) - 확인 필요. 선박 미배분
A6: =IF(C6="","",COUNTA($C$5:C6)) -> 2 | C6: 디앤오 | D6: NORTH LIGHT | F6: =IF(E6="","",IFERROR(INDEX(코드관리!$C$7:$C$66,MATCH(E6,코드관리!$B$7:$B$66,0)),"미등록 코드")) | I6: Desktop | J6: 비과세 | K6: KRW | L6: 3680000 | N6: =IF(L6="","",IF(K6="USD",ROUND(L6*설정!$C$4,0),L6)) -> 3680000 | O6: =IF(N6="","",IF(AND(J6="과세",M6="VAT포함"),ROUND(N6/(1+설정!$C$5),0),N6)) -> 3680000 | P6: =IF(N6="","",IF(J6="과세",IF(M6="VAT포함",N6-O6,ROUND(O6*설정!$C$5,0)),0)) -> 0 | Q6: =IF(N6="","",O6+P6) -> 3680000 | S6: =IF(OR(N6="",R6<>"Y"),"",ROUND(O6*설정!$C$5,0))
A7: =IF(C7="","",COUNTA($C$5:C7)) -> 3 | C7: 디앤오 | D7: NORTH LIGHT | F7: =IF(E7="","",IFERROR(INDEX(코드관리!$C$7:$C$66,MATCH(E7,코드관리!$B$7:$B$66,0)),"미등록 코드")) | I7: NAS Storage | J7: 비과세 | K7: USD | L7: 2800 | N7: =IF(L7="","",IF(K7="USD",ROUND(L7*설정!$C$4,0),L7)) -> 3780000 | O7: =IF(N7="","",IF(AND(J7="과세",M7="VAT포함"),ROUND(N7/(1+설정!$C$5),0),N7)) -> 3780000 | P7: =IF(N7="","",IF(J7="과세",IF(M7="VAT포함",N7-O7,ROUND(O7*설정!$C$5,0)),0)) -> 0 | Q7: =IF(N7="","",O7+P7) -> 3780000 | S7: =IF(OR(N7="",R7<>"Y"),"",ROUND(O7*설정!$C$5,0)) | T7: USD 2,800 (설정 환율 적용)
A8: =IF(C8="","",COUNTA($C$5:C8)) -> 4 | C8: 디앤오 | D8: NORTH LIGHT | F8: =IF(E8="","",IFERROR(INDEX(코드관리!$C$7:$C$66,MATCH(E8,코드관리!$B$7:$B$66,0)),"미등록 코드")) | I8: Monitor | J8: 비과세 | K8: KRW | L8: 160000 | N8: =IF(L8="","",IF(K8="USD",ROUND(L8*설정!$C$4,0),L8)) -> 160000 | O8: =IF(N8="","",IF(AND(J8="과세",M8="VAT포함"),ROUND(N8/(1+설정!$C$5),0),N8)) -> 160000 | P8: =IF(N8="","",IF(J8="과세",IF(M8="VAT포함",N8-O8,ROUND(O8*설정!$C$5,0)),0)) -> 0 | Q8: =IF(N8="","",O8+P8) -> 160000 | S8: =IF(OR(N8="",R8<>"Y"),"",ROUND(O8*설정!$C$5,0))
A9: =IF(C9="","",COUNTA($C$5:C9)) -> 5 | C9: 디앤오 | D9: NORTH MOON | F9: =IF(E9="","",IFERROR(INDEX(코드관리!$C$7:$C$66,MATCH(E9,코드관리!$B$7:$B$66,0)),"미등록 코드")) | I9: Desktop | J9: 비과세 | K9: KRW | L9: 3680000 | N9: =IF(L9="","",IF(K9="USD",ROUND(L9*설정!$C$4,0),L9)) -> 3680000 | O9: =IF(N9="","",IF(AND(J9="과세",M9="VAT포함"),ROUND(N9/(1+설정!$C$5),0),N9)) -> 3680000 | P9: =IF(N9="","",IF(J9="과세",IF(M9="VAT포함",N9-O9,ROUND(O9*설정!$C$5,0)),0)) -> 0 | Q9: =IF(N9="","",O9+P9) -> 3680000 | S9: =IF(OR(N9="",R9<>"Y"),"",ROUND(O9*설정!$C$5,0))
A10: =IF(C10="","",COUNTA($C$5:C10)) -> 6 | C10: 디앤오 | D10: NORTH MOON | F10: =IF(E10="","",IFERROR(INDEX(코드관리!$C$7:$C$66,MATCH(E10,코드관리!$B$7:$B$66,0)),"미등록 코드")) | I10: NAS Storage | J10: 비과세 | K10: USD | L10: 2800 | N10: =IF(L10="","",IF(K10="USD",ROUND(L10*설정!$C$4,0),L10)) -> 3780000 | O10: =IF(N10="","",IF(AND(J10="과세",M10="VAT포함"),ROUND(N10/(1+설정!$C$5),0),N10)) -> 3780000 | P10: =IF(N10="","",IF(J10="과세",IF(M10="VAT포함",N10-O10,ROUND(O10*설정!$C$5,0)),0)) -> 0 | Q10: =IF(N10="","",O10+P10) -> 3780000 | S10: =IF(OR(N10="",R10<>"Y"),"",ROUND(O10*설정!$C$5,0)) | T10: USD 2,800 (설정 환율 적용)
A11: =IF(C11="","",COUNTA($C$5:C11)) -> 7 | C11: 디앤오 | D11: NORTH MOON | F11: =IF(E11="","",IFERROR(INDEX(코드관리!$C$7:$C$66,MATCH(E11,코드관리!$B$7:$B$66,0)),"미등록 코드")) | I11: Monitor | J11: 비과세 | K11: KRW | L11: 160000 | N11: =IF(L11="","",IF(K11="USD",ROUND(L11*설정!$C$4,0),L11)) -> 160000 | O11: =IF(N11="","",IF(AND(J11="과세",M11="VAT포함"),ROUND(N11/(1+설정!$C$5),0),N11)) -> 160000 | P11: =IF(N11="","",IF(J11="과세",IF(M11="VAT포함",N11-O11,ROUND(O11*설정!$C$5,0)),0)) -> 0 | Q11: =IF(N11="","",O11+P11) -> 160000 | S11: =IF(OR(N11="",R11<>"Y"),"",ROUND(O11*설정!$C$5,0))
A12: =IF(C12="","",COUNTA($C$5:C12)) -> 8 | C12: 디앤오 | D12: NORTH OCEAN | F12: =IF(E12="","",IFERROR(INDEX(코드관리!$C$7:$C$66,MATCH(E12,코드관리!$B$7:$B$66,0)),"미등록 코드")) | I12: Server | J12: 비과세 | K12: USD | L12: 26000 | N12: =IF(L12="","",IF(K12="USD",ROUND(L12*설정!$C$4,0),L12)) -> 35100000 | O12: =IF(N12="","",IF(AND(J12="과세",M12="VAT포함"),ROUND(N12/(1+설정!$C$5),0),N12)) -> 35100000 | P12: =IF(N12="","",IF(J12="과세",IF(M12="VAT포함",N12-O12,ROUND(O12*설정!$C$5,0)),0)) -> 0 | Q12: =IF(N12="","",O12+P12) -> 35100000 | S12: =IF(OR(N12="",R12<>"Y"),"",ROUND(O12*설정!$C$5,0)) | T12: USD 26,000 (설정 환율 적용)
A13: =IF(C13="","",COUNTA($C$5:C13)) -> 9 | C13: 디앤오 | D13: NORTH OCEAN | F13: =IF(E13="","",IFERROR(INDEX(코드관리!$C$7:$C$66,MATCH(E13,코드관리!$B$7:$B$66,0)),"미등록 코드")) | I13: NAS Storage | J13: 비과세 | K13: USD | L13: 2800 | N13: =IF(L13="","",IF(K13="USD",ROUND(L13*설정!$C$4,0),L13)) -> 3780000 | O13: =IF(N13="","",IF(AND(J13="과세",M13="VAT포함"),ROUND(N13/(1+설정!$C$5),0),N13)) -> 3780000 | P13: =IF(N13="","",IF(J13="과세",IF(M13="VAT포함",N13-O13,ROUND(O13*설정!$C$5,0)),0)) -> 0 | Q13: =IF(N13="","",O13+P13) -> 3780000 | S13: =IF(OR(N13="",R13<>"Y"),"",ROUND(O13*설정!$C$5,0)) | T13: USD 2,800 (설정 환율 적용)
A14: =IF(C14="","",COUNTA($C$5:C14)) -> 10 | C14: 디앤오 | D14: NORTH VALLEY | F14: =IF(E14="","",IFERROR(INDEX(코드관리!$C$7:$C$66,MATCH(E14,코드관리!$B$7:$B$66,0)),"미등록 코드")) | I14: Server | J14: 비과세 | K14: USD | L14: 26000 | N14: =IF(L14="","",IF(K14="USD",ROUND(L14*설정!$C$4,0),L14)) -> 35100000 | O14: =IF(N14="","",IF(AND(J14="과세",M14="VAT포함"),ROUND(N14/(1+설정!$C$5),0),N14)) -> 35100000 | P14: =IF(N14="","",IF(J14="과세",IF(M14="VAT포함",N14-O14,ROUND(O14*설정!$C$5,0)),0)) -> 0 | Q14: =IF(N14="","",O14+P14) -> 35100000 | S14: =IF(OR(N14="",R14<>"Y"),"",ROUND(O14*설정!$C$5,0)) | T14: USD 26,000 (설정 환율 적용)
A15: =IF(C15="","",COUNTA($C$5:C15)) -> 11 | C15: 디앤오 | D15: NORTH VALLEY | F15: =IF(E15="","",IFERROR(INDEX(코드관리!$C$7:$C$66,MATCH(E15,코드관리!$B$7:$B$66,0)),"미등록 코드")) | I15: NAS Storage | J15: 비과세 | K15: USD | L15: 2800 | N15: =IF(L15="","",IF(K15="USD",ROUND(L15*설정!$C$4,0),L15)) -> 3780000 | O15: =IF(N15="","",IF(AND(J15="과세",M15="VAT포함"),ROUND(N15/(1+설정!$C$5),0),N15)) -> 3780000 | P15: =IF(N15="","",IF(J15="과세",IF(M15="VAT포함",N15-O15,ROUND(O15*설정!$C$5,0)),0)) -> 0 | Q15: =IF(N15="","",O15+P15) -> 3780000 | S15: =IF(OR(N15="",R15<>"Y"),"",ROUND(O15*설정!$C$5,0)) | T15: USD 2,800 (설정 환율 적용)
A16: =IF(C16="","",COUNTA($C$5:C16)) -> 12 | C16: 비아이자이로 | D16: NORTH LIGHT | F16: =IF(E16="","",IFERROR(INDEX(코드관리!$C$7:$C$66,MATCH(E16,코드관리!$B$7:$B$66,0)),"미등록 코드")) | I16: Laptop | J16: 비과세 | K16: KRW | L16: 33800000 | N16: =IF(L16="","",IF(K16="USD",ROUND(L16*설정!$C$4,0),L16)) -> 33800000 | O16: =IF(N16="","",IF(AND(J16="과세",M16="VAT포함"),ROUND(N16/(1+설정!$C$5),0),N16)) -> 33800000 | P16: =IF(N16="","",IF(J16="과세",IF(M16="VAT포함",N16-O16,ROUND(O16*설정!$C$5,0)),0)) -> 0 | Q16: =IF(N16="","",O16+P16) -> 33800000 | S16: =IF(OR(N16="",R16<>"Y"),"",ROUND(O16*설정!$C$5,0)) | T16: 선박별 33,800,000 (4척 각각) - 확인 필요
A17: =IF(C17="","",COUNTA($C$5:C17)) -> 13 | C17: 비아이자이로 | D17: NORTH LIGHT | F17: =IF(E17="","",IFERROR(INDEX(코드관리!$C$7:$C$66,MATCH(E17,코드관리!$B$7:$B$66,0)),"미등록 코드")) | I17: 네트워크 셋팅 | J17: 비과세 | K17: KRW | L17: 7990000 | N17: =IF(L17="","",IF(K17="USD",ROUND(L17*설정!$C$4,0),L17)) -> 7990000 | O17: =IF(N17="","",IF(AND(J17="과세",M17="VAT포함"),ROUND(N17/(1+설정!$C$5),0),N17)) -> 7990000 | P17: =IF(N17="","",IF(J17="과세",IF(M17="VAT포함",N17-O17,ROUND(O17*설정!$C$5,0)),0)) -> 0 | Q17: =IF(N17="","",O17+P17) -> 7990000 | S17: =IF(OR(N17="",R17<>"Y"),"",ROUND(O17*설정!$C$5,0))
A18: =IF(C18="","",COUNTA($C$5:C18)) -> 14 | C18: 비아이자이로 | D18: NORTH MOON | F18: =IF(E18="","",IFERROR(INDEX(코드관리!$C$7:$C$66,MATCH(E18,코드관리!$B$7:$B$66,0)),"미등록 코드")) | I18: Laptop | J18: 비과세 | K18: KRW | L18: 33800000 | N18: =IF(L18="","",IF(K18="USD",ROUND(L18*설정!$C$4,0),L18)) -> 33800000 | O18: =IF(N18="","",IF(AND(J18="과세",M18="VAT포함"),ROUND(N18/(1+설정!$C$5),0),N18)) -> 33800000 | P18: =IF(N18="","",IF(J18="과세",IF(M18="VAT포함",N18-O18,ROUND(O18*설정!$C$5,0)),0)) -> 0 | Q18: =IF(N18="","",O18+P18) -> 33800000 | S18: =IF(OR(N18="",R18<>"Y"),"",ROUND(O18*설정!$C$5,0)) | T18: 선박별 33,800,000 (4척 각각) - 확인 필요
A19: =IF(C19="","",COUNTA($C$5:C19)) -> 15 | C19: 비아이자이로 | D19: NORTH MOON | F19: =IF(E19="","",IFERROR(INDEX(코드관리!$C$7:$C$66,MATCH(E19,코드관리!$B$7:$B$66,0)),"미등록 코드")) | I19: 네트워크 셋팅 | J19: 비과세 | K19: KRW | L19: 7290000 | N19: =IF(L19="","",IF(K19="USD",ROUND(L19*설정!$C$4,0),L19)) -> 7290000 | O19: =IF(N19="","",IF(AND(J19="과세",M19="VAT포함"),ROUND(N19/(1+설정!$C$5),0),N19)) -> 7290000 | P19: =IF(N19="","",IF(J19="과세",IF(M19="VAT포함",N19-O19,ROUND(O19*설정!$C$5,0)),0)) -> 0 | Q19: =IF(N19="","",O19+P19) -> 7290000 | S19: =IF(OR(N19="",R19<>"Y"),"",ROUND(O19*설정!$C$5,0))
A20: =IF(C20="","",COUNTA($C$5:C20)) -> 16 | C20: 비아이자이로 | D20: NORTH OCEAN | F20: =IF(E20="","",IFERROR(INDEX(코드관리!$C$7:$C$66,MATCH(E20,코드관리!$B$7:$B$66,0)),"미등록 코드")) | I20: Laptop | J20: 비과세 | K20: KRW | L20: 33800000 | N20: =IF(L20="","",IF(K20="USD",ROUND(L20*설정!$C$4,0),L20)) -> 33800000 | O20: =IF(N20="","",IF(AND(J20="과세",M20="VAT포함"),ROUND(N20/(1+설정!$C$5),0),N20)) -> 33800000 | P20: =IF(N20="","",IF(J20="과세",IF(M20="VAT포함",N20-O20,ROUND(O20*설정!$C$5,0)),0)) -> 0 | Q20: =IF(N20="","",O20+P20) -> 33800000 | S20: =IF(OR(N20="",R20<>"Y"),"",ROUND(O20*설정!$C$5,0)) | T20: 선박별 33,800,000 (4척 각각) - 확인 필요
A21: =IF(C21="","",COUNTA($C$5:C21)) -> 17 | C21: 비아이자이로 | D21: NORTH OCEAN | F21: =IF(E21="","",IFERROR(INDEX(코드관리!$C$7:$C$66,MATCH(E21,코드관리!$B$7:$B$66,0)),"미등록 코드")) | I21: 네트워크 셋팅 | J21: 비과세 | K21: KRW | L21: 7040000 | N21: =IF(L21="","",IF(K21="USD",ROUND(L21*설정!$C$4,0),L21)) -> 7040000 | O21: =IF(N21="","",IF(AND(J21="과세",M21="VAT포함"),ROUND(N21/(1+설정!$C$5),0),N21)) -> 7040000 | P21: =IF(N21="","",IF(J21="과세",IF(M21="VAT포함",N21-O21,ROUND(O21*설정!$C$5,0)),0)) -> 0 | Q21: =IF(N21="","",O21+P21) -> 7040000 | S21: =IF(OR(N21="",R21<>"Y"),"",ROUND(O21*설정!$C$5,0))
A22: =IF(C22="","",COUNTA($C$5:C22)) -> 18 | C22: 비아이자이로 | D22: NORTH VALLEY | F22: =IF(E22="","",IFERROR(INDEX(코드관리!$C$7:$C$66,MATCH(E22,코드관리!$B$7:$B$66,0)),"미등록 코드")) | I22: Laptop | J22: 비과세 | K22: KRW | L22: 33800000 | N22: =IF(L22="","",IF(K22="USD",ROUND(L22*설정!$C$4,0),L22)) -> 33800000 | O22: =IF(N22="","",IF(AND(J22="과세",M22="VAT포함"),ROUND(N22/(1+설정!$C$5),0),N22)) -> 33800000 | P22: =IF(N22="","",IF(J22="과세",IF(M22="VAT포함",N22-O22,ROUND(O22*설정!$C$5,0)),0)) -> 0 | Q22: =IF(N22="","",O22+P22) -> 33800000 | S22: =IF(OR(N22="",R22<>"Y"),"",ROUND(O22*설정!$C$5,0)) | T22: 선박별 33,800,000 (4척 각각) - 확인 필요
A23: =IF(C23="","",COUNTA($C$5:C23)) -> 19 | C23: 비아이자이로 | D23: NORTH VALLEY | F23: =IF(E23="","",IFERROR(INDEX(코드관리!$C$7:$C$66,MATCH(E23,코드관리!$B$7:$B$66,0)),"미등록 코드")) | I23: 네트워크 셋팅 | J23: 비과세 | K23: KRW | L23: 8700000 | N23: =IF(L23="","",IF(K23="USD",ROUND(L23*설정!$C$4,0),L23)) -> 8700000 | O23: =IF(N23="","",IF(AND(J23="과세",M23="VAT포함"),ROUND(N23/(1+설정!$C$5),0),N23)) -> 8700000 | P23: =IF(N23="","",IF(J23="과세",IF(M23="VAT포함",N23-O23,ROUND(O23*설정!$C$5,0)),0)) -> 0 | Q23: =IF(N23="","",O23+P23) -> 8700000 | S23: =IF(OR(N23="",R23<>"Y"),"",ROUND(O23*설정!$C$5,0))
A24: =IF(C24="","",COUNTA($C$5:C24)) -> 20 | C24: 시웨이글로벌 | D24: 공통(미배분) | F24: =IF(E24="","",IFERROR(INDEX(코드관리!$C$7:$C$66,MATCH(E24,코드관리!$B$7:$B$66,0)),"미등록 코드")) | I24: (품목 확인 필요) | J24: 비과세 | K24: KRW | L24: 27300000 | N24: =IF(L24="","",IF(K24="USD",ROUND(L24*설정!$C$4,0),L24)) -> 27300000 | O24: =IF(N24="","",IF(AND(J24="과세",M24="VAT포함"),ROUND(N24/(1+설정!$C$5),0),N24)) -> 27300000 | P24: =IF(N24="","",IF(J24="과세",IF(M24="VAT포함",N24-O24,ROUND(O24*설정!$C$5,0)),0)) -> 0 | Q24: =IF(N24="","",O24+P24) -> 27300000 | R24: Y | S24: =IF(OR(N24="",R24<>"Y"),"",ROUND(O24*설정!$C$5,0)) -> 2730000 | T24: 적재허가서 문제로 현재 부가세별도. 부가세 10% 추가 가능성
A25: =IF(C25="","",COUNTA($C$5:C25)) -> 21 | B25: 46289 | C25: 옥슨앤파트너스 | D25: NORTH LIGHT | F25: =IF(E25="","",IFERROR(INDEX(코드관리!$C$7:$C$66,MATCH(E25,코드관리!$B$7:$B$66,0)),"미등록 코드")) | H25: GOS-26-0984 | I25: Stamp (바뀐 선명) | J25: 비과세 | K25: KRW | L25: 981600 | N25: =IF(L25="","",IF(K25="USD",ROUND(L25*설정!$C$4,0),L25)) -> 981600 | O25: =IF(N25="","",IF(AND(J25="과세",M25="VAT포함"),ROUND(N25/(1+설정!$C$5),0),N25)) -> 981600 | P25: =IF(N25="","",IF(J25="과세",IF(M25="VAT포함",N25-O25,ROUND(O25*설정!$C$5,0)),0)) -> 0 | Q25: =IF(N25="","",O25+P25) -> 981600 | S25: =IF(OR(N25="",R25<>"Y"),"",ROUND(O25*설정!$C$5,0)) | T25: 옥슨 INV 2026-10-02 / 납품 여수항. 신규 선명 AEOLUS
A26: =IF(C26="","",COUNTA($C$5:C26)) -> 22 | B26: 46289 | C26: 옥슨앤파트너스 | D26: NORTH LIGHT | F26: =IF(E26="","",IFERROR(INDEX(코드관리!$C$7:$C$66,MATCH(E26,코드관리!$B$7:$B$66,0)),"미등록 코드")) | H26: IOB-26-0993 | I26: Safety boots & Goggle | J26: 비과세 | K26: KRW | L26: 2256796 | N26: =IF(L26="","",IF(K26="USD",ROUND(L26*설정!$C$4,0),L26)) -> 2256796 | O26: =IF(N26="","",IF(AND(J26="과세",M26="VAT포함"),ROUND(N26/(1+설정!$C$5),0),N26)) -> 2256796 | P26: =IF(N26="","",IF(J26="과세",IF(M26="VAT포함",N26-O26,ROUND(O26*설정!$C$5,0)),0)) -> 0 | Q26: =IF(N26="","",O26+P26) -> 2256796 | S26: =IF(OR(N26="",R26<>"Y"),"",ROUND(O26*설정!$C$5,0)) | T26: 옥슨 INV 2026-10-02 / 납품 여수항. 방한화, 보안경, 고글
A27: =IF(C27="","",COUNTA($C$5:C27)) -> 23 | B27: 46296 | C27: 옥슨앤파트너스 | D27: NORTH LIGHT | F27: =IF(E27="","",IFERROR(INDEX(코드관리!$C$7:$C$66,MATCH(E27,코드관리!$B$7:$B$66,0)),"미등록 코드")) | H27: IOB-4VS-26-1010 | I27: 방한돕바, 안전모, 안전모 끈 | J27: 비과세 | K27: KRW | L27: 1342000 | N27: =IF(L27="","",IF(K27="USD",ROUND(L27*설정!$C$4,0),L27)) -> 1342000 | O27: =IF(N27="","",IF(AND(J27="과세",M27="VAT포함"),ROUND(N27/(1+설정!$C$5),0),N27)) -> 1342000 | P27: =IF(N27="","",IF(J27="과세",IF(M27="VAT포함",N27-O27,ROUND(O27*설정!$C$5,0)),0)) -> 0 | Q27: =IF(N27="","",O27+P27) -> 1342000 | S27: =IF(OR(N27="",R27<>"Y"),"",ROUND(O27*설정!$C$5,0)) | T27: 옥슨 INV 2026-10-02 / 납품 여수항. 4척 공통 발주(IOB-4VS) 중 해당 선박분
A28: =IF(C28="","",COUNTA($C$5:C28)) -> 24 | B28: 46296 | C28: 옥슨앤파트너스 | D28: NORTH LIGHT | F28: =IF(E28="","",IFERROR(INDEX(코드관리!$C$7:$C$66,MATCH(E28,코드관리!$B$7:$B$66,0)),"미등록 코드")) | H28: IOB-4VS-26-1014 | I28: 방한용품 (방한장갑, 발열내의, 바라클라바, 양말, 넥워머 등) | J28: 비과세 | K28: KRW | L28: 3689825 | N28: =IF(L28="","",IF(K28="USD",ROUND(L28*설정!$C$4,0),L28)) -> 3689825 | O28: =IF(N28="","",IF(AND(J28="과세",M28="VAT포함"),ROUND(N28/(1+설정!$C$5),0),N28)) -> 3689825 | P28: =IF(N28="","",IF(J28="과세",IF(M28="VAT포함",N28-O28,ROUND(O28*설정!$C$5,0)),0)) -> 0 | Q28: =IF(N28="","",O28+P28) -> 3689825 | S28: =IF(OR(N28="",R28<>"Y"),"",ROUND(O28*설정!$C$5,0)) | T28: 옥슨 INV 2026-10-02 / 납품 여수항. 4척 공통 발주(IOB-4VS) 중 해당 선박분
A29: =IF(C29="","",COUNTA($C$5:C29)) -> 25 | B29: 46296 | C29: 옥슨앤파트너스 | D29: NORTH LIGHT | F29: =IF(E29="","",IFERROR(INDEX(코드관리!$C$7:$C$66,MATCH(E29,코드관리!$B$7:$B$66,0)),"미등록 코드")) | H29: IOB-4VS-26-1017 | I29: 절연장갑 (1000V / 7500V) | J29: 비과세 | K29: KRW | L29: 380800 | N29: =IF(L29="","",IF(K29="USD",ROUND(L29*설정!$C$4,0),L29)) -> 380800 | O29: =IF(N29="","",IF(AND(J29="과세",M29="VAT포함"),ROUND(N29/(1+설정!$C$5),0),N29)) -> 380800 | P29: =IF(N29="","",IF(J29="과세",IF(M29="VAT포함",N29-O29,ROUND(O29*설정!$C$5,0)),0)) -> 0 | Q29: =IF(N29="","",O29+P29) -> 380800 | S29: =IF(OR(N29="",R29<>"Y"),"",ROUND(O29*설정!$C$5,0)) | T29: 옥슨 INV 2026-10-02 / 납품 여수항. 4척 공통 발주(IOB-4VS) 중 해당 선박분
A30: =IF(C30="","",COUNTA($C$5:C30)) -> 26 | B30: 46296 | C30: 옥슨앤파트너스 | D30: NORTH LIGHT | F30: =IF(E30="","",IFERROR(INDEX(코드관리!$C$7:$C$66,MATCH(E30,코드관리!$B$7:$B$66,0)),"미등록 코드")) | H30: IOB-NOL-26-1023 | I30: 염화칼슘 25kg x 8 bags | J30: 비과세 | K30: KRW | L30: 151800 | N30: =IF(L30="","",IF(K30="USD",ROUND(L30*설정!$C$4,0),L30)) -> 151800 | O30: =IF(N30="","",IF(AND(J30="과세",M30="VAT포함"),ROUND(N30/(1+설정!$C$5),0),N30)) -> 151800 | P30: =IF(N30="","",IF(J30="과세",IF(M30="VAT포함",N30-O30,ROUND(O30*설정!$C$5,0)),0)) -> 0 | Q30: =IF(N30="","",O30+P30) -> 151800 | S30: =IF(OR(N30="",R30<>"Y"),"",ROUND(O30*설정!$C$5,0)) | T30: 옥슨 INV 2026-10-02 / 납품 여수항. 4척 분배 8/8/8/4 bags (@18,975)
A31: =IF(C31="","",COUNTA($C$5:C31)) -> 27 | B31: 46296 | C31: 옥슨앤파트너스 | D31: NORTH LIGHT | F31: =IF(E31="","",IFERROR(INDEX(코드관리!$C$7:$C$66,MATCH(E31,코드관리!$B$7:$B$66,0)),"미등록 코드")) | H31: IOB-NOL-26-1028 | I31: M/E Oxygen sensor (A/B) 3 sets | J31: 비과세 | K31: KRW | L31: 5175000 | N31: =IF(L31="","",IF(K31="USD",ROUND(L31*설정!$C$4,0),L31)) -> 5175000 | O31: =IF(N31="","",IF(AND(J31="과세",M31="VAT포함"),ROUND(N31/(1+설정!$C$5),0),N31)) -> 5175000 | P31: =IF(N31="","",IF(J31="과세",IF(M31="VAT포함",N31-O31,ROUND(O31*설정!$C$5,0)),0)) -> 0 | Q31: =IF(N31="","",O31+P31) -> 5175000 | S31: =IF(OR(N31="",R31<>"Y"),"",ROUND(O31*설정!$C$5,0)) | T31: 옥슨 INV 2026-10-02 / 납품 여수항. 4척에 3개씩 보급 (HANWHA MAN B&W 5G70ME-C10.5, @1,725,000)
A32: =IF(C32="","",COUNTA($C$5:C32)) -> 28 | B32: 46297 | C32: 옥슨앤파트너스 | D32: NORTH LIGHT | F32: =IF(E32="","",IFERROR(INDEX(코드관리!$C$7:$C$66,MATCH(E32,코드관리!$B$7:$B$66,0)),"미등록 코드")) | H32: IOB-NOL-26-1050 (CLAIM NO. C-059) | I32: IGG O2 Sensor - Analyzer ass'y | J32: 비과세 | K32: KRW | L32: 4400000 | N32: =IF(L32="","",IF(K32="USD",ROUND(L32*설정!$C$4,0),L32)) -> 4400000 | O32: =IF(N32="","",IF(AND(J32="과세",M32="VAT포함"),ROUND(N32/(1+설정!$C$5),0),N32)) -> 4400000 | P32: =IF(N32="","",IF(J32="과세",IF(M32="VAT포함",N32-O32,ROUND(O32*설정!$C$5,0)),0)) -> 0 | Q32: =IF(N32="","",O32+P32) -> 4400000 | S32: =IF(OR(N32="",R32<>"Y"),"",ROUND(O32*설정!$C$5,0)) | T32: 옥슨 INV 2026-10-02 / 납품 여수항. Claim No. C-059 / KANGRIM OA-Z-IG2
A33: =IF(C33="","",COUNTA($C$5:C33)) -> 29 | B33: 46289 | C33: 옥슨앤파트너스 | D33: NORTH MOON | F33: =IF(E33="","",IFERROR(INDEX(코드관리!$C$7:$C$66,MATCH(E33,코드관리!$B$7:$B$66,0)),"미등록 코드")) | H33: GOS-26-0984 | I33: Stamp (바뀐 선명) | J33: 비과세 | K33: KRW | L33: 981600 | N33: =IF(L33="","",IF(K33="USD",ROUND(L33*설정!$C$4,0),L33)) -> 981600 | O33: =IF(N33="","",IF(AND(J33="과세",M33="VAT포함"),ROUND(N33/(1+설정!$C$5),0),N33)) -> 981600 | P33: =IF(N33="","",IF(J33="과세",IF(M33="VAT포함",N33-O33,ROUND(O33*설정!$C$5,0)),0)) -> 0 | Q33: =IF(N33="","",O33+P33) -> 981600 | S33: =IF(OR(N33="",R33<>"Y"),"",ROUND(O33*설정!$C$5,0)) | T33: 옥슨 INV 2026-10-02 / 납품 여수항. 신규 선명 MELICERTES
A34: =IF(C34="","",COUNTA($C$5:C34)) -> 30 | B34: 46289 | C34: 옥슨앤파트너스 | D34: NORTH MOON | F34: =IF(E34="","",IFERROR(INDEX(코드관리!$C$7:$C$66,MATCH(E34,코드관리!$B$7:$B$66,0)),"미등록 코드")) | H34: IOB-26-0993 | I34: Safety boots & Goggle | J34: 비과세 | K34: KRW | L34: 1258180 | N34: =IF(L34="","",IF(K34="USD",ROUND(L34*설정!$C$4,0),L34)) -> 1258180 | O34: =IF(N34="","",IF(AND(J34="과세",M34="VAT포함"),ROUND(N34/(1+설정!$C$5),0),N34)) -> 1258180 | P34: =IF(N34="","",IF(J34="과세",IF(M34="VAT포함",N34-O34,ROUND(O34*설정!$C$5,0)),0)) -> 0 | Q34: =IF(N34="","",O34+P34) -> 1258180 | S34: =IF(OR(N34="",R34<>"Y"),"",ROUND(O34*설정!$C$5,0)) | T34: 옥슨 INV 2026-10-02 / 납품 여수항. 방한화, 보안경, 고글
A35: =IF(C35="","",COUNTA($C$5:C35)) -> 31 | B35: 46296 | C35: 옥슨앤파트너스 | D35: NORTH MOON | F35: =IF(E35="","",IFERROR(INDEX(코드관리!$C$7:$C$66,MATCH(E35,코드관리!$B$7:$B$66,0)),"미등록 코드")) | H35: IOB-NMO-26-1000 (A260923-002) | I35: Engine part (선용품) | J35: 비과세 | K35: KRW | L35: 16651957 | N35: =IF(L35="","",IF(K35="USD",ROUND(L35*설정!$C$4,0),L35)) -> 16651957 | O35: =IF(N35="","",IF(AND(J35="과세",M35="VAT포함"),ROUND(N35/(1+설정!$C$5),0),N35)) -> 16651957 | P35: =IF(N35="","",IF(J35="과세",IF(M35="VAT포함",N35-O35,ROUND(O35*설정!$C$5,0)),0)) -> 0 | Q35: =IF(N35="","",O35+P35) -> 16651957 | S35: =IF(OR(N35="",R35<>"Y"),"",ROUND(O35*설정!$C$5,0)) | T35: 옥슨 INV 2026-10-02 / 납품 여수항
A36: =IF(C36="","",COUNTA($C$5:C36)) -> 32 | B36: 46296 | C36: 옥슨앤파트너스 | D36: NORTH MOON | F36: =IF(E36="","",IFERROR(INDEX(코드관리!$C$7:$C$66,MATCH(E36,코드관리!$B$7:$B$66,0)),"미등록 코드")) | H36: IOB-NMO-26-1001 (A260923-004) | I36: Deck part | J36: 비과세 | K36: KRW | L36: 5290660 | N36: =IF(L36="","",IF(K36="USD",ROUND(L36*설정!$C$4,0),L36)) -> 5290660 | O36: =IF(N36="","",IF(AND(J36="과세",M36="VAT포함"),ROUND(N36/(1+설정!$C$5),0),N36)) -> 5290660 | P36: =IF(N36="","",IF(J36="과세",IF(M36="VAT포함",N36-O36,ROUND(O36*설정!$C$5,0)),0)) -> 0 | Q36: =IF(N36="","",O36+P36) -> 5290660 | S36: =IF(OR(N36="",R36<>"Y"),"",ROUND(O36*설정!$C$5,0)) | T36: 옥슨 INV 2026-10-02 / 납품 여수항
... A80: =IF(C80="","",COUNTA($C$5:C80)) -> 76 | B80: 46297 | C80: 옥슨앤파트너스 | D80: NORTH VALLEY | F80: =IF(E80="","",IFERROR(INDEX(코드관리!$C$7:$C$66,MATCH(E80,코드관리!$B$7:$B$66,0)),"미등록 코드")) | H80: INVOICE | I80: 포장비 (Packing) | J80: 비과세 | K80: KRW | L80: 220000 | N80: =IF(L80="","",IF(K80="USD",ROUND(L80*설정!$C$4,0),L80)) -> 220000 | O80: =IF(N80="","",IF(AND(J80="과세",M80="VAT포함"),ROUND(N80/(1+설정!$C$5),0),N80)) -> 220000 | P80: =IF(N80="","",IF(J80="과세",IF(M80="VAT포함",N80-O80,ROUND(O80*설정!$C$5,0)),0)) -> 0 | Q80: =IF(N80="","",O80+P80) -> 220000 | S80: =IF(OR(N80="",R80<>"Y"),"",ROUND(O80*설정!$C$5,0)) | T80: 옥슨 INV 2026-10-02 Additional charge. Wooden pallet x3 (135,000) + Ton bag x17 (85,000)
A81: =IF(C81="","",COUNTA($C$5:C81)) -> 77 | B81: 46282 | C81: 옥슨앤파트너스 | D81: OFFICE | F81: =IF(E81="","",IFERROR(INDEX(코드관리!$C$7:$C$66,MATCH(E81,코드관리!$B$7:$B$66,0)),"미등록 코드")) | I81: 사무실 물품 - 감독님 작업복, 헬멧 | J81: 비과세 | K81: KRW | L81: 241500 | N81: =IF(L81="","",IF(K81="USD",ROUND(L81*설정!$C$4,0),L81)) -> 241500 | O81: =IF(N81="","",IF(AND(J81="과세",M81="VAT포함"),ROUND(N81/(1+설정!$C$5),0),N81)) -> 241500 | P81: =IF(N81="","",IF(J81="과세",IF(M81="VAT포함",N81-O81,ROUND(O81*설정!$C$5,0)),0)) -> 0 | Q81: =IF(N81="","",O81+P81) -> 241500 | S81: =IF(OR(N81="",R81<>"Y"),"",ROUND(O81*설정!$C$5,0)) | T81: ※ 10/2 인보이스 미포함 - 별도 청구 확인 필요. 선박 아님 (OFFICE)
A82: =IF(C82="","",COUNTA($C$5:C82)) -> 78 | C82: 옥슨앤파트너스 | D82: NORTH LIGHT | F82: =IF(E82="","",IFERROR(INDEX(코드관리!$C$7:$C$66,MATCH(E82,코드관리!$B$7:$B$66,0)),"미등록 코드")) | I82: Extra spare parts - Air filter element | J82: 비과세 | K82: KRW | L82: 20493000 | N82: =IF(L82="","",IF(K82="USD",ROUND(L82*설정!$C$4,0),L82)) -> 20493000 | O82: =IF(N82="","",IF(AND(J82="과세",M82="VAT포함"),ROUND(N82/(1+설정!$C$5),0),N82)) -> 20493000 | P82: =IF(N82="","",IF(J82="과세",IF(M82="VAT포함",N82-O82,ROUND(O82*설정!$C$5,0)),0)) -> 0 | Q82: =IF(N82="","",O82+P82) -> 20493000 | S82: =IF(OR(N82="",R82<>"Y"),"",ROUND(O82*설정!$C$5,0)) | T82: ※ 10/2 인보이스 미포함 - 별도 청구 확인 필요. NORTH LIGHT로 견적, Lead time 때문에 기존 보급 안 되었던 건
A83: =IF(C83="","",COUNTA($C$5:C83)) -> 79 | C83: 옥슨앤파트너스 | D83: NORTH VALLEY | F83: =IF(E83="","",IFERROR(INDEX(코드관리!$C$7:$C$66,MATCH(E83,코드관리!$B$7:$B$66,0)),"미등록 코드")) | I83: Extra spare parts - PH sensor for EGR | J83: 비과세 | K83: KRW | L83: 2530000 | N83: =IF(L83="","",IF(K83="USD",ROUND(L83*설정!$C$4,0),L83)) -> 2530000 | O83: =IF(N83="","",IF(AND(J83="과세",M83="VAT포함"),ROUND(N83/(1+설정!$C$5),0),N83)) -> 2530000 | P83: =IF(N83="","",IF(J83="과세",IF(M83="VAT포함",N83-O83,ROUND(O83*설정!$C$5,0)),0)) -> 0 | Q83: =IF(N83="","",O83+P83) -> 2530000 | S83: =IF(OR(N83="",R83<>"Y"),"",ROUND(O83*설정!$C$5,0)) | T83: ※ 10/2 인보이스 미포함 - 별도 청구 확인 필요. Lead time 때문에 기존 보급 안 되었던 건
A84: =IF(C84="","",COUNTA($C$5:C84)) -> 80 | B84: 46268 | C84: 옥슨앤파트너스 | D84: NORTH LIGHT | F84: =IF(E84="","",IFERROR(INDEX(코드관리!$C$7:$C$66,MATCH(E84,코드관리!$B$7:$B$66,0)),"미등록 코드")) | I84: 작업복 | J84: 비과세 | K84: KRW | L84: 9174000 | N84: =IF(L84="","",IF(K84="USD",ROUND(L84*설정!$C$4,0),L84)) -> 9174000 | O84: =IF(N84="","",IF(AND(J84="과세",M84="VAT포함"),ROUND(N84/(1+설정!$C$5),0),N84)) -> 9174000 | P84: =IF(N84="","",IF(J84="과세",IF(M84="VAT포함",N84-O84,ROUND(O84*설정!$C$5,0)),0)) -> 0 | Q84: =IF(N84="","",O84+P84) -> 9174000 | S84: =IF(OR(N84="",R84<>"Y"),"",ROUND(O84*설정!$C$5,0)) | T84: ※ 10/2 인보이스 미포함 - 별도 청구 확인 필요. 9/3 구매 진행 (작업기간 9/3~9/22)
...

Sheet 코드관리
B2: 코드 관리
B3: 파란 글씨 칸에 입력. 여기 등록한 OPEX 코드는 'OPEX 상세' 시트 D열 드롭다운과 계정명 자동표시에 사용됩니다.
B5: ① OPEX 코드표 | G5: ② 업체별 구매코드 (한 업체에 여러 코드 등록 가능)
B6: OPEX 코드 | C6: 계정명 | D6: 설명 | G6: 업체명 | H6: 업체 구매코드 | I6: 품목명 | J6: 연결 OPEX 코드 | K6: 비고
G7: (예시) 디앤오 | H7: DNO-NAS-01 | I7: NAS Storage | K7: 예시 행 - 삭제 후 사용

Sheet 설정
B2: 설정값
B4: 환율 (KRW / USD) | C4: 1350 | D4: USD 금액 원화환산에 사용. 결제/청구 시점 환율로 수정하세요. (현재값은 임시: 제이앤캐이 주부식 원화/달러 비율 평균 약 1,340~1,365 참고)
B5: 부가세율 | C5: 0.1 | D5: 과세 항목 부가세 계산에 사용
B8: 목록 (드롭다운 원본)
B9: 선박 | C9: 과세구분 | D9: 금액기준 | E9: 통화 | F9: 업체
B10: NORTH LIGHT | C10: 과세 | D10: VAT별도 | E10: KRW | F10: 고려문화사
B11: NORTH MOON | C11: 비과세 | D11: VAT포함 | E11: USD | F11: 네오맥스
B12: NORTH OCEAN | F12: 디앤오
B13: NORTH VALLEY | F13: 비아이자이로
B14: OFFICE | F14: 시웨이글로벌
B15: 공통(미배분) | F15: 옥슨앤파트너스
F16: 제이앤캐이
F17: 한국해양개발
F18: 한일후지코리아
F19: 해인쉽스서비스
F20: 화인컴에스이
B26: ※ 업체 추가 시 업체 목록 아래 빈칸에 이어서 입력하면 드롭다운에 반영됩니다 (10개까지).
