Workbook

Sheet 전체
A1: 점심 식당 리스트 – 부산 중앙동·남포동 일대 (43곳)
A2: 맨 아래 빈 행에 추가하면 분류 시트에 자동 반영됩니다. 영업상태는 캡처 시점 기준이라 방문 전 확인 필요. 분류 시트는 수식으로 자동 채워집니다(직접 수정 X).
A3: ※ 대략 가격은 메뉴 종류 기준 추정치(원)입니다. 홍가네(네이버 표시가)·용문(전달받은 코스가)만 실제 값이고, 나머지는 실제와 다를 수 있으니 방문 전 확인하세요. 도보시간(대교로 119 기준)은 지도 앱으로 확인해 입력해 주세요.
A5: No. | B5: 분류 | C5: 식당명 | D5: 네이버 업종 | E5: 영업상태 (캡처 시점) | F5: 예약 | G5: 주소 | H5: 층 / 호 / 건물 | I5: 도보(분) 대교로119 기준 | J5: 평점 (네이버) | K5: 전화 | L5: 대표메뉴 | M5: 대략 가격 (원) ※추정 | N5: 소개 | O5: 메모 | P5: key
A6: =IF(C6="","",ROW()-5) -> 1 | B6: 중식 | C6: 편의방 | D6: 딤섬,중식만두 | E6: 영업 중 | G6: 부산 중구 중앙동4가 30-5 | H6: 1층 | L6: 딤섬·군만두 | M6: 6,000~9,000 | N6: 딤섬·중식만두 전문점. 가볍게 먹기 좋은 만두집 | P6: =IF(OR(B6="",C6=""),"",B6&"|"&COUNTIF($B$6:B6,B6)) -> 중식|1
A7: =IF(C7="","",ROW()-5) -> 2 | B7: 일식 | C7: 리틀훅라멘 | D7: 일본식라면 | E7: 영업 중 | G7: 부산 중구 대청로137번길 4 (중앙동3가 17-1) | H7: 1층 | J7: 리뷰 110 | L7: 라멘 | M7: 9,000~12,000 | N7: 고등어의 깊은 맛이 담긴 걸쭉한 스프 | O7: 15:00 브레이크타임 / 중앙역 7번 출구 103m | P7: =IF(OR(B7="",C7=""),"",B7&"|"&COUNTIF($B$6:B7,B7)) -> 일식|1
A8: =IF(C8="","",ROW()-5) -> 3 | B8: 일식 | C8: 성식당 중앙본점 | D8: 초밥,롤 | E8: 영업 중 | G8: 부산 중구 중앙동3가 14-11 | H8: 1층 | L8: 연어초밥·롤 세트 | M8: 10,000~20,000 | N8: 초밥·롤 전문점 (포장 도시락 사진이 많음) | P8: =IF(OR(B8="",C8=""),"",B8&"|"&COUNTIF($B$6:B8,B8)) -> 일식|2
A9: =IF(C9="","",ROW()-5) -> 4 | B9: 한식 | C9: 기와집 | D9: 한식 | E9: 영업 중 | G9: 부산 중구 중앙동3가 19-2 | H9: 1층 | L9: 한식 (메뉴 확인 필요) | N9: 한식당. 메뉴·가격은 확인 필요 | P9: =IF(OR(B9="",C9=""),"",B9&"|"&COUNTIF($B$6:B9,B9)) -> 한식|1
A10: =IF(C10="","",ROW()-5) -> 5 | B10: 고기·족발 | C10: 국제상인 짬뽕족발 | D10: 족발,보쌈 | E10: 브레이크타임 | G10: 부산 중구 중앙동4가 29-8 | L10: 족발·보쌈 | M10: 소 28,000~35,000 | N10: 족발·보쌈 전문점 (브레이크타임 있음) | P10: =IF(OR(B10="",C10=""),"",B10&"|"&COUNTIF($B$6:B10,B10)) -> 고기·족발|1
A11: =IF(C11="","",ROW()-5) -> 6 | B11: 면 | C11: 1969부원동칼국수 남포본점 | D11: 칼국수,만두 | E11: 영업 중 | G11: 부산 중구 남포동2가 36 | H11: 1층 | L11: 칼국수·만두 | M11: 7,000~9,000 | N11: 55주년 현판이 있는 노포 칼국수집. 칼국수·만두 | P11: =IF(OR(B11="",C11=""),"",B11&"|"&COUNTIF($B$6:B11,B11)) -> 면|1
A12: =IF(C12="","",ROW()-5) -> 7 | B12: 한식 | C12: 청기와개미집 | D12: 한식 | E12: 정보 없음 | G12: 부산 중구 동광동3가 24-1 | L12: 한식 (메뉴 확인 필요) | N12: 한식당. 메뉴·가격은 확인 필요 | P12: =IF(OR(B12="",C12=""),"",B12&"|"&COUNTIF($B$6:B12,B12)) -> 한식|2
A13: =IF(C13="","",ROW()-5) -> 8 | B13: 한식 | C13: 미니한식당 | D13: 한식 | E13: 정보 없음 | G13: 부산 중구 중앙동2가 33 | L13: 한식 (메뉴 확인 필요) | N13: 한식당. 메뉴·가격은 확인 필요 | P13: =IF(OR(B13="",C13=""),"",B13&"|"&COUNTIF($B$6:B13,B13)) -> 한식|3
A14: =IF(C14="","",ROW()-5) -> 9 | B14: 면 | C14: 재성밀면 | D14: 냉면 | E14: 영업 중 | G14: 부산 중구 동광동3가 17-2 | L14: 밀면·냉면 | M14: 8,000~10,000 | N14: 부산식 밀면 전문점 (네이버 업종: 냉면) | P14: =IF(OR(B14="",C14=""),"",B14&"|"&COUNTIF($B$6:B14,B14)) -> 면|2
A15: =IF(C15="","",ROW()-5) -> 10 | B15: 국밥·탕 | C15: 중앙본가국밥 | D15: 국밥 | E15: 영업 중 | G15: 부산 중구 중앙동2가 49-18 | H15: 1층 | L15: 국밥 | M15: 9,000~11,000 | N15: 국밥 전문점. 넓은 홀 | P15: =IF(OR(B15="",C15=""),"",B15&"|"&COUNTIF($B$6:B15,B15)) -> 국밥·탕|1
A16: =IF(C16="","",ROW()-5) -> 11 | B16: 한식 | C16: 대나무집 | D16: 한식 | E16: 영업 중 | G16: 부산 중구 중앙동3가 13-8 | L16: 한식 (메뉴 확인 필요) | N16: 한식당. 메뉴·가격은 확인 필요 | P16: =IF(OR(B16="",C16=""),"",B16&"|"&COUNTIF($B$6:B16,B16)) -> 한식|4
A17: =IF(C17="","",ROW()-5) -> 12 | B17: 한식 | C17: 전주식당 | D17: 한식 | E17: 영업 중 | G17: 부산 중구 중앙동3가 19-4 | L17: 한식 (메뉴 확인 필요) | N17: 한식당. 메뉴·가격은 확인 필요 | P17: =IF(OR(B17="",C17=""),"",B17&"|"&COUNTIF($B$6:B17,B17)) -> 한식|5
A18: =IF(C18="","",ROW()-5) -> 13 | B18: 한식 | C18: 오봉집 중앙점 | D18: 한식 | E18: 영업 중 | F18: O | G18: 부산 중구 중앙동3가 10-5 | H18: 1층 | L18: 낙지볶음·보쌈 (사진 기준 추정) | M18: 15,000~20,000 | N18: 예약 가능한 한식당. 매콤한 볶음과 보쌈 사진이 많음 | P18: =IF(OR(B18="",C18=""),"",B18&"|"&COUNTIF($B$6:B18,B18)) -> 한식|6
A19: =IF(C19="","",ROW()-5) -> 14 | B19: 국밥·탕 | C19: 한양왕순대돼지국밥 | D19: 국밥 | E19: 정보 없음 | G19: 부산 중구 중앙동1가 22-10 | L19: 순대·돼지국밥 | M19: 9,000~11,000 | N19: 순대와 돼지국밥 전문점 | P19: =IF(OR(B19="",C19=""),"",B19&"|"&COUNTIF($B$6:B19,B19)) -> 국밥·탕|2
A20: =IF(C20="","",ROW()-5) -> 15 | B20: 일식 | C20: 어스 | D20: 일식당 | E20: 영업 중 | G20: 부산 중구 중앙동3가 14-9 | H20: 1층 | L20: 일식 (메뉴 확인 필요) | N20: 일식당. 메뉴·가격은 확인 필요 | P20: =IF(OR(B20="",C20=""),"",B20&"|"&COUNTIF($B$6:B20,B20)) -> 일식|3
A21: =IF(C21="","",ROW()-5) -> 16 | B21: 면 | C21: 중앙모밀 | D21: 국수 | E21: 영업 중 | G21: 부산 중구 중앙동2가 27-2 | L21: 모밀·국수 | M21: 6,000~8,000 | N21: 모밀·국수를 가볍게 먹는 곳 (김 올린 국수 사진) | P21: =IF(OR(B21="",C21=""),"",B21&"|"&COUNTIF($B$6:B21,B21)) -> 면|3
A22: =IF(C22="","",ROW()-5) -> 17 | B22: 롯데백화점 | C22: 복주걱 롯데광복점 | D22: 한식뷔페 | E22: 영업 중 | G22: 부산 중구 중앙동7가 20-1 (롯데백화점 광복점) | H22: 10F F&B | K22: 051-678-3026 | L22: 한식뷔페 (1인) | M22: 15,000~20,000 | N22: 신선한 제철 나물과 고기 요리 등 한식 반찬 무제한 뷔페 | P22: =IF(OR(B22="",C22=""),"",B22&"|"&COUNTIF($B$6:B22,B22)) -> 롯데백화점|1
A23: =IF(C23="","",ROW()-5) -> 18 | B23: 롯데백화점 | C23: 류센소 롯데백화점 광복점 | D23: 일식당 | E23: 영업 중 | G23: 부산 중구 중앙동7가 20-1 (롯데백화점 광복점) | H23: 본관 B1 | L23: 일식 (메뉴 확인 필요) | N23: 롯데백화점 본관 지하 1층 일식당. 메뉴·가격은 확인 필요 | P23: =IF(OR(B23="",C23=""),"",B23&"|"&COUNTIF($B$6:B23,B23)) -> 롯데백화점|2
A24: =IF(C24="","",ROW()-5) -> 19 | B24: 한식 | C24: 한식레스토랑 여름 부산본점 | D24: 한식 | E24: 영업 중 | F24: O | G24: 부산 중구 중앙동6가 3-2 | H24: 2층 201·202·203호 | L24: 한식 정식 (돌솥밥·반찬 한 상) | N24: 예약 가능한 한식 레스토랑. 반찬이 여러 가지 나오는 한 상 차림. 가격 확인 필요 | P24: =IF(OR(B24="",C24=""),"",B24&"|"&COUNTIF($B$6:B24,B24)) -> 한식|7
A25: =IF(C25="","",ROW()-5) -> 20 | B25: 롯데백화점 | C25: 라이옥 롯데백화점 광복점 | D25: 베트남음식 | E25: 영업 중 | G25: 부산 중구 중앙동7가 20-1 (롯데백화점 광복점) | H25: 10F | L25: 쌀국수·베트남 요리 | M25: 12,000~16,000 | N25: 롯데백화점 10층 베트남 음식점 | P25: =IF(OR(B25="",C25=""),"",B25&"|"&COUNTIF($B$6:B25,B25)) -> 롯데백화점|3
A26: =IF(C26="","",ROW()-5) -> 21 | B26: 고기·족발 | C26: 참숯생갈비 | D26: 육류,고기요리 | E26: 영업 중 | G26: 부산 중구 중앙동5가 1-18 | L26: 생갈비 (1인분) | M26: 25,000~35,000 | N26: 참숯 고기구이 전문점 (육류·고기요리) | P26: =IF(OR(B26="",C26=""),"",B26&"|"&COUNTIF($B$6:B26,B26)) -> 고기·족발|2
A27: =IF(C27="","",ROW()-5) -> 22 | B27: 한식 | C27: 고품격한식뷔페 | D27: 한식 | E27: 영업 종료 | G27: 부산 중구 중앙동6가 3-2 | H27: 1층 101호 | L27: 한식뷔페 (1인) | N27: 한식 뷔페. 현재 영업 종료로 표시됨 | P27: =IF(OR(B27="",C27=""),"",B27&"|"&COUNTIF($B$6:B27,B27)) -> 한식|8
A28: =IF(C28="","",ROW()-5) -> 23 | B28: 중식 | C28: 동해반점 | D28: 중식당 | E28: 정보 없음 | G28: 부산 중구 중앙동6가 3-1 | L28: 짜장·짬뽕·탕수육 | M28: 7,000~10,000 | N28: 동네 중화요리 전문점 | P28: =IF(OR(B28="",C28=""),"",B28&"|"&COUNTIF($B$6:B28,B28)) -> 중식|2
A29: =IF(C29="","",ROW()-5) -> 24 | B29: 한식 | C29: 다복정 | D29: 한식 | E29: 정보 없음 | G29: 부산 중구 중앙동5가 10-3 | L29: 한식 (메뉴 확인 필요) | N29: 한식당. 메뉴·가격은 확인 필요 | P29: =IF(OR(B29="",C29=""),"",B29&"|"&COUNTIF($B$6:B29,B29)) -> 한식|9
A30: =IF(C30="","",ROW()-5) -> 25 | B30: 국밥·탕 | C30: 섬진강재첩국 | D30: 한식 (재첩국) | E30: 영업 종료 | G30: 부산 중구 동광동2가 10-4 | L30: 재첩국 | M30: 10,000~13,000 | N30: 재첩국 위주의 한식 (영업 종료로 표시됨) | O30: 재첩국이라 국밥·탕으로 분류 | P30: =IF(OR(B30="",C30=""),"",B30&"|"&COUNTIF($B$6:B30,B30)) -> 국밥·탕|3
A31: =IF(C31="","",ROW()-5) -> 26 | B31: 면 | C31: 얼큰이칼국수 | D31: 칼국수,만두 | E31: 영업 중 | G31: 부산 영도구 해양로 70 | H31: 1층 | J31: ★4.47 (리뷰 2,471) | K31: 0507-1320-5213 | L31: 얼큰칼국수·충무김밥 | M31: 8,000~10,000 | N31: 깔끔한 충무김밥과 얼큰칼국수의 조화 | O31: 15:00 라스트오더 / ※ 영도구 (중구 아님) | P31: =IF(OR(B31="",C31=""),"",B31&"|"&COUNTIF($B$6:B31,B31)) -> 면|4
A32: =IF(C32="","",ROW()-5) -> 27 | B32: 롯데백화점 | C32: 수수하지만장해 롯데백화점 광복점 | D32: 돈가스 | E32: 영업 중 | G32: 부산 중구 중앙동7가 20-1 (롯데백화점 광복점) | H32: 본관 B1 | L32: 치즈돈가스·등심/안심 돈가스 | M32: 12,000~17,000 | N32: 롯데백화점 본관 지하 1층 돈가스 전문점. 치즈 돈가스 사진이 많음 | P32: =IF(OR(B32="",C32=""),"",B32&"|"&COUNTIF($B$6:B32,B32)) -> 롯데백화점|4
A33: =IF(C33="","",ROW()-5) -> 28 | B33: 고기·족발 | C33: 홍가네 | D33: 육류,고기요리 | E33: 브레이크타임 | G33: 부산 중구 해관로 31 | H33: 1,2층 | J33: ★4.8 (리뷰 265) | L33: 언양불고기 (200g) | M33: 18,000 (200g) | N33: 점심특선 언양불고기 · ₩18,000 (200g) | O33: 17:00 영업 시작 / 중앙역 1번 출구 175m | P33: =IF(OR(B33="",C33=""),"",B33&"|"&COUNTIF($B$6:B33,B33)) -> 고기·족발|3
A34: =IF(C34="","",ROW()-5) -> 29 | B34: 양식·아시안 | C34: 라이프버거 | D34: 수제버거 | E34: 정보 없음 | G34: 부산 중구 중앙대로49번길 7 | L34: 수제버거 | M34: 7,000~10,000 | N34: 빨간 간판의 미국식 수제버거집 | O34: 주소는 웹검색 기준 – 방문 전 확인 | P34: =IF(OR(B34="",C34=""),"",B34&"|"&COUNTIF($B$6:B34,B34)) -> 양식·아시안|1
A35: =IF(C35="","",ROW()-5) -> 30 | B35: 중식 | C35: 용문 | D35: 중식 | E35: 정보 없음 | L35: 코스요리 | M35: 20,000 (코스) | N35: 점심 코스요리 2만원인 중식당 | O35: 중구 지점 확인 안 됨 – 웹검색에는 연제구 거제천로 209 용문각만 나옴 (같은 곳인지 확인 필요) | P35: =IF(OR(B35="",C35=""),"",B35&"|"&COUNTIF($B$6:B35,B35)) -> 중식|3
A36: =IF(C36="","",ROW()-5) -> 31 | B36: 회·해산물 | C36: 회백반·물회·생대구탕 집 (이름 확인 필요) | D36: 회백반,물회,생대구탕 | E36: 정보 없음 | L36: 회백반·물회·생대구탕 | M36: 15,000~20,000 | N36: 회백반·물회·생대구탕을 파는 횟집 | O36: 가게 이름 확인 필요 | P36: =IF(OR(B36="",C36=""),"",B36&"|"&COUNTIF($B$6:B36,B36)) -> 회·해산물|1
A37: =IF(C37="","",ROW()-5) -> 32 | B37: 국밥·탕 | C37: 남포설렁탕 | D37: 설렁탕 | E37: 정보 없음 | G37: 부산 중구 구덕로34번길 8 | L37: 설렁탕 | M37: 10,000~12,000 | N37: 남포동 설렁탕 전문점 | O37: 주소는 웹검색 기준 (이름: 링크 검색어) – 확인 필요 | P37: =IF(OR(B37="",C37=""),"",B37&"|"&COUNTIF($B$6:B37,B37)) -> 국밥·탕|4
A38: =IF(C38="","",ROW()-5) -> 33 | B38: 롯데백화점 | C38: 조방낙지1번가 | D38: 낙곱새 | E38: 정보 없음 | G38: 부산 중구 중앙동7가 20-1 (롯데백화점 광복점) | H38: 10F F&B | K38: 051-678-3062 | L38: 낙곱새 | M38: 14,000~17,000 | N38: 매콤달콤 양념에 낙지·새우·곱창을 넣어 밥에 비벼 먹는 낙곱새 | P38: =IF(OR(B38="",C38=""),"",B38&"|"&COUNTIF($B$6:B38,B38)) -> 롯데백화점|5
A39: =IF(C39="","",ROW()-5) -> 34 | B39: 롯데백화점 | C39: 항아리수제면가 | D39: 칼국수 | E39: 정보 없음 | G39: 부산 중구 중앙동7가 20-1 (롯데백화점 광복점) | H39: B1 F&B | K39: 051-678-3007 | L39: 해물칼국수 | M39: 9,000~12,000 | N39: 진한 해산물 육수에 수제 면발의 칼국수 | O39: 전화번호가 퍼틴과 동일 – 확인 필요 | P39: =IF(OR(B39="",C39=""),"",B39&"|"&COUNTIF($B$6:B39,B39)) -> 롯데백화점|6
A40: =IF(C40="","",ROW()-5) -> 35 | B40: 롯데백화점 | C40: 퍼틴 | D40: 베트남 쌀국수 | E40: 정보 없음 | G40: 부산 중구 중앙동7가 20-1 (롯데백화점 광복점) | H40: B1 F&B | K40: 051-678-3007 | L40: 쌀국수 | M40: 12,000~15,000 | N40: 하노이식 쌀국수 – 사골 육수와 파 고명 | O40: 전화번호가 항아리수제면가와 동일 – 확인 필요 | P40: =IF(OR(B40="",C40=""),"",B40&"|"&COUNTIF($B$6:B40,B40)) -> 롯데백화점|7
A41: =IF(C41="","",ROW()-5) -> 36 | B41: 롯데백화점 | C41: 반반식당 | D41: 김치찌개 | E41: 정보 없음 | G41: 부산 중구 중앙동7가 20-1 (롯데백화점 광복점) | H41: B1 F&B | K41: 051-678-3008 | L41: 김치찌개 | M41: 9,000~11,000 | N41: 돼지고기와 묵은지 반반 김치찌개 | P41: =IF(OR(B41="",C41=""),"",B41&"|"&COUNTIF($B$6:B41,B41)) -> 롯데백화점|8
...

Sheet 한식
A1: 한식 | C1: =COUNTIF(전체!$B$6:$B$75,"한식")&"곳" -> 9곳
A2: ※ "전체" 시트에서 분류를 지정하면 자동으로 채워집니다 (수식 시트, 직접 수정 X). 대략 가격은 추정치입니다. | R2: 한식
A4: No. | B4: 식당명 | C4: 네이버 업종 | D4: 영업상태 (캡처 시점) | E4: 예약 | F4: 주소 | G4: 층 / 호 / 건물 | H4: 도보(분) 대교로119 기준 | I4: 평점 (네이버) | J4: 전화 | K4: 대표메뉴 | L4: 대략 가격 (원) ※추정 | M4: 소개 | N4: 메모 | O4: row
A5: =IF($O5="","",1) -> 1 | B5: =IF($O5="","",IF(INDEX(전체!$C$6:$C$75,$O5)="","",INDEX(전체!$C$6:$C$75,$O5))) -> 기와집 | C5: =IF($O5="","",IF(INDEX(전체!$D$6:$D$75,$O5)="","",INDEX(전체!$D$6:$D$75,$O5))) -> 한식 | D5: =IF($O5="","",IF(INDEX(전체!$E$6:$E$75,$O5)="","",INDEX(전체!$E$6:$E$75,$O5))) -> 영업 중 | E5: =IF($O5="","",IF(INDEX(전체!$F$6:$F$75,$O5)="","",INDEX(전체!$F$6:$F$75,$O5))) | F5: =IF($O5="","",IF(INDEX(전체!$G$6:$G$75,$O5)="","",INDEX(전체!$G$6:$G$75,$O5))) -> 부산 중구 중앙동3가 19-2 | G5: =IF($O5="","",IF(INDEX(전체!$H$6:$H$75,$O5)="","",INDEX(전체!$H$6:$H$75,$O5))) -> 1층 | H5: =IF($O5="","",IF(INDEX(전체!$I$6:$I$75,$O5)="","",INDEX(전체!$I$6:$I$75,$O5))) | I5: =IF($O5="","",IF(INDEX(전체!$J$6:$J$75,$O5)="","",INDEX(전체!$J$6:$J$75,$O5))) | J5: =IF($O5="","",IF(INDEX(전체!$K$6:$K$75,$O5)="","",INDEX(전체!$K$6:$K$75,$O5))) | K5: =IF($O5="","",IF(INDEX(전체!$L$6:$L$75,$O5)="","",INDEX(전체!$L$6:$L$75,$O5))) -> 한식 (메뉴 확인 필요) | L5: =IF($O5="","",IF(INDEX(전체!$M$6:$M$75,$O5)="","",INDEX(전체!$M$6:$M$75,$O5))) | M5: =IF($O5="","",IF(INDEX(전체!$N$6:$N$75,$O5)="","",INDEX(전체!$N$6:$N$75,$O5))) -> 한식당. 메뉴·가격은 확인 필요 | N5: =IF($O5="","",IF(INDEX(전체!$O$6:$O$75,$O5)="","",INDEX(전체!$O$6:$O$75,$O5))) | O5: =IFERROR(MATCH($R$2&"|"&1,전체!$P$6:$P$75,0),"") -> 4
A6: =IF($O6="","",2) -> 2 | B6: =IF($O6="","",IF(INDEX(전체!$C$6:$C$75,$O6)="","",INDEX(전체!$C$6:$C$75,$O6))) -> 청기와개미집 | C6: =IF($O6="","",IF(INDEX(전체!$D$6:$D$75,$O6)="","",INDEX(전체!$D$6:$D$75,$O6))) -> 한식 | D6: =IF($O6="","",IF(INDEX(전체!$E$6:$E$75,$O6)="","",INDEX(전체!$E$6:$E$75,$O6))) -> 정보 없음 | E6: =IF($O6="","",IF(INDEX(전체!$F$6:$F$75,$O6)="","",INDEX(전체!$F$6:$F$75,$O6))) | F6: =IF($O6="","",IF(INDEX(전체!$G$6:$G$75,$O6)="","",INDEX(전체!$G$6:$G$75,$O6))) -> 부산 중구 동광동3가 24-1 | G6: =IF($O6="","",IF(INDEX(전체!$H$6:$H$75,$O6)="","",INDEX(전체!$H$6:$H$75,$O6))) | H6: =IF($O6="","",IF(INDEX(전체!$I$6:$I$75,$O6)="","",INDEX(전체!$I$6:$I$75,$O6))) | I6: =IF($O6="","",IF(INDEX(전체!$J$6:$J$75,$O6)="","",INDEX(전체!$J$6:$J$75,$O6))) | J6: =IF($O6="","",IF(INDEX(전체!$K$6:$K$75,$O6)="","",INDEX(전체!$K$6:$K$75,$O6))) | K6: =IF($O6="","",IF(INDEX(전체!$L$6:$L$75,$O6)="","",INDEX(전체!$L$6:$L$75,$O6))) -> 한식 (메뉴 확인 필요) | L6: =IF($O6="","",IF(INDEX(전체!$M$6:$M$75,$O6)="","",INDEX(전체!$M$6:$M$75,$O6))) | M6: =IF($O6="","",IF(INDEX(전체!$N$6:$N$75,$O6)="","",INDEX(전체!$N$6:$N$75,$O6))) -> 한식당. 메뉴·가격은 확인 필요 | N6: =IF($O6="","",IF(INDEX(전체!$O$6:$O$75,$O6)="","",INDEX(전체!$O$6:$O$75,$O6))) | O6: =IFERROR(MATCH($R$2&"|"&2,전체!$P$6:$P$75,0),"") -> 7
A7: =IF($O7="","",3) -> 3 | B7: =IF($O7="","",IF(INDEX(전체!$C$6:$C$75,$O7)="","",INDEX(전체!$C$6:$C$75,$O7))) -> 미니한식당 | C7: =IF($O7="","",IF(INDEX(전체!$D$6:$D$75,$O7)="","",INDEX(전체!$D$6:$D$75,$O7))) -> 한식 | D7: =IF($O7="","",IF(INDEX(전체!$E$6:$E$75,$O7)="","",INDEX(전체!$E$6:$E$75,$O7))) -> 정보 없음 | E7: =IF($O7="","",IF(INDEX(전체!$F$6:$F$75,$O7)="","",INDEX(전체!$F$6:$F$75,$O7))) | F7: =IF($O7="","",IF(INDEX(전체!$G$6:$G$75,$O7)="","",INDEX(전체!$G$6:$G$75,$O7))) -> 부산 중구 중앙동2가 33 | G7: =IF($O7="","",IF(INDEX(전체!$H$6:$H$75,$O7)="","",INDEX(전체!$H$6:$H$75,$O7))) | H7: =IF($O7="","",IF(INDEX(전체!$I$6:$I$75,$O7)="","",INDEX(전체!$I$6:$I$75,$O7))) | I7: =IF($O7="","",IF(INDEX(전체!$J$6:$J$75,$O7)="","",INDEX(전체!$J$6:$J$75,$O7))) | J7: =IF($O7="","",IF(INDEX(전체!$K$6:$K$75,$O7)="","",INDEX(전체!$K$6:$K$75,$O7))) | K7: =IF($O7="","",IF(INDEX(전체!$L$6:$L$75,$O7)="","",INDEX(전체!$L$6:$L$75,$O7))) -> 한식 (메뉴 확인 필요) | L7: =IF($O7="","",IF(INDEX(전체!$M$6:$M$75,$O7)="","",INDEX(전체!$M$6:$M$75,$O7))) | M7: =IF($O7="","",IF(INDEX(전체!$N$6:$N$75,$O7)="","",INDEX(전체!$N$6:$N$75,$O7))) -> 한식당. 메뉴·가격은 확인 필요 | N7: =IF($O7="","",IF(INDEX(전체!$O$6:$O$75,$O7)="","",INDEX(전체!$O$6:$O$75,$O7))) | O7: =IFERROR(MATCH($R$2&"|"&3,전체!$P$6:$P$75,0),"") -> 8
A8: =IF($O8="","",4) -> 4 | B8: =IF($O8="","",IF(INDEX(전체!$C$6:$C$75,$O8)="","",INDEX(전체!$C$6:$C$75,$O8))) -> 대나무집 | C8: =IF($O8="","",IF(INDEX(전체!$D$6:$D$75,$O8)="","",INDEX(전체!$D$6:$D$75,$O8))) -> 한식 | D8: =IF($O8="","",IF(INDEX(전체!$E$6:$E$75,$O8)="","",INDEX(전체!$E$6:$E$75,$O8))) -> 영업 중 | E8: =IF($O8="","",IF(INDEX(전체!$F$6:$F$75,$O8)="","",INDEX(전체!$F$6:$F$75,$O8))) | F8: =IF($O8="","",IF(INDEX(전체!$G$6:$G$75,$O8)="","",INDEX(전체!$G$6:$G$75,$O8))) -> 부산 중구 중앙동3가 13-8 | G8: =IF($O8="","",IF(INDEX(전체!$H$6:$H$75,$O8)="","",INDEX(전체!$H$6:$H$75,$O8))) | H8: =IF($O8="","",IF(INDEX(전체!$I$6:$I$75,$O8)="","",INDEX(전체!$I$6:$I$75,$O8))) | I8: =IF($O8="","",IF(INDEX(전체!$J$6:$J$75,$O8)="","",INDEX(전체!$J$6:$J$75,$O8))) | J8: =IF($O8="","",IF(INDEX(전체!$K$6:$K$75,$O8)="","",INDEX(전체!$K$6:$K$75,$O8))) | K8: =IF($O8="","",IF(INDEX(전체!$L$6:$L$75,$O8)="","",INDEX(전체!$L$6:$L$75,$O8))) -> 한식 (메뉴 확인 필요) | L8: =IF($O8="","",IF(INDEX(전체!$M$6:$M$75,$O8)="","",INDEX(전체!$M$6:$M$75,$O8))) | M8: =IF($O8="","",IF(INDEX(전체!$N$6:$N$75,$O8)="","",INDEX(전체!$N$6:$N$75,$O8))) -> 한식당. 메뉴·가격은 확인 필요 | N8: =IF($O8="","",IF(INDEX(전체!$O$6:$O$75,$O8)="","",INDEX(전체!$O$6:$O$75,$O8))) | O8: =IFERROR(MATCH($R$2&"|"&4,전체!$P$6:$P$75,0),"") -> 11
A9: =IF($O9="","",5) -> 5 | B9: =IF($O9="","",IF(INDEX(전체!$C$6:$C$75,$O9)="","",INDEX(전체!$C$6:$C$75,$O9))) -> 전주식당 | C9: =IF($O9="","",IF(INDEX(전체!$D$6:$D$75,$O9)="","",INDEX(전체!$D$6:$D$75,$O9))) -> 한식 | D9: =IF($O9="","",IF(INDEX(전체!$E$6:$E$75,$O9)="","",INDEX(전체!$E$6:$E$75,$O9))) -> 영업 중 | E9: =IF($O9="","",IF(INDEX(전체!$F$6:$F$75,$O9)="","",INDEX(전체!$F$6:$F$75,$O9))) | F9: =IF($O9="","",IF(INDEX(전체!$G$6:$G$75,$O9)="","",INDEX(전체!$G$6:$G$75,$O9))) -> 부산 중구 중앙동3가 19-4 | G9: =IF($O9="","",IF(INDEX(전체!$H$6:$H$75,$O9)="","",INDEX(전체!$H$6:$H$75,$O9))) | H9: =IF($O9="","",IF(INDEX(전체!$I$6:$I$75,$O9)="","",INDEX(전체!$I$6:$I$75,$O9))) | I9: =IF($O9="","",IF(INDEX(전체!$J$6:$J$75,$O9)="","",INDEX(전체!$J$6:$J$75,$O9))) | J9: =IF($O9="","",IF(INDEX(전체!$K$6:$K$75,$O9)="","",INDEX(전체!$K$6:$K$75,$O9))) | K9: =IF($O9="","",IF(INDEX(전체!$L$6:$L$75,$O9)="","",INDEX(전체!$L$6:$L$75,$O9))) -> 한식 (메뉴 확인 필요) | L9: =IF($O9="","",IF(INDEX(전체!$M$6:$M$75,$O9)="","",INDEX(전체!$M$6:$M$75,$O9))) | M9: =IF($O9="","",IF(INDEX(전체!$N$6:$N$75,$O9)="","",INDEX(전체!$N$6:$N$75,$O9))) -> 한식당. 메뉴·가격은 확인 필요 | N9: =IF($O9="","",IF(INDEX(전체!$O$6:$O$75,$O9)="","",INDEX(전체!$O$6:$O$75,$O9))) | O9: =IFERROR(MATCH($R$2&"|"&5,전체!$P$6:$P$75,0),"") -> 12
A10: =IF($O10="","",6) -> 6 | B10: =IF($O10="","",IF(INDEX(전체!$C$6:$C$75,$O10)="","",INDEX(전체!$C$6:$C$75,$O10))) -> 오봉집 중앙점 | C10: =IF($O10="","",IF(INDEX(전체!$D$6:$D$75,$O10)="","",INDEX(전체!$D$6:$D$75,$O10))) -> 한식 | D10: =IF($O10="","",IF(INDEX(전체!$E$6:$E$75,$O10)="","",INDEX(전체!$E$6:$E$75,$O10))) -> 영업 중 | E10: =IF($O10="","",IF(INDEX(전체!$F$6:$F$75,$O10)="","",INDEX(전체!$F$6:$F$75,$O10))) -> O | F10: =IF($O10="","",IF(INDEX(전체!$G$6:$G$75,$O10)="","",INDEX(전체!$G$6:$G$75,$O10))) -> 부산 중구 중앙동3가 10-5 | G10: =IF($O10="","",IF(INDEX(전체!$H$6:$H$75,$O10)="","",INDEX(전체!$H$6:$H$75,$O10))) -> 1층 | H10: =IF($O10="","",IF(INDEX(전체!$I$6:$I$75,$O10)="","",INDEX(전체!$I$6:$I$75,$O10))) | I10: =IF($O10="","",IF(INDEX(전체!$J$6:$J$75,$O10)="","",INDEX(전체!$J$6:$J$75,$O10))) | J10: =IF($O10="","",IF(INDEX(전체!$K$6:$K$75,$O10)="","",INDEX(전체!$K$6:$K$75,$O10))) | K10: =IF($O10="","",IF(INDEX(전체!$L$6:$L$75,$O10)="","",INDEX(전체!$L$6:$L$75,$O10))) -> 낙지볶음·보쌈 (사진 기준 추정) | L10: =IF($O10="","",IF(INDEX(전체!$M$6:$M$75,$O10)="","",INDEX(전체!$M$6:$M$75,$O10))) -> 15,000~20,000 | M10: =IF($O10="","",IF(INDEX(전체!$N$6:$N$75,$O10)="","",INDEX(전체!$N$6:$N$75,$O10))) -> 예약 가능한 한식당. 매콤한 볶음과 보쌈 사진이 많음 | N10: =IF($O10="","",IF(INDEX(전체!$O$6:$O$75,$O10)="","",INDEX(전체!$O$6:$O$75,$O10))) | O10: =IFERROR(MATCH($R$2&"|"&6,전체!$P$6:$P$75,0),"") -> 13
A11: =IF($O11="","",7) -> 7 | B11: =IF($O11="","",IF(INDEX(전체!$C$6:$C$75,$O11)="","",INDEX(전체!$C$6:$C$75,$O11))) -> 한식레스토랑 여름 부산본점 | C11: =IF($O11="","",IF(INDEX(전체!$D$6:$D$75,$O11)="","",INDEX(전체!$D$6:$D$75,$O11))) -> 한식 | D11: =IF($O11="","",IF(INDEX(전체!$E$6:$E$75,$O11)="","",INDEX(전체!$E$6:$E$75,$O11))) -> 영업 중 | E11: =IF($O11="","",IF(INDEX(전체!$F$6:$F$75,$O11)="","",INDEX(전체!$F$6:$F$75,$O11))) -> O | F11: =IF($O11="","",IF(INDEX(전체!$G$6:$G$75,$O11)="","",INDEX(전체!$G$6:$G$75,$O11))) -> 부산 중구 중앙동6가 3-2 | G11: =IF($O11="","",IF(INDEX(전체!$H$6:$H$75,$O11)="","",INDEX(전체!$H$6:$H$75,$O11))) -> 2층 201·202·203호 | H11: =IF($O11="","",IF(INDEX(전체!$I$6:$I$75,$O11)="","",INDEX(전체!$I$6:$I$75,$O11))) | I11: =IF($O11="","",IF(INDEX(전체!$J$6:$J$75,$O11)="","",INDEX(전체!$J$6:$J$75,$O11))) | J11: =IF($O11="","",IF(INDEX(전체!$K$6:$K$75,$O11)="","",INDEX(전체!$K$6:$K$75,$O11))) | K11: =IF($O11="","",IF(INDEX(전체!$L$6:$L$75,$O11)="","",INDEX(전체!$L$6:$L$75,$O11))) -> 한식 정식 (돌솥밥·반찬 한 상) | L11: =IF($O11="","",IF(INDEX(전체!$M$6:$M$75,$O11)="","",INDEX(전체!$M$6:$M$75,$O11))) | M11: =IF($O11="","",IF(INDEX(전체!$N$6:$N$75,$O11)="","",INDEX(전체!$N$6:$N$75,$O11))) -> 예약 가능한 한식 레스토랑. 반찬이 여러 가지 나오는 한 상 차림. 가격 확인 필요 | N11: =IF($O11="","",IF(INDEX(전체!$O$6:$O$75,$O11)="","",INDEX(전체!$O$6:$O$75,$O11))) | O11: =IFERROR(MATCH($R$2&"|"&7,전체!$P$6:$P$75,0),"") -> 19
A12: =IF($O12="","",8) -> 8 | B12: =IF($O12="","",IF(INDEX(전체!$C$6:$C$75,$O12)="","",INDEX(전체!$C$6:$C$75,$O12))) -> 고품격한식뷔페 | C12: =IF($O12="","",IF(INDEX(전체!$D$6:$D$75,$O12)="","",INDEX(전체!$D$6:$D$75,$O12))) -> 한식 | D12: =IF($O12="","",IF(INDEX(전체!$E$6:$E$75,$O12)="","",INDEX(전체!$E$6:$E$75,$O12))) -> 영업 종료 | E12: =IF($O12="","",IF(INDEX(전체!$F$6:$F$75,$O12)="","",INDEX(전체!$F$6:$F$75,$O12))) | F12: =IF($O12="","",IF(INDEX(전체!$G$6:$G$75,$O12)="","",INDEX(전체!$G$6:$G$75,$O12))) -> 부산 중구 중앙동6가 3-2 | G12: =IF($O12="","",IF(INDEX(전체!$H$6:$H$75,$O12)="","",INDEX(전체!$H$6:$H$75,$O12))) -> 1층 101호 | H12: =IF($O12="","",IF(INDEX(전체!$I$6:$I$75,$O12)="","",INDEX(전체!$I$6:$I$75,$O12))) | I12: =IF($O12="","",IF(INDEX(전체!$J$6:$J$75,$O12)="","",INDEX(전체!$J$6:$J$75,$O12))) | J12: =IF($O12="","",IF(INDEX(전체!$K$6:$K$75,$O12)="","",INDEX(전체!$K$6:$K$75,$O12))) | K12: =IF($O12="","",IF(INDEX(전체!$L$6:$L$75,$O12)="","",INDEX(전체!$L$6:$L$75,$O12))) -> 한식뷔페 (1인) | L12: =IF($O12="","",IF(INDEX(전체!$M$6:$M$75,$O12)="","",INDEX(전체!$M$6:$M$75,$O12))) | M12: =IF($O12="","",IF(INDEX(전체!$N$6:$N$75,$O12)="","",INDEX(전체!$N$6:$N$75,$O12))) -> 한식 뷔페. 현재 영업 종료로 표시됨 | N12: =IF($O12="","",IF(INDEX(전체!$O$6:$O$75,$O12)="","",INDEX(전체!$O$6:$O$75,$O12))) | O12: =IFERROR(MATCH($R$2&"|"&8,전체!$P$6:$P$75,0),"") -> 22
A13: =IF($O13="","",9) -> 9 | B13: =IF($O13="","",IF(INDEX(전체!$C$6:$C$75,$O13)="","",INDEX(전체!$C$6:$C$75,$O13))) -> 다복정 | C13: =IF($O13="","",IF(INDEX(전체!$D$6:$D$75,$O13)="","",INDEX(전체!$D$6:$D$75,$O13))) -> 한식 | D13: =IF($O13="","",IF(INDEX(전체!$E$6:$E$75,$O13)="","",INDEX(전체!$E$6:$E$75,$O13))) -> 정보 없음 | E13: =IF($O13="","",IF(INDEX(전체!$F$6:$F$75,$O13)="","",INDEX(전체!$F$6:$F$75,$O13))) | F13: =IF($O13="","",IF(INDEX(전체!$G$6:$G$75,$O13)="","",INDEX(전체!$G$6:$G$75,$O13))) -> 부산 중구 중앙동5가 10-3 | G13: =IF($O13="","",IF(INDEX(전체!$H$6:$H$75,$O13)="","",INDEX(전체!$H$6:$H$75,$O13))) | H13: =IF($O13="","",IF(INDEX(전체!$I$6:$I$75,$O13)="","",INDEX(전체!$I$6:$I$75,$O13))) | I13: =IF($O13="","",IF(INDEX(전체!$J$6:$J$75,$O13)="","",INDEX(전체!$J$6:$J$75,$O13))) | J13: =IF($O13="","",IF(INDEX(전체!$K$6:$K$75,$O13)="","",INDEX(전체!$K$6:$K$75,$O13))) | K13: =IF($O13="","",IF(INDEX(전체!$L$6:$L$75,$O13)="","",INDEX(전체!$L$6:$L$75,$O13))) -> 한식 (메뉴 확인 필요) | L13: =IF($O13="","",IF(INDEX(전체!$M$6:$M$75,$O13)="","",INDEX(전체!$M$6:$M$75,$O13))) | M13: =IF($O13="","",IF(INDEX(전체!$N$6:$N$75,$O13)="","",INDEX(전체!$N$6:$N$75,$O13))) -> 한식당. 메뉴·가격은 확인 필요 | N13: =IF($O13="","",IF(INDEX(전체!$O$6:$O$75,$O13)="","",INDEX(전체!$O$6:$O$75,$O13))) | O13: =IFERROR(MATCH($R$2&"|"&9,전체!$P$6:$P$75,0),"") -> 24
A14: =IF($O14="","",10) | B14: =IF($O14="","",IF(INDEX(전체!$C$6:$C$75,$O14)="","",INDEX(전체!$C$6:$C$75,$O14))) | C14: =IF($O14="","",IF(INDEX(전체!$D$6:$D$75,$O14)="","",INDEX(전체!$D$6:$D$75,$O14))) | D14: =IF($O14="","",IF(INDEX(전체!$E$6:$E$75,$O14)="","",INDEX(전체!$E$6:$E$75,$O14))) | E14: =IF($O14="","",IF(INDEX(전체!$F$6:$F$75,$O14)="","",INDEX(전체!$F$6:$F$75,$O14))) | F14: =IF($O14="","",IF(INDEX(전체!$G$6:$G$75,$O14)="","",INDEX(전체!$G$6:$G$75,$O14))) | G14: =IF($O14="","",IF(INDEX(전체!$H$6:$H$75,$O14)="","",INDEX(전체!$H$6:$H$75,$O14))) | H14: =IF($O14="","",IF(INDEX(전체!$I$6:$I$75,$O14)="","",INDEX(전체!$I$6:$I$75,$O14))) | I14: =IF($O14="","",IF(INDEX(전체!$J$6:$J$75,$O14)="","",INDEX(전체!$J$6:$J$75,$O14))) | J14: =IF($O14="","",IF(INDEX(전체!$K$6:$K$75,$O14)="","",INDEX(전체!$K$6:$K$75,$O14))) | K14: =IF($O14="","",IF(INDEX(전체!$L$6:$L$75,$O14)="","",INDEX(전체!$L$6:$L$75,$O14))) | L14: =IF($O14="","",IF(INDEX(전체!$M$6:$M$75,$O14)="","",INDEX(전체!$M$6:$M$75,$O14))) | M14: =IF($O14="","",IF(INDEX(전체!$N$6:$N$75,$O14)="","",INDEX(전체!$N$6:$N$75,$O14))) | N14: =IF($O14="","",IF(INDEX(전체!$O$6:$O$75,$O14)="","",INDEX(전체!$O$6:$O$75,$O14))) | O14: =IFERROR(MATCH($R$2&"|"&10,전체!$P$6:$P$75,0),"")
A15: =IF($O15="","",11) | B15: =IF($O15="","",IF(INDEX(전체!$C$6:$C$75,$O15)="","",INDEX(전체!$C$6:$C$75,$O15))) | C15: =IF($O15="","",IF(INDEX(전체!$D$6:$D$75,$O15)="","",INDEX(전체!$D$6:$D$75,$O15))) | D15: =IF($O15="","",IF(INDEX(전체!$E$6:$E$75,$O15)="","",INDEX(전체!$E$6:$E$75,$O15))) | E15: =IF($O15="","",IF(INDEX(전체!$F$6:$F$75,$O15)="","",INDEX(전체!$F$6:$F$75,$O15))) | F15: =IF($O15="","",IF(INDEX(전체!$G$6:$G$75,$O15)="","",INDEX(전체!$G$6:$G$75,$O15))) | G15: =IF($O15="","",IF(INDEX(전체!$H$6:$H$75,$O15)="","",INDEX(전체!$H$6:$H$75,$O15))) | H15: =IF($O15="","",IF(INDEX(전체!$I$6:$I$75,$O15)="","",INDEX(전체!$I$6:$I$75,$O15))) | I15: =IF($O15="","",IF(INDEX(전체!$J$6:$J$75,$O15)="","",INDEX(전체!$J$6:$J$75,$O15))) | J15: =IF($O15="","",IF(INDEX(전체!$K$6:$K$75,$O15)="","",INDEX(전체!$K$6:$K$75,$O15))) | K15: =IF($O15="","",IF(INDEX(전체!$L$6:$L$75,$O15)="","",INDEX(전체!$L$6:$L$75,$O15))) | L15: =IF($O15="","",IF(INDEX(전체!$M$6:$M$75,$O15)="","",INDEX(전체!$M$6:$M$75,$O15))) | M15: =IF($O15="","",IF(INDEX(전체!$N$6:$N$75,$O15)="","",INDEX(전체!$N$6:$N$75,$O15))) | N15: =IF($O15="","",IF(INDEX(전체!$O$6:$O$75,$O15)="","",INDEX(전체!$O$6:$O$75,$O15))) | O15: =IFERROR(MATCH($R$2&"|"&11,전체!$P$6:$P$75,0),"")
A16: =IF($O16="","",12) | B16: =IF($O16="","",IF(INDEX(전체!$C$6:$C$75,$O16)="","",INDEX(전체!$C$6:$C$75,$O16))) | C16: =IF($O16="","",IF(INDEX(전체!$D$6:$D$75,$O16)="","",INDEX(전체!$D$6:$D$75,$O16))) | D16: =IF($O16="","",IF(INDEX(전체!$E$6:$E$75,$O16)="","",INDEX(전체!$E$6:$E$75,$O16))) | E16: =IF($O16="","",IF(INDEX(전체!$F$6:$F$75,$O16)="","",INDEX(전체!$F$6:$F$75,$O16))) | F16: =IF($O16="","",IF(INDEX(전체!$G$6:$G$75,$O16)="","",INDEX(전체!$G$6:$G$75,$O16))) | G16: =IF($O16="","",IF(INDEX(전체!$H$6:$H$75,$O16)="","",INDEX(전체!$H$6:$H$75,$O16))) | H16: =IF($O16="","",IF(INDEX(전체!$I$6:$I$75,$O16)="","",INDEX(전체!$I$6:$I$75,$O16))) | I16: =IF($O16="","",IF(INDEX(전체!$J$6:$J$75,$O16)="","",INDEX(전체!$J$6:$J$75,$O16))) | J16: =IF($O16="","",IF(INDEX(전체!$K$6:$K$75,$O16)="","",INDEX(전체!$K$6:$K$75,$O16))) | K16: =IF($O16="","",IF(INDEX(전체!$L$6:$L$75,$O16)="","",INDEX(전체!$L$6:$L$75,$O16))) | L16: =IF($O16="","",IF(INDEX(전체!$M$6:$M$75,$O16)="","",INDEX(전체!$M$6:$M$75,$O16))) | M16: =IF($O16="","",IF(INDEX(전체!$N$6:$N$75,$O16)="","",INDEX(전체!$N$6:$N$75,$O16))) | N16: =IF($O16="","",IF(INDEX(전체!$O$6:$O$75,$O16)="","",INDEX(전체!$O$6:$O$75,$O16))) | O16: =IFERROR(MATCH($R$2&"|"&12,전체!$P$6:$P$75,0),"")
A17: =IF($O17="","",13) | B17: =IF($O17="","",IF(INDEX(전체!$C$6:$C$75,$O17)="","",INDEX(전체!$C$6:$C$75,$O17))) | C17: =IF($O17="","",IF(INDEX(전체!$D$6:$D$75,$O17)="","",INDEX(전체!$D$6:$D$75,$O17))) | D17: =IF($O17="","",IF(INDEX(전체!$E$6:$E$75,$O17)="","",INDEX(전체!$E$6:$E$75,$O17))) | E17: =IF($O17="","",IF(INDEX(전체!$F$6:$F$75,$O17)="","",INDEX(전체!$F$6:$F$75,$O17))) | F17: =IF($O17="","",IF(INDEX(전체!$G$6:$G$75,$O17)="","",INDEX(전체!$G$6:$G$75,$O17))) | G17: =IF($O17="","",IF(INDEX(전체!$H$6:$H$75,$O17)="","",INDEX(전체!$H$6:$H$75,$O17))) | H17: =IF($O17="","",IF(INDEX(전체!$I$6:$I$75,$O17)="","",INDEX(전체!$I$6:$I$75,$O17))) | I17: =IF($O17="","",IF(INDEX(전체!$J$6:$J$75,$O17)="","",INDEX(전체!$J$6:$J$75,$O17))) | J17: =IF($O17="","",IF(INDEX(전체!$K$6:$K$75,$O17)="","",INDEX(전체!$K$6:$K$75,$O17))) | K17: =IF($O17="","",IF(INDEX(전체!$L$6:$L$75,$O17)="","",INDEX(전체!$L$6:$L$75,$O17))) | L17: =IF($O17="","",IF(INDEX(전체!$M$6:$M$75,$O17)="","",INDEX(전체!$M$6:$M$75,$O17))) | M17: =IF($O17="","",IF(INDEX(전체!$N$6:$N$75,$O17)="","",INDEX(전체!$N$6:$N$75,$O17))) | N17: =IF($O17="","",IF(INDEX(전체!$O$6:$O$75,$O17)="","",INDEX(전체!$O$6:$O$75,$O17))) | O17: =IFERROR(MATCH($R$2&"|"&13,전체!$P$6:$P$75,0),"")
A18: =IF($O18="","",14) | B18: =IF($O18="","",IF(INDEX(전체!$C$6:$C$75,$O18)="","",INDEX(전체!$C$6:$C$75,$O18))) | C18: =IF($O18="","",IF(INDEX(전체!$D$6:$D$75,$O18)="","",INDEX(전체!$D$6:$D$75,$O18))) | D18: =IF($O18="","",IF(INDEX(전체!$E$6:$E$75,$O18)="","",INDEX(전체!$E$6:$E$75,$O18))) | E18: =IF($O18="","",IF(INDEX(전체!$F$6:$F$75,$O18)="","",INDEX(전체!$F$6:$F$75,$O18))) | F18: =IF($O18="","",IF(INDEX(전체!$G$6:$G$75,$O18)="","",INDEX(전체!$G$6:$G$75,$O18))) | G18: =IF($O18="","",IF(INDEX(전체!$H$6:$H$75,$O18)="","",INDEX(전체!$H$6:$H$75,$O18))) | H18: =IF($O18="","",IF(INDEX(전체!$I$6:$I$75,$O18)="","",INDEX(전체!$I$6:$I$75,$O18))) | I18: =IF($O18="","",IF(INDEX(전체!$J$6:$J$75,$O18)="","",INDEX(전체!$J$6:$J$75,$O18))) | J18: =IF($O18="","",IF(INDEX(전체!$K$6:$K$75,$O18)="","",INDEX(전체!$K$6:$K$75,$O18))) | K18: =IF($O18="","",IF(INDEX(전체!$L$6:$L$75,$O18)="","",INDEX(전체!$L$6:$L$75,$O18))) | L18: =IF($O18="","",IF(INDEX(전체!$M$6:$M$75,$O18)="","",INDEX(전체!$M$6:$M$75,$O18))) | M18: =IF($O18="","",IF(INDEX(전체!$N$6:$N$75,$O18)="","",INDEX(전체!$N$6:$N$75,$O18))) | N18: =IF($O18="","",IF(INDEX(전체!$O$6:$O$75,$O18)="","",INDEX(전체!$O$6:$O$75,$O18))) | O18: =IFERROR(MATCH($R$2&"|"&14,전체!$P$6:$P$75,0),"")
A19: =IF($O19="","",15) | B19: =IF($O19="","",IF(INDEX(전체!$C$6:$C$75,$O19)="","",INDEX(전체!$C$6:$C$75,$O19))) | C19: =IF($O19="","",IF(INDEX(전체!$D$6:$D$75,$O19)="","",INDEX(전체!$D$6:$D$75,$O19))) | D19: =IF($O19="","",IF(INDEX(전체!$E$6:$E$75,$O19)="","",INDEX(전체!$E$6:$E$75,$O19))) | E19: =IF($O19="","",IF(INDEX(전체!$F$6:$F$75,$O19)="","",INDEX(전체!$F$6:$F$75,$O19))) | F19: =IF($O19="","",IF(INDEX(전체!$G$6:$G$75,$O19)="","",INDEX(전체!$G$6:$G$75,$O19))) | G19: =IF($O19="","",IF(INDEX(전체!$H$6:$H$75,$O19)="","",INDEX(전체!$H$6:$H$75,$O19))) | H19: =IF($O19="","",IF(INDEX(전체!$I$6:$I$75,$O19)="","",INDEX(전체!$I$6:$I$75,$O19))) | I19: =IF($O19="","",IF(INDEX(전체!$J$6:$J$75,$O19)="","",INDEX(전체!$J$6:$J$75,$O19))) | J19: =IF($O19="","",IF(INDEX(전체!$K$6:$K$75,$O19)="","",INDEX(전체!$K$6:$K$75,$O19))) | K19: =IF($O19="","",IF(INDEX(전체!$L$6:$L$75,$O19)="","",INDEX(전체!$L$6:$L$75,$O19))) | L19: =IF($O19="","",IF(INDEX(전체!$M$6:$M$75,$O19)="","",INDEX(전체!$M$6:$M$75,$O19))) | M19: =IF($O19="","",IF(INDEX(전체!$N$6:$N$75,$O19)="","",INDEX(전체!$N$6:$N$75,$O19))) | N19: =IF($O19="","",IF(INDEX(전체!$O$6:$O$75,$O19)="","",INDEX(전체!$O$6:$O$75,$O19))) | O19: =IFERROR(MATCH($R$2&"|"&15,전체!$P$6:$P$75,0),"")
A20: =IF($O20="","",16) | B20: =IF($O20="","",IF(INDEX(전체!$C$6:$C$75,$O20)="","",INDEX(전체!$C$6:$C$75,$O20))) | C20: =IF($O20="","",IF(INDEX(전체!$D$6:$D$75,$O20)="","",INDEX(전체!$D$6:$D$75,$O20))) | D20: =IF($O20="","",IF(INDEX(전체!$E$6:$E$75,$O20)="","",INDEX(전체!$E$6:$E$75,$O20))) | E20: =IF($O20="","",IF(INDEX(전체!$F$6:$F$75,$O20)="","",INDEX(전체!$F$6:$F$75,$O20))) | F20: =IF($O20="","",IF(INDEX(전체!$G$6:$G$75,$O20)="","",INDEX(전체!$G$6:$G$75,$O20))) | G20: =IF($O20="","",IF(INDEX(전체!$H$6:$H$75,$O20)="","",INDEX(전체!$H$6:$H$75,$O20))) | H20: =IF($O20="","",IF(INDEX(전체!$I$6:$I$75,$O20)="","",INDEX(전체!$I$6:$I$75,$O20))) | I20: =IF($O20="","",IF(INDEX(전체!$J$6:$J$75,$O20)="","",INDEX(전체!$J$6:$J$75,$O20))) | J20: =IF($O20="","",IF(INDEX(전체!$K$6:$K$75,$O20)="","",INDEX(전체!$K$6:$K$75,$O20))) | K20: =IF($O20="","",IF(INDEX(전체!$L$6:$L$75,$O20)="","",INDEX(전체!$L$6:$L$75,$O20))) | L20: =IF($O20="","",IF(INDEX(전체!$M$6:$M$75,$O20)="","",INDEX(전체!$M$6:$M$75,$O20))) | M20: =IF($O20="","",IF(INDEX(전체!$N$6:$N$75,$O20)="","",INDEX(전체!$N$6:$N$75,$O20))) | N20: =IF($O20="","",IF(INDEX(전체!$O$6:$O$75,$O20)="","",INDEX(전체!$O$6:$O$75,$O20))) | O20: =IFERROR(MATCH($R$2&"|"&16,전체!$P$6:$P$75,0),"")
A21: =IF($O21="","",17) | B21: =IF($O21="","",IF(INDEX(전체!$C$6:$C$75,$O21)="","",INDEX(전체!$C$6:$C$75,$O21))) | C21: =IF($O21="","",IF(INDEX(전체!$D$6:$D$75,$O21)="","",INDEX(전체!$D$6:$D$75,$O21))) | D21: =IF($O21="","",IF(INDEX(전체!$E$6:$E$75,$O21)="","",INDEX(전체!$E$6:$E$75,$O21))) | E21: =IF($O21="","",IF(INDEX(전체!$F$6:$F$75,$O21)="","",INDEX(전체!$F$6:$F$75,$O21))) | F21: =IF($O21="","",IF(INDEX(전체!$G$6:$G$75,$O21)="","",INDEX(전체!$G$6:$G$75,$O21))) | G21: =IF($O21="","",IF(INDEX(전체!$H$6:$H$75,$O21)="","",INDEX(전체!$H$6:$H$75,$O21))) | H21: =IF($O21="","",IF(INDEX(전체!$I$6:$I$75,$O21)="","",INDEX(전체!$I$6:$I$75,$O21))) | I21: =IF($O21="","",IF(INDEX(전체!$J$6:$J$75,$O21)="","",INDEX(전체!$J$6:$J$75,$O21))) | J21: =IF($O21="","",IF(INDEX(전체!$K$6:$K$75,$O21)="","",INDEX(전체!$K$6:$K$75,$O21))) | K21: =IF($O21="","",IF(INDEX(전체!$L$6:$L$75,$O21)="","",INDEX(전체!$L$6:$L$75,$O21))) | L21: =IF($O21="","",IF(INDEX(전체!$M$6:$M$75,$O21)="","",INDEX(전체!$M$6:$M$75,$O21))) | M21: =IF($O21="","",IF(INDEX(전체!$N$6:$N$75,$O21)="","",INDEX(전체!$N$6:$N$75,$O21))) | N21: =IF($O21="","",IF(INDEX(전체!$O$6:$O$75,$O21)="","",INDEX(전체!$O$6:$O$75,$O21))) | O21: =IFERROR(MATCH($R$2&"|"&17,전체!$P$6:$P$75,0),"")
A22: =IF($O22="","",18) | B22: =IF($O22="","",IF(INDEX(전체!$C$6:$C$75,$O22)="","",INDEX(전체!$C$6:$C$75,$O22))) | C22: =IF($O22="","",IF(INDEX(전체!$D$6:$D$75,$O22)="","",INDEX(전체!$D$6:$D$75,$O22))) | D22: =IF($O22="","",IF(INDEX(전체!$E$6:$E$75,$O22)="","",INDEX(전체!$E$6:$E$75,$O22))) | E22: =IF($O22="","",IF(INDEX(전체!$F$6:$F$75,$O22)="","",INDEX(전체!$F$6:$F$75,$O22))) | F22: =IF($O22="","",IF(INDEX(전체!$G$6:$G$75,$O22)="","",INDEX(전체!$G$6:$G$75,$O22))) | G22: =IF($O22="","",IF(INDEX(전체!$H$6:$H$75,$O22)="","",INDEX(전체!$H$6:$H$75,$O22))) | H22: =IF($O22="","",IF(INDEX(전체!$I$6:$I$75,$O22)="","",INDEX(전체!$I$6:$I$75,$O22))) | I22: =IF($O22="","",IF(INDEX(전체!$J$6:$J$75,$O22)="","",INDEX(전체!$J$6:$J$75,$O22))) | J22: =IF($O22="","",IF(INDEX(전체!$K$6:$K$75,$O22)="","",INDEX(전체!$K$6:$K$75,$O22))) | K22: =IF($O22="","",IF(INDEX(전체!$L$6:$L$75,$O22)="","",INDEX(전체!$L$6:$L$75,$O22))) | L22: =IF($O22="","",IF(INDEX(전체!$M$6:$M$75,$O22)="","",INDEX(전체!$M$6:$M$75,$O22))) | M22: =IF($O22="","",IF(INDEX(전체!$N$6:$N$75,$O22)="","",INDEX(전체!$N$6:$N$75,$O22))) | N22: =IF($O22="","",IF(INDEX(전체!$O$6:$O$75,$O22)="","",INDEX(전체!$O$6:$O$75,$O22))) | O22: =IFERROR(MATCH($R$2&"|"&18,전체!$P$6:$P$75,0),"")
A23: =IF($O23="","",19) | B23: =IF($O23="","",IF(INDEX(전체!$C$6:$C$75,$O23)="","",INDEX(전체!$C$6:$C$75,$O23))) | C23: =IF($O23="","",IF(INDEX(전체!$D$6:$D$75,$O23)="","",INDEX(전체!$D$6:$D$75,$O23))) | D23: =IF($O23="","",IF(INDEX(전체!$E$6:$E$75,$O23)="","",INDEX(전체!$E$6:$E$75,$O23))) | E23: =IF($O23="","",IF(INDEX(전체!$F$6:$F$75,$O23)="","",INDEX(전체!$F$6:$F$75,$O23))) | F23: =IF($O23="","",IF(INDEX(전체!$G$6:$G$75,$O23)="","",INDEX(전체!$G$6:$G$75,$O23))) | G23: =IF($O23="","",IF(INDEX(전체!$H$6:$H$75,$O23)="","",INDEX(전체!$H$6:$H$75,$O23))) | H23: =IF($O23="","",IF(INDEX(전체!$I$6:$I$75,$O23)="","",INDEX(전체!$I$6:$I$75,$O23))) | I23: =IF($O23="","",IF(INDEX(전체!$J$6:$J$75,$O23)="","",INDEX(전체!$J$6:$J$75,$O23))) | J23: =IF($O23="","",IF(INDEX(전체!$K$6:$K$75,$O23)="","",INDEX(전체!$K$6:$K$75,$O23))) | K23: =IF($O23="","",IF(INDEX(전체!$L$6:$L$75,$O23)="","",INDEX(전체!$L$6:$L$75,$O23))) | L23: =IF($O23="","",IF(INDEX(전체!$M$6:$M$75,$O23)="","",INDEX(전체!$M$6:$M$75,$O23))) | M23: =IF($O23="","",IF(INDEX(전체!$N$6:$N$75,$O23)="","",INDEX(전체!$N$6:$N$75,$O23))) | N23: =IF($O23="","",IF(INDEX(전체!$O$6:$O$75,$O23)="","",INDEX(전체!$O$6:$O$75,$O23))) | O23: =IFERROR(MATCH($R$2&"|"&19,전체!$P$6:$P$75,0),"")
A24: =IF($O24="","",20) | B24: =IF($O24="","",IF(INDEX(전체!$C$6:$C$75,$O24)="","",INDEX(전체!$C$6:$C$75,$O24))) | C24: =IF($O24="","",IF(INDEX(전체!$D$6:$D$75,$O24)="","",INDEX(전체!$D$6:$D$75,$O24))) | D24: =IF($O24="","",IF(INDEX(전체!$E$6:$E$75,$O24)="","",INDEX(전체!$E$6:$E$75,$O24))) | E24: =IF($O24="","",IF(INDEX(전체!$F$6:$F$75,$O24)="","",INDEX(전체!$F$6:$F$75,$O24))) | F24: =IF($O24="","",IF(INDEX(전체!$G$6:$G$75,$O24)="","",INDEX(전체!$G$6:$G$75,$O24))) | G24: =IF($O24="","",IF(INDEX(전체!$H$6:$H$75,$O24)="","",INDEX(전체!$H$6:$H$75,$O24))) | H24: =IF($O24="","",IF(INDEX(전체!$I$6:$I$75,$O24)="","",INDEX(전체!$I$6:$I$75,$O24))) | I24: =IF($O24="","",IF(INDEX(전체!$J$6:$J$75,$O24)="","",INDEX(전체!$J$6:$J$75,$O24))) | J24: =IF($O24="","",IF(INDEX(전체!$K$6:$K$75,$O24)="","",INDEX(전체!$K$6:$K$75,$O24))) | K24: =IF($O24="","",IF(INDEX(전체!$L$6:$L$75,$O24)="","",INDEX(전체!$L$6:$L$75,$O24))) | L24: =IF($O24="","",IF(INDEX(전체!$M$6:$M$75,$O24)="","",INDEX(전체!$M$6:$M$75,$O24))) | M24: =IF($O24="","",IF(INDEX(전체!$N$6:$N$75,$O24)="","",INDEX(전체!$N$6:$N$75,$O24))) | N24: =IF($O24="","",IF(INDEX(전체!$O$6:$O$75,$O24)="","",INDEX(전체!$O$6:$O$75,$O24))) | O24: =IFERROR(MATCH($R$2&"|"&20,전체!$P$6:$P$75,0),"")
A25: =IF($O25="","",21) | B25: =IF($O25="","",IF(INDEX(전체!$C$6:$C$75,$O25)="","",INDEX(전체!$C$6:$C$75,$O25))) | C25: =IF($O25="","",IF(INDEX(전체!$D$6:$D$75,$O25)="","",INDEX(전체!$D$6:$D$75,$O25))) | D25: =IF($O25="","",IF(INDEX(전체!$E$6:$E$75,$O25)="","",INDEX(전체!$E$6:$E$75,$O25))) | E25: =IF($O25="","",IF(INDEX(전체!$F$6:$F$75,$O25)="","",INDEX(전체!$F$6:$F$75,$O25))) | F25: =IF($O25="","",IF(INDEX(전체!$G$6:$G$75,$O25)="","",INDEX(전체!$G$6:$G$75,$O25))) | G25: =IF($O25="","",IF(INDEX(전체!$H$6:$H$75,$O25)="","",INDEX(전체!$H$6:$H$75,$O25))) | H25: =IF($O25="","",IF(INDEX(전체!$I$6:$I$75,$O25)="","",INDEX(전체!$I$6:$I$75,$O25))) | I25: =IF($O25="","",IF(INDEX(전체!$J$6:$J$75,$O25)="","",INDEX(전체!$J$6:$J$75,$O25))) | J25: =IF($O25="","",IF(INDEX(전체!$K$6:$K$75,$O25)="","",INDEX(전체!$K$6:$K$75,$O25))) | K25: =IF($O25="","",IF(INDEX(전체!$L$6:$L$75,$O25)="","",INDEX(전체!$L$6:$L$75,$O25))) | L25: =IF($O25="","",IF(INDEX(전체!$M$6:$M$75,$O25)="","",INDEX(전체!$M$6:$M$75,$O25))) | M25: =IF($O25="","",IF(INDEX(전체!$N$6:$N$75,$O25)="","",INDEX(전체!$N$6:$N$75,$O25))) | N25: =IF($O25="","",IF(INDEX(전체!$O$6:$O$75,$O25)="","",INDEX(전체!$O$6:$O$75,$O25))) | O25: =IFERROR(MATCH($R$2&"|"&21,전체!$P$6:$P$75,0),"")
A26: =IF($O26="","",22) | B26: =IF($O26="","",IF(INDEX(전체!$C$6:$C$75,$O26)="","",INDEX(전체!$C$6:$C$75,$O26))) | C26: =IF($O26="","",IF(INDEX(전체!$D$6:$D$75,$O26)="","",INDEX(전체!$D$6:$D$75,$O26))) | D26: =IF($O26="","",IF(INDEX(전체!$E$6:$E$75,$O26)="","",INDEX(전체!$E$6:$E$75,$O26))) | E26: =IF($O26="","",IF(INDEX(전체!$F$6:$F$75,$O26)="","",INDEX(전체!$F$6:$F$75,$O26))) | F26: =IF($O26="","",IF(INDEX(전체!$G$6:$G$75,$O26)="","",INDEX(전체!$G$6:$G$75,$O26))) | G26: =IF($O26="","",IF(INDEX(전체!$H$6:$H$75,$O26)="","",INDEX(전체!$H$6:$H$75,$O26))) | H26: =IF($O26="","",IF(INDEX(전체!$I$6:$I$75,$O26)="","",INDEX(전체!$I$6:$I$75,$O26))) | I26: =IF($O26="","",IF(INDEX(전체!$J$6:$J$75,$O26)="","",INDEX(전체!$J$6:$J$75,$O26))) | J26: =IF($O26="","",IF(INDEX(전체!$K$6:$K$75,$O26)="","",INDEX(전체!$K$6:$K$75,$O26))) | K26: =IF($O26="","",IF(INDEX(전체!$L$6:$L$75,$O26)="","",INDEX(전체!$L$6:$L$75,$O26))) | L26: =IF($O26="","",IF(INDEX(전체!$M$6:$M$75,$O26)="","",INDEX(전체!$M$6:$M$75,$O26))) | M26: =IF($O26="","",IF(INDEX(전체!$N$6:$N$75,$O26)="","",INDEX(전체!$N$6:$N$75,$O26))) | N26: =IF($O26="","",IF(INDEX(전체!$O$6:$O$75,$O26)="","",INDEX(전체!$O$6:$O$75,$O26))) | O26: =IFERROR(MATCH($R$2&"|"&22,전체!$P$6:$P$75,0),"")
A27: =IF($O27="","",23) | B27: =IF($O27="","",IF(INDEX(전체!$C$6:$C$75,$O27)="","",INDEX(전체!$C$6:$C$75,$O27))) | C27: =IF($O27="","",IF(INDEX(전체!$D$6:$D$75,$O27)="","",INDEX(전체!$D$6:$D$75,$O27))) | D27: =IF($O27="","",IF(INDEX(전체!$E$6:$E$75,$O27)="","",INDEX(전체!$E$6:$E$75,$O27))) | E27: =IF($O27="","",IF(INDEX(전체!$F$6:$F$75,$O27)="","",INDEX(전체!$F$6:$F$75,$O27))) | F27: =IF($O27="","",IF(INDEX(전체!$G$6:$G$75,$O27)="","",INDEX(전체!$G$6:$G$75,$O27))) | G27: =IF($O27="","",IF(INDEX(전체!$H$6:$H$75,$O27)="","",INDEX(전체!$H$6:$H$75,$O27))) | H27: =IF($O27="","",IF(INDEX(전체!$I$6:$I$75,$O27)="","",INDEX(전체!$I$6:$I$75,$O27))) | I27: =IF($O27="","",IF(INDEX(전체!$J$6:$J$75,$O27)="","",INDEX(전체!$J$6:$J$75,$O27))) | J27: =IF($O27="","",IF(INDEX(전체!$K$6:$K$75,$O27)="","",INDEX(전체!$K$6:$K$75,$O27))) | K27: =IF($O27="","",IF(INDEX(전체!$L$6:$L$75,$O27)="","",INDEX(전체!$L$6:$L$75,$O27))) | L27: =IF($O27="","",IF(INDEX(전체!$M$6:$M$75,$O27)="","",INDEX(전체!$M$6:$M$75,$O27))) | M27: =IF($O27="","",IF(INDEX(전체!$N$6:$N$75,$O27)="","",INDEX(전체!$N$6:$N$75,$O27))) | N27: =IF($O27="","",IF(INDEX(전체!$O$6:$O$75,$O27)="","",INDEX(전체!$O$6:$O$75,$O27))) | O27: =IFERROR(MATCH($R$2&"|"&23,전체!$P$6:$P$75,0),"")
A28: =IF($O28="","",24) | B28: =IF($O28="","",IF(INDEX(전체!$C$6:$C$75,$O28)="","",INDEX(전체!$C$6:$C$75,$O28))) | C28: =IF($O28="","",IF(INDEX(전체!$D$6:$D$75,$O28)="","",INDEX(전체!$D$6:$D$75,$O28))) | D28: =IF($O28="","",IF(INDEX(전체!$E$6:$E$75,$O28)="","",INDEX(전체!$E$6:$E$75,$O28))) | E28: =IF($O28="","",IF(INDEX(전체!$F$6:$F$75,$O28)="","",INDEX(전체!$F$6:$F$75,$O28))) | F28: =IF($O28="","",IF(INDEX(전체!$G$6:$G$75,$O28)="","",INDEX(전체!$G$6:$G$75,$O28))) | G28: =IF($O28="","",IF(INDEX(전체!$H$6:$H$75,$O28)="","",INDEX(전체!$H$6:$H$75,$O28))) | H28: =IF($O28="","",IF(INDEX(전체!$I$6:$I$75,$O28)="","",INDEX(전체!$I$6:$I$75,$O28))) | I28: =IF($O28="","",IF(INDEX(전체!$J$6:$J$75,$O28)="","",INDEX(전체!$J$6:$J$75,$O28))) | J28: =IF($O28="","",IF(INDEX(전체!$K$6:$K$75,$O28)="","",INDEX(전체!$K$6:$K$75,$O28))) | K28: =IF($O28="","",IF(INDEX(전체!$L$6:$L$75,$O28)="","",INDEX(전체!$L$6:$L$75,$O28))) | L28: =IF($O28="","",IF(INDEX(전체!$M$6:$M$75,$O28)="","",INDEX(전체!$M$6:$M$75,$O28))) | M28: =IF($O28="","",IF(INDEX(전체!$N$6:$N$75,$O28)="","",INDEX(전체!$N$6:$N$75,$O28))) | N28: =IF($O28="","",IF(INDEX(전체!$O$6:$O$75,$O28)="","",INDEX(전체!$O$6:$O$75,$O28))) | O28: =IFERROR(MATCH($R$2&"|"&24,전체!$P$6:$P$75,0),"")
A29: =IF($O29="","",25) | B29: =IF($O29="","",IF(INDEX(전체!$C$6:$C$75,$O29)="","",INDEX(전체!$C$6:$C$75,$O29))) | C29: =IF($O29="","",IF(INDEX(전체!$D$6:$D$75,$O29)="","",INDEX(전체!$D$6:$D$75,$O29))) | D29: =IF($O29="","",IF(INDEX(전체!$E$6:$E$75,$O29)="","",INDEX(전체!$E$6:$E$75,$O29))) | E29: =IF($O29="","",IF(INDEX(전체!$F$6:$F$75,$O29)="","",INDEX(전체!$F$6:$F$75,$O29))) | F29: =IF($O29="","",IF(INDEX(전체!$G$6:$G$75,$O29)="","",INDEX(전체!$G$6:$G$75,$O29))) | G29: =IF($O29="","",IF(INDEX(전체!$H$6:$H$75,$O29)="","",INDEX(전체!$H$6:$H$75,$O29))) | H29: =IF($O29="","",IF(INDEX(전체!$I$6:$I$75,$O29)="","",INDEX(전체!$I$6:$I$75,$O29))) | I29: =IF($O29="","",IF(INDEX(전체!$J$6:$J$75,$O29)="","",INDEX(전체!$J$6:$J$75,$O29))) | J29: =IF($O29="","",IF(INDEX(전체!$K$6:$K$75,$O29)="","",INDEX(전체!$K$6:$K$75,$O29))) | K29: =IF($O29="","",IF(INDEX(전체!$L$6:$L$75,$O29)="","",INDEX(전체!$L$6:$L$75,$O29))) | L29: =IF($O29="","",IF(INDEX(전체!$M$6:$M$75,$O29)="","",INDEX(전체!$M$6:$M$75,$O29))) | M29: =IF($O29="","",IF(INDEX(전체!$N$6:$N$75,$O29)="","",INDEX(전체!$N$6:$N$75,$O29))) | N29: =IF($O29="","",IF(INDEX(전체!$O$6:$O$75,$O29)="","",INDEX(전체!$O$6:$O$75,$O29))) | O29: =IFERROR(MATCH($R$2&"|"&25,전체!$P$6:$P$75,0),"")

Sheet 고기·족발
A1: 고기·족발 | C1: =COUNTIF(전체!$B$6:$B$75,"고기·족발")&"곳" -> 3곳
A2: ※ "전체" 시트에서 분류를 지정하면 자동으로 채워집니다 (수식 시트, 직접 수정 X). 대략 가격은 추정치입니다. | R2: 고기·족발
A4: No. | B4: 식당명 | C4: 네이버 업종 | D4: 영업상태 (캡처 시점) | E4: 예약 | F4: 주소 | G4: 층 / 호 / 건물 | H4: 도보(분) 대교로119 기준 | I4: 평점 (네이버) | J4: 전화 | K4: 대표메뉴 | L4: 대략 가격 (원) ※추정 | M4: 소개 | N4: 메모 | O4: row
A5: =IF($O5="","",1) -> 1 | B5: =IF($O5="","",IF(INDEX(전체!$C$6:$C$75,$O5)="","",INDEX(전체!$C$6:$C$75,$O5))) -> 국제상인 짬뽕족발 | C5: =IF($O5="","",IF(INDEX(전체!$D$6:$D$75,$O5)="","",INDEX(전체!$D$6:$D$75,$O5))) -> 족발,보쌈 | D5: =IF($O5="","",IF(INDEX(전체!$E$6:$E$75,$O5)="","",INDEX(전체!$E$6:$E$75,$O5))) -> 브레이크타임 | E5: =IF($O5="","",IF(INDEX(전체!$F$6:$F$75,$O5)="","",INDEX(전체!$F$6:$F$75,$O5))) | F5: =IF($O5="","",IF(INDEX(전체!$G$6:$G$75,$O5)="","",INDEX(전체!$G$6:$G$75,$O5))) -> 부산 중구 중앙동4가 29-8 | G5: =IF($O5="","",IF(INDEX(전체!$H$6:$H$75,$O5)="","",INDEX(전체!$H$6:$H$75,$O5))) | H5: =IF($O5="","",IF(INDEX(전체!$I$6:$I$75,$O5)="","",INDEX(전체!$I$6:$I$75,$O5))) | I5: =IF($O5="","",IF(INDEX(전체!$J$6:$J$75,$O5)="","",INDEX(전체!$J$6:$J$75,$O5))) | J5: =IF($O5="","",IF(INDEX(전체!$K$6:$K$75,$O5)="","",INDEX(전체!$K$6:$K$75,$O5))) | K5: =IF($O5="","",IF(INDEX(전체!$L$6:$L$75,$O5)="","",INDEX(전체!$L$6:$L$75,$O5))) -> 족발·보쌈 | L5: =IF($O5="","",IF(INDEX(전체!$M$6:$M$75,$O5)="","",INDEX(전체!$M$6:$M$75,$O5))) -> 소 28,000~35,000 | M5: =IF($O5="","",IF(INDEX(전체!$N$6:$N$75,$O5)="","",INDEX(전체!$N$6:$N$75,$O5))) -> 족발·보쌈 전문점 (브레이크타임 있음) | N5: =IF($O5="","",IF(INDEX(전체!$O$6:$O$75,$O5)="","",INDEX(전체!$O$6:$O$75,$O5))) | O5: =IFERROR(MATCH($R$2&"|"&1,전체!$P$6:$P$75,0),"") -> 5
A6: =IF($O6="","",2) -> 2 | B6: =IF($O6="","",IF(INDEX(전체!$C$6:$C$75,$O6)="","",INDEX(전체!$C$6:$C$75,$O6))) -> 참숯생갈비 | C6: =IF($O6="","",IF(INDEX(전체!$D$6:$D$75,$O6)="","",INDEX(전체!$D$6:$D$75,$O6))) -> 육류,고기요리 | D6: =IF($O6="","",IF(INDEX(전체!$E$6:$E$75,$O6)="","",INDEX(전체!$E$6:$E$75,$O6))) -> 영업 중 | E6: =IF($O6="","",IF(INDEX(전체!$F$6:$F$75,$O6)="","",INDEX(전체!$F$6:$F$75,$O6))) | F6: =IF($O6="","",IF(INDEX(전체!$G$6:$G$75,$O6)="","",INDEX(전체!$G$6:$G$75,$O6))) -> 부산 중구 중앙동5가 1-18 | G6: =IF($O6="","",IF(INDEX(전체!$H$6:$H$75,$O6)="","",INDEX(전체!$H$6:$H$75,$O6))) | H6: =IF($O6="","",IF(INDEX(전체!$I$6:$I$75,$O6)="","",INDEX(전체!$I$6:$I$75,$O6))) | I6: =IF($O6="","",IF(INDEX(전체!$J$6:$J$75,$O6)="","",INDEX(전체!$J$6:$J$75,$O6))) | J6: =IF($O6="","",IF(INDEX(전체!$K$6:$K$75,$O6)="","",INDEX(전체!$K$6:$K$75,$O6))) | K6: =IF($O6="","",IF(INDEX(전체!$L$6:$L$75,$O6)="","",INDEX(전체!$L$6:$L$75,$O6))) -> 생갈비 (1인분) | L6: =IF($O6="","",IF(INDEX(전체!$M$6:$M$75,$O6)="","",INDEX(전체!$M$6:$M$75,$O6))) -> 25,000~35,000 | M6: =IF($O6="","",IF(INDEX(전체!$N$6:$N$75,$O6)="","",INDEX(전체!$N$6:$N$75,$O6))) -> 참숯 고기구이 전문점 (육류·고기요리) | N6: =IF($O6="","",IF(INDEX(전체!$O$6:$O$75,$O6)="","",INDEX(전체!$O$6:$O$75,$O6))) | O6: =IFERROR(MATCH($R$2&"|"&2,전체!$P$6:$P$75,0),"") -> 21
A7: =IF($O7="","",3) -> 3 | B7: =IF($O7="","",IF(INDEX(전체!$C$6:$C$75,$O7)="","",INDEX(전체!$C$6:$C$75,$O7))) -> 홍가네 | C7: =IF($O7="","",IF(INDEX(전체!$D$6:$D$75,$O7)="","",INDEX(전체!$D$6:$D$75,$O7))) -> 육류,고기요리 | D7: =IF($O7="","",IF(INDEX(전체!$E$6:$E$75,$O7)="","",INDEX(전체!$E$6:$E$75,$O7))) -> 브레이크타임 | E7: =IF($O7="","",IF(INDEX(전체!$F$6:$F$75,$O7)="","",INDEX(전체!$F$6:$F$75,$O7))) | F7: =IF($O7="","",IF(INDEX(전체!$G$6:$G$75,$O7)="","",INDEX(전체!$G$6:$G$75,$O7))) -> 부산 중구 해관로 31 | G7: =IF($O7="","",IF(INDEX(전체!$H$6:$H$75,$O7)="","",INDEX(전체!$H$6:$H$75,$O7))) -> 1,2층 | H7: =IF($O7="","",IF(INDEX(전체!$I$6:$I$75,$O7)="","",INDEX(전체!$I$6:$I$75,$O7))) | I7: =IF($O7="","",IF(INDEX(전체!$J$6:$J$75,$O7)="","",INDEX(전체!$J$6:$J$75,$O7))) -> ★4.8 (리뷰 265) | J7: =IF($O7="","",IF(INDEX(전체!$K$6:$K$75,$O7)="","",INDEX(전체!$K$6:$K$75,$O7))) | K7: =IF($O7="","",IF(INDEX(전체!$L$6:$L$75,$O7)="","",INDEX(전체!$L$6:$L$75,$O7))) -> 언양불고기 (200g) | L7: =IF($O7="","",IF(INDEX(전체!$M$6:$M$75,$O7)="","",INDEX(전체!$M$6:$M$75,$O7))) -> 18,000 (200g) | M7: =IF($O7="","",IF(INDEX(전체!$N$6:$N$75,$O7)="","",INDEX(전체!$N$6:$N$75,$O7))) -> 점심특선 언양불고기 · ₩18,000 (200g) | N7: =IF($O7="","",IF(INDEX(전체!$O$6:$O$75,$O7)="","",INDEX(전체!$O$6:$O$75,$O7))) -> 17:00 영업 시작 / 중앙역 1번 출구 175m | O7: =IFERROR(MATCH($R$2&"|"&3,전체!$P$6:$P$75,0),"") -> 28
A8: =IF($O8="","",4) | B8: =IF($O8="","",IF(INDEX(전체!$C$6:$C$75,$O8)="","",INDEX(전체!$C$6:$C$75,$O8))) | C8: =IF($O8="","",IF(INDEX(전체!$D$6:$D$75,$O8)="","",INDEX(전체!$D$6:$D$75,$O8))) | D8: =IF($O8="","",IF(INDEX(전체!$E$6:$E$75,$O8)="","",INDEX(전체!$E$6:$E$75,$O8))) | E8: =IF($O8="","",IF(INDEX(전체!$F$6:$F$75,$O8)="","",INDEX(전체!$F$6:$F$75,$O8))) | F8: =IF($O8="","",IF(INDEX(전체!$G$6:$G$75,$O8)="","",INDEX(전체!$G$6:$G$75,$O8))) | G8: =IF($O8="","",IF(INDEX(전체!$H$6:$H$75,$O8)="","",INDEX(전체!$H$6:$H$75,$O8))) | H8: =IF($O8="","",IF(INDEX(전체!$I$6:$I$75,$O8)="","",INDEX(전체!$I$6:$I$75,$O8))) | I8: =IF($O8="","",IF(INDEX(전체!$J$6:$J$75,$O8)="","",INDEX(전체!$J$6:$J$75,$O8))) | J8: =IF($O8="","",IF(INDEX(전체!$K$6:$K$75,$O8)="","",INDEX(전체!$K$6:$K$75,$O8))) | K8: =IF($O8="","",IF(INDEX(전체!$L$6:$L$75,$O8)="","",INDEX(전체!$L$6:$L$75,$O8))) | L8: =IF($O8="","",IF(INDEX(전체!$M$6:$M$75,$O8)="","",INDEX(전체!$M$6:$M$75,$O8))) | M8: =IF($O8="","",IF(INDEX(전체!$N$6:$N$75,$O8)="","",INDEX(전체!$N$6:$N$75,$O8))) | N8: =IF($O8="","",IF(INDEX(전체!$O$6:$O$75,$O8)="","",INDEX(전체!$O$6:$O$75,$O8))) | O8: =IFERROR(MATCH($R$2&"|"&4,전체!$P$6:$P$75,0),"")
A9: =IF($O9="","",5) | B9: =IF($O9="","",IF(INDEX(전체!$C$6:$C$75,$O9)="","",INDEX(전체!$C$6:$C$75,$O9))) | C9: =IF($O9="","",IF(INDEX(전체!$D$6:$D$75,$O9)="","",INDEX(전체!$D$6:$D$75,$O9))) | D9: =IF($O9="","",IF(INDEX(전체!$E$6:$E$75,$O9)="","",INDEX(전체!$E$6:$E$75,$O9))) | E9: =IF($O9="","",IF(INDEX(전체!$F$6:$F$75,$O9)="","",INDEX(전체!$F$6:$F$75,$O9))) | F9: =IF($O9="","",IF(INDEX(전체!$G$6:$G$75,$O9)="","",INDEX(전체!$G$6:$G$75,$O9))) | G9: =IF($O9="","",IF(INDEX(전체!$H$6:$H$75,$O9)="","",INDEX(전체!$H$6:$H$75,$O9))) | H9: =IF($O9="","",IF(INDEX(전체!$I$6:$I$75,$O9)="","",INDEX(전체!$I$6:$I$75,$O9))) | I9: =IF($O9="","",IF(INDEX(전체!$J$6:$J$75,$O9)="","",INDEX(전체!$J$6:$J$75,$O9))) | J9: =IF($O9="","",IF(INDEX(전체!$K$6:$K$75,$O9)="","",INDEX(전체!$K$6:$K$75,$O9))) | K9: =IF($O9="","",IF(INDEX(전체!$L$6:$L$75,$O9)="","",INDEX(전체!$L$6:$L$75,$O9))) | L9: =IF($O9="","",IF(INDEX(전체!$M$6:$M$75,$O9)="","",INDEX(전체!$M$6:$M$75,$O9))) | M9: =IF($O9="","",IF(INDEX(전체!$N$6:$N$75,$O9)="","",INDEX(전체!$N$6:$N$75,$O9))) | N9: =IF($O9="","",IF(INDEX(전체!$O$6:$O$75,$O9)="","",INDEX(전체!$O$6:$O$75,$O9))) | O9: =IFERROR(MATCH($R$2&"|"&5,전체!$P$6:$P$75,0),"")
A10: =IF($O10="","",6) | B10: =IF($O10="","",IF(INDEX(전체!$C$6:$C$75,$O10)="","",INDEX(전체!$C$6:$C$75,$O10))) | C10: =IF($O10="","",IF(INDEX(전체!$D$6:$D$75,$O10)="","",INDEX(전체!$D$6:$D$75,$O10))) | D10: =IF($O10="","",IF(INDEX(전체!$E$6:$E$75,$O10)="","",INDEX(전체!$E$6:$E$75,$O10))) | E10: =IF($O10="","",IF(INDEX(전체!$F$6:$F$75,$O10)="","",INDEX(전체!$F$6:$F$75,$O10))) | F10: =IF($O10="","",IF(INDEX(전체!$G$6:$G$75,$O10)="","",INDEX(전체!$G$6:$G$75,$O10))) | G10: =IF($O10="","",IF(INDEX(전체!$H$6:$H$75,$O10)="","",INDEX(전체!$H$6:$H$75,$O10))) | H10: =IF($O10="","",IF(INDEX(전체!$I$6:$I$75,$O10)="","",INDEX(전체!$I$6:$I$75,$O10))) | I10: =IF($O10="","",IF(INDEX(전체!$J$6:$J$75,$O10)="","",INDEX(전체!$J$6:$J$75,$O10))) | J10: =IF($O10="","",IF(INDEX(전체!$K$6:$K$75,$O10)="","",INDEX(전체!$K$6:$K$75,$O10))) | K10: =IF($O10="","",IF(INDEX(전체!$L$6:$L$75,$O10)="","",INDEX(전체!$L$6:$L$75,$O10))) | L10: =IF($O10="","",IF(INDEX(전체!$M$6:$M$75,$O10)="","",INDEX(전체!$M$6:$M$75,$O10))) | M10: =IF($O10="","",IF(INDEX(전체!$N$6:$N$75,$O10)="","",INDEX(전체!$N$6:$N$75,$O10))) | N10: =IF($O10="","",IF(INDEX(전체!$O$6:$O$75,$O10)="","",INDEX(전체!$O$6:$O$75,$O10))) | O10: =IFERROR(MATCH($R$2&"|"&6,전체!$P$6:$P$75,0),"")
A11: =IF($O11="","",7) | B11: =IF($O11="","",IF(INDEX(전체!$C$6:$C$75,$O11)="","",INDEX(전체!$C$6:$C$75,$O11))) | C11: =IF($O11="","",IF(INDEX(전체!$D$6:$D$75,$O11)="","",INDEX(전체!$D$6:$D$75,$O11))) | D11: =IF($O11="","",IF(INDEX(전체!$E$6:$E$75,$O11)="","",INDEX(전체!$E$6:$E$75,$O11))) | E11: =IF($O11="","",IF(INDEX(전체!$F$6:$F$75,$O11)="","",INDEX(전체!$F$6:$F$75,$O11))) | F11: =IF($O11="","",IF(INDEX(전체!$G$6:$G$75,$O11)="","",INDEX(전체!$G$6:$G$75,$O11))) | G11: =IF($O11="","",IF(INDEX(전체!$H$6:$H$75,$O11)="","",INDEX(전체!$H$6:$H$75,$O11))) | H11: =IF($O11="","",IF(INDEX(전체!$I$6:$I$75,$O11)="","",INDEX(전체!$I$6:$I$75,$O11))) | I11: =IF($O11="","",IF(INDEX(전체!$J$6:$J$75,$O11)="","",INDEX(전체!$J$6:$J$75,$O11))) | J11: =IF($O11="","",IF(INDEX(전체!$K$6:$K$75,$O11)="","",INDEX(전체!$K$6:$K$75,$O11))) | K11: =IF($O11="","",IF(INDEX(전체!$L$6:$L$75,$O11)="","",INDEX(전체!$L$6:$L$75,$O11))) | L11: =IF($O11="","",IF(INDEX(전체!$M$6:$M$75,$O11)="","",INDEX(전체!$M$6:$M$75,$O11))) | M11: =IF($O11="","",IF(INDEX(전체!$N$6:$N$75,$O11)="","",INDEX(전체!$N$6:$N$75,$O11))) | N11: =IF($O11="","",IF(INDEX(전체!$O$6:$O$75,$O11)="","",INDEX(전체!$O$6:$O$75,$O11))) | O11: =IFERROR(MATCH($R$2&"|"&7,전체!$P$6:$P$75,0),"")
A12: =IF($O12="","",8) | B12: =IF($O12="","",IF(INDEX(전체!$C$6:$C$75,$O12)="","",INDEX(전체!$C$6:$C$75,$O12))) | C12: =IF($O12="","",IF(INDEX(전체!$D$6:$D$75,$O12)="","",INDEX(전체!$D$6:$D$75,$O12))) | D12: =IF($O12="","",IF(INDEX(전체!$E$6:$E$75,$O12)="","",INDEX(전체!$E$6:$E$75,$O12))) | E12: =IF($O12="","",IF(INDEX(전체!$F$6:$F$75,$O12)="","",INDEX(전체!$F$6:$F$75,$O12))) | F12: =IF($O12="","",IF(INDEX(전체!$G$6:$G$75,$O12)="","",INDEX(전체!$G$6:$G$75,$O12))) | G12: =IF($O12="","",IF(INDEX(전체!$H$6:$H$75,$O12)="","",INDEX(전체!$H$6:$H$75,$O12))) | H12: =IF($O12="","",IF(INDEX(전체!$I$6:$I$75,$O12)="","",INDEX(전체!$I$6:$I$75,$O12))) | I12: =IF($O12="","",IF(INDEX(전체!$J$6:$J$75,$O12)="","",INDEX(전체!$J$6:$J$75,$O12))) | J12: =IF($O12="","",IF(INDEX(전체!$K$6:$K$75,$O12)="","",INDEX(전체!$K$6:$K$75,$O12))) | K12: =IF($O12="","",IF(INDEX(전체!$L$6:$L$75,$O12)="","",INDEX(전체!$L$6:$L$75,$O12))) | L12: =IF($O12="","",IF(INDEX(전체!$M$6:$M$75,$O12)="","",INDEX(전체!$M$6:$M$75,$O12))) | M12: =IF($O12="","",IF(INDEX(전체!$N$6:$N$75,$O12)="","",INDEX(전체!$N$6:$N$75,$O12))) | N12: =IF($O12="","",IF(INDEX(전체!$O$6:$O$75,$O12)="","",INDEX(전체!$O$6:$O$75,$O12))) | O12: =IFERROR(MATCH($R$2&"|"&8,전체!$P$6:$P$75,0),"")
A13: =IF($O13="","",9) | B13: =IF($O13="","",IF(INDEX(전체!$C$6:$C$75,$O13)="","",INDEX(전체!$C$6:$C$75,$O13))) | C13: =IF($O13="","",IF(INDEX(전체!$D$6:$D$75,$O13)="","",INDEX(전체!$D$6:$D$75,$O13))) | D13: =IF($O13="","",IF(INDEX(전체!$E$6:$E$75,$O13)="","",INDEX(전체!$E$6:$E$75,$O13))) | E13: =IF($O13="","",IF(INDEX(전체!$F$6:$F$75,$O13)="","",INDEX(전체!$F$6:$F$75,$O13))) | F13: =IF($O13="","",IF(INDEX(전체!$G$6:$G$75,$O13)="","",INDEX(전체!$G$6:$G$75,$O13))) | G13: =IF($O13="","",IF(INDEX(전체!$H$6:$H$75,$O13)="","",INDEX(전체!$H$6:$H$75,$O13))) | H13: =IF($O13="","",IF(INDEX(전체!$I$6:$I$75,$O13)="","",INDEX(전체!$I$6:$I$75,$O13))) | I13: =IF($O13="","",IF(INDEX(전체!$J$6:$J$75,$O13)="","",INDEX(전체!$J$6:$J$75,$O13))) | J13: =IF($O13="","",IF(INDEX(전체!$K$6:$K$75,$O13)="","",INDEX(전체!$K$6:$K$75,$O13))) | K13: =IF($O13="","",IF(INDEX(전체!$L$6:$L$75,$O13)="","",INDEX(전체!$L$6:$L$75,$O13))) | L13: =IF($O13="","",IF(INDEX(전체!$M$6:$M$75,$O13)="","",INDEX(전체!$M$6:$M$75,$O13))) | M13: =IF($O13="","",IF(INDEX(전체!$N$6:$N$75,$O13)="","",INDEX(전체!$N$6:$N$75,$O13))) | N13: =IF($O13="","",IF(INDEX(전체!$O$6:$O$75,$O13)="","",INDEX(전체!$O$6:$O$75,$O13))) | O13: =IFERROR(MATCH($R$2&"|"&9,전체!$P$6:$P$75,0),"")
A14: =IF($O14="","",10) | B14: =IF($O14="","",IF(INDEX(전체!$C$6:$C$75,$O14)="","",INDEX(전체!$C$6:$C$75,$O14))) | C14: =IF($O14="","",IF(INDEX(전체!$D$6:$D$75,$O14)="","",INDEX(전체!$D$6:$D$75,$O14))) | D14: =IF($O14="","",IF(INDEX(전체!$E$6:$E$75,$O14)="","",INDEX(전체!$E$6:$E$75,$O14))) | E14: =IF($O14="","",IF(INDEX(전체!$F$6:$F$75,$O14)="","",INDEX(전체!$F$6:$F$75,$O14))) | F14: =IF($O14="","",IF(INDEX(전체!$G$6:$G$75,$O14)="","",INDEX(전체!$G$6:$G$75,$O14))) | G14: =IF($O14="","",IF(INDEX(전체!$H$6:$H$75,$O14)="","",INDEX(전체!$H$6:$H$75,$O14))) | H14: =IF($O14="","",IF(INDEX(전체!$I$6:$I$75,$O14)="","",INDEX(전체!$I$6:$I$75,$O14))) | I14: =IF($O14="","",IF(INDEX(전체!$J$6:$J$75,$O14)="","",INDEX(전체!$J$6:$J$75,$O14))) | J14: =IF($O14="","",IF(INDEX(전체!$K$6:$K$75,$O14)="","",INDEX(전체!$K$6:$K$75,$O14))) | K14: =IF($O14="","",IF(INDEX(전체!$L$6:$L$75,$O14)="","",INDEX(전체!$L$6:$L$75,$O14))) | L14: =IF($O14="","",IF(INDEX(전체!$M$6:$M$75,$O14)="","",INDEX(전체!$M$6:$M$75,$O14))) | M14: =IF($O14="","",IF(INDEX(전체!$N$6:$N$75,$O14)="","",INDEX(전체!$N$6:$N$75,$O14))) | N14: =IF($O14="","",IF(INDEX(전체!$O$6:$O$75,$O14)="","",INDEX(전체!$O$6:$O$75,$O14))) | O14: =IFERROR(MATCH($R$2&"|"&10,전체!$P$6:$P$75,0),"")
A15: =IF($O15="","",11) | B15: =IF($O15="","",IF(INDEX(전체!$C$6:$C$75,$O15)="","",INDEX(전체!$C$6:$C$75,$O15))) | C15: =IF($O15="","",IF(INDEX(전체!$D$6:$D$75,$O15)="","",INDEX(전체!$D$6:$D$75,$O15))) | D15: =IF($O15="","",IF(INDEX(전체!$E$6:$E$75,$O15)="","",INDEX(전체!$E$6:$E$75,$O15))) | E15: =IF($O15="","",IF(INDEX(전체!$F$6:$F$75,$O15)="","",INDEX(전체!$F$6:$F$75,$O15))) | F15: =IF($O15="","",IF(INDEX(전체!$G$6:$G$75,$O15)="","",INDEX(전체!$G$6:$G$75,$O15))) | G15: =IF($O15="","",IF(INDEX(전체!$H$6:$H$75,$O15)="","",INDEX(전체!$H$6:$H$75,$O15))) | H15: =IF($O15="","",IF(INDEX(전체!$I$6:$I$75,$O15)="","",INDEX(전체!$I$6:$I$75,$O15))) | I15: =IF($O15="","",IF(INDEX(전체!$J$6:$J$75,$O15)="","",INDEX(전체!$J$6:$J$75,$O15))) | J15: =IF($O15="","",IF(INDEX(전체!$K$6:$K$75,$O15)="","",INDEX(전체!$K$6:$K$75,$O15))) | K15: =IF($O15="","",IF(INDEX(전체!$L$6:$L$75,$O15)="","",INDEX(전체!$L$6:$L$75,$O15))) | L15: =IF($O15="","",IF(INDEX(전체!$M$6:$M$75,$O15)="","",INDEX(전체!$M$6:$M$75,$O15))) | M15: =IF($O15="","",IF(INDEX(전체!$N$6:$N$75,$O15)="","",INDEX(전체!$N$6:$N$75,$O15))) | N15: =IF($O15="","",IF(INDEX(전체!$O$6:$O$75,$O15)="","",INDEX(전체!$O$6:$O$75,$O15))) | O15: =IFERROR(MATCH($R$2&"|"&11,전체!$P$6:$P$75,0),"")
A16: =IF($O16="","",12) | B16: =IF($O16="","",IF(INDEX(전체!$C$6:$C$75,$O16)="","",INDEX(전체!$C$6:$C$75,$O16))) | C16: =IF($O16="","",IF(INDEX(전체!$D$6:$D$75,$O16)="","",INDEX(전체!$D$6:$D$75,$O16))) | D16: =IF($O16="","",IF(INDEX(전체!$E$6:$E$75,$O16)="","",INDEX(전체!$E$6:$E$75,$O16))) | E16: =IF($O16="","",IF(INDEX(전체!$F$6:$F$75,$O16)="","",INDEX(전체!$F$6:$F$75,$O16))) | F16: =IF($O16="","",IF(INDEX(전체!$G$6:$G$75,$O16)="","",INDEX(전체!$G$6:$G$75,$O16))) | G16: =IF($O16="","",IF(INDEX(전체!$H$6:$H$75,$O16)="","",INDEX(전체!$H$6:$H$75,$O16))) | H16: =IF($O16="","",IF(INDEX(전체!$I$6:$I$75,$O16)="","",INDEX(전체!$I$6:$I$75,$O16))) | I16: =IF($O16="","",IF(INDEX(전체!$J$6:$J$75,$O16)="","",INDEX(전체!$J$6:$J$75,$O16))) | J16: =IF($O16="","",IF(INDEX(전체!$K$6:$K$75,$O16)="","",INDEX(전체!$K$6:$K$75,$O16))) | K16: =IF($O16="","",IF(INDEX(전체!$L$6:$L$75,$O16)="","",INDEX(전체!$L$6:$L$75,$O16))) | L16: =IF($O16="","",IF(INDEX(전체!$M$6:$M$75,$O16)="","",INDEX(전체!$M$6:$M$75,$O16))) | M16: =IF($O16="","",IF(INDEX(전체!$N$6:$N$75,$O16)="","",INDEX(전체!$N$6:$N$75,$O16))) | N16: =IF($O16="","",IF(INDEX(전체!$O$6:$O$75,$O16)="","",INDEX(전체!$O$6:$O$75,$O16))) | O16: =IFERROR(MATCH($R$2&"|"&12,전체!$P$6:$P$75,0),"")
A17: =IF($O17="","",13) | B17: =IF($O17="","",IF(INDEX(전체!$C$6:$C$75,$O17)="","",INDEX(전체!$C$6:$C$75,$O17))) | C17: =IF($O17="","",IF(INDEX(전체!$D$6:$D$75,$O17)="","",INDEX(전체!$D$6:$D$75,$O17))) | D17: =IF($O17="","",IF(INDEX(전체!$E$6:$E$75,$O17)="","",INDEX(전체!$E$6:$E$75,$O17))) | E17: =IF($O17="","",IF(INDEX(전체!$F$6:$F$75,$O17)="","",INDEX(전체!$F$6:$F$75,$O17))) | F17: =IF($O17="","",IF(INDEX(전체!$G$6:$G$75,$O17)="","",INDEX(전체!$G$6:$G$75,$O17))) | G17: =IF($O17="","",IF(INDEX(전체!$H$6:$H$75,$O17)="","",INDEX(전체!$H$6:$H$75,$O17))) | H17: =IF($O17="","",IF(INDEX(전체!$I$6:$I$75,$O17)="","",INDEX(전체!$I$6:$I$75,$O17))) | I17: =IF($O17="","",IF(INDEX(전체!$J$6:$J$75,$O17)="","",INDEX(전체!$J$6:$J$75,$O17))) | J17: =IF($O17="","",IF(INDEX(전체!$K$6:$K$75,$O17)="","",INDEX(전체!$K$6:$K$75,$O17))) | K17: =IF($O17="","",IF(INDEX(전체!$L$6:$L$75,$O17)="","",INDEX(전체!$L$6:$L$75,$O17))) | L17: =IF($O17="","",IF(INDEX(전체!$M$6:$M$75,$O17)="","",INDEX(전체!$M$6:$M$75,$O17))) | M17: =IF($O17="","",IF(INDEX(전체!$N$6:$N$75,$O17)="","",INDEX(전체!$N$6:$N$75,$O17))) | N17: =IF($O17="","",IF(INDEX(전체!$O$6:$O$75,$O17)="","",INDEX(전체!$O$6:$O$75,$O17))) | O17: =IFERROR(MATCH($R$2&"|"&13,전체!$P$6:$P$75,0),"")
A18: =IF($O18="","",14) | B18: =IF($O18="","",IF(INDEX(전체!$C$6:$C$75,$O18)="","",INDEX(전체!$C$6:$C$75,$O18))) | C18: =IF($O18="","",IF(INDEX(전체!$D$6:$D$75,$O18)="","",INDEX(전체!$D$6:$D$75,$O18))) | D18: =IF($O18="","",IF(INDEX(전체!$E$6:$E$75,$O18)="","",INDEX(전체!$E$6:$E$75,$O18))) | E18: =IF($O18="","",IF(INDEX(전체!$F$6:$F$75,$O18)="","",INDEX(전체!$F$6:$F$75,$O18))) | F18: =IF($O18="","",IF(INDEX(전체!$G$6:$G$75,$O18)="","",INDEX(전체!$G$6:$G$75,$O18))) | G18: =IF($O18="","",IF(INDEX(전체!$H$6:$H$75,$O18)="","",INDEX(전체!$H$6:$H$75,$O18))) | H18: =IF($O18="","",IF(INDEX(전체!$I$6:$I$75,$O18)="","",INDEX(전체!$I$6:$I$75,$O18))) | I18: =IF($O18="","",IF(INDEX(전체!$J$6:$J$75,$O18)="","",INDEX(전체!$J$6:$J$75,$O18))) | J18: =IF($O18="","",IF(INDEX(전체!$K$6:$K$75,$O18)="","",INDEX(전체!$K$6:$K$75,$O18))) | K18: =IF($O18="","",IF(INDEX(전체!$L$6:$L$75,$O18)="","",INDEX(전체!$L$6:$L$75,$O18))) | L18: =IF($O18="","",IF(INDEX(전체!$M$6:$M$75,$O18)="","",INDEX(전체!$M$6:$M$75,$O18))) | M18: =IF($O18="","",IF(INDEX(전체!$N$6:$N$75,$O18)="","",INDEX(전체!$N$6:$N$75,$O18))) | N18: =IF($O18="","",IF(INDEX(전체!$O$6:$O$75,$O18)="","",INDEX(전체!$O$6:$O$75,$O18))) | O18: =IFERROR(MATCH($R$2&"|"&14,전체!$P$6:$P$75,0),"")
A19: =IF($O19="","",15) | B19: =IF($O19="","",IF(INDEX(전체!$C$6:$C$75,$O19)="","",INDEX(전체!$C$6:$C$75,$O19))) | C19: =IF($O19="","",IF(INDEX(전체!$D$6:$D$75,$O19)="","",INDEX(전체!$D$6:$D$75,$O19))) | D19: =IF($O19="","",IF(INDEX(전체!$E$6:$E$75,$O19)="","",INDEX(전체!$E$6:$E$75,$O19))) | E19: =IF($O19="","",IF(INDEX(전체!$F$6:$F$75,$O19)="","",INDEX(전체!$F$6:$F$75,$O19))) | F19: =IF($O19="","",IF(INDEX(전체!$G$6:$G$75,$O19)="","",INDEX(전체!$G$6:$G$75,$O19))) | G19: =IF($O19="","",IF(INDEX(전체!$H$6:$H$75,$O19)="","",INDEX(전체!$H$6:$H$75,$O19))) | H19: =IF($O19="","",IF(INDEX(전체!$I$6:$I$75,$O19)="","",INDEX(전체!$I$6:$I$75,$O19))) | I19: =IF($O19="","",IF(INDEX(전체!$J$6:$J$75,$O19)="","",INDEX(전체!$J$6:$J$75,$O19))) | J19: =IF($O19="","",IF(INDEX(전체!$K$6:$K$75,$O19)="","",INDEX(전체!$K$6:$K$75,$O19))) | K19: =IF($O19="","",IF(INDEX(전체!$L$6:$L$75,$O19)="","",INDEX(전체!$L$6:$L$75,$O19))) | L19: =IF($O19="","",IF(INDEX(전체!$M$6:$M$75,$O19)="","",INDEX(전체!$M$6:$M$75,$O19))) | M19: =IF($O19="","",IF(INDEX(전체!$N$6:$N$75,$O19)="","",INDEX(전체!$N$6:$N$75,$O19))) | N19: =IF($O19="","",IF(INDEX(전체!$O$6:$O$75,$O19)="","",INDEX(전체!$O$6:$O$75,$O19))) | O19: =IFERROR(MATCH($R$2&"|"&15,전체!$P$6:$P$75,0),"")
A20: =IF($O20="","",16) | B20: =IF($O20="","",IF(INDEX(전체!$C$6:$C$75,$O20)="","",INDEX(전체!$C$6:$C$75,$O20))) | C20: =IF($O20="","",IF(INDEX(전체!$D$6:$D$75,$O20)="","",INDEX(전체!$D$6:$D$75,$O20))) | D20: =IF($O20="","",IF(INDEX(전체!$E$6:$E$75,$O20)="","",INDEX(전체!$E$6:$E$75,$O20))) | E20: =IF($O20="","",IF(INDEX(전체!$F$6:$F$75,$O20)="","",INDEX(전체!$F$6:$F$75,$O20))) | F20: =IF($O20="","",IF(INDEX(전체!$G$6:$G$75,$O20)="","",INDEX(전체!$G$6:$G$75,$O20))) | G20: =IF($O20="","",IF(INDEX(전체!$H$6:$H$75,$O20)="","",INDEX(전체!$H$6:$H$75,$O20))) | H20: =IF($O20="","",IF(INDEX(전체!$I$6:$I$75,$O20)="","",INDEX(전체!$I$6:$I$75,$O20))) | I20: =IF($O20="","",IF(INDEX(전체!$J$6:$J$75,$O20)="","",INDEX(전체!$J$6:$J$75,$O20))) | J20: =IF($O20="","",IF(INDEX(전체!$K$6:$K$75,$O20)="","",INDEX(전체!$K$6:$K$75,$O20))) | K20: =IF($O20="","",IF(INDEX(전체!$L$6:$L$75,$O20)="","",INDEX(전체!$L$6:$L$75,$O20))) | L20: =IF($O20="","",IF(INDEX(전체!$M$6:$M$75,$O20)="","",INDEX(전체!$M$6:$M$75,$O20))) | M20: =IF($O20="","",IF(INDEX(전체!$N$6:$N$75,$O20)="","",INDEX(전체!$N$6:$N$75,$O20))) | N20: =IF($O20="","",IF(INDEX(전체!$O$6:$O$75,$O20)="","",INDEX(전체!$O$6:$O$75,$O20))) | O20: =IFERROR(MATCH($R$2&"|"&16,전체!$P$6:$P$75,0),"")
