Workbook

Sheet 통합 청구
A1: NORTH FLEET – LUB OIL REQUISITION (통합 청구 리스트)
A2: 녹색 = 선박 시트에서 가져온 값(수식), 파란색 = 입력값. 각 선박 시트(North Light / Moon / Ocean / Valley)를 수정하면 자동 반영됩니다.
B3: 1 CAN – 오일 (L) | C3: 20 | D3: ← 가정값: Light 'CAN' → L 환산 (Epona SA 220: 40L = 20L/CAN, Valley 20L pail 기준)
B4: 1 CAN – 그리스 (KG) | C4: 18 | D4: ← 가정값: Light 'CAN' → KG 환산 (Bioadhesive: 108 KG = 6 CAN, Valley 18KG pail 기준)
A6: No. | B6: Item (Lub Oil / Grease) | C6: Unit | D6: NORTH LIGHT | F6: NORTH MOON | H6: NORTH OCEAN | J6: NORTH VALLEY | L6: TOTAL REQ | M6: Remarks
D7: ROB | E7: REQ | F7: ROB | G7: REQ | H7: ROB | I7: REQ | J7: ROB | K7: REQ
A8: ■ 청구 품목 (21) – 이름순
A9: 1 | B9: BARELF CH 100 | C9: L | D9: =IF(COUNTIFS('North Light'!$B$6:$B$38,$B9,'North Light'!$E$6:$E$38,"<>")=0,"",SUMIFS('North Light'!$E$6:$E$38,'North Light'!$B$6:$B$38,$B9)) | E9: =IF(COUNTIFS('North Light'!$B$6:$B$38,$B9,'North Light'!$F$6:$F$38,"<>")=0,"",SUMIFS('North Light'!$F$6:$F$38,'North Light'!$B$6:$B$38,$B9)) -> 160 | F9: =IF(COUNTIFS('North Moon'!$B$6:$B$13,$B9,'North Moon'!$E$6:$E$13,"<>")=0,"",SUMIFS('North Moon'!$E$6:$E$13,'North Moon'!$B$6:$B$13,$B9)) -> 106 | G9: =IF(COUNTIFS('North Moon'!$B$6:$B$13,$B9,'North Moon'!$F$6:$F$13,"<>")=0,"",SUMIFS('North Moon'!$F$6:$F$13,'North Moon'!$B$6:$B$13,$B9)) -> 200 | H9: =IF(COUNTIFS('North Ocean'!$B$6:$B$17,$B9,'North Ocean'!$E$6:$E$17,"<>")=0,"",SUMIFS('North Ocean'!$E$6:$E$17,'North Ocean'!$B$6:$B$17,$B9)) | I9: =IF(COUNTIFS('North Ocean'!$B$6:$B$17,$B9,'North Ocean'!$F$6:$F$17,"<>")=0,"",SUMIFS('North Ocean'!$F$6:$F$17,'North Ocean'!$B$6:$B$17,$B9)) | J9: =IF(COUNTIFS('North Valley'!$B$6:$B$22,$B9,'North Valley'!$E$6:$E$22,"<>")=0,"",SUMIFS('North Valley'!$E$6:$E$22,'North Valley'!$B$6:$B$22,$B9)) | K9: =IF(COUNTIFS('North Valley'!$B$6:$B$22,$B9,'North Valley'!$F$6:$F$22,"<>")=0,"",SUMIFS('North Valley'!$F$6:$F$22,'North Valley'!$B$6:$B$22,$B9)) | L9: =SUM(E9,G9,I9,K9) -> 360
A10: 2 | B10: BARELF SM 46 | C10: L | D10: =IF(COUNTIFS('North Light'!$B$6:$B$38,$B10,'North Light'!$E$6:$E$38,"<>")=0,"",SUMIFS('North Light'!$E$6:$E$38,'North Light'!$B$6:$B$38,$B10)) | E10: =IF(COUNTIFS('North Light'!$B$6:$B$38,$B10,'North Light'!$F$6:$F$38,"<>")=0,"",SUMIFS('North Light'!$F$6:$F$38,'North Light'!$B$6:$B$38,$B10)) -> 120 | F10: =IF(COUNTIFS('North Moon'!$B$6:$B$13,$B10,'North Moon'!$E$6:$E$13,"<>")=0,"",SUMIFS('North Moon'!$E$6:$E$13,'North Moon'!$B$6:$B$13,$B10)) -> 120 | G10: =IF(COUNTIFS('North Moon'!$B$6:$B$13,$B10,'North Moon'!$F$6:$F$13,"<>")=0,"",SUMIFS('North Moon'!$F$6:$F$13,'North Moon'!$B$6:$B$13,$B10)) -> 300 | H10: =IF(COUNTIFS('North Ocean'!$B$6:$B$17,$B10,'North Ocean'!$E$6:$E$17,"<>")=0,"",SUMIFS('North Ocean'!$E$6:$E$17,'North Ocean'!$B$6:$B$17,$B10)) | I10: =IF(COUNTIFS('North Ocean'!$B$6:$B$17,$B10,'North Ocean'!$F$6:$F$17,"<>")=0,"",SUMIFS('North Ocean'!$F$6:$F$17,'North Ocean'!$B$6:$B$17,$B10)) -> 120 | J10: =IF(COUNTIFS('North Valley'!$B$6:$B$22,$B10,'North Valley'!$E$6:$E$22,"<>")=0,"",SUMIFS('North Valley'!$E$6:$E$22,'North Valley'!$B$6:$B$22,$B10)) | K10: =IF(COUNTIFS('North Valley'!$B$6:$B$22,$B10,'North Valley'!$F$6:$F$22,"<>")=0,"",SUMIFS('North Valley'!$F$6:$F$22,'North Valley'!$B$6:$B$22,$B10)) | L10: =SUM(E10,G10,I10,K10) -> 540
A11: 3 | B11: BIOADHESIVE PLUS | C11: KG | D11: =IF(COUNTIFS('North Light'!$B$6:$B$38,$B11,'North Light'!$E$6:$E$38,"<>")=0,"",SUMIFS('North Light'!$E$6:$E$38,'North Light'!$B$6:$B$38,$B11)) | E11: =IF(COUNTIFS('North Light'!$B$6:$B$38,$B11,'North Light'!$F$6:$F$38,"<>")=0,"",SUMIFS('North Light'!$F$6:$F$38,'North Light'!$B$6:$B$38,$B11)) -> 108 | F11: =IF(COUNTIFS('North Moon'!$B$6:$B$13,$B11,'North Moon'!$E$6:$E$13,"<>")=0,"",SUMIFS('North Moon'!$E$6:$E$13,'North Moon'!$B$6:$B$13,$B11)) | G11: =IF(COUNTIFS('North Moon'!$B$6:$B$13,$B11,'North Moon'!$F$6:$F$13,"<>")=0,"",SUMIFS('North Moon'!$F$6:$F$13,'North Moon'!$B$6:$B$13,$B11)) | H11: =IF(COUNTIFS('North Ocean'!$B$6:$B$17,$B11,'North Ocean'!$E$6:$E$17,"<>")=0,"",SUMIFS('North Ocean'!$E$6:$E$17,'North Ocean'!$B$6:$B$17,$B11)) | I11: =IF(COUNTIFS('North Ocean'!$B$6:$B$17,$B11,'North Ocean'!$F$6:$F$17,"<>")=0,"",SUMIFS('North Ocean'!$F$6:$F$17,'North Ocean'!$B$6:$B$17,$B11)) | J11: =IF(COUNTIFS('North Valley'!$B$6:$B$22,$B11,'North Valley'!$E$6:$E$22,"<>")=0,"",SUMIFS('North Valley'!$E$6:$E$22,'North Valley'!$B$6:$B$22,$B11)) -> 140 | K11: =IF(COUNTIFS('North Valley'!$B$6:$B$22,$B11,'North Valley'!$F$6:$F$22,"<>")=0,"",SUMIFS('North Valley'!$F$6:$F$22,'North Valley'!$B$6:$B$22,$B11)) -> 54 | L11: =SUM(E11,G11,I11,K11) -> 162
A12: 4 | B12: BIOMULTIS EP 0 | C12: KG | D12: =IF(COUNTIFS('North Light'!$B$6:$B$38,$B12,'North Light'!$E$6:$E$38,"<>")=0,"",SUMIFS('North Light'!$E$6:$E$38,'North Light'!$B$6:$B$38,$B12)) | E12: =IF(COUNTIFS('North Light'!$B$6:$B$38,$B12,'North Light'!$F$6:$F$38,"<>")=0,"",SUMIFS('North Light'!$F$6:$F$38,'North Light'!$B$6:$B$38,$B12)) | F12: =IF(COUNTIFS('North Moon'!$B$6:$B$13,$B12,'North Moon'!$E$6:$E$13,"<>")=0,"",SUMIFS('North Moon'!$E$6:$E$13,'North Moon'!$B$6:$B$13,$B12)) | G12: =IF(COUNTIFS('North Moon'!$B$6:$B$13,$B12,'North Moon'!$F$6:$F$13,"<>")=0,"",SUMIFS('North Moon'!$F$6:$F$13,'North Moon'!$B$6:$B$13,$B12)) | H12: =IF(COUNTIFS('North Ocean'!$B$6:$B$17,$B12,'North Ocean'!$E$6:$E$17,"<>")=0,"",SUMIFS('North Ocean'!$E$6:$E$17,'North Ocean'!$B$6:$B$17,$B12)) | I12: =IF(COUNTIFS('North Ocean'!$B$6:$B$17,$B12,'North Ocean'!$F$6:$F$17,"<>")=0,"",SUMIFS('North Ocean'!$F$6:$F$17,'North Ocean'!$B$6:$B$17,$B12)) | J12: =IF(COUNTIFS('North Valley'!$B$6:$B$22,$B12,'North Valley'!$E$6:$E$22,"<>")=0,"",SUMIFS('North Valley'!$E$6:$E$22,'North Valley'!$B$6:$B$22,$B12)) -> 36 | K12: =IF(COUNTIFS('North Valley'!$B$6:$B$22,$B12,'North Valley'!$F$6:$F$22,"<>")=0,"",SUMIFS('North Valley'!$F$6:$F$22,'North Valley'!$B$6:$B$22,$B12)) -> 36 | L12: =SUM(E12,G12,I12,K12) -> 36
A13: 5 | B13: BSE 170 | C13: L | D13: =IF(COUNTIFS('North Light'!$B$6:$B$38,$B13,'North Light'!$E$6:$E$38,"<>")=0,"",SUMIFS('North Light'!$E$6:$E$38,'North Light'!$B$6:$B$38,$B13)) | E13: =IF(COUNTIFS('North Light'!$B$6:$B$38,$B13,'North Light'!$F$6:$F$38,"<>")=0,"",SUMIFS('North Light'!$F$6:$F$38,'North Light'!$B$6:$B$38,$B13)) | F13: =IF(COUNTIFS('North Moon'!$B$6:$B$13,$B13,'North Moon'!$E$6:$E$13,"<>")=0,"",SUMIFS('North Moon'!$E$6:$E$13,'North Moon'!$B$6:$B$13,$B13)) | G13: =IF(COUNTIFS('North Moon'!$B$6:$B$13,$B13,'North Moon'!$F$6:$F$13,"<>")=0,"",SUMIFS('North Moon'!$F$6:$F$13,'North Moon'!$B$6:$B$13,$B13)) | H13: =IF(COUNTIFS('North Ocean'!$B$6:$B$17,$B13,'North Ocean'!$E$6:$E$17,"<>")=0,"",SUMIFS('North Ocean'!$E$6:$E$17,'North Ocean'!$B$6:$B$17,$B13)) | I13: =IF(COUNTIFS('North Ocean'!$B$6:$B$17,$B13,'North Ocean'!$F$6:$F$17,"<>")=0,"",SUMIFS('North Ocean'!$F$6:$F$17,'North Ocean'!$B$6:$B$17,$B13)) | J13: =IF(COUNTIFS('North Valley'!$B$6:$B$22,$B13,'North Valley'!$E$6:$E$22,"<>")=0,"",SUMIFS('North Valley'!$E$6:$E$22,'North Valley'!$B$6:$B$22,$B13)) -> 130 | K13: =IF(COUNTIFS('North Valley'!$B$6:$B$22,$B13,'North Valley'!$F$6:$F$22,"<>")=0,"",SUMIFS('North Valley'!$F$6:$F$22,'North Valley'!$B$6:$B$22,$B13)) -> 100 | L13: =SUM(E13,G13,I13,K13) -> 100 | M13: Bitzer (Valley)
A14: 6 | B14: CARTER SH 150 | C14: L | D14: =IF(COUNTIFS('North Light'!$B$6:$B$38,$B14,'North Light'!$E$6:$E$38,"<>")=0,"",SUMIFS('North Light'!$E$6:$E$38,'North Light'!$B$6:$B$38,$B14)) | E14: =IF(COUNTIFS('North Light'!$B$6:$B$38,$B14,'North Light'!$F$6:$F$38,"<>")=0,"",SUMIFS('North Light'!$F$6:$F$38,'North Light'!$B$6:$B$38,$B14)) -> 180 | F14: =IF(COUNTIFS('North Moon'!$B$6:$B$13,$B14,'North Moon'!$E$6:$E$13,"<>")=0,"",SUMIFS('North Moon'!$E$6:$E$13,'North Moon'!$B$6:$B$13,$B14)) | G14: =IF(COUNTIFS('North Moon'!$B$6:$B$13,$B14,'North Moon'!$F$6:$F$13,"<>")=0,"",SUMIFS('North Moon'!$F$6:$F$13,'North Moon'!$B$6:$B$13,$B14)) | H14: =IF(COUNTIFS('North Ocean'!$B$6:$B$17,$B14,'North Ocean'!$E$6:$E$17,"<>")=0,"",SUMIFS('North Ocean'!$E$6:$E$17,'North Ocean'!$B$6:$B$17,$B14)) -> 27 | I14: =IF(COUNTIFS('North Ocean'!$B$6:$B$17,$B14,'North Ocean'!$F$6:$F$17,"<>")=0,"",SUMIFS('North Ocean'!$F$6:$F$17,'North Ocean'!$B$6:$B$17,$B14)) -> 40 | J14: =IF(COUNTIFS('North Valley'!$B$6:$B$22,$B14,'North Valley'!$E$6:$E$22,"<>")=0,"",SUMIFS('North Valley'!$E$6:$E$22,'North Valley'!$B$6:$B$22,$B14)) | K14: =IF(COUNTIFS('North Valley'!$B$6:$B$22,$B14,'North Valley'!$F$6:$F$22,"<>")=0,"",SUMIFS('North Valley'!$F$6:$F$22,'North Valley'!$B$6:$B$22,$B14)) | L14: =SUM(E14,G14,I14,K14) -> 220
A15: 7 | B15: CERAN AD PLUS | C15: KG | D15: =IF(COUNTIFS('North Light'!$B$6:$B$38,$B15,'North Light'!$E$6:$E$38,"<>")=0,"",SUMIFS('North Light'!$E$6:$E$38,'North Light'!$B$6:$B$38,$B15)) | E15: =IF(COUNTIFS('North Light'!$B$6:$B$38,$B15,'North Light'!$F$6:$F$38,"<>")=0,"",SUMIFS('North Light'!$F$6:$F$38,'North Light'!$B$6:$B$38,$B15)) | F15: =IF(COUNTIFS('North Moon'!$B$6:$B$13,$B15,'North Moon'!$E$6:$E$13,"<>")=0,"",SUMIFS('North Moon'!$E$6:$E$13,'North Moon'!$B$6:$B$13,$B15)) | G15: =IF(COUNTIFS('North Moon'!$B$6:$B$13,$B15,'North Moon'!$F$6:$F$13,"<>")=0,"",SUMIFS('North Moon'!$F$6:$F$13,'North Moon'!$B$6:$B$13,$B15)) | H15: =IF(COUNTIFS('North Ocean'!$B$6:$B$17,$B15,'North Ocean'!$E$6:$E$17,"<>")=0,"",SUMIFS('North Ocean'!$E$6:$E$17,'North Ocean'!$B$6:$B$17,$B15)) -> 27 | I15: =IF(COUNTIFS('North Ocean'!$B$6:$B$17,$B15,'North Ocean'!$F$6:$F$17,"<>")=0,"",SUMIFS('North Ocean'!$F$6:$F$17,'North Ocean'!$B$6:$B$17,$B15)) -> 72 | J15: =IF(COUNTIFS('North Valley'!$B$6:$B$22,$B15,'North Valley'!$E$6:$E$22,"<>")=0,"",SUMIFS('North Valley'!$E$6:$E$22,'North Valley'!$B$6:$B$22,$B15)) | K15: =IF(COUNTIFS('North Valley'!$B$6:$B$22,$B15,'North Valley'!$F$6:$F$22,"<>")=0,"",SUMIFS('North Valley'!$F$6:$F$22,'North Valley'!$B$6:$B$22,$B15)) | L15: =SUM(E15,G15,I15,K15) -> 72
A16: 8 | B16: CERAN XM 220 | C16: KG | D16: =IF(COUNTIFS('North Light'!$B$6:$B$38,$B16,'North Light'!$E$6:$E$38,"<>")=0,"",SUMIFS('North Light'!$E$6:$E$38,'North Light'!$B$6:$B$38,$B16)) | E16: =IF(COUNTIFS('North Light'!$B$6:$B$38,$B16,'North Light'!$F$6:$F$38,"<>")=0,"",SUMIFS('North Light'!$F$6:$F$38,'North Light'!$B$6:$B$38,$B16)) -> 108 | F16: =IF(COUNTIFS('North Moon'!$B$6:$B$13,$B16,'North Moon'!$E$6:$E$13,"<>")=0,"",SUMIFS('North Moon'!$E$6:$E$13,'North Moon'!$B$6:$B$13,$B16)) | G16: =IF(COUNTIFS('North Moon'!$B$6:$B$13,$B16,'North Moon'!$F$6:$F$13,"<>")=0,"",SUMIFS('North Moon'!$F$6:$F$13,'North Moon'!$B$6:$B$13,$B16)) | H16: =IF(COUNTIFS('North Ocean'!$B$6:$B$17,$B16,'North Ocean'!$E$6:$E$17,"<>")=0,"",SUMIFS('North Ocean'!$E$6:$E$17,'North Ocean'!$B$6:$B$17,$B16)) -> 52 | I16: =IF(COUNTIFS('North Ocean'!$B$6:$B$17,$B16,'North Ocean'!$F$6:$F$17,"<>")=0,"",SUMIFS('North Ocean'!$F$6:$F$17,'North Ocean'!$B$6:$B$17,$B16)) -> 90 | J16: =IF(COUNTIFS('North Valley'!$B$6:$B$22,$B16,'North Valley'!$E$6:$E$22,"<>")=0,"",SUMIFS('North Valley'!$E$6:$E$22,'North Valley'!$B$6:$B$22,$B16)) -> 70 | K16: =IF(COUNTIFS('North Valley'!$B$6:$B$22,$B16,'North Valley'!$F$6:$F$22,"<>")=0,"",SUMIFS('North Valley'!$F$6:$F$22,'North Valley'!$B$6:$B$22,$B16)) -> 180 | L16: =SUM(E16,G16,I16,K16) -> 378
A17: 9 | B17: DACNIS 46 | C17: L | D17: =IF(COUNTIFS('North Light'!$B$6:$B$38,$B17,'North Light'!$E$6:$E$38,"<>")=0,"",SUMIFS('North Light'!$E$6:$E$38,'North Light'!$B$6:$B$38,$B17)) | E17: =IF(COUNTIFS('North Light'!$B$6:$B$38,$B17,'North Light'!$F$6:$F$38,"<>")=0,"",SUMIFS('North Light'!$F$6:$F$38,'North Light'!$B$6:$B$38,$B17)) | F17: =IF(COUNTIFS('North Moon'!$B$6:$B$13,$B17,'North Moon'!$E$6:$E$13,"<>")=0,"",SUMIFS('North Moon'!$E$6:$E$13,'North Moon'!$B$6:$B$13,$B17)) | G17: =IF(COUNTIFS('North Moon'!$B$6:$B$13,$B17,'North Moon'!$F$6:$F$13,"<>")=0,"",SUMIFS('North Moon'!$F$6:$F$13,'North Moon'!$B$6:$B$13,$B17)) | H17: =IF(COUNTIFS('North Ocean'!$B$6:$B$17,$B17,'North Ocean'!$E$6:$E$17,"<>")=0,"",SUMIFS('North Ocean'!$E$6:$E$17,'North Ocean'!$B$6:$B$17,$B17)) | I17: =IF(COUNTIFS('North Ocean'!$B$6:$B$17,$B17,'North Ocean'!$F$6:$F$17,"<>")=0,"",SUMIFS('North Ocean'!$F$6:$F$17,'North Ocean'!$B$6:$B$17,$B17)) | J17: =IF(COUNTIFS('North Valley'!$B$6:$B$22,$B17,'North Valley'!$E$6:$E$22,"<>")=0,"",SUMIFS('North Valley'!$E$6:$E$22,'North Valley'!$B$6:$B$22,$B17)) -> 40 | K17: =IF(COUNTIFS('North Valley'!$B$6:$B$22,$B17,'North Valley'!$F$6:$F$22,"<>")=0,"",SUMIFS('North Valley'!$F$6:$F$22,'North Valley'!$B$6:$B$22,$B17)) -> 160 | L17: =SUM(E17,G17,I17,K17) -> 160
A18: 10 | B18: DACNIS 100 | C18: L | D18: =IF(COUNTIFS('North Light'!$B$6:$B$38,$B18,'North Light'!$E$6:$E$38,"<>")=0,"",SUMIFS('North Light'!$E$6:$E$38,'North Light'!$B$6:$B$38,$B18)) | E18: =IF(COUNTIFS('North Light'!$B$6:$B$38,$B18,'North Light'!$F$6:$F$38,"<>")=0,"",SUMIFS('North Light'!$F$6:$F$38,'North Light'!$B$6:$B$38,$B18)) | F18: =IF(COUNTIFS('North Moon'!$B$6:$B$13,$B18,'North Moon'!$E$6:$E$13,"<>")=0,"",SUMIFS('North Moon'!$E$6:$E$13,'North Moon'!$B$6:$B$13,$B18)) | G18: =IF(COUNTIFS('North Moon'!$B$6:$B$13,$B18,'North Moon'!$F$6:$F$13,"<>")=0,"",SUMIFS('North Moon'!$F$6:$F$13,'North Moon'!$B$6:$B$13,$B18)) | H18: =IF(COUNTIFS('North Ocean'!$B$6:$B$17,$B18,'North Ocean'!$E$6:$E$17,"<>")=0,"",SUMIFS('North Ocean'!$E$6:$E$17,'North Ocean'!$B$6:$B$17,$B18)) | I18: =IF(COUNTIFS('North Ocean'!$B$6:$B$17,$B18,'North Ocean'!$F$6:$F$17,"<>")=0,"",SUMIFS('North Ocean'!$F$6:$F$17,'North Ocean'!$B$6:$B$17,$B18)) | J18: =IF(COUNTIFS('North Valley'!$B$6:$B$22,$B18,'North Valley'!$E$6:$E$22,"<>")=0,"",SUMIFS('North Valley'!$E$6:$E$22,'North Valley'!$B$6:$B$22,$B18)) -> 150 | K18: =IF(COUNTIFS('North Valley'!$B$6:$B$22,$B18,'North Valley'!$F$6:$F$22,"<>")=0,"",SUMIFS('North Valley'!$F$6:$F$22,'North Valley'!$B$6:$B$22,$B18)) -> 100 | L18: =SUM(E18,G18,I18,K18) -> 100
A19: 11 | B19: ELFMATIC G3 | C19: L | D19: =IF(COUNTIFS('North Light'!$B$6:$B$38,$B19,'North Light'!$E$6:$E$38,"<>")=0,"",SUMIFS('North Light'!$E$6:$E$38,'North Light'!$B$6:$B$38,$B19)) | E19: =IF(COUNTIFS('North Light'!$B$6:$B$38,$B19,'North Light'!$F$6:$F$38,"<>")=0,"",SUMIFS('North Light'!$F$6:$F$38,'North Light'!$B$6:$B$38,$B19)) -> 40 | F19: =IF(COUNTIFS('North Moon'!$B$6:$B$13,$B19,'North Moon'!$E$6:$E$13,"<>")=0,"",SUMIFS('North Moon'!$E$6:$E$13,'North Moon'!$B$6:$B$13,$B19)) -> 0 | G19: =IF(COUNTIFS('North Moon'!$B$6:$B$13,$B19,'North Moon'!$F$6:$F$13,"<>")=0,"",SUMIFS('North Moon'!$F$6:$F$13,'North Moon'!$B$6:$B$13,$B19)) -> 20 | H19: =IF(COUNTIFS('North Ocean'!$B$6:$B$17,$B19,'North Ocean'!$E$6:$E$17,"<>")=0,"",SUMIFS('North Ocean'!$E$6:$E$17,'North Ocean'!$B$6:$B$17,$B19)) | I19: =IF(COUNTIFS('North Ocean'!$B$6:$B$17,$B19,'North Ocean'!$F$6:$F$17,"<>")=0,"",SUMIFS('North Ocean'!$F$6:$F$17,'North Ocean'!$B$6:$B$17,$B19)) | J19: =IF(COUNTIFS('North Valley'!$B$6:$B$22,$B19,'North Valley'!$E$6:$E$22,"<>")=0,"",SUMIFS('North Valley'!$E$6:$E$22,'North Valley'!$B$6:$B$22,$B19)) | K19: =IF(COUNTIFS('North Valley'!$B$6:$B$22,$B19,'North Valley'!$F$6:$F$22,"<>")=0,"",SUMIFS('North Valley'!$F$6:$F$22,'North Valley'!$B$6:$B$22,$B19)) | L19: =SUM(E19,G19,I19,K19) -> 60
A20: 12 | B20: EPONA SA 220 | C20: L | D20: =IF(COUNTIFS('North Light'!$B$6:$B$38,$B20,'North Light'!$E$6:$E$38,"<>")=0,"",SUMIFS('North Light'!$E$6:$E$38,'North Light'!$B$6:$B$38,$B20)) | E20: =IF(COUNTIFS('North Light'!$B$6:$B$38,$B20,'North Light'!$F$6:$F$38,"<>")=0,"",SUMIFS('North Light'!$F$6:$F$38,'North Light'!$B$6:$B$38,$B20)) -> 40 | F20: =IF(COUNTIFS('North Moon'!$B$6:$B$13,$B20,'North Moon'!$E$6:$E$13,"<>")=0,"",SUMIFS('North Moon'!$E$6:$E$13,'North Moon'!$B$6:$B$13,$B20)) | G20: =IF(COUNTIFS('North Moon'!$B$6:$B$13,$B20,'North Moon'!$F$6:$F$13,"<>")=0,"",SUMIFS('North Moon'!$F$6:$F$13,'North Moon'!$B$6:$B$13,$B20)) | H20: =IF(COUNTIFS('North Ocean'!$B$6:$B$17,$B20,'North Ocean'!$E$6:$E$17,"<>")=0,"",SUMIFS('North Ocean'!$E$6:$E$17,'North Ocean'!$B$6:$B$17,$B20)) -> 48 | I20: =IF(COUNTIFS('North Ocean'!$B$6:$B$17,$B20,'North Ocean'!$F$6:$F$17,"<>")=0,"",SUMIFS('North Ocean'!$F$6:$F$17,'North Ocean'!$B$6:$B$17,$B20)) -> 20 | J20: =IF(COUNTIFS('North Valley'!$B$6:$B$22,$B20,'North Valley'!$E$6:$E$22,"<>")=0,"",SUMIFS('North Valley'!$E$6:$E$22,'North Valley'!$B$6:$B$22,$B20)) -> 50 | K20: =IF(COUNTIFS('North Valley'!$B$6:$B$22,$B20,'North Valley'!$F$6:$F$22,"<>")=0,"",SUMIFS('North Valley'!$F$6:$F$22,'North Valley'!$B$6:$B$22,$B20)) -> 60 | L20: =SUM(E20,G20,I20,K20) -> 120
A21: 13 | B21: EPONA Z 220 | C21: L | D21: =IF(COUNTIFS('North Light'!$B$6:$B$38,$B21,'North Light'!$E$6:$E$38,"<>")=0,"",SUMIFS('North Light'!$E$6:$E$38,'North Light'!$B$6:$B$38,$B21)) | E21: =IF(COUNTIFS('North Light'!$B$6:$B$38,$B21,'North Light'!$F$6:$F$38,"<>")=0,"",SUMIFS('North Light'!$F$6:$F$38,'North Light'!$B$6:$B$38,$B21)) | F21: =IF(COUNTIFS('North Moon'!$B$6:$B$13,$B21,'North Moon'!$E$6:$E$13,"<>")=0,"",SUMIFS('North Moon'!$E$6:$E$13,'North Moon'!$B$6:$B$13,$B21)) | G21: =IF(COUNTIFS('North Moon'!$B$6:$B$13,$B21,'North Moon'!$F$6:$F$13,"<>")=0,"",SUMIFS('North Moon'!$F$6:$F$13,'North Moon'!$B$6:$B$13,$B21)) | H21: =IF(COUNTIFS('North Ocean'!$B$6:$B$17,$B21,'North Ocean'!$E$6:$E$17,"<>")=0,"",SUMIFS('North Ocean'!$E$6:$E$17,'North Ocean'!$B$6:$B$17,$B21)) | I21: =IF(COUNTIFS('North Ocean'!$B$6:$B$17,$B21,'North Ocean'!$F$6:$F$17,"<>")=0,"",SUMIFS('North Ocean'!$F$6:$F$17,'North Ocean'!$B$6:$B$17,$B21)) | J21: =IF(COUNTIFS('North Valley'!$B$6:$B$22,$B21,'North Valley'!$E$6:$E$22,"<>")=0,"",SUMIFS('North Valley'!$E$6:$E$22,'North Valley'!$B$6:$B$22,$B21)) -> 80 | K21: =IF(COUNTIFS('North Valley'!$B$6:$B$22,$B21,'North Valley'!$F$6:$F$22,"<>")=0,"",SUMIFS('North Valley'!$F$6:$F$22,'North Valley'!$B$6:$B$22,$B21)) -> 60 | L21: =SUM(E21,G21,I21,K21) -> 60
A22: 14 | B22: EPONA Z 460 | C22: L | D22: =IF(COUNTIFS('North Light'!$B$6:$B$38,$B22,'North Light'!$E$6:$E$38,"<>")=0,"",SUMIFS('North Light'!$E$6:$E$38,'North Light'!$B$6:$B$38,$B22)) | E22: =IF(COUNTIFS('North Light'!$B$6:$B$38,$B22,'North Light'!$F$6:$F$38,"<>")=0,"",SUMIFS('North Light'!$F$6:$F$38,'North Light'!$B$6:$B$38,$B22)) -> 40 | F22: =IF(COUNTIFS('North Moon'!$B$6:$B$13,$B22,'North Moon'!$E$6:$E$13,"<>")=0,"",SUMIFS('North Moon'!$E$6:$E$13,'North Moon'!$B$6:$B$13,$B22)) | G22: =IF(COUNTIFS('North Moon'!$B$6:$B$13,$B22,'North Moon'!$F$6:$F$13,"<>")=0,"",SUMIFS('North Moon'!$F$6:$F$13,'North Moon'!$B$6:$B$13,$B22)) | H22: =IF(COUNTIFS('North Ocean'!$B$6:$B$17,$B22,'North Ocean'!$E$6:$E$17,"<>")=0,"",SUMIFS('North Ocean'!$E$6:$E$17,'North Ocean'!$B$6:$B$17,$B22)) | I22: =IF(COUNTIFS('North Ocean'!$B$6:$B$17,$B22,'North Ocean'!$F$6:$F$17,"<>")=0,"",SUMIFS('North Ocean'!$F$6:$F$17,'North Ocean'!$B$6:$B$17,$B22)) -> 40 | J22: =IF(COUNTIFS('North Valley'!$B$6:$B$22,$B22,'North Valley'!$E$6:$E$22,"<>")=0,"",SUMIFS('North Valley'!$E$6:$E$22,'North Valley'!$B$6:$B$22,$B22)) -> 20 | K22: =IF(COUNTIFS('North Valley'!$B$6:$B$22,$B22,'North Valley'!$F$6:$F$22,"<>")=0,"",SUMIFS('North Valley'!$F$6:$F$22,'North Valley'!$B$6:$B$22,$B22)) -> 20 | L22: =SUM(E22,G22,I22,K22) -> 100
A23: 15 | B23: MULTIS COMPLEX SHD 100 | C23: KG | D23: =IF(COUNTIFS('North Light'!$B$6:$B$38,$B23,'North Light'!$E$6:$E$38,"<>")=0,"",SUMIFS('North Light'!$E$6:$E$38,'North Light'!$B$6:$B$38,$B23)) | E23: =IF(COUNTIFS('North Light'!$B$6:$B$38,$B23,'North Light'!$F$6:$F$38,"<>")=0,"",SUMIFS('North Light'!$F$6:$F$38,'North Light'!$B$6:$B$38,$B23)) | F23: =IF(COUNTIFS('North Moon'!$B$6:$B$13,$B23,'North Moon'!$E$6:$E$13,"<>")=0,"",SUMIFS('North Moon'!$E$6:$E$13,'North Moon'!$B$6:$B$13,$B23)) | G23: =IF(COUNTIFS('North Moon'!$B$6:$B$13,$B23,'North Moon'!$F$6:$F$13,"<>")=0,"",SUMIFS('North Moon'!$F$6:$F$13,'North Moon'!$B$6:$B$13,$B23)) | H23: =IF(COUNTIFS('North Ocean'!$B$6:$B$17,$B23,'North Ocean'!$E$6:$E$17,"<>")=0,"",SUMIFS('North Ocean'!$E$6:$E$17,'North Ocean'!$B$6:$B$17,$B23)) | I23: =IF(COUNTIFS('North Ocean'!$B$6:$B$17,$B23,'North Ocean'!$F$6:$F$17,"<>")=0,"",SUMIFS('North Ocean'!$F$6:$F$17,'North Ocean'!$B$6:$B$17,$B23)) | J23: =IF(COUNTIFS('North Valley'!$B$6:$B$22,$B23,'North Valley'!$E$6:$E$22,"<>")=0,"",SUMIFS('North Valley'!$E$6:$E$22,'North Valley'!$B$6:$B$22,$B23)) -> 0 | K23: =IF(COUNTIFS('North Valley'!$B$6:$B$22,$B23,'North Valley'!$F$6:$F$22,"<>")=0,"",SUMIFS('North Valley'!$F$6:$F$22,'North Valley'!$B$6:$B$22,$B23)) -> 18 | L23: =SUM(E23,G23,I23,K23) -> 18
A24: 16 | B24: MULTIS COMPLEX SHD 220 | C24: KG | D24: =IF(COUNTIFS('North Light'!$B$6:$B$38,$B24,'North Light'!$E$6:$E$38,"<>")=0,"",SUMIFS('North Light'!$E$6:$E$38,'North Light'!$B$6:$B$38,$B24)) | E24: =IF(COUNTIFS('North Light'!$B$6:$B$38,$B24,'North Light'!$F$6:$F$38,"<>")=0,"",SUMIFS('North Light'!$F$6:$F$38,'North Light'!$B$6:$B$38,$B24)) | F24: =IF(COUNTIFS('North Moon'!$B$6:$B$13,$B24,'North Moon'!$E$6:$E$13,"<>")=0,"",SUMIFS('North Moon'!$E$6:$E$13,'North Moon'!$B$6:$B$13,$B24)) | G24: =IF(COUNTIFS('North Moon'!$B$6:$B$13,$B24,'North Moon'!$F$6:$F$13,"<>")=0,"",SUMIFS('North Moon'!$F$6:$F$13,'North Moon'!$B$6:$B$13,$B24)) | H24: =IF(COUNTIFS('North Ocean'!$B$6:$B$17,$B24,'North Ocean'!$E$6:$E$17,"<>")=0,"",SUMIFS('North Ocean'!$E$6:$E$17,'North Ocean'!$B$6:$B$17,$B24)) | I24: =IF(COUNTIFS('North Ocean'!$B$6:$B$17,$B24,'North Ocean'!$F$6:$F$17,"<>")=0,"",SUMIFS('North Ocean'!$F$6:$F$17,'North Ocean'!$B$6:$B$17,$B24)) | J24: =IF(COUNTIFS('North Valley'!$B$6:$B$22,$B24,'North Valley'!$E$6:$E$22,"<>")=0,"",SUMIFS('North Valley'!$E$6:$E$22,'North Valley'!$B$6:$B$22,$B24)) -> 102 | K24: =IF(COUNTIFS('North Valley'!$B$6:$B$22,$B24,'North Valley'!$F$6:$F$22,"<>")=0,"",SUMIFS('North Valley'!$F$6:$F$22,'North Valley'!$B$6:$B$22,$B24)) -> 90 | L24: =SUM(E24,G24,I24,K24) -> 90
A25: 17 | B25: MULTIS EP 2 | C25: KG | D25: =IF(COUNTIFS('North Light'!$B$6:$B$38,$B25,'North Light'!$E$6:$E$38,"<>")=0,"",SUMIFS('North Light'!$E$6:$E$38,'North Light'!$B$6:$B$38,$B25)) | E25: =IF(COUNTIFS('North Light'!$B$6:$B$38,$B25,'North Light'!$F$6:$F$38,"<>")=0,"",SUMIFS('North Light'!$F$6:$F$38,'North Light'!$B$6:$B$38,$B25)) -> 54 | F25: =IF(COUNTIFS('North Moon'!$B$6:$B$13,$B25,'North Moon'!$E$6:$E$13,"<>")=0,"",SUMIFS('North Moon'!$E$6:$E$13,'North Moon'!$B$6:$B$13,$B25)) | G25: =IF(COUNTIFS('North Moon'!$B$6:$B$13,$B25,'North Moon'!$F$6:$F$13,"<>")=0,"",SUMIFS('North Moon'!$F$6:$F$13,'North Moon'!$B$6:$B$13,$B25)) | H25: =IF(COUNTIFS('North Ocean'!$B$6:$B$17,$B25,'North Ocean'!$E$6:$E$17,"<>")=0,"",SUMIFS('North Ocean'!$E$6:$E$17,'North Ocean'!$B$6:$B$17,$B25)) | I25: =IF(COUNTIFS('North Ocean'!$B$6:$B$17,$B25,'North Ocean'!$F$6:$F$17,"<>")=0,"",SUMIFS('North Ocean'!$F$6:$F$17,'North Ocean'!$B$6:$B$17,$B25)) | J25: =IF(COUNTIFS('North Valley'!$B$6:$B$22,$B25,'North Valley'!$E$6:$E$22,"<>")=0,"",SUMIFS('North Valley'!$E$6:$E$22,'North Valley'!$B$6:$B$22,$B25)) | K25: =IF(COUNTIFS('North Valley'!$B$6:$B$22,$B25,'North Valley'!$F$6:$F$22,"<>")=0,"",SUMIFS('North Valley'!$F$6:$F$22,'North Valley'!$B$6:$B$22,$B25)) | L25: =SUM(E25,G25,I25,K25) -> 54
A26: 18 | B26: PRESLIA 100 | C26: L | D26: =IF(COUNTIFS('North Light'!$B$6:$B$38,$B26,'North Light'!$E$6:$E$38,"<>")=0,"",SUMIFS('North Light'!$E$6:$E$38,'North Light'!$B$6:$B$38,$B26)) | E26: =IF(COUNTIFS('North Light'!$B$6:$B$38,$B26,'North Light'!$F$6:$F$38,"<>")=0,"",SUMIFS('North Light'!$F$6:$F$38,'North Light'!$B$6:$B$38,$B26)) | F26: =IF(COUNTIFS('North Moon'!$B$6:$B$13,$B26,'North Moon'!$E$6:$E$13,"<>")=0,"",SUMIFS('North Moon'!$E$6:$E$13,'North Moon'!$B$6:$B$13,$B26)) | G26: =IF(COUNTIFS('North Moon'!$B$6:$B$13,$B26,'North Moon'!$F$6:$F$13,"<>")=0,"",SUMIFS('North Moon'!$F$6:$F$13,'North Moon'!$B$6:$B$13,$B26)) | H26: =IF(COUNTIFS('North Ocean'!$B$6:$B$17,$B26,'North Ocean'!$E$6:$E$17,"<>")=0,"",SUMIFS('North Ocean'!$E$6:$E$17,'North Ocean'!$B$6:$B$17,$B26)) -> 1400 | I26: =IF(COUNTIFS('North Ocean'!$B$6:$B$17,$B26,'North Ocean'!$F$6:$F$17,"<>")=0,"",SUMIFS('North Ocean'!$F$6:$F$17,'North Ocean'!$B$6:$B$17,$B26)) -> 400 | J26: =IF(COUNTIFS('North Valley'!$B$6:$B$22,$B26,'North Valley'!$E$6:$E$22,"<>")=0,"",SUMIFS('North Valley'!$E$6:$E$22,'North Valley'!$B$6:$B$22,$B26)) | K26: =IF(COUNTIFS('North Valley'!$B$6:$B$22,$B26,'North Valley'!$F$6:$F$22,"<>")=0,"",SUMIFS('North Valley'!$F$6:$F$22,'North Valley'!$B$6:$B$22,$B26)) | L26: =SUM(E26,G26,I26,K26) -> 400
A27: 19 | B27: SHELL GADUS S5 V42P 2.5 | C27: KG | D27: =IF(COUNTIFS('North Light'!$B$6:$B$38,$B27,'North Light'!$E$6:$E$38,"<>")=0,"",SUMIFS('North Light'!$E$6:$E$38,'North Light'!$B$6:$B$38,$B27)) | E27: =IF(COUNTIFS('North Light'!$B$6:$B$38,$B27,'North Light'!$F$6:$F$38,"<>")=0,"",SUMIFS('North Light'!$F$6:$F$38,'North Light'!$B$6:$B$38,$B27)) | F27: =IF(COUNTIFS('North Moon'!$B$6:$B$13,$B27,'North Moon'!$E$6:$E$13,"<>")=0,"",SUMIFS('North Moon'!$E$6:$E$13,'North Moon'!$B$6:$B$13,$B27)) | G27: =IF(COUNTIFS('North Moon'!$B$6:$B$13,$B27,'North Moon'!$F$6:$F$13,"<>")=0,"",SUMIFS('North Moon'!$F$6:$F$13,'North Moon'!$B$6:$B$13,$B27)) | H27: =IF(COUNTIFS('North Ocean'!$B$6:$B$17,$B27,'North Ocean'!$E$6:$E$17,"<>")=0,"",SUMIFS('North Ocean'!$E$6:$E$17,'North Ocean'!$B$6:$B$17,$B27)) | I27: =IF(COUNTIFS('North Ocean'!$B$6:$B$17,$B27,'North Ocean'!$F$6:$F$17,"<>")=0,"",SUMIFS('North Ocean'!$F$6:$F$17,'North Ocean'!$B$6:$B$17,$B27)) | J27: =IF(COUNTIFS('North Valley'!$B$6:$B$22,$B27,'North Valley'!$E$6:$E$22,"<>")=0,"",SUMIFS('North Valley'!$E$6:$E$22,'North Valley'!$B$6:$B$22,$B27)) -> 0 | K27: =IF(COUNTIFS('North Valley'!$B$6:$B$22,$B27,'North Valley'!$F$6:$F$22,"<>")=0,"",SUMIFS('North Valley'!$F$6:$F$22,'North Valley'!$B$6:$B$22,$B27)) -> 1.9 | L27: =SUM(E27,G27,I27,K27) -> 1.9 | M27: Valley: 5 tube × 380g
A28: 20 | B28: TALUSIA HD 40 | C28: L | D28: =IF(COUNTIFS('North Light'!$B$6:$B$38,$B28,'North Light'!$E$6:$E$38,"<>")=0,"",SUMIFS('North Light'!$E$6:$E$38,'North Light'!$B$6:$B$38,$B28)) -> 25680 | E28: =IF(COUNTIFS('North Light'!$B$6:$B$38,$B28,'North Light'!$F$6:$F$38,"<>")=0,"",SUMIFS('North Light'!$F$6:$F$38,'North Light'!$B$6:$B$38,$B28)) -> 21000 | F28: =IF(COUNTIFS('North Moon'!$B$6:$B$13,$B28,'North Moon'!$E$6:$E$13,"<>")=0,"",SUMIFS('North Moon'!$E$6:$E$13,'North Moon'!$B$6:$B$13,$B28)) -> 25080 | G28: =IF(COUNTIFS('North Moon'!$B$6:$B$13,$B28,'North Moon'!$F$6:$F$13,"<>")=0,"",SUMIFS('North Moon'!$F$6:$F$13,'North Moon'!$B$6:$B$13,$B28)) -> 30000 | H28: =IF(COUNTIFS('North Ocean'!$B$6:$B$17,$B28,'North Ocean'!$E$6:$E$17,"<>")=0,"",SUMIFS('North Ocean'!$E$6:$E$17,'North Ocean'!$B$6:$B$17,$B28)) | I28: =IF(COUNTIFS('North Ocean'!$B$6:$B$17,$B28,'North Ocean'!$F$6:$F$17,"<>")=0,"",SUMIFS('North Ocean'!$F$6:$F$17,'North Ocean'!$B$6:$B$17,$B28)) -> 15000 | J28: =IF(COUNTIFS('North Valley'!$B$6:$B$22,$B28,'North Valley'!$E$6:$E$22,"<>")=0,"",SUMIFS('North Valley'!$E$6:$E$22,'North Valley'!$B$6:$B$22,$B28)) -> 19500 | K28: =IF(COUNTIFS('North Valley'!$B$6:$B$22,$B28,'North Valley'!$F$6:$F$22,"<>")=0,"",SUMIFS('North Valley'!$F$6:$F$22,'North Valley'!$B$6:$B$22,$B28)) -> 45000 | L28: =SUM(E28,G28,I28,K28) -> 111000 | M28: M/E CYLINDER OIL. Light ROB = 3개 탱크 합계
A29: 21 | B29: TMC AEON TH 9000 | C29: L | D29: =IF(COUNTIFS('North Light'!$B$6:$B$38,$B29,'North Light'!$E$6:$E$38,"<>")=0,"",SUMIFS('North Light'!$E$6:$E$38,'North Light'!$B$6:$B$38,$B29)) | E29: =IF(COUNTIFS('North Light'!$B$6:$B$38,$B29,'North Light'!$F$6:$F$38,"<>")=0,"",SUMIFS('North Light'!$F$6:$F$38,'North Light'!$B$6:$B$38,$B29)) | F29: =IF(COUNTIFS('North Moon'!$B$6:$B$13,$B29,'North Moon'!$E$6:$E$13,"<>")=0,"",SUMIFS('North Moon'!$E$6:$E$13,'North Moon'!$B$6:$B$13,$B29)) -> 130 | G29: =IF(COUNTIFS('North Moon'!$B$6:$B$13,$B29,'North Moon'!$F$6:$F$13,"<>")=0,"",SUMIFS('North Moon'!$F$6:$F$13,'North Moon'!$B$6:$B$13,$B29)) -> 100 | H29: =IF(COUNTIFS('North Ocean'!$B$6:$B$17,$B29,'North Ocean'!$E$6:$E$17,"<>")=0,"",SUMIFS('North Ocean'!$E$6:$E$17,'North Ocean'!$B$6:$B$17,$B29)) -> 70 | I29: =IF(COUNTIFS('North Ocean'!$B$6:$B$17,$B29,'North Ocean'!$F$6:$F$17,"<>")=0,"",SUMIFS('North Ocean'!$F$6:$F$17,'North Ocean'!$B$6:$B$17,$B29)) -> 120 | J29: =IF(COUNTIFS('North Valley'!$B$6:$B$22,$B29,'North Valley'!$E$6:$E$22,"<>")=0,"",SUMIFS('North Valley'!$E$6:$E$22,'North Valley'!$B$6:$B$22,$B29)) -> 70 | K29: =IF(COUNTIFS('North Valley'!$B$6:$B$22,$B29,'North Valley'!$F$6:$F$22,"<>")=0,"",SUMIFS('North Valley'!$F$6:$F$22,'North Valley'!$B$6:$B$22,$B29)) -> 75.6 | L29: =SUM(E29,G29,I29,K29) -> 295.6 | M29: Gardner Denver AEON 9000 / NITROGEN COMPRESSOR (Valley: 단종 표기). Moon 값은 원본 Quantity/ROB 확인 필요
A31: ■ 청구 없음 – CHART/재고에만 있는 품목 (16) – 이름순
A32: 1 | B32: ATLANTA MARINE D 3005 | C32: L | D32: =IF(COUNTIFS('North Light'!$B$6:$B$38,$B32,'North Light'!$E$6:$E$38,"<>")=0,"",SUMIFS('North Light'!$E$6:$E$38,'North Light'!$B$6:$B$38,$B32)) | E32: =IF(COUNTIFS('North Light'!$B$6:$B$38,$B32,'North Light'!$F$6:$F$38,"<>")=0,"",SUMIFS('North Light'!$F$6:$F$38,'North Light'!$B$6:$B$38,$B32)) | F32: =IF(COUNTIFS('North Moon'!$B$6:$B$13,$B32,'North Moon'!$E$6:$E$13,"<>")=0,"",SUMIFS('North Moon'!$E$6:$E$13,'North Moon'!$B$6:$B$13,$B32)) | G32: =IF(COUNTIFS('North Moon'!$B$6:$B$13,$B32,'North Moon'!$F$6:$F$13,"<>")=0,"",SUMIFS('North Moon'!$F$6:$F$13,'North Moon'!$B$6:$B$13,$B32)) | H32: =IF(COUNTIFS('North Ocean'!$B$6:$B$17,$B32,'North Ocean'!$E$6:$E$17,"<>")=0,"",SUMIFS('North Ocean'!$E$6:$E$17,'North Ocean'!$B$6:$B$17,$B32)) | I32: =IF(COUNTIFS('North Ocean'!$B$6:$B$17,$B32,'North Ocean'!$F$6:$F$17,"<>")=0,"",SUMIFS('North Ocean'!$F$6:$F$17,'North Ocean'!$B$6:$B$17,$B32)) | J32: =IF(COUNTIFS('North Valley'!$B$6:$B$22,$B32,'North Valley'!$E$6:$E$22,"<>")=0,"",SUMIFS('North Valley'!$E$6:$E$22,'North Valley'!$B$6:$B$22,$B32)) | K32: =IF(COUNTIFS('North Valley'!$B$6:$B$22,$B32,'North Valley'!$F$6:$F$22,"<>")=0,"",SUMIFS('North Valley'!$F$6:$F$22,'North Valley'!$B$6:$B$22,$B32)) | L32: =SUM(E32,G32,I32,K32) -> 0
A33: 2 | B33: AZOLLA AF 46 | C33: L | D33: =IF(COUNTIFS('North Light'!$B$6:$B$38,$B33,'North Light'!$E$6:$E$38,"<>")=0,"",SUMIFS('North Light'!$E$6:$E$38,'North Light'!$B$6:$B$38,$B33)) | E33: =IF(COUNTIFS('North Light'!$B$6:$B$38,$B33,'North Light'!$F$6:$F$38,"<>")=0,"",SUMIFS('North Light'!$F$6:$F$38,'North Light'!$B$6:$B$38,$B33)) | F33: =IF(COUNTIFS('North Moon'!$B$6:$B$13,$B33,'North Moon'!$E$6:$E$13,"<>")=0,"",SUMIFS('North Moon'!$E$6:$E$13,'North Moon'!$B$6:$B$13,$B33)) | G33: =IF(COUNTIFS('North Moon'!$B$6:$B$13,$B33,'North Moon'!$F$6:$F$13,"<>")=0,"",SUMIFS('North Moon'!$F$6:$F$13,'North Moon'!$B$6:$B$13,$B33)) | H33: =IF(COUNTIFS('North Ocean'!$B$6:$B$17,$B33,'North Ocean'!$E$6:$E$17,"<>")=0,"",SUMIFS('North Ocean'!$E$6:$E$17,'North Ocean'!$B$6:$B$17,$B33)) | I33: =IF(COUNTIFS('North Ocean'!$B$6:$B$17,$B33,'North Ocean'!$F$6:$F$17,"<>")=0,"",SUMIFS('North Ocean'!$F$6:$F$17,'North Ocean'!$B$6:$B$17,$B33)) | J33: =IF(COUNTIFS('North Valley'!$B$6:$B$22,$B33,'North Valley'!$E$6:$E$22,"<>")=0,"",SUMIFS('North Valley'!$E$6:$E$22,'North Valley'!$B$6:$B$22,$B33)) | K33: =IF(COUNTIFS('North Valley'!$B$6:$B$22,$B33,'North Valley'!$F$6:$F$22,"<>")=0,"",SUMIFS('North Valley'!$F$6:$F$22,'North Valley'!$B$6:$B$22,$B33)) | L33: =SUM(E33,G33,I33,K33) -> 0
A34: 3 | B34: BIOMULTIS EP 2 | C34: KG | D34: =IF(COUNTIFS('North Light'!$B$6:$B$38,$B34,'North Light'!$E$6:$E$38,"<>")=0,"",SUMIFS('North Light'!$E$6:$E$38,'North Light'!$B$6:$B$38,$B34)) | E34: =IF(COUNTIFS('North Light'!$B$6:$B$38,$B34,'North Light'!$F$6:$F$38,"<>")=0,"",SUMIFS('North Light'!$F$6:$F$38,'North Light'!$B$6:$B$38,$B34)) | F34: =IF(COUNTIFS('North Moon'!$B$6:$B$13,$B34,'North Moon'!$E$6:$E$13,"<>")=0,"",SUMIFS('North Moon'!$E$6:$E$13,'North Moon'!$B$6:$B$13,$B34)) | G34: =IF(COUNTIFS('North Moon'!$B$6:$B$13,$B34,'North Moon'!$F$6:$F$13,"<>")=0,"",SUMIFS('North Moon'!$F$6:$F$13,'North Moon'!$B$6:$B$13,$B34)) | H34: =IF(COUNTIFS('North Ocean'!$B$6:$B$17,$B34,'North Ocean'!$E$6:$E$17,"<>")=0,"",SUMIFS('North Ocean'!$E$6:$E$17,'North Ocean'!$B$6:$B$17,$B34)) | I34: =IF(COUNTIFS('North Ocean'!$B$6:$B$17,$B34,'North Ocean'!$F$6:$F$17,"<>")=0,"",SUMIFS('North Ocean'!$F$6:$F$17,'North Ocean'!$B$6:$B$17,$B34)) | J34: =IF(COUNTIFS('North Valley'!$B$6:$B$22,$B34,'North Valley'!$E$6:$E$22,"<>")=0,"",SUMIFS('North Valley'!$E$6:$E$22,'North Valley'!$B$6:$B$22,$B34)) | K34: =IF(COUNTIFS('North Valley'!$B$6:$B$22,$B34,'North Valley'!$F$6:$F$22,"<>")=0,"",SUMIFS('North Valley'!$F$6:$F$22,'North Valley'!$B$6:$B$22,$B34)) | L34: =SUM(E34,G34,I34,K34) -> 0
A35: 4 | B35: DISOLA M 4015 | C35: L | D35: =IF(COUNTIFS('North Light'!$B$6:$B$38,$B35,'North Light'!$E$6:$E$38,"<>")=0,"",SUMIFS('North Light'!$E$6:$E$38,'North Light'!$B$6:$B$38,$B35)) | E35: =IF(COUNTIFS('North Light'!$B$6:$B$38,$B35,'North Light'!$F$6:$F$38,"<>")=0,"",SUMIFS('North Light'!$F$6:$F$38,'North Light'!$B$6:$B$38,$B35)) | F35: =IF(COUNTIFS('North Moon'!$B$6:$B$13,$B35,'North Moon'!$E$6:$E$13,"<>")=0,"",SUMIFS('North Moon'!$E$6:$E$13,'North Moon'!$B$6:$B$13,$B35)) | G35: =IF(COUNTIFS('North Moon'!$B$6:$B$13,$B35,'North Moon'!$F$6:$F$13,"<>")=0,"",SUMIFS('North Moon'!$F$6:$F$13,'North Moon'!$B$6:$B$13,$B35)) | H35: =IF(COUNTIFS('North Ocean'!$B$6:$B$17,$B35,'North Ocean'!$E$6:$E$17,"<>")=0,"",SUMIFS('North Ocean'!$E$6:$E$17,'North Ocean'!$B$6:$B$17,$B35)) | I35: =IF(COUNTIFS('North Ocean'!$B$6:$B$17,$B35,'North Ocean'!$F$6:$F$17,"<>")=0,"",SUMIFS('North Ocean'!$F$6:$F$17,'North Ocean'!$B$6:$B$17,$B35)) | J35: =IF(COUNTIFS('North Valley'!$B$6:$B$22,$B35,'North Valley'!$E$6:$E$22,"<>")=0,"",SUMIFS('North Valley'!$E$6:$E$22,'North Valley'!$B$6:$B$22,$B35)) | K35: =IF(COUNTIFS('North Valley'!$B$6:$B$22,$B35,'North Valley'!$F$6:$F$22,"<>")=0,"",SUMIFS('North Valley'!$F$6:$F$22,'North Valley'!$B$6:$B$22,$B35)) | L35: =SUM(E35,G35,I35,K35) -> 0
A36: 5 | B36: DISOLA W 15W40 | C36: L | D36: =IF(COUNTIFS('North Light'!$B$6:$B$38,$B36,'North Light'!$E$6:$E$38,"<>")=0,"",SUMIFS('North Light'!$E$6:$E$38,'North Light'!$B$6:$B$38,$B36)) | E36: =IF(COUNTIFS('North Light'!$B$6:$B$38,$B36,'North Light'!$F$6:$F$38,"<>")=0,"",SUMIFS('North Light'!$F$6:$F$38,'North Light'!$B$6:$B$38,$B36)) | F36: =IF(COUNTIFS('North Moon'!$B$6:$B$13,$B36,'North Moon'!$E$6:$E$13,"<>")=0,"",SUMIFS('North Moon'!$E$6:$E$13,'North Moon'!$B$6:$B$13,$B36)) | G36: =IF(COUNTIFS('North Moon'!$B$6:$B$13,$B36,'North Moon'!$F$6:$F$13,"<>")=0,"",SUMIFS('North Moon'!$F$6:$F$13,'North Moon'!$B$6:$B$13,$B36)) | H36: =IF(COUNTIFS('North Ocean'!$B$6:$B$17,$B36,'North Ocean'!$E$6:$E$17,"<>")=0,"",SUMIFS('North Ocean'!$E$6:$E$17,'North Ocean'!$B$6:$B$17,$B36)) | I36: =IF(COUNTIFS('North Ocean'!$B$6:$B$17,$B36,'North Ocean'!$F$6:$F$17,"<>")=0,"",SUMIFS('North Ocean'!$F$6:$F$17,'North Ocean'!$B$6:$B$17,$B36)) | J36: =IF(COUNTIFS('North Valley'!$B$6:$B$22,$B36,'North Valley'!$E$6:$E$22,"<>")=0,"",SUMIFS('North Valley'!$E$6:$E$22,'North Valley'!$B$6:$B$22,$B36)) | K36: =IF(COUNTIFS('North Valley'!$B$6:$B$22,$B36,'North Valley'!$F$6:$F$22,"<>")=0,"",SUMIFS('North Valley'!$F$6:$F$22,'North Valley'!$B$6:$B$22,$B36)) | L36: =SUM(E36,G36,I36,K36) -> 0
A37: 6 | B37: KOBELCO KL-435-46 | C37: L | D37: =IF(COUNTIFS('North Light'!$B$6:$B$38,$B37,'North Light'!$E$6:$E$38,"<>")=0,"",SUMIFS('North Light'!$E$6:$E$38,'North Light'!$B$6:$B$38,$B37)) | E37: =IF(COUNTIFS('North Light'!$B$6:$B$38,$B37,'North Light'!$F$6:$F$38,"<>")=0,"",SUMIFS('North Light'!$F$6:$F$38,'North Light'!$B$6:$B$38,$B37)) | F37: =IF(COUNTIFS('North Moon'!$B$6:$B$13,$B37,'North Moon'!$E$6:$E$13,"<>")=0,"",SUMIFS('North Moon'!$E$6:$E$13,'North Moon'!$B$6:$B$13,$B37)) | G37: =IF(COUNTIFS('North Moon'!$B$6:$B$13,$B37,'North Moon'!$F$6:$F$13,"<>")=0,"",SUMIFS('North Moon'!$F$6:$F$13,'North Moon'!$B$6:$B$13,$B37)) | H37: =IF(COUNTIFS('North Ocean'!$B$6:$B$17,$B37,'North Ocean'!$E$6:$E$17,"<>")=0,"",SUMIFS('North Ocean'!$E$6:$E$17,'North Ocean'!$B$6:$B$17,$B37)) | I37: =IF(COUNTIFS('North Ocean'!$B$6:$B$17,$B37,'North Ocean'!$F$6:$F$17,"<>")=0,"",SUMIFS('North Ocean'!$F$6:$F$17,'North Ocean'!$B$6:$B$17,$B37)) | J37: =IF(COUNTIFS('North Valley'!$B$6:$B$22,$B37,'North Valley'!$E$6:$E$22,"<>")=0,"",SUMIFS('North Valley'!$E$6:$E$22,'North Valley'!$B$6:$B$22,$B37)) | K37: =IF(COUNTIFS('North Valley'!$B$6:$B$22,$B37,'North Valley'!$F$6:$F$22,"<>")=0,"",SUMIFS('North Valley'!$F$6:$F$22,'North Valley'!$B$6:$B$22,$B37)) | L37: =SUM(E37,G37,I37,K37) -> 0
A38: 7 | B38: LOCTITE 8104 | C38: KG | D38: =IF(COUNTIFS('North Light'!$B$6:$B$38,$B38,'North Light'!$E$6:$E$38,"<>")=0,"",SUMIFS('North Light'!$E$6:$E$38,'North Light'!$B$6:$B$38,$B38)) | E38: =IF(COUNTIFS('North Light'!$B$6:$B$38,$B38,'North Light'!$F$6:$F$38,"<>")=0,"",SUMIFS('North Light'!$F$6:$F$38,'North Light'!$B$6:$B$38,$B38)) | F38: =IF(COUNTIFS('North Moon'!$B$6:$B$13,$B38,'North Moon'!$E$6:$E$13,"<>")=0,"",SUMIFS('North Moon'!$E$6:$E$13,'North Moon'!$B$6:$B$13,$B38)) | G38: =IF(COUNTIFS('North Moon'!$B$6:$B$13,$B38,'North Moon'!$F$6:$F$13,"<>")=0,"",SUMIFS('North Moon'!$F$6:$F$13,'North Moon'!$B$6:$B$13,$B38)) | H38: =IF(COUNTIFS('North Ocean'!$B$6:$B$17,$B38,'North Ocean'!$E$6:$E$17,"<>")=0,"",SUMIFS('North Ocean'!$E$6:$E$17,'North Ocean'!$B$6:$B$17,$B38)) | I38: =IF(COUNTIFS('North Ocean'!$B$6:$B$17,$B38,'North Ocean'!$F$6:$F$17,"<>")=0,"",SUMIFS('North Ocean'!$F$6:$F$17,'North Ocean'!$B$6:$B$17,$B38)) | J38: =IF(COUNTIFS('North Valley'!$B$6:$B$22,$B38,'North Valley'!$E$6:$E$22,"<>")=0,"",SUMIFS('North Valley'!$E$6:$E$22,'North Valley'!$B$6:$B$22,$B38)) | K38: =IF(COUNTIFS('North Valley'!$B$6:$B$22,$B38,'North Valley'!$F$6:$F$22,"<>")=0,"",SUMIFS('North Valley'!$F$6:$F$22,'North Valley'!$B$6:$B$22,$B38)) | L38: =SUM(E38,G38,I38,K38) -> 0
A39: 8 | B39: LOCTITE 8150 | C39: KG | D39: =IF(COUNTIFS('North Light'!$B$6:$B$38,$B39,'North Light'!$E$6:$E$38,"<>")=0,"",SUMIFS('North Light'!$E$6:$E$38,'North Light'!$B$6:$B$38,$B39)) | E39: =IF(COUNTIFS('North Light'!$B$6:$B$38,$B39,'North Light'!$F$6:$F$38,"<>")=0,"",SUMIFS('North Light'!$F$6:$F$38,'North Light'!$B$6:$B$38,$B39)) | F39: =IF(COUNTIFS('North Moon'!$B$6:$B$13,$B39,'North Moon'!$E$6:$E$13,"<>")=0,"",SUMIFS('North Moon'!$E$6:$E$13,'North Moon'!$B$6:$B$13,$B39)) | G39: =IF(COUNTIFS('North Moon'!$B$6:$B$13,$B39,'North Moon'!$F$6:$F$13,"<>")=0,"",SUMIFS('North Moon'!$F$6:$F$13,'North Moon'!$B$6:$B$13,$B39)) | H39: =IF(COUNTIFS('North Ocean'!$B$6:$B$17,$B39,'North Ocean'!$E$6:$E$17,"<>")=0,"",SUMIFS('North Ocean'!$E$6:$E$17,'North Ocean'!$B$6:$B$17,$B39)) | I39: =IF(COUNTIFS('North Ocean'!$B$6:$B$17,$B39,'North Ocean'!$F$6:$F$17,"<>")=0,"",SUMIFS('North Ocean'!$F$6:$F$17,'North Ocean'!$B$6:$B$17,$B39)) | J39: =IF(COUNTIFS('North Valley'!$B$6:$B$22,$B39,'North Valley'!$E$6:$E$22,"<>")=0,"",SUMIFS('North Valley'!$E$6:$E$22,'North Valley'!$B$6:$B$22,$B39)) | K39: =IF(COUNTIFS('North Valley'!$B$6:$B$22,$B39,'North Valley'!$F$6:$F$22,"<>")=0,"",SUMIFS('North Valley'!$F$6:$F$22,'North Valley'!$B$6:$B$22,$B39)) | L39: =SUM(E39,G39,I39,K39) -> 0
A40: 9 | B40: PLANETELF ACD 46 | C40: L | D40: =IF(COUNTIFS('North Light'!$B$6:$B$38,$B40,'North Light'!$E$6:$E$38,"<>")=0,"",SUMIFS('North Light'!$E$6:$E$38,'North Light'!$B$6:$B$38,$B40)) | E40: =IF(COUNTIFS('North Light'!$B$6:$B$38,$B40,'North Light'!$F$6:$F$38,"<>")=0,"",SUMIFS('North Light'!$F$6:$F$38,'North Light'!$B$6:$B$38,$B40)) | F40: =IF(COUNTIFS('North Moon'!$B$6:$B$13,$B40,'North Moon'!$E$6:$E$13,"<>")=0,"",SUMIFS('North Moon'!$E$6:$E$13,'North Moon'!$B$6:$B$13,$B40)) | G40: =IF(COUNTIFS('North Moon'!$B$6:$B$13,$B40,'North Moon'!$F$6:$F$13,"<>")=0,"",SUMIFS('North Moon'!$F$6:$F$13,'North Moon'!$B$6:$B$13,$B40)) | H40: =IF(COUNTIFS('North Ocean'!$B$6:$B$17,$B40,'North Ocean'!$E$6:$E$17,"<>")=0,"",SUMIFS('North Ocean'!$E$6:$E$17,'North Ocean'!$B$6:$B$17,$B40)) | I40: =IF(COUNTIFS('North Ocean'!$B$6:$B$17,$B40,'North Ocean'!$F$6:$F$17,"<>")=0,"",SUMIFS('North Ocean'!$F$6:$F$17,'North Ocean'!$B$6:$B$17,$B40)) | J40: =IF(COUNTIFS('North Valley'!$B$6:$B$22,$B40,'North Valley'!$E$6:$E$22,"<>")=0,"",SUMIFS('North Valley'!$E$6:$E$22,'North Valley'!$B$6:$B$22,$B40)) | K40: =IF(COUNTIFS('North Valley'!$B$6:$B$22,$B40,'North Valley'!$F$6:$F$22,"<>")=0,"",SUMIFS('North Valley'!$F$6:$F$22,'North Valley'!$B$6:$B$22,$B40)) | L40: =SUM(E40,G40,I40,K40) -> 0
A41: 10 | B41: PLANETELF ACD 68 | C41: L | D41: =IF(COUNTIFS('North Light'!$B$6:$B$38,$B41,'North Light'!$E$6:$E$38,"<>")=0,"",SUMIFS('North Light'!$E$6:$E$38,'North Light'!$B$6:$B$38,$B41)) | E41: =IF(COUNTIFS('North Light'!$B$6:$B$38,$B41,'North Light'!$F$6:$F$38,"<>")=0,"",SUMIFS('North Light'!$F$6:$F$38,'North Light'!$B$6:$B$38,$B41)) | F41: =IF(COUNTIFS('North Moon'!$B$6:$B$13,$B41,'North Moon'!$E$6:$E$13,"<>")=0,"",SUMIFS('North Moon'!$E$6:$E$13,'North Moon'!$B$6:$B$13,$B41)) | G41: =IF(COUNTIFS('North Moon'!$B$6:$B$13,$B41,'North Moon'!$F$6:$F$13,"<>")=0,"",SUMIFS('North Moon'!$F$6:$F$13,'North Moon'!$B$6:$B$13,$B41)) | H41: =IF(COUNTIFS('North Ocean'!$B$6:$B$17,$B41,'North Ocean'!$E$6:$E$17,"<>")=0,"",SUMIFS('North Ocean'!$E$6:$E$17,'North Ocean'!$B$6:$B$17,$B41)) | I41: =IF(COUNTIFS('North Ocean'!$B$6:$B$17,$B41,'North Ocean'!$F$6:$F$17,"<>")=0,"",SUMIFS('North Ocean'!$F$6:$F$17,'North Ocean'!$B$6:$B$17,$B41)) | J41: =IF(COUNTIFS('North Valley'!$B$6:$B$22,$B41,'North Valley'!$E$6:$E$22,"<>")=0,"",SUMIFS('North Valley'!$E$6:$E$22,'North Valley'!$B$6:$B$22,$B41)) | K41: =IF(COUNTIFS('North Valley'!$B$6:$B$22,$B41,'North Valley'!$F$6:$F$22,"<>")=0,"",SUMIFS('North Valley'!$F$6:$F$22,'North Valley'!$B$6:$B$22,$B41)) | L41: =SUM(E41,G41,I41,K41) -> 0
A42: 11 | B42: PRESLIA 32 | C42: L | D42: =IF(COUNTIFS('North Light'!$B$6:$B$38,$B42,'North Light'!$E$6:$E$38,"<>")=0,"",SUMIFS('North Light'!$E$6:$E$38,'North Light'!$B$6:$B$38,$B42)) | E42: =IF(COUNTIFS('North Light'!$B$6:$B$38,$B42,'North Light'!$F$6:$F$38,"<>")=0,"",SUMIFS('North Light'!$F$6:$F$38,'North Light'!$B$6:$B$38,$B42)) | F42: =IF(COUNTIFS('North Moon'!$B$6:$B$13,$B42,'North Moon'!$E$6:$E$13,"<>")=0,"",SUMIFS('North Moon'!$E$6:$E$13,'North Moon'!$B$6:$B$13,$B42)) | G42: =IF(COUNTIFS('North Moon'!$B$6:$B$13,$B42,'North Moon'!$F$6:$F$13,"<>")=0,"",SUMIFS('North Moon'!$F$6:$F$13,'North Moon'!$B$6:$B$13,$B42)) | H42: =IF(COUNTIFS('North Ocean'!$B$6:$B$17,$B42,'North Ocean'!$E$6:$E$17,"<>")=0,"",SUMIFS('North Ocean'!$E$6:$E$17,'North Ocean'!$B$6:$B$17,$B42)) | I42: =IF(COUNTIFS('North Ocean'!$B$6:$B$17,$B42,'North Ocean'!$F$6:$F$17,"<>")=0,"",SUMIFS('North Ocean'!$F$6:$F$17,'North Ocean'!$B$6:$B$17,$B42)) | J42: =IF(COUNTIFS('North Valley'!$B$6:$B$22,$B42,'North Valley'!$E$6:$E$22,"<>")=0,"",SUMIFS('North Valley'!$E$6:$E$22,'North Valley'!$B$6:$B$22,$B42)) | K42: =IF(COUNTIFS('North Valley'!$B$6:$B$22,$B42,'North Valley'!$F$6:$F$22,"<>")=0,"",SUMIFS('North Valley'!$F$6:$F$22,'North Valley'!$B$6:$B$22,$B42)) | L42: =SUM(E42,G42,I42,K42) -> 0
...

Sheet North Light
A1: NORTH LIGHT – LUB OIL REQUISITION
A2: Source: 1. Lub oil Initial supply list (North Light) – 장비별 행을 품목 단위로 통합. TOTAL Q'TY NEEDED 기재 품목만 청구, 나머지는 '청구 없음'.
A3: REQ = 청구(필요) 수량, 표준단위(L/KG) 환산값. CAN 단위는 '통합 청구' C3/C4 환산값 사용. 파란색 = 원본 입력값, 검정 = 수식.
A5: No. | B5: Item (Lub Oil / Grease) | C5: Equipment / Use | D5: Unit | E5: ROB | F5: REQ | G5: Original entry | H5: Remarks
A6: ■ 청구 품목 (10)
A7: 1 | B7: BARELF CH 100 | C7: Main air compressor | D7: L | F7: =8*'통합 청구'!$C$3 -> 160 | G7: 8 CAN | H7: 1 can/month
A8: 2 | B8: BARELF SM 46 | C8: Control/Service air compressor | D8: L | F8: =6*'통합 청구'!$C$3 -> 120 | G8: 6 CAN | H8: 40 ltr/set
A9: 3 | B9: BIOADHESIVE PLUS | C9: STEERING GEAR, EMERGENCY TOWING SYSTEM & ESCORTING PULL BACK SYSTEM | D9: KG | F9: 108 | G9: 108 KG (6 CAN) | H9: 1 can/month
A10: 4 | B10: CARTER SH 150 | C10: windlass/winch gear box gear oil | D10: L | F10: =9*'통합 청구'!$C$3 -> 180 | G10: 9 CAN | H10: each gear box 30~35ltr
A11: 5 | B11: CERAN XM 220 | C11: DECK MACHINERY, HOSE HANDLING CRANE, PROVISION CRANE 외 11건 | D11: KG | F11: 108 | G11: 108 KG (6 CAN) | H11: 1 can/month
A12: 6 | B12: ELFMATIC G3 | C12: life boat davit gear box oil | D12: L | F12: =2*'통합 청구'!$C$3 -> 40 | G12: 2 CAN | H12: Nil
A13: 7 | B13: EPONA SA 220 | C13: GE LO PURIFIER | D13: L | F13: 40 | G13: 40 L (20L/CAN) | H13: FOR DECK EQUIPMENTS GEAR BOX OIL
A14: 8 | B14: EPONA Z 460 | C14: GE turning gear | D14: L | F14: =2*'통합 청구'!$C$3 -> 40 | G14: 2 CAN
A15: 9 | B15: MULTIS EP 2 | C15: General propose | D15: KG | F15: =3*'통합 청구'!$C$4 -> 54 | G15: 3 CAN | H15: 0.5 can/month
A16: 10 | B16: TALUSIA HD 40 | C16: MAIN ENGINE | D16: L | E16: =21250+740+3690 -> 25680 | F16: 21000 | G16: 21000 L | H16: 90% TANK VOLUME; 현재 잔량 #1- 21250ltr, #2- 740ltr, #3- 3690ltr (In use) ※ ROB = 3개 탱크 합계
A17: ■ 청구 없음 – CHART/재고에만 있는 품목 (21)
A18: 1 | B18: ATLANTA MARINE D 3005 | C18: STERN TUBE BEARING AND SEAL, MAIN ENGINE, INTERMEDIATE SHAFT BEARING | D18: L
A19: 2 | B19: AZOLLA AF 46 | C19: VR COMPRESSOR | D19: L
A20: 3 | B20: BIOMULTIS EP 2 | C20: PROPELLER CAP | D20: KG
A21: 4 | B21: CERAN AD PLUS | C21: DECK MACHINERY, AUX. BOILER, EGE 외 10건 | D21: KG
A22: 5 | B22: DACNIS 100 | C22: MAIN AIR COMPRESSOR | D22: L
A23: 6 | B23: DISOLA M 4015 | C23: GENERATOR ENGINE | D23: L
A24: 7 | B24: DISOLA W 15W40 | C24: EMERGENCY GENERATOR, LIFE/RESCUE BOAT WITH ENGINE, EMERGENCY TOWING SYSTEM & | D24: L
A25: 8 | B25: EPONA Z 220 | C25: LIFE/RESCUE BOAT WITH ENGINE, DECK MACHINERY, EMERGENCY TOWING SYSTEM & ESCORTING PULL BACK SYSTEM 외 12건 | D25: L
A26: 9 | B26: KOBELCO KL-435-46 | C26: FG COMPRESSOR I & FG COMPRESSOR II, FG COMPRESSOR I, FG COMPRESSOR II | D26: L
A27: 10 | B27: LOCTITE 8104 | C27: VR COMPRESSOR ASSEMBLY | D27: KG | H27: PURCHASED AT HELKEL.
A28: 11 | B28: LOCTITE 8150 | C28: VR COMPRESSOR ASSEMBLY | D28: KG | H28: PURCHASED AT HELKEL.
A29: 12 | B29: PLANETELF ACD 46 | C29: PROV. REF. PLANT | D29: L | H29: FIRST CHANGE : ABT. 100~ 200 HOURS
A30: 13 | B30: PLANETELF ACD 68 | C30: AIR-CON. PLANT FOR ACCOM | D30: L
A31: 14 | B31: PRESLIA 32 | C31: MAIN MOTOR LO UNIT FOR FGC I, MAIN MOTOR LO UNIT FOR FGC II | D31: L
A32: 15 | B32: PRESLIA 68 | C32: STEERING GEAR, WATER SPRAY PUMP, NO.1~NO.4 BOILER WATER CIRC. PUMP | D32: L
A33: 16 | B33: PRESLIA 100 | C33: BOG BOOST COMPRESSOR | D33: L
A34: 17 | B34: SHELL GADUS S5 V42P 2.5 | C34: VR COMPRESSOR MOTOR | D34: KG | H34: OIL SUPPLIER: SHELL OIL SUPPLIER : MOBIL OIL SUPPLIER : SKF
A35: 18 | B35: VISGA 15 | C35: WATER DRAIN PUMP FOR SECONDARY, WATER DRAIN PUMP FOR GLYCOL WATER, WATER DRAIN PUMP FOR OILY BILGE FOR 외 3건 | D35: L
A36: 19 | B36: VISGA 32 | C36: DECK MACHINERY, LATHE MACHINE, ME HYD. TOP BRACHING 외 10건 | D36: L | H36: INITIALLY FILLED BY MAKER BUT SHOULD BE REPLACED BEFORE SEA TRIALL; INITIALLY FILLED BY MAKER BUT SHOULD BE REPLACED BEFORE SEA TRIAL; INITIALLY FILLED BY MAKER BUT SHOULD BE REPLACED BEFORE SEA TRIAL; CHANGED FROM RANDO HDZ 22 TO HDZ 32 WITH MAKER, CHEVRON CONFIRMED
A37: 20 | B37: VISGA 46 | C37: HOSE HANDLING CRANE, PROVISION CRANE, CARGO COMPRESSOR ROOM AND ELEC. ROOM CRANE 외 1건 | D37: L | H37: INITIALLY FILLED BY MAKER BUT SHULD BE REPLACED BEFORE SEA TRIAL
A38: 21 | B38: VISGA 68 | C38: HFO PURIFIER, ME LO PURIFIER | D38: L

Sheet North Moon
A1: NORTH MOON – LUB OIL REQUISITION
A2: Source: North MOON LUBE OIL.xlsx (Oil & Grease) – 원본 'Quantity (Liters)'를 REQ로 사용.
A3: REQ = 청구(필요) 수량, 표준단위(L/KG) 환산값. CAN 단위는 '통합 청구' C3/C4 환산값 사용. 파란색 = 원본 입력값, 검정 = 수식.
A5: No. | B5: Item (Lub Oil / Grease) | C5: Equipment / Use | D5: Unit | E5: ROB | F5: REQ | G5: Original entry | H5: Remarks
A6: ■ 청구 품목 (5)
A7: 1 | B7: BARELF CH 100 | D7: L | E7: 106 | F7: 200 | G7: 200 Liters
A8: 2 | B8: BARELF SM 46 | D8: L | E8: 120 | F8: 300 | G8: 300 Liters
A9: 3 | B9: ELFMATIC G3 | D9: L | E9: 0 | F9: 20 | G9: 20 Liters
A10: 4 | B10: TALUSIA HD 40 | D10: L | E10: 25080 | F10: 30000 | G10: 30000 Liters | H10: M/E CYLINDER OIL
A11: 5 | B11: TMC AEON TH 9000 | C11: NITROGEN COMPRESSOR | D11: L | E11: 130 | F11: 100 | G11: 100 Liters | H11: ※ 원본: Quantity 100 / ROB 130 (ROB가 더 큼). Valley 파일 Sheet1 에는 ROB 100 / REQ 130 으로 기재 → 확인 필요
A12: ■ 청구 없음 – CHART/재고에만 있는 품목 (0)
B13: (해당 없음 – 원본에 청구 없는 품목 없음)

Sheet North Ocean
A1: NORTH OCEAN – LUB OIL REQUISITION
A2: Source: NORTH OCEAN ER Lub Oil.xlsx – TOTAL Q'TY NEEDED를 REQ로, ROB는 비고란에서 추출.
A3: REQ = 청구(필요) 수량, 표준단위(L/KG) 환산값. CAN 단위는 '통합 청구' C3/C4 환산값 사용. 파란색 = 원본 입력값, 검정 = 수식.
A5: No. | B5: Item (Lub Oil / Grease) | C5: Equipment / Use | D5: Unit | E5: ROB | F5: REQ | G5: Original entry | H5: Remarks
A6: ■ 청구 품목 (9)
A7: 1 | B7: BARELF SM 46 | C7: GS AND CONTROL AIR COMPRESSOR | D7: L | F7: 120 | G7: 120 L
A8: 2 | B8: CARTER SH 150 | C8: DECK MACHINERY | D8: L | E8: 27 | F8: 40 | G8: 40 L | H8: ROB: 27 Lit.
A9: 3 | B9: CERAN AD PLUS | C9: DECK MACHINERY | D9: KG | E9: 27 | F9: 72 | G9: 72 KG | H9: ROB: 27 kg
A10: 4 | B10: CERAN XM 220 | C10: DECK MACHINERY | D10: KG | E10: 52 | F10: 90 | G10: 90 KG | H10: ROB: 52 kg.
A11: 5 | B11: EPONA SA 220 | C11: GE LO PURIFIER | D11: L | E11: 48 | F11: 20 | G11: 20 L | H11: ROB: 48 ltrs. Multipurpose oil for purifiers and deck equipment.
A12: 6 | B12: EPONA Z 460 | C12: OWS DIESEL GENERATOR TURNING GEAR | D12: L | F12: 40 | G12: 40 L
A13: 7 | B13: PRESLIA 100 | C13: BOG BOOST COMPRESSOR (CRANK CASE) | D13: L | E13: 1400 | F13: 400 | G13: 400 L | H13: Initial Sump Charge 1500 Lit present ROB 1400 Lit
A14: 8 | B14: TALUSIA HD 40 | C14: MAIN ENGINE | D14: L | F14: 15000 | G14: 15000 L
A15: 9 | B15: TMC AEON TH 9000 | C15: NITROGEN COMPRESSOR | D15: L | E15: 70 | F15: 120 | G15: 120 L | H15: ROB 70 Lit. Required for scheduled maintenenace
A16: ■ 청구 없음 – CHART/재고에만 있는 품목 (0)
B17: (해당 없음 – 원본에 청구 없는 품목 없음)

Sheet North Valley
A1: NORTH VALLEY – LUB OIL REQUISITION
A2: Source: North Valley Lub. oil requisition.xlsx – Vessel Northvalley | IMO 9958327 | Req. date 2026-09-20 | Port/ETA Yeosu / 2026-09-25 | Requested by Jeonghun Lim (Chief Engineer)
A3: REQ = 청구(필요) 수량, 표준단위(L/KG) 환산값. CAN 단위는 '통합 청구' C3/C4 환산값 사용. 파란색 = 원본 입력값, 검정 = 수식.
A5: No. | B5: Item (Lub Oil / Grease) | C5: Equipment / Use | D5: Unit | E5: ROB | F5: REQ | G5: Original entry | H5: Remarks
A6: ■ 청구 품목 (14)
A7: 1 | B7: BIOADHESIVE PLUS | D7: KG | E7: 140 | F7: =3*18 -> 54 | G7: 3 X 18KG | H7: Brand: TOTAL
A8: 2 | B8: BIOMULTIS EP 0 | D8: KG | E8: 36 | F8: =2*18 -> 36 | G8: 2 X 18KG | H8: Brand: TOTAL
A9: 3 | B9: BSE 170 | D9: L | E9: 130 | F9: 100 | G9: 10 X 10L | H9: Brand: Bitzer
A10: 4 | B10: CERAN XM 220 | D10: KG | E10: 70 | F10: =10*18 -> 180 | G10: 10 X 18KG | H10: Brand: TOTAL
A11: 5 | B11: DACNIS 46 | D11: L | E11: 40 | F11: 160 | G11: 8 X 20L | H11: Brand: TOTAL
A12: 6 | B12: DACNIS 100 | D12: L | E12: 150 | F12: 100 | G12: 5 X 20L | H12: Brand: TOTAL
A13: 7 | B13: EPONA SA 220 | D13: L | E13: 50 | F13: 60 | G13: 3 X 20L | H13: Brand: TOTAL
A14: 8 | B14: EPONA Z 220 | D14: L | E14: 80 | F14: 60 | G14: 3 X 20L | H14: Brand: TOTAL
A15: 9 | B15: EPONA Z 460 | D15: L | E15: 20 | F15: 20 | G15: 1 X 20L | H15: Brand: TOTAL
A16: 10 | B16: MULTIS COMPLEX SHD 100 | D16: KG | E16: 0 | F16: 18 | G16: 1 X 18KG | H16: Brand: TOTAL
A17: 11 | B17: MULTIS COMPLEX SHD 220 | D17: KG | E17: 102 | F17: =5*18 -> 90 | G17: 5 X 18KG | H17: Brand: TOTAL
A18: 12 | B18: SHELL GADUS S5 V42P 2.5 | D18: KG | E18: 0 | F18: =0.38*5 -> 1.9 | G18: 5 X 380g TUBE | H18: Brand: Shell
A19: 13 | B19: TALUSIA HD 40 | D19: L | E19: 19500 | F19: 45000 | G19: BULK 45,000L
A20: 14 | B20: TMC AEON TH 9000 | C20: NITROGEN COMPRESSOR | D20: L | E20: 70 | F20: =4*18.9 -> 75.6 | G20: 4 X 18.9L | H20: Brand: Gardner Denver / TMC AEON TH9000 (단종)
A21: ■ 청구 없음 – CHART/재고에만 있는 품목 (0)
B22: (해당 없음 – 원본에 청구 없는 품목 없음)
